2022-12-14 12:51:16,526 INFO org.apache.hadoop.yarn.server.resourcemanager.ResourceManager: STARTUP_MSG: 
/************************************************************
STARTUP_MSG: Starting ResourceManager
STARTUP_MSG:   host = adh-test-00-mnode1.ru-central1.internal/10.130.0.4
STARTUP_MSG:   args = []
STARTUP_MSG:   version = 3.1.2
STARTUP_MSG:   build = git@ssh.gitlab.adsw.io:arenadata/infrastructure/code/ci/prj_adh.git -r 15525ac41ebda8bc83c285e9b6ea7fb9921fd7fd; compiled by 'jenkins' on 2022-09-08T14:33Z
STARTUP_MSG:   java = 1.8.0_352
************************************************************/
2022-12-14 12:51:16,534 INFO org.apache.hadoop.yarn.server.resourcemanager.ResourceManager: registered UNIX signal handlers for [TERM, HUP, INT]
2022-12-14 12:51:16,707 INFO org.apache.hadoop.conf.Configuration: found resource core-site.xml at file:/etc/hadoop/conf/core-site.xml
2022-12-14 12:51:16,800 INFO org.apache.hadoop.conf.Configuration: resource-types.xml not found
2022-12-14 12:51:16,801 INFO org.apache.hadoop.yarn.util.resource.ResourceUtils: Unable to find 'resource-types.xml'.
2022-12-14 12:51:16,889 INFO org.apache.hadoop.conf.Configuration: found resource yarn-site.xml at file:/etc/hadoop/conf/yarn-site.xml
2022-12-14 12:51:16,928 INFO org.apache.hadoop.yarn.event.AsyncDispatcher: Registering class org.apache.hadoop.yarn.server.resourcemanager.RMFatalEventType for class org.apache.hadoop.yarn.server.resourcemanager.ResourceManager$RMFatalEventDispatcher
2022-12-14 12:51:16,963 INFO org.apache.hadoop.yarn.server.resourcemanager.security.NMTokenSecretManagerInRM: NMTokenKeyRollingInterval: 86400000ms and NMTokenKeyActivationDelay: 900000ms
2022-12-14 12:51:16,967 INFO org.apache.hadoop.yarn.server.resourcemanager.security.RMContainerTokenSecretManager: ContainerTokenKeyRollingInterval: 86400000ms and ContainerTokenKeyActivationDelay: 900000ms
2022-12-14 12:51:16,971 INFO org.apache.hadoop.yarn.server.resourcemanager.security.AMRMTokenSecretManager: AMRMTokenKeyRollingInterval: 86400000ms and AMRMTokenKeyActivationDelay: 900000 ms
2022-12-14 12:51:17,033 INFO org.apache.hadoop.yarn.server.resourcemanager.recovery.RMStateStoreFactory: Using RMStateStore implementation - class org.apache.hadoop.yarn.server.resourcemanager.recovery.LeveldbRMStateStore
2022-12-14 12:51:17,034 INFO org.apache.hadoop.yarn.event.AsyncDispatcher: Registering class org.apache.hadoop.yarn.server.resourcemanager.recovery.RMStateStoreEventType for class org.apache.hadoop.yarn.server.resourcemanager.recovery.RMStateStore$ForwardingEventHandler
2022-12-14 12:51:17,039 INFO org.apache.hadoop.yarn.event.AsyncDispatcher: Registering class org.apache.hadoop.yarn.server.resourcemanager.NodesListManagerEventType for class org.apache.hadoop.yarn.server.resourcemanager.NodesListManager
2022-12-14 12:51:17,039 INFO org.apache.hadoop.yarn.server.resourcemanager.ResourceManager: Using Scheduler: org.apache.hadoop.yarn.server.resourcemanager.scheduler.capacity.CapacityScheduler
2022-12-14 12:51:17,076 INFO org.apache.hadoop.yarn.event.AsyncDispatcher: Registering class org.apache.hadoop.yarn.server.resourcemanager.scheduler.event.SchedulerEventType for class org.apache.hadoop.yarn.event.EventDispatcher
2022-12-14 12:51:17,077 INFO org.apache.hadoop.yarn.event.AsyncDispatcher: Registering class org.apache.hadoop.yarn.server.resourcemanager.rmapp.RMAppEventType for class org.apache.hadoop.yarn.server.resourcemanager.ResourceManager$ApplicationEventDispatcher
2022-12-14 12:51:17,078 INFO org.apache.hadoop.yarn.event.AsyncDispatcher: Registering class org.apache.hadoop.yarn.server.resourcemanager.rmapp.attempt.RMAppAttemptEventType for class org.apache.hadoop.yarn.server.resourcemanager.ResourceManager$ApplicationAttemptEventDispatcher
2022-12-14 12:51:17,079 INFO org.apache.hadoop.yarn.event.AsyncDispatcher: Registering class org.apache.hadoop.yarn.server.resourcemanager.rmnode.RMNodeEventType for class org.apache.hadoop.yarn.server.resourcemanager.ResourceManager$NodeEventDispatcher
2022-12-14 12:51:17,192 WARN org.apache.hadoop.metrics2.impl.MetricsConfig: Cannot locate configuration: tried hadoop-metrics2-resourcemanager.properties,hadoop-metrics2.properties
2022-12-14 12:51:17,209 INFO org.apache.hadoop.metrics2.impl.MetricsSystemImpl: Scheduled Metric snapshot period at 10 second(s).
2022-12-14 12:51:17,209 INFO org.apache.hadoop.metrics2.impl.MetricsSystemImpl: ResourceManager metrics system started
2022-12-14 12:51:17,227 INFO org.apache.hadoop.yarn.security.YarnAuthorizationProvider: org.apache.hadoop.yarn.security.ConfiguredYarnAuthorizer is instantiated.
2022-12-14 12:51:17,229 INFO org.apache.hadoop.yarn.event.AsyncDispatcher: Registering class org.apache.hadoop.yarn.server.resourcemanager.RMAppManagerEventType for class org.apache.hadoop.yarn.server.resourcemanager.RMAppManager
2022-12-14 12:51:17,237 INFO org.apache.hadoop.yarn.event.AsyncDispatcher: Registering class org.apache.hadoop.yarn.server.resourcemanager.amlauncher.AMLauncherEventType for class org.apache.hadoop.yarn.server.resourcemanager.amlauncher.ApplicationMasterLauncher
2022-12-14 12:51:17,239 INFO org.apache.hadoop.yarn.server.resourcemanager.RMNMInfo: Registered RMNMInfo MBean
2022-12-14 12:51:17,239 INFO org.apache.hadoop.yarn.server.resourcemanager.rmapp.monitor.RMAppLifetimeMonitor: Application lifelime monitor interval set to 3000 ms.
2022-12-14 12:51:17,245 INFO org.apache.hadoop.util.HostsFileReader: Refreshing hosts (include/exclude) list
2022-12-14 12:51:17,245 INFO org.apache.hadoop.util.HostsFileReader: Adding a node "adh-test-00-mnode1.ru-central1.internal" to the list of included hosts from /etc/hadoop/conf/include-path
2022-12-14 12:51:17,245 INFO org.apache.hadoop.util.HostsFileReader: Adding a node "adh-test-00-mnode2.ru-central1.internal" to the list of included hosts from /etc/hadoop/conf/include-path
2022-12-14 12:51:17,245 INFO org.apache.hadoop.util.HostsFileReader: Adding a node "adh-test-00-mnode3.ru-central1.internal" to the list of included hosts from /etc/hadoop/conf/include-path
2022-12-14 12:51:17,274 INFO org.apache.hadoop.conf.Configuration: found resource capacity-scheduler.xml at file:/etc/hadoop/conf/capacity-scheduler.xml
2022-12-14 12:51:17,289 INFO org.apache.hadoop.yarn.server.resourcemanager.scheduler.AbstractYarnScheduler: Minimum allocation = <memory:1024, vCores:1>
2022-12-14 12:51:17,289 INFO org.apache.hadoop.yarn.server.resourcemanager.scheduler.AbstractYarnScheduler: Maximum allocation = <memory:4096, vCores:2>
2022-12-14 12:51:17,327 INFO org.apache.hadoop.yarn.server.resourcemanager.scheduler.capacity.CapacitySchedulerConfiguration: max alloc mb per queue for root is undefined
2022-12-14 12:51:17,327 INFO org.apache.hadoop.yarn.server.resourcemanager.scheduler.capacity.CapacitySchedulerConfiguration: max alloc vcore per queue for root is undefined
2022-12-14 12:51:17,337 INFO org.apache.hadoop.yarn.server.resourcemanager.scheduler.capacity.ParentQueue: root, capacity=1.0, absoluteCapacity=1.0, maxCapacity=1.0, absoluteMaxCapacity=1.0, state=RUNNING, acls=ADMINISTER_QUEUE:*SUBMIT_APP:*, labels=*,
, reservationsContinueLooking=true, orderingPolicy=utilization, priority=0
2022-12-14 12:51:17,338 INFO org.apache.hadoop.yarn.server.resourcemanager.scheduler.capacity.ParentQueue: Initialized parent-queue root name=root, fullname=root
2022-12-14 12:51:17,352 INFO org.apache.hadoop.yarn.server.resourcemanager.scheduler.capacity.CapacitySchedulerConfiguration: max alloc mb per queue for root.default is undefined
2022-12-14 12:51:17,352 INFO org.apache.hadoop.yarn.server.resourcemanager.scheduler.capacity.CapacitySchedulerConfiguration: max alloc vcore per queue for root.default is undefined
2022-12-14 12:51:17,357 INFO org.apache.hadoop.yarn.server.resourcemanager.scheduler.capacity.LeafQueue: Initializing default
capacity = 1.0 [= (float) configuredCapacity / 100 ]
absoluteCapacity = 1.0 [= parentAbsoluteCapacity * capacity ]
maxCapacity = 1.0 [= configuredMaxCapacity ]
absoluteMaxCapacity = 1.0 [= 1.0 maximumCapacity undefined, (parentAbsoluteMaxCapacity * maximumCapacity) / 100 otherwise ]
effectiveMinResource=<memory:0, vCores:0>
 , effectiveMaxResource=<memory:0, vCores:0>
userLimit = 100 [= configuredUserLimit ]
userLimitFactor = 1.0 [= configuredUserLimitFactor ]
maxApplications = 10000 [= configuredMaximumSystemApplicationsPerQueue or (int)(configuredMaximumSystemApplications * absoluteCapacity)]
maxApplicationsPerUser = 10000 [= (int)(maxApplications * (userLimit / 100.0f) * userLimitFactor) ]
usedCapacity = 0.0 [= usedResourcesMemory / (clusterResourceMemory * absoluteCapacity)]
absoluteUsedCapacity = 0.0 [= usedResourcesMemory / clusterResourceMemory]
maxAMResourcePerQueuePercent = 0.2 [= configuredMaximumAMResourcePercent ]
minimumAllocationFactor = 0.75 [= (float)(maximumAllocationMemory - minimumAllocationMemory) / maximumAllocationMemory ]
maximumAllocation = <memory:4096, vCores:2> [= configuredMaxAllocation ]
numContainers = 0 [= currentNumContainers ]
state = RUNNING [= configuredState ]
acls = ADMINISTER_QUEUE:*SUBMIT_APP:* [= configuredAcls ]
nodeLocalityDelay = 40
rackLocalityAdditionalDelay = -1
labels=*,
reservationsContinueLooking = true
preemptionDisabled = true
defaultAppPriorityPerQueue = 0
priority = 0
maxLifetime = -1 seconds
defaultLifetime = -1 seconds
2022-12-14 12:51:17,357 INFO org.apache.hadoop.yarn.server.resourcemanager.scheduler.capacity.CapacitySchedulerQueueManager: Initialized queue: default: capacity=1.0, absoluteCapacity=1.0, usedResources=<memory:0, vCores:0>, usedCapacity=0.0, absoluteUsedCapacity=0.0, numApps=0, numContainers=0, effectiveMinResource=<memory:0, vCores:0> , effectiveMaxResource=<memory:0, vCores:0>
2022-12-14 12:51:17,357 INFO org.apache.hadoop.yarn.server.resourcemanager.scheduler.capacity.CapacitySchedulerQueueManager: Initialized queue: root: numChildQueue= 1, capacity=1.0, absoluteCapacity=1.0, usedResources=<memory:0, vCores:0>usedCapacity=0.0, numApps=0, numContainers=0
2022-12-14 12:51:17,359 INFO org.apache.hadoop.yarn.server.resourcemanager.scheduler.capacity.CapacitySchedulerQueueManager: Initialized root queue root: numChildQueue= 1, capacity=1.0, absoluteCapacity=1.0, usedResources=<memory:0, vCores:0>usedCapacity=0.0, numApps=0, numContainers=0
2022-12-14 12:51:17,359 INFO org.apache.hadoop.yarn.server.resourcemanager.placement.UserGroupMappingPlacementRule: Initialized queue mappings, override: false
2022-12-14 12:51:17,360 INFO org.apache.hadoop.yarn.server.resourcemanager.scheduler.capacity.CapacityScheduler: Initialized CapacityScheduler with calculator=class org.apache.hadoop.yarn.util.resource.DefaultResourceCalculator, minimumAllocation=<<memory:1024, vCores:1>>, maximumAllocation=<<memory:4096, vCores:2>>, asynchronousScheduling=false, asyncScheduleInterval=5ms
2022-12-14 12:51:17,363 INFO org.apache.hadoop.conf.Configuration: dynamic-resources.xml not found
2022-12-14 12:51:17,365 INFO org.apache.hadoop.yarn.server.resourcemanager.AMSProcessingChain: Initializing AMS Processing chain. Root Processor=[org.apache.hadoop.yarn.server.resourcemanager.DefaultAMSProcessor].
2022-12-14 12:51:17,365 INFO org.apache.hadoop.yarn.server.resourcemanager.ApplicationMasterService: disabled placement handler will be used, all scheduling requests will be rejected.
2022-12-14 12:51:17,368 INFO org.apache.hadoop.yarn.server.resourcemanager.AMSProcessingChain: Adding [org.apache.hadoop.yarn.server.resourcemanager.scheduler.constraint.processor.DisabledPlacementProcessor] tp top of AMS Processing chain. 
2022-12-14 12:51:17,572 INFO org.apache.hadoop.yarn.client.api.impl.TimelineClientImpl: Timeline service address: adh-test-00-mnode2.ru-central1.internal:8188
2022-12-14 12:51:17,842 INFO org.apache.hadoop.yarn.event.AsyncDispatcher: Registering class org.apache.hadoop.yarn.server.resourcemanager.metrics.AbstractSystemMetricsPublisher$SystemMetricsEventType for class org.apache.hadoop.yarn.server.resourcemanager.metrics.TimelineServiceV1Publisher$TimelineV1EventHandler
2022-12-14 12:51:17,842 INFO org.apache.hadoop.yarn.event.AsyncDispatcher: Registering class org.apache.hadoop.yarn.server.resourcemanager.metrics.AbstractSystemMetricsPublisher$SystemMetricsEventType for class org.apache.hadoop.yarn.server.resourcemanager.metrics.TimelineServiceV1Publisher$TimelineV1EventHandler
2022-12-14 12:51:17,842 INFO org.apache.hadoop.yarn.event.AsyncDispatcher: Registering class org.apache.hadoop.yarn.server.resourcemanager.metrics.AbstractSystemMetricsPublisher$SystemMetricsEventType for class org.apache.hadoop.yarn.server.resourcemanager.metrics.TimelineServiceV1Publisher$TimelineV1EventHandler
2022-12-14 12:51:17,842 INFO org.apache.hadoop.yarn.event.AsyncDispatcher: Registering class org.apache.hadoop.yarn.server.resourcemanager.metrics.AbstractSystemMetricsPublisher$SystemMetricsEventType for class org.apache.hadoop.yarn.server.resourcemanager.metrics.TimelineServiceV1Publisher$TimelineV1EventHandler
2022-12-14 12:51:17,842 INFO org.apache.hadoop.yarn.event.AsyncDispatcher: Registering class org.apache.hadoop.yarn.server.resourcemanager.metrics.AbstractSystemMetricsPublisher$SystemMetricsEventType for class org.apache.hadoop.yarn.server.resourcemanager.metrics.TimelineServiceV1Publisher$TimelineV1EventHandler
2022-12-14 12:51:17,842 INFO org.apache.hadoop.yarn.event.AsyncDispatcher: Registering class org.apache.hadoop.yarn.server.resourcemanager.metrics.AbstractSystemMetricsPublisher$SystemMetricsEventType for class org.apache.hadoop.yarn.server.resourcemanager.metrics.TimelineServiceV1Publisher$TimelineV1EventHandler
2022-12-14 12:51:17,842 INFO org.apache.hadoop.yarn.event.AsyncDispatcher: Registering class org.apache.hadoop.yarn.server.resourcemanager.metrics.AbstractSystemMetricsPublisher$SystemMetricsEventType for class org.apache.hadoop.yarn.server.resourcemanager.metrics.TimelineServiceV1Publisher$TimelineV1EventHandler
2022-12-14 12:51:17,842 INFO org.apache.hadoop.yarn.event.AsyncDispatcher: Registering class org.apache.hadoop.yarn.server.resourcemanager.metrics.AbstractSystemMetricsPublisher$SystemMetricsEventType for class org.apache.hadoop.yarn.server.resourcemanager.metrics.TimelineServiceV1Publisher$TimelineV1EventHandler
2022-12-14 12:51:17,842 INFO org.apache.hadoop.yarn.event.AsyncDispatcher: Registering class org.apache.hadoop.yarn.server.resourcemanager.metrics.AbstractSystemMetricsPublisher$SystemMetricsEventType for class org.apache.hadoop.yarn.server.resourcemanager.metrics.TimelineServiceV1Publisher$TimelineV1EventHandler
2022-12-14 12:51:17,842 INFO org.apache.hadoop.yarn.event.AsyncDispatcher: Registering class org.apache.hadoop.yarn.server.resourcemanager.metrics.AbstractSystemMetricsPublisher$SystemMetricsEventType for class org.apache.hadoop.yarn.server.resourcemanager.metrics.TimelineServiceV1Publisher$TimelineV1EventHandler
2022-12-14 12:51:17,889 INFO org.eclipse.jetty.util.log: Logging initialized @1921ms
2022-12-14 12:51:17,937 INFO org.apache.hadoop.yarn.server.resourcemanager.ResourceManager: Using webapps at: file:/usr/lib/hadoop-yarn/webapps/ui2
2022-12-14 12:51:17,990 INFO org.apache.hadoop.security.authentication.server.AuthenticationFilter: Unable to initialize FileSignerSecretProvider, falling back to use random secrets.
2022-12-14 12:51:17,994 INFO org.apache.hadoop.http.HttpRequestLog: Http request log for http.requests.resourcemanager is not defined
2022-12-14 12:51:17,998 INFO org.apache.hadoop.http.HttpServer2: Added global filter 'safety' (class=org.apache.hadoop.http.HttpServer2$QuotingInputFilter)
2022-12-14 12:51:18,003 INFO org.apache.hadoop.http.HttpServer2: Added filter RMAuthenticationFilter (class=org.apache.hadoop.yarn.server.security.http.RMAuthenticationFilter) to context cluster
2022-12-14 12:51:18,003 INFO org.apache.hadoop.http.HttpServer2: Added filter RMAuthenticationFilter (class=org.apache.hadoop.yarn.server.security.http.RMAuthenticationFilter) to context logs
2022-12-14 12:51:18,003 INFO org.apache.hadoop.http.HttpServer2: Added filter RMAuthenticationFilter (class=org.apache.hadoop.yarn.server.security.http.RMAuthenticationFilter) to context static
2022-12-14 12:51:18,004 INFO org.apache.hadoop.http.HttpServer2: Added filter static_user_filter (class=org.apache.hadoop.http.lib.StaticUserWebFilter$StaticUserFilter) to context cluster
2022-12-14 12:51:18,004 INFO org.apache.hadoop.http.HttpServer2: Added filter static_user_filter (class=org.apache.hadoop.http.lib.StaticUserWebFilter$StaticUserFilter) to context logs
2022-12-14 12:51:18,004 INFO org.apache.hadoop.http.HttpServer2: Added filter static_user_filter (class=org.apache.hadoop.http.lib.StaticUserWebFilter$StaticUserFilter) to context static
2022-12-14 12:51:18,006 INFO org.apache.hadoop.http.HttpServer2: adding path spec: /cluster/*
2022-12-14 12:51:18,006 INFO org.apache.hadoop.http.HttpServer2: adding path spec: /ws/*
2022-12-14 12:51:18,006 INFO org.apache.hadoop.http.HttpServer2: adding path spec: /app/*
2022-12-14 12:51:18,447 INFO org.apache.hadoop.yarn.webapp.WebApps: Registered webapp guice modules
2022-12-14 12:51:18,455 INFO org.apache.hadoop.http.HttpServer2: Jetty bound to port 8088
2022-12-14 12:51:18,457 INFO org.eclipse.jetty.server.Server: jetty-9.3.24.v20180605, build timestamp: 2018-06-05T17:11:56Z, git hash: 84205aa28f11a4f31f2a3b86d1bba2cc8ab69827
2022-12-14 12:51:18,490 INFO org.apache.hadoop.security.authentication.server.AuthenticationFilter: Unable to initialize FileSignerSecretProvider, falling back to use random secrets.
2022-12-14 12:51:18,501 INFO org.apache.hadoop.security.token.delegation.AbstractDelegationTokenSecretManager: Updating the current master key for generating delegation tokens
2022-12-14 12:51:18,505 INFO org.apache.hadoop.security.token.delegation.AbstractDelegationTokenSecretManager: Starting expired delegation token remover thread, tokenRemoverScanInterval=60 min(s)
2022-12-14 12:51:18,505 INFO org.apache.hadoop.security.token.delegation.AbstractDelegationTokenSecretManager: Updating the current master key for generating delegation tokens
2022-12-14 12:51:18,506 INFO org.eclipse.jetty.server.handler.ContextHandler: Started o.e.j.s.ServletContextHandler@61526469{/logs,file:///var/log/hadoop-yarn/,AVAILABLE}
2022-12-14 12:51:18,507 INFO org.eclipse.jetty.server.handler.ContextHandler: Started o.e.j.s.ServletContextHandler@7c351808{/static,jar:file:/usr/lib/hadoop-yarn/hadoop-yarn-common-3.1.2.jar!/webapps/static,AVAILABLE}
2022-12-14 12:51:19,460 INFO org.eclipse.jetty.server.handler.ContextHandler: Started o.e.j.w.WebAppContext@16c587de{/,file:///tmp/jetty-0.0.0.0-8088-cluster-_-any-7341471459559095666.dir/webapp/,AVAILABLE}{/cluster}
2022-12-14 12:51:19,498 INFO org.eclipse.jetty.webapp.StandardDescriptorProcessor: NO JSP Support for /ui2, did not find org.eclipse.jetty.jsp.JettyJspServlet
2022-12-14 12:51:19,506 INFO org.eclipse.jetty.server.handler.ContextHandler: Started o.e.j.w.WebAppContext@3b1ed14b{/ui2,file:///usr/lib/hadoop-yarn/webapps/ui2/,AVAILABLE}
2022-12-14 12:51:19,513 INFO org.eclipse.jetty.server.AbstractConnector: Started ServerConnector@13741d5a{HTTP/1.1,[http/1.1]}{0.0.0.0:8088}
2022-12-14 12:51:19,514 INFO org.eclipse.jetty.server.Server: Started @3548ms
2022-12-14 12:51:19,514 INFO org.apache.hadoop.yarn.webapp.WebApps: Web app cluster started at 8088
2022-12-14 12:51:19,683 INFO org.apache.hadoop.ipc.CallQueueManager: Using callQueue: class java.util.concurrent.LinkedBlockingQueue queueCapacity: 100 scheduler: class org.apache.hadoop.ipc.DefaultRpcScheduler
2022-12-14 12:51:19,695 INFO org.apache.hadoop.ipc.Server: Starting Socket Reader #1 for port 8033
2022-12-14 12:51:19,729 INFO org.apache.hadoop.yarn.factories.impl.pb.RpcServerFactoryPBImpl: Adding protocol org.apache.hadoop.yarn.server.api.ResourceManagerAdministrationProtocolPB to the server
2022-12-14 12:51:19,729 INFO org.apache.hadoop.ipc.Server: IPC Server Responder: starting
2022-12-14 12:51:19,729 INFO org.apache.hadoop.ipc.Server: IPC Server listener on 8033: starting
2022-12-14 12:51:19,732 INFO org.apache.hadoop.yarn.server.resourcemanager.ResourceManager: Transitioning to active state
2022-12-14 12:51:19,845 INFO org.apache.hadoop.yarn.server.resourcemanager.recovery.LeveldbRMStateStore: Using state database at /srv/hadoop-yarn/leveldb-state-store/yarn-rm-state for recovery
2022-12-14 12:51:19,865 INFO org.apache.hadoop.yarn.server.resourcemanager.recovery.LeveldbRMStateStore: Creating state database at /srv/hadoop-yarn/leveldb-state-store/yarn-rm-state
2022-12-14 12:51:19,886 INFO org.apache.hadoop.yarn.server.resourcemanager.ResourceManager: Recovery started
2022-12-14 12:51:19,889 INFO org.apache.hadoop.yarn.server.resourcemanager.recovery.RMStateStore: Loaded RM state version info 1.1
2022-12-14 12:51:19,896 INFO org.apache.hadoop.yarn.server.resourcemanager.recovery.LeveldbRMStateStore: Recovered 0 RM delegation token master keys
2022-12-14 12:51:19,896 INFO org.apache.hadoop.yarn.server.resourcemanager.recovery.LeveldbRMStateStore: Recovered 0 RM delegation tokens
2022-12-14 12:51:19,896 INFO org.apache.hadoop.yarn.server.resourcemanager.recovery.LeveldbRMStateStore: Recovered 0 applications and 0 application attempts
2022-12-14 12:51:19,896 INFO org.apache.hadoop.yarn.server.resourcemanager.recovery.LeveldbRMStateStore: Recovered 0 reservations
2022-12-14 12:51:19,896 INFO org.apache.hadoop.yarn.server.resourcemanager.security.RMDelegationTokenSecretManager: recovering RMDelegationTokenSecretManager.
2022-12-14 12:51:19,896 INFO org.apache.hadoop.yarn.server.resourcemanager.RMAppManager: Recovering 0 applications
2022-12-14 12:51:19,896 INFO org.apache.hadoop.yarn.server.resourcemanager.RMAppManager: Successfully recovered 0 out of 0 applications
2022-12-14 12:51:19,896 INFO org.apache.hadoop.yarn.server.resourcemanager.ResourceManager: Recovery ended
2022-12-14 12:51:19,906 INFO org.apache.hadoop.yarn.server.resourcemanager.recovery.RMStateStore: Updating AMRMToken
2022-12-14 12:51:19,907 INFO org.apache.hadoop.yarn.server.resourcemanager.security.RMContainerTokenSecretManager: Rolling master-key for container-tokens
2022-12-14 12:51:19,907 INFO org.apache.hadoop.yarn.server.resourcemanager.security.NMTokenSecretManagerInRM: Rolling master-key for nm-tokens
2022-12-14 12:51:19,907 INFO org.apache.hadoop.security.token.delegation.AbstractDelegationTokenSecretManager: Updating the current master key for generating delegation tokens
2022-12-14 12:51:19,907 INFO org.apache.hadoop.yarn.server.resourcemanager.security.RMDelegationTokenSecretManager: storing master key with keyID 1
2022-12-14 12:51:19,907 INFO org.apache.hadoop.yarn.server.resourcemanager.recovery.RMStateStore: Storing RMDTMasterKey.
2022-12-14 12:51:19,908 INFO org.apache.hadoop.security.token.delegation.AbstractDelegationTokenSecretManager: Starting expired delegation token remover thread, tokenRemoverScanInterval=60 min(s)
2022-12-14 12:51:19,909 INFO org.apache.hadoop.security.token.delegation.AbstractDelegationTokenSecretManager: Updating the current master key for generating delegation tokens
2022-12-14 12:51:19,909 INFO org.apache.hadoop.yarn.server.resourcemanager.security.RMDelegationTokenSecretManager: storing master key with keyID 2
2022-12-14 12:51:19,909 INFO org.apache.hadoop.yarn.server.resourcemanager.recovery.RMStateStore: Storing RMDTMasterKey.
2022-12-14 12:51:20,596 INFO org.apache.hadoop.yarn.nodelabels.FileSystemNodeLabelsStore: Finished write mirror at:hdfs:/system/yarn/node-labels/nodelabel.mirror
2022-12-14 12:51:20,596 INFO org.apache.hadoop.yarn.nodelabels.FileSystemNodeLabelsStore: Finished create editlog file at:hdfs:/system/yarn/node-labels/nodelabel.editlog
2022-12-14 12:51:20,597 INFO org.apache.hadoop.yarn.event.AsyncDispatcher: Registering class org.apache.hadoop.yarn.nodelabels.event.NodeLabelsStoreEventType for class org.apache.hadoop.yarn.nodelabels.CommonNodeLabelsManager$ForwardingEventHandler
2022-12-14 12:51:20,613 INFO org.apache.hadoop.ipc.CallQueueManager: Using callQueue: class java.util.concurrent.LinkedBlockingQueue queueCapacity: 5000 scheduler: class org.apache.hadoop.ipc.DefaultRpcScheduler
2022-12-14 12:51:20,614 INFO org.apache.hadoop.ipc.Server: Starting Socket Reader #1 for port 8031
2022-12-14 12:51:20,617 INFO org.apache.hadoop.yarn.factories.impl.pb.RpcServerFactoryPBImpl: Adding protocol org.apache.hadoop.yarn.server.api.ResourceTrackerPB to the server
2022-12-14 12:51:20,617 INFO org.apache.hadoop.ipc.Server: IPC Server Responder: starting
2022-12-14 12:51:20,617 INFO org.apache.hadoop.ipc.Server: IPC Server listener on 8031: starting
2022-12-14 12:51:20,630 INFO org.apache.hadoop.util.JvmPauseMonitor: Starting JVM pause monitor
2022-12-14 12:51:20,641 INFO org.apache.hadoop.ipc.CallQueueManager: Using callQueue: class java.util.concurrent.LinkedBlockingQueue queueCapacity: 5000 scheduler: class org.apache.hadoop.ipc.DefaultRpcScheduler
2022-12-14 12:51:20,648 INFO org.apache.hadoop.ipc.Server: Starting Socket Reader #1 for port 8030
2022-12-14 12:51:20,656 INFO org.apache.hadoop.yarn.factories.impl.pb.RpcServerFactoryPBImpl: Adding protocol org.apache.hadoop.yarn.api.ApplicationMasterProtocolPB to the server
2022-12-14 12:51:20,658 INFO org.apache.hadoop.ipc.Server: IPC Server Responder: starting
2022-12-14 12:51:20,661 INFO org.apache.hadoop.ipc.Server: IPC Server listener on 8030: starting
2022-12-14 12:51:20,811 INFO org.apache.hadoop.ipc.CallQueueManager: Using callQueue: class java.util.concurrent.LinkedBlockingQueue queueCapacity: 5000 scheduler: class org.apache.hadoop.ipc.DefaultRpcScheduler
2022-12-14 12:51:20,812 INFO org.apache.hadoop.ipc.Server: Starting Socket Reader #1 for port 8032
2022-12-14 12:51:20,815 INFO org.apache.hadoop.yarn.factories.impl.pb.RpcServerFactoryPBImpl: Adding protocol org.apache.hadoop.yarn.api.ApplicationClientProtocolPB to the server
2022-12-14 12:51:20,815 INFO org.apache.hadoop.ipc.Server: IPC Server Responder: starting
2022-12-14 12:51:20,815 INFO org.apache.hadoop.ipc.Server: IPC Server listener on 8032: starting
2022-12-14 12:51:20,824 INFO org.apache.hadoop.yarn.server.resourcemanager.ResourceManager: Transitioned to active state
2022-12-14 12:51:56,007 INFO org.apache.hadoop.yarn.server.resourcemanager.ResourceTrackerService: NodeManager from node adh-test-00-mnode2.ru-central1.internal(cmPort: 8041 httpPort: 8042) registered with capability: <memory:7057, vCores:2>, assigned nodeId adh-test-00-mnode2.ru-central1.internal:8041
2022-12-14 12:51:56,013 INFO org.apache.hadoop.yarn.server.resourcemanager.rmnode.RMNodeImpl: adh-test-00-mnode2.ru-central1.internal:8041 Node Transitioned from NEW to RUNNING
2022-12-14 12:51:56,042 INFO org.apache.hadoop.yarn.server.resourcemanager.scheduler.capacity.CapacityScheduler: Added node adh-test-00-mnode2.ru-central1.internal:8041 clusterResource: <memory:7057, vCores:2>
2022-12-14 12:51:56,084 INFO org.apache.hadoop.yarn.server.resourcemanager.RMActiveServiceContext: Scheduler recovery is done. Start allocating new containers.
2022-12-14 12:51:56,232 INFO org.apache.hadoop.yarn.server.resourcemanager.ResourceTrackerService: NodeManager from node adh-test-00-mnode3.ru-central1.internal(cmPort: 8041 httpPort: 8042) registered with capability: <memory:7057, vCores:2>, assigned nodeId adh-test-00-mnode3.ru-central1.internal:8041
2022-12-14 12:51:56,234 INFO org.apache.hadoop.yarn.server.resourcemanager.rmnode.RMNodeImpl: adh-test-00-mnode3.ru-central1.internal:8041 Node Transitioned from NEW to RUNNING
2022-12-14 12:51:56,236 INFO org.apache.hadoop.yarn.server.resourcemanager.scheduler.capacity.CapacityScheduler: Added node adh-test-00-mnode3.ru-central1.internal:8041 clusterResource: <memory:14114, vCores:4>
2022-12-14 12:51:56,738 INFO org.apache.hadoop.yarn.server.resourcemanager.ResourceTrackerService: NodeManager from node adh-test-00-mnode1.ru-central1.internal(cmPort: 8041 httpPort: 8042) registered with capability: <memory:7057, vCores:2>, assigned nodeId adh-test-00-mnode1.ru-central1.internal:8041
2022-12-14 12:51:56,738 INFO org.apache.hadoop.yarn.server.resourcemanager.rmnode.RMNodeImpl: adh-test-00-mnode1.ru-central1.internal:8041 Node Transitioned from NEW to RUNNING
2022-12-14 12:51:56,742 INFO org.apache.hadoop.yarn.server.resourcemanager.scheduler.capacity.CapacityScheduler: Added node adh-test-00-mnode1.ru-central1.internal:8041 clusterResource: <memory:21171, vCores:6>
2022-12-14 12:55:04,429 INFO org.apache.hadoop.yarn.server.resourcemanager.ClientRMService: Allocated new applicationId: 1
2022-12-14 12:55:05,242 INFO org.apache.hadoop.yarn.server.resourcemanager.scheduler.capacity.CapacityScheduler: Application 'application_1671022279734_0001' is submitted without priority hence considering default queue/cluster priority: 0
2022-12-14 12:55:05,242 INFO org.apache.hadoop.yarn.server.resourcemanager.scheduler.capacity.CapacityScheduler: Priority '0' is acceptable in queue : default for application: application_1671022279734_0001
2022-12-14 12:55:05,267 INFO org.apache.hadoop.yarn.server.resourcemanager.ClientRMService: Application with id 1 submitted by user yarn
2022-12-14 12:55:05,268 INFO org.apache.hadoop.yarn.server.resourcemanager.rmapp.RMAppImpl: Storing application with id application_1671022279734_0001
2022-12-14 12:55:05,270 INFO org.apache.hadoop.yarn.server.resourcemanager.RMAuditLogger: USER=yarn	IP=10.130.0.4	OPERATION=Submit Application Request	TARGET=ClientRMService	RESULT=SUCCESS	APPID=application_1671022279734_0001	CALLERCONTEXT=CLI	QUEUENAME=default
2022-12-14 12:55:05,276 INFO org.apache.hadoop.yarn.server.resourcemanager.recovery.RMStateStore: Storing info for app: application_1671022279734_0001
2022-12-14 12:55:05,276 INFO org.apache.hadoop.yarn.server.resourcemanager.rmapp.RMAppImpl: application_1671022279734_0001 State change from NEW to NEW_SAVING on event = START
2022-12-14 12:55:05,330 INFO org.apache.hadoop.yarn.server.resourcemanager.rmapp.RMAppImpl: application_1671022279734_0001 State change from NEW_SAVING to SUBMITTED on event = APP_NEW_SAVED
2022-12-14 12:55:05,337 INFO org.apache.hadoop.yarn.server.resourcemanager.scheduler.capacity.ParentQueue: Application added - appId: application_1671022279734_0001 user: yarn leaf-queue of parent: root #applications: 1
2022-12-14 12:55:05,338 INFO org.apache.hadoop.yarn.server.resourcemanager.scheduler.capacity.CapacityScheduler: Accepted application application_1671022279734_0001 from user: yarn, in queue: default
2022-12-14 12:55:05,352 INFO org.apache.hadoop.yarn.server.resourcemanager.rmapp.RMAppImpl: application_1671022279734_0001 State change from SUBMITTED to ACCEPTED on event = APP_ACCEPTED
2022-12-14 12:55:05,391 INFO org.apache.hadoop.yarn.server.resourcemanager.ApplicationMasterService: Registering app attempt : appattempt_1671022279734_0001_000001
2022-12-14 12:55:05,393 INFO org.apache.hadoop.yarn.server.resourcemanager.rmapp.attempt.RMAppAttemptImpl: appattempt_1671022279734_0001_000001 State change from NEW to SUBMITTED on event = START
2022-12-14 12:55:05,423 INFO org.apache.hadoop.yarn.server.resourcemanager.scheduler.capacity.LeafQueue: Application application_1671022279734_0001 from user: yarn activated in queue: default
2022-12-14 12:55:05,423 INFO org.apache.hadoop.yarn.server.resourcemanager.scheduler.capacity.LeafQueue: Application added - appId: application_1671022279734_0001 user: yarn, leaf-queue: default #user-pending-applications: 0 #user-active-applications: 1 #queue-pending-applications: 0 #queue-active-applications: 1
2022-12-14 12:55:05,423 INFO org.apache.hadoop.yarn.server.resourcemanager.scheduler.capacity.CapacityScheduler: Added Application Attempt appattempt_1671022279734_0001_000001 to scheduler from user yarn in queue default
2022-12-14 12:55:05,434 INFO org.apache.hadoop.yarn.server.resourcemanager.rmapp.attempt.RMAppAttemptImpl: appattempt_1671022279734_0001_000001 State change from SUBMITTED to SCHEDULED on event = ATTEMPT_ADDED
2022-12-14 12:55:05,633 INFO org.apache.hadoop.yarn.server.resourcemanager.scheduler.capacity.allocator.AbstractContainerAllocator: assignedContainer application attempt=appattempt_1671022279734_0001_000001 container=null queue=default clusterResource=<memory:21171, vCores:6> type=OFF_SWITCH requestedPartition=
2022-12-14 12:55:05,639 INFO org.apache.hadoop.yarn.server.resourcemanager.rmcontainer.RMContainerImpl: container_1671022279734_0001_01_000001 Container Transitioned from NEW to ALLOCATED
2022-12-14 12:55:05,640 INFO org.apache.hadoop.yarn.server.resourcemanager.scheduler.common.fica.FiCaSchedulerNode: Assigned container container_1671022279734_0001_01_000001 of capacity <memory:2048, vCores:1> on host adh-test-00-mnode2.ru-central1.internal:8041, which has 1 containers, <memory:2048, vCores:1> used and <memory:5009, vCores:1> available after allocation
2022-12-14 12:55:05,640 INFO org.apache.hadoop.yarn.server.resourcemanager.RMAuditLogger: USER=yarn	OPERATION=AM Allocated Container	TARGET=SchedulerApp	RESULT=SUCCESS	APPID=application_1671022279734_0001	CONTAINERID=container_1671022279734_0001_01_000001	RESOURCE=<memory:2048, vCores:1>	QUEUENAME=default
2022-12-14 12:55:05,675 INFO org.apache.hadoop.yarn.server.resourcemanager.security.NMTokenSecretManagerInRM: Sending NMToken for nodeId : adh-test-00-mnode2.ru-central1.internal:8041 for container : container_1671022279734_0001_01_000001
2022-12-14 12:55:05,693 INFO org.apache.hadoop.yarn.server.resourcemanager.rmcontainer.RMContainerImpl: container_1671022279734_0001_01_000001 Container Transitioned from ALLOCATED to ACQUIRED
2022-12-14 12:55:05,695 INFO org.apache.hadoop.yarn.server.resourcemanager.security.NMTokenSecretManagerInRM: Clear node set for appattempt_1671022279734_0001_000001
2022-12-14 12:55:05,695 INFO org.apache.hadoop.yarn.server.resourcemanager.rmapp.attempt.RMAppAttemptImpl: Storing attempt: AppId: application_1671022279734_0001 AttemptId: appattempt_1671022279734_0001_000001 MasterContainer: Container: [ContainerId: container_1671022279734_0001_01_000001, AllocationRequestId: -1, Version: 0, NodeId: adh-test-00-mnode2.ru-central1.internal:8041, NodeHttpAddress: adh-test-00-mnode2.ru-central1.internal:8042, Resource: <memory:2048, vCores:1>, Priority: 0, Token: Token { kind: ContainerToken, service: 10.130.0.5:8041 }, ExecutionType: GUARANTEED, ]
2022-12-14 12:55:05,698 INFO org.apache.hadoop.yarn.server.resourcemanager.scheduler.capacity.ParentQueue: assignedContainer queue=root usedCapacity=0.0967361 absoluteUsedCapacity=0.0967361 used=<memory:2048, vCores:1> cluster=<memory:21171, vCores:6>
2022-12-14 12:55:05,698 INFO org.apache.hadoop.yarn.server.resourcemanager.scheduler.capacity.CapacityScheduler: Allocation proposal accepted
2022-12-14 12:55:05,708 INFO org.apache.hadoop.yarn.server.resourcemanager.rmapp.attempt.RMAppAttemptImpl: appattempt_1671022279734_0001_000001 State change from SCHEDULED to ALLOCATED_SAVING on event = CONTAINER_ALLOCATED
2022-12-14 12:55:05,714 INFO org.apache.hadoop.yarn.server.resourcemanager.rmapp.attempt.RMAppAttemptImpl: appattempt_1671022279734_0001_000001 State change from ALLOCATED_SAVING to ALLOCATED on event = ATTEMPT_NEW_SAVED
2022-12-14 12:55:05,719 INFO org.apache.hadoop.yarn.server.resourcemanager.amlauncher.AMLauncher: Launching masterappattempt_1671022279734_0001_000001
2022-12-14 12:55:05,797 INFO org.apache.hadoop.yarn.server.resourcemanager.amlauncher.AMLauncher: Setting up container Container: [ContainerId: container_1671022279734_0001_01_000001, AllocationRequestId: -1, Version: 0, NodeId: adh-test-00-mnode2.ru-central1.internal:8041, NodeHttpAddress: adh-test-00-mnode2.ru-central1.internal:8042, Resource: <memory:2048, vCores:1>, Priority: 0, Token: Token { kind: ContainerToken, service: 10.130.0.5:8041 }, ExecutionType: GUARANTEED, ] for AM appattempt_1671022279734_0001_000001
2022-12-14 12:55:05,798 INFO org.apache.hadoop.yarn.server.resourcemanager.security.AMRMTokenSecretManager: Create AMRMToken for ApplicationAttempt: appattempt_1671022279734_0001_000001
2022-12-14 12:55:05,943 INFO org.apache.hadoop.yarn.server.resourcemanager.security.AMRMTokenSecretManager: Creating password for appattempt_1671022279734_0001_000001
2022-12-14 12:55:06,249 INFO org.apache.hadoop.yarn.server.resourcemanager.amlauncher.AMLauncher: Done launching container Container: [ContainerId: container_1671022279734_0001_01_000001, AllocationRequestId: -1, Version: 0, NodeId: adh-test-00-mnode2.ru-central1.internal:8041, NodeHttpAddress: adh-test-00-mnode2.ru-central1.internal:8042, Resource: <memory:2048, vCores:1>, Priority: 0, Token: Token { kind: ContainerToken, service: 10.130.0.5:8041 }, ExecutionType: GUARANTEED, ] for AM appattempt_1671022279734_0001_000001
2022-12-14 12:55:06,249 INFO org.apache.hadoop.yarn.server.resourcemanager.rmapp.attempt.RMAppAttemptImpl: appattempt_1671022279734_0001_000001 State change from ALLOCATED to LAUNCHED on event = LAUNCHED
2022-12-14 12:55:06,635 INFO org.apache.hadoop.yarn.server.resourcemanager.rmcontainer.RMContainerImpl: container_1671022279734_0001_01_000001 Container Transitioned from ACQUIRED to RUNNING
2022-12-14 12:55:10,642 INFO SecurityLogger.org.apache.hadoop.ipc.Server: Auth successful for appattempt_1671022279734_0001_000001 (auth:SIMPLE)
2022-12-14 12:55:10,660 INFO org.apache.hadoop.yarn.server.resourcemanager.DefaultAMSProcessor: AM registration appattempt_1671022279734_0001_000001
2022-12-14 12:55:10,661 INFO org.apache.hadoop.yarn.server.resourcemanager.RMAuditLogger: USER=yarn	IP=10.130.0.5	OPERATION=Register App Master	TARGET=ApplicationMasterService	RESULT=SUCCESS	APPID=application_1671022279734_0001	APPATTEMPTID=appattempt_1671022279734_0001_000001
2022-12-14 12:55:10,661 INFO org.apache.hadoop.yarn.server.resourcemanager.rmapp.attempt.RMAppAttemptImpl: appattempt_1671022279734_0001_000001 State change from LAUNCHED to RUNNING on event = REGISTERED
2022-12-14 12:55:10,661 INFO org.apache.hadoop.yarn.server.resourcemanager.rmapp.RMAppImpl: application_1671022279734_0001 State change from ACCEPTED to RUNNING on event = ATTEMPT_REGISTERED
2022-12-14 12:55:11,959 INFO org.apache.hadoop.yarn.server.resourcemanager.scheduler.capacity.allocator.AbstractContainerAllocator: assignedContainer application attempt=appattempt_1671022279734_0001_000001 container=null queue=default clusterResource=<memory:21171, vCores:6> type=NODE_LOCAL requestedPartition=
2022-12-14 12:55:11,960 INFO org.apache.hadoop.yarn.server.resourcemanager.rmcontainer.RMContainerImpl: container_1671022279734_0001_01_000002 Container Transitioned from NEW to ALLOCATED
2022-12-14 12:55:11,960 INFO org.apache.hadoop.yarn.server.resourcemanager.scheduler.common.fica.FiCaSchedulerNode: Assigned container container_1671022279734_0001_01_000002 of capacity <memory:1024, vCores:1> on host adh-test-00-mnode3.ru-central1.internal:8041, which has 1 containers, <memory:1024, vCores:1> used and <memory:6033, vCores:1> available after allocation
2022-12-14 12:55:11,960 INFO org.apache.hadoop.yarn.server.resourcemanager.RMAuditLogger: USER=yarn	OPERATION=AM Allocated Container	TARGET=SchedulerApp	RESULT=SUCCESS	APPID=application_1671022279734_0001	CONTAINERID=container_1671022279734_0001_01_000002	RESOURCE=<memory:1024, vCores:1>	QUEUENAME=default
2022-12-14 12:55:11,960 INFO org.apache.hadoop.yarn.server.resourcemanager.scheduler.capacity.ParentQueue: assignedContainer queue=root usedCapacity=0.14510415 absoluteUsedCapacity=0.14510415 used=<memory:3072, vCores:2> cluster=<memory:21171, vCores:6>
2022-12-14 12:55:11,960 INFO org.apache.hadoop.yarn.server.resourcemanager.scheduler.capacity.CapacityScheduler: Allocation proposal accepted
2022-12-14 12:55:11,960 INFO org.apache.hadoop.yarn.server.resourcemanager.scheduler.capacity.allocator.AbstractContainerAllocator: assignedContainer application attempt=appattempt_1671022279734_0001_000001 container=null queue=default clusterResource=<memory:21171, vCores:6> type=NODE_LOCAL requestedPartition=
2022-12-14 12:55:11,961 INFO org.apache.hadoop.yarn.server.resourcemanager.rmcontainer.RMContainerImpl: container_1671022279734_0001_01_000003 Container Transitioned from NEW to ALLOCATED
2022-12-14 12:55:11,961 INFO org.apache.hadoop.yarn.server.resourcemanager.scheduler.common.fica.FiCaSchedulerNode: Assigned container container_1671022279734_0001_01_000003 of capacity <memory:1024, vCores:1> on host adh-test-00-mnode3.ru-central1.internal:8041, which has 2 containers, <memory:2048, vCores:2> used and <memory:5009, vCores:0> available after allocation
2022-12-14 12:55:11,961 INFO org.apache.hadoop.yarn.server.resourcemanager.RMAuditLogger: USER=yarn	OPERATION=AM Allocated Container	TARGET=SchedulerApp	RESULT=SUCCESS	APPID=application_1671022279734_0001	CONTAINERID=container_1671022279734_0001_01_000003	RESOURCE=<memory:1024, vCores:1>	QUEUENAME=default
2022-12-14 12:55:11,961 INFO org.apache.hadoop.yarn.server.resourcemanager.scheduler.capacity.ParentQueue: assignedContainer queue=root usedCapacity=0.1934722 absoluteUsedCapacity=0.1934722 used=<memory:4096, vCores:3> cluster=<memory:21171, vCores:6>
2022-12-14 12:55:11,961 INFO org.apache.hadoop.yarn.server.resourcemanager.scheduler.capacity.CapacityScheduler: Allocation proposal accepted
2022-12-14 12:55:11,961 INFO org.apache.hadoop.yarn.server.resourcemanager.scheduler.capacity.allocator.AbstractContainerAllocator: assignedContainer application attempt=appattempt_1671022279734_0001_000001 container=null queue=default clusterResource=<memory:21171, vCores:6> type=NODE_LOCAL requestedPartition=
2022-12-14 12:55:11,962 INFO org.apache.hadoop.yarn.server.resourcemanager.rmcontainer.RMContainerImpl: container_1671022279734_0001_01_000004 Container Transitioned from NEW to ALLOCATED
2022-12-14 12:55:11,962 INFO org.apache.hadoop.yarn.server.resourcemanager.scheduler.common.fica.FiCaSchedulerNode: Assigned container container_1671022279734_0001_01_000004 of capacity <memory:1024, vCores:1> on host adh-test-00-mnode3.ru-central1.internal:8041, which has 3 containers, <memory:3072, vCores:3> used and <memory:3985, vCores:-1> available after allocation
2022-12-14 12:55:11,962 INFO org.apache.hadoop.yarn.server.resourcemanager.RMAuditLogger: USER=yarn	OPERATION=AM Allocated Container	TARGET=SchedulerApp	RESULT=SUCCESS	APPID=application_1671022279734_0001	CONTAINERID=container_1671022279734_0001_01_000004	RESOURCE=<memory:1024, vCores:1>	QUEUENAME=default
2022-12-14 12:55:11,962 INFO org.apache.hadoop.yarn.server.resourcemanager.scheduler.capacity.ParentQueue: assignedContainer queue=root usedCapacity=0.24184026 absoluteUsedCapacity=0.24184026 used=<memory:5120, vCores:4> cluster=<memory:21171, vCores:6>
2022-12-14 12:55:11,962 INFO org.apache.hadoop.yarn.server.resourcemanager.scheduler.capacity.CapacityScheduler: Allocation proposal accepted
2022-12-14 12:55:11,962 INFO org.apache.hadoop.yarn.server.resourcemanager.scheduler.capacity.allocator.AbstractContainerAllocator: assignedContainer application attempt=appattempt_1671022279734_0001_000001 container=null queue=default clusterResource=<memory:21171, vCores:6> type=NODE_LOCAL requestedPartition=
2022-12-14 12:55:11,963 INFO org.apache.hadoop.yarn.server.resourcemanager.rmcontainer.RMContainerImpl: container_1671022279734_0001_01_000005 Container Transitioned from NEW to ALLOCATED
2022-12-14 12:55:11,963 INFO org.apache.hadoop.yarn.server.resourcemanager.scheduler.common.fica.FiCaSchedulerNode: Assigned container container_1671022279734_0001_01_000005 of capacity <memory:1024, vCores:1> on host adh-test-00-mnode3.ru-central1.internal:8041, which has 4 containers, <memory:4096, vCores:4> used and <memory:2961, vCores:-2> available after allocation
2022-12-14 12:55:11,963 INFO org.apache.hadoop.yarn.server.resourcemanager.RMAuditLogger: USER=yarn	OPERATION=AM Allocated Container	TARGET=SchedulerApp	RESULT=SUCCESS	APPID=application_1671022279734_0001	CONTAINERID=container_1671022279734_0001_01_000005	RESOURCE=<memory:1024, vCores:1>	QUEUENAME=default
2022-12-14 12:55:11,963 INFO org.apache.hadoop.yarn.server.resourcemanager.scheduler.capacity.ParentQueue: assignedContainer queue=root usedCapacity=0.2902083 absoluteUsedCapacity=0.2902083 used=<memory:6144, vCores:5> cluster=<memory:21171, vCores:6>
2022-12-14 12:55:11,963 INFO org.apache.hadoop.yarn.server.resourcemanager.scheduler.capacity.CapacityScheduler: Allocation proposal accepted
2022-12-14 12:55:11,964 INFO org.apache.hadoop.yarn.server.resourcemanager.scheduler.capacity.allocator.AbstractContainerAllocator: assignedContainer application attempt=appattempt_1671022279734_0001_000001 container=null queue=default clusterResource=<memory:21171, vCores:6> type=NODE_LOCAL requestedPartition=
2022-12-14 12:55:11,964 INFO org.apache.hadoop.yarn.server.resourcemanager.rmcontainer.RMContainerImpl: container_1671022279734_0001_01_000006 Container Transitioned from NEW to ALLOCATED
2022-12-14 12:55:11,964 INFO org.apache.hadoop.yarn.server.resourcemanager.scheduler.common.fica.FiCaSchedulerNode: Assigned container container_1671022279734_0001_01_000006 of capacity <memory:1024, vCores:1> on host adh-test-00-mnode3.ru-central1.internal:8041, which has 5 containers, <memory:5120, vCores:5> used and <memory:1937, vCores:-3> available after allocation
2022-12-14 12:55:11,964 INFO org.apache.hadoop.yarn.server.resourcemanager.RMAuditLogger: USER=yarn	OPERATION=AM Allocated Container	TARGET=SchedulerApp	RESULT=SUCCESS	APPID=application_1671022279734_0001	CONTAINERID=container_1671022279734_0001_01_000006	RESOURCE=<memory:1024, vCores:1>	QUEUENAME=default
2022-12-14 12:55:11,964 INFO org.apache.hadoop.yarn.server.resourcemanager.scheduler.capacity.ParentQueue: assignedContainer queue=root usedCapacity=0.33857635 absoluteUsedCapacity=0.33857635 used=<memory:7168, vCores:6> cluster=<memory:21171, vCores:6>
2022-12-14 12:55:11,964 INFO org.apache.hadoop.yarn.server.resourcemanager.scheduler.capacity.CapacityScheduler: Allocation proposal accepted
2022-12-14 12:55:11,965 INFO org.apache.hadoop.yarn.server.resourcemanager.scheduler.capacity.allocator.AbstractContainerAllocator: assignedContainer application attempt=appattempt_1671022279734_0001_000001 container=null queue=default clusterResource=<memory:21171, vCores:6> type=NODE_LOCAL requestedPartition=
2022-12-14 12:55:11,965 INFO org.apache.hadoop.yarn.server.resourcemanager.rmcontainer.RMContainerImpl: container_1671022279734_0001_01_000007 Container Transitioned from NEW to ALLOCATED
2022-12-14 12:55:11,965 INFO org.apache.hadoop.yarn.server.resourcemanager.scheduler.common.fica.FiCaSchedulerNode: Assigned container container_1671022279734_0001_01_000007 of capacity <memory:1024, vCores:1> on host adh-test-00-mnode3.ru-central1.internal:8041, which has 6 containers, <memory:6144, vCores:6> used and <memory:913, vCores:-4> available after allocation
2022-12-14 12:55:11,965 INFO org.apache.hadoop.yarn.server.resourcemanager.RMAuditLogger: USER=yarn	OPERATION=AM Allocated Container	TARGET=SchedulerApp	RESULT=SUCCESS	APPID=application_1671022279734_0001	CONTAINERID=container_1671022279734_0001_01_000007	RESOURCE=<memory:1024, vCores:1>	QUEUENAME=default
2022-12-14 12:55:11,965 INFO org.apache.hadoop.yarn.server.resourcemanager.scheduler.capacity.ParentQueue: assignedContainer queue=root usedCapacity=0.3869444 absoluteUsedCapacity=0.3869444 used=<memory:8192, vCores:7> cluster=<memory:21171, vCores:6>
2022-12-14 12:55:11,965 INFO org.apache.hadoop.yarn.server.resourcemanager.scheduler.capacity.CapacityScheduler: Allocation proposal accepted
2022-12-14 12:55:12,210 INFO org.apache.hadoop.yarn.server.resourcemanager.scheduler.capacity.allocator.AbstractContainerAllocator: assignedContainer application attempt=appattempt_1671022279734_0001_000001 container=null queue=default clusterResource=<memory:21171, vCores:6> type=NODE_LOCAL requestedPartition=
2022-12-14 12:55:12,211 INFO org.apache.hadoop.yarn.server.resourcemanager.rmcontainer.RMContainerImpl: container_1671022279734_0001_01_000008 Container Transitioned from NEW to ALLOCATED
2022-12-14 12:55:12,211 INFO org.apache.hadoop.yarn.server.resourcemanager.scheduler.common.fica.FiCaSchedulerNode: Assigned container container_1671022279734_0001_01_000008 of capacity <memory:1024, vCores:1> on host adh-test-00-mnode1.ru-central1.internal:8041, which has 1 containers, <memory:1024, vCores:1> used and <memory:6033, vCores:1> available after allocation
2022-12-14 12:55:12,211 INFO org.apache.hadoop.yarn.server.resourcemanager.RMAuditLogger: USER=yarn	OPERATION=AM Allocated Container	TARGET=SchedulerApp	RESULT=SUCCESS	APPID=application_1671022279734_0001	CONTAINERID=container_1671022279734_0001_01_000008	RESOURCE=<memory:1024, vCores:1>	QUEUENAME=default
2022-12-14 12:55:12,211 INFO org.apache.hadoop.yarn.server.resourcemanager.scheduler.capacity.ParentQueue: assignedContainer queue=root usedCapacity=0.43531245 absoluteUsedCapacity=0.43531245 used=<memory:9216, vCores:8> cluster=<memory:21171, vCores:6>
2022-12-14 12:55:12,211 INFO org.apache.hadoop.yarn.server.resourcemanager.scheduler.capacity.CapacityScheduler: Allocation proposal accepted
2022-12-14 12:55:12,211 INFO org.apache.hadoop.yarn.server.resourcemanager.scheduler.capacity.allocator.AbstractContainerAllocator: assignedContainer application attempt=appattempt_1671022279734_0001_000001 container=null queue=default clusterResource=<memory:21171, vCores:6> type=NODE_LOCAL requestedPartition=
2022-12-14 12:55:12,212 INFO org.apache.hadoop.yarn.server.resourcemanager.rmcontainer.RMContainerImpl: container_1671022279734_0001_01_000009 Container Transitioned from NEW to ALLOCATED
2022-12-14 12:55:12,212 INFO org.apache.hadoop.yarn.server.resourcemanager.scheduler.common.fica.FiCaSchedulerNode: Assigned container container_1671022279734_0001_01_000009 of capacity <memory:1024, vCores:1> on host adh-test-00-mnode1.ru-central1.internal:8041, which has 2 containers, <memory:2048, vCores:2> used and <memory:5009, vCores:0> available after allocation
2022-12-14 12:55:12,212 INFO org.apache.hadoop.yarn.server.resourcemanager.RMAuditLogger: USER=yarn	OPERATION=AM Allocated Container	TARGET=SchedulerApp	RESULT=SUCCESS	APPID=application_1671022279734_0001	CONTAINERID=container_1671022279734_0001_01_000009	RESOURCE=<memory:1024, vCores:1>	QUEUENAME=default
2022-12-14 12:55:12,212 INFO org.apache.hadoop.yarn.server.resourcemanager.scheduler.capacity.ParentQueue: assignedContainer queue=root usedCapacity=0.48368052 absoluteUsedCapacity=0.48368052 used=<memory:10240, vCores:9> cluster=<memory:21171, vCores:6>
2022-12-14 12:55:12,212 INFO org.apache.hadoop.yarn.server.resourcemanager.scheduler.capacity.CapacityScheduler: Allocation proposal accepted
2022-12-14 12:55:12,212 INFO org.apache.hadoop.yarn.server.resourcemanager.scheduler.capacity.allocator.AbstractContainerAllocator: assignedContainer application attempt=appattempt_1671022279734_0001_000001 container=null queue=default clusterResource=<memory:21171, vCores:6> type=NODE_LOCAL requestedPartition=
2022-12-14 12:55:12,212 INFO org.apache.hadoop.yarn.server.resourcemanager.rmcontainer.RMContainerImpl: container_1671022279734_0001_01_000010 Container Transitioned from NEW to ALLOCATED
2022-12-14 12:55:12,213 INFO org.apache.hadoop.yarn.server.resourcemanager.scheduler.common.fica.FiCaSchedulerNode: Assigned container container_1671022279734_0001_01_000010 of capacity <memory:1024, vCores:1> on host adh-test-00-mnode1.ru-central1.internal:8041, which has 3 containers, <memory:3072, vCores:3> used and <memory:3985, vCores:-1> available after allocation
2022-12-14 12:55:12,213 INFO org.apache.hadoop.yarn.server.resourcemanager.RMAuditLogger: USER=yarn	OPERATION=AM Allocated Container	TARGET=SchedulerApp	RESULT=SUCCESS	APPID=application_1671022279734_0001	CONTAINERID=container_1671022279734_0001_01_000010	RESOURCE=<memory:1024, vCores:1>	QUEUENAME=default
2022-12-14 12:55:12,213 INFO org.apache.hadoop.yarn.server.resourcemanager.scheduler.capacity.ParentQueue: assignedContainer queue=root usedCapacity=0.5320486 absoluteUsedCapacity=0.5320486 used=<memory:11264, vCores:10> cluster=<memory:21171, vCores:6>
2022-12-14 12:55:12,213 INFO org.apache.hadoop.yarn.server.resourcemanager.scheduler.capacity.CapacityScheduler: Allocation proposal accepted
2022-12-14 12:55:12,213 INFO org.apache.hadoop.yarn.server.resourcemanager.scheduler.capacity.allocator.AbstractContainerAllocator: assignedContainer application attempt=appattempt_1671022279734_0001_000001 container=null queue=default clusterResource=<memory:21171, vCores:6> type=NODE_LOCAL requestedPartition=
2022-12-14 12:55:12,213 INFO org.apache.hadoop.yarn.server.resourcemanager.rmcontainer.RMContainerImpl: container_1671022279734_0001_01_000011 Container Transitioned from NEW to ALLOCATED
2022-12-14 12:55:12,213 INFO org.apache.hadoop.yarn.server.resourcemanager.scheduler.common.fica.FiCaSchedulerNode: Assigned container container_1671022279734_0001_01_000011 of capacity <memory:1024, vCores:1> on host adh-test-00-mnode1.ru-central1.internal:8041, which has 4 containers, <memory:4096, vCores:4> used and <memory:2961, vCores:-2> available after allocation
2022-12-14 12:55:12,213 INFO org.apache.hadoop.yarn.server.resourcemanager.RMAuditLogger: USER=yarn	OPERATION=AM Allocated Container	TARGET=SchedulerApp	RESULT=SUCCESS	APPID=application_1671022279734_0001	CONTAINERID=container_1671022279734_0001_01_000011	RESOURCE=<memory:1024, vCores:1>	QUEUENAME=default
2022-12-14 12:55:12,213 INFO org.apache.hadoop.yarn.server.resourcemanager.scheduler.capacity.ParentQueue: assignedContainer queue=root usedCapacity=0.5804166 absoluteUsedCapacity=0.5804166 used=<memory:12288, vCores:11> cluster=<memory:21171, vCores:6>
2022-12-14 12:55:12,213 INFO org.apache.hadoop.yarn.server.resourcemanager.scheduler.capacity.CapacityScheduler: Allocation proposal accepted
2022-12-14 12:55:12,214 INFO org.apache.hadoop.yarn.server.resourcemanager.scheduler.capacity.allocator.AbstractContainerAllocator: assignedContainer application attempt=appattempt_1671022279734_0001_000001 container=null queue=default clusterResource=<memory:21171, vCores:6> type=NODE_LOCAL requestedPartition=
2022-12-14 12:55:12,214 INFO org.apache.hadoop.yarn.server.resourcemanager.rmcontainer.RMContainerImpl: container_1671022279734_0001_01_000012 Container Transitioned from NEW to ALLOCATED
2022-12-14 12:55:12,214 INFO org.apache.hadoop.yarn.server.resourcemanager.scheduler.common.fica.FiCaSchedulerNode: Assigned container container_1671022279734_0001_01_000012 of capacity <memory:1024, vCores:1> on host adh-test-00-mnode1.ru-central1.internal:8041, which has 5 containers, <memory:5120, vCores:5> used and <memory:1937, vCores:-3> available after allocation
2022-12-14 12:55:12,214 INFO org.apache.hadoop.yarn.server.resourcemanager.RMAuditLogger: USER=yarn	OPERATION=AM Allocated Container	TARGET=SchedulerApp	RESULT=SUCCESS	APPID=application_1671022279734_0001	CONTAINERID=container_1671022279734_0001_01_000012	RESOURCE=<memory:1024, vCores:1>	QUEUENAME=default
2022-12-14 12:55:12,214 INFO org.apache.hadoop.yarn.server.resourcemanager.scheduler.capacity.ParentQueue: assignedContainer queue=root usedCapacity=0.62878466 absoluteUsedCapacity=0.62878466 used=<memory:13312, vCores:12> cluster=<memory:21171, vCores:6>
2022-12-14 12:55:12,214 INFO org.apache.hadoop.yarn.server.resourcemanager.scheduler.capacity.CapacityScheduler: Allocation proposal accepted
2022-12-14 12:55:12,214 INFO org.apache.hadoop.yarn.server.resourcemanager.scheduler.capacity.allocator.AbstractContainerAllocator: assignedContainer application attempt=appattempt_1671022279734_0001_000001 container=null queue=default clusterResource=<memory:21171, vCores:6> type=NODE_LOCAL requestedPartition=
2022-12-14 12:55:12,215 INFO org.apache.hadoop.yarn.server.resourcemanager.rmcontainer.RMContainerImpl: container_1671022279734_0001_01_000013 Container Transitioned from NEW to ALLOCATED
2022-12-14 12:55:12,215 INFO org.apache.hadoop.yarn.server.resourcemanager.scheduler.common.fica.FiCaSchedulerNode: Assigned container container_1671022279734_0001_01_000013 of capacity <memory:1024, vCores:1> on host adh-test-00-mnode1.ru-central1.internal:8041, which has 6 containers, <memory:6144, vCores:6> used and <memory:913, vCores:-4> available after allocation
2022-12-14 12:55:12,215 INFO org.apache.hadoop.yarn.server.resourcemanager.RMAuditLogger: USER=yarn	OPERATION=AM Allocated Container	TARGET=SchedulerApp	RESULT=SUCCESS	APPID=application_1671022279734_0001	CONTAINERID=container_1671022279734_0001_01_000013	RESOURCE=<memory:1024, vCores:1>	QUEUENAME=default
2022-12-14 12:55:12,215 INFO org.apache.hadoop.yarn.server.resourcemanager.scheduler.capacity.ParentQueue: assignedContainer queue=root usedCapacity=0.6771527 absoluteUsedCapacity=0.6771527 used=<memory:14336, vCores:13> cluster=<memory:21171, vCores:6>
2022-12-14 12:55:12,215 INFO org.apache.hadoop.yarn.server.resourcemanager.scheduler.capacity.CapacityScheduler: Allocation proposal accepted
2022-12-14 12:55:12,651 INFO org.apache.hadoop.yarn.server.resourcemanager.scheduler.capacity.allocator.AbstractContainerAllocator: assignedContainer application attempt=appattempt_1671022279734_0001_000001 container=null queue=default clusterResource=<memory:21171, vCores:6> type=NODE_LOCAL requestedPartition=
2022-12-14 12:55:12,652 INFO org.apache.hadoop.yarn.server.resourcemanager.rmcontainer.RMContainerImpl: container_1671022279734_0001_01_000014 Container Transitioned from NEW to ALLOCATED
2022-12-14 12:55:12,652 INFO org.apache.hadoop.yarn.server.resourcemanager.scheduler.common.fica.FiCaSchedulerNode: Assigned container container_1671022279734_0001_01_000014 of capacity <memory:1024, vCores:1> on host adh-test-00-mnode2.ru-central1.internal:8041, which has 2 containers, <memory:3072, vCores:2> used and <memory:3985, vCores:0> available after allocation
2022-12-14 12:55:12,652 INFO org.apache.hadoop.yarn.server.resourcemanager.RMAuditLogger: USER=yarn	OPERATION=AM Allocated Container	TARGET=SchedulerApp	RESULT=SUCCESS	APPID=application_1671022279734_0001	CONTAINERID=container_1671022279734_0001_01_000014	RESOURCE=<memory:1024, vCores:1>	QUEUENAME=default
2022-12-14 12:55:12,652 INFO org.apache.hadoop.yarn.server.resourcemanager.scheduler.capacity.ParentQueue: assignedContainer queue=root usedCapacity=0.72552073 absoluteUsedCapacity=0.72552073 used=<memory:15360, vCores:14> cluster=<memory:21171, vCores:6>
2022-12-14 12:55:12,652 INFO org.apache.hadoop.yarn.server.resourcemanager.scheduler.capacity.CapacityScheduler: Allocation proposal accepted
2022-12-14 12:55:12,653 INFO org.apache.hadoop.yarn.server.resourcemanager.scheduler.capacity.allocator.AbstractContainerAllocator: assignedContainer application attempt=appattempt_1671022279734_0001_000001 container=null queue=default clusterResource=<memory:21171, vCores:6> type=NODE_LOCAL requestedPartition=
2022-12-14 12:55:12,653 INFO org.apache.hadoop.yarn.server.resourcemanager.rmcontainer.RMContainerImpl: container_1671022279734_0001_01_000015 Container Transitioned from NEW to ALLOCATED
2022-12-14 12:55:12,653 INFO org.apache.hadoop.yarn.server.resourcemanager.scheduler.common.fica.FiCaSchedulerNode: Assigned container container_1671022279734_0001_01_000015 of capacity <memory:1024, vCores:1> on host adh-test-00-mnode2.ru-central1.internal:8041, which has 3 containers, <memory:4096, vCores:3> used and <memory:2961, vCores:-1> available after allocation
2022-12-14 12:55:12,653 INFO org.apache.hadoop.yarn.server.resourcemanager.RMAuditLogger: USER=yarn	OPERATION=AM Allocated Container	TARGET=SchedulerApp	RESULT=SUCCESS	APPID=application_1671022279734_0001	CONTAINERID=container_1671022279734_0001_01_000015	RESOURCE=<memory:1024, vCores:1>	QUEUENAME=default
2022-12-14 12:55:12,653 INFO org.apache.hadoop.yarn.server.resourcemanager.scheduler.capacity.ParentQueue: assignedContainer queue=root usedCapacity=0.7738888 absoluteUsedCapacity=0.7738888 used=<memory:16384, vCores:15> cluster=<memory:21171, vCores:6>
2022-12-14 12:55:12,653 INFO org.apache.hadoop.yarn.server.resourcemanager.scheduler.capacity.CapacityScheduler: Allocation proposal accepted
2022-12-14 12:55:12,654 INFO org.apache.hadoop.yarn.server.resourcemanager.scheduler.capacity.allocator.AbstractContainerAllocator: assignedContainer application attempt=appattempt_1671022279734_0001_000001 container=null queue=default clusterResource=<memory:21171, vCores:6> type=NODE_LOCAL requestedPartition=
2022-12-14 12:55:12,654 INFO org.apache.hadoop.yarn.server.resourcemanager.rmcontainer.RMContainerImpl: container_1671022279734_0001_01_000016 Container Transitioned from NEW to ALLOCATED
2022-12-14 12:55:12,654 INFO org.apache.hadoop.yarn.server.resourcemanager.scheduler.common.fica.FiCaSchedulerNode: Assigned container container_1671022279734_0001_01_000016 of capacity <memory:1024, vCores:1> on host adh-test-00-mnode2.ru-central1.internal:8041, which has 4 containers, <memory:5120, vCores:4> used and <memory:1937, vCores:-2> available after allocation
2022-12-14 12:55:12,654 INFO org.apache.hadoop.yarn.server.resourcemanager.RMAuditLogger: USER=yarn	OPERATION=AM Allocated Container	TARGET=SchedulerApp	RESULT=SUCCESS	APPID=application_1671022279734_0001	CONTAINERID=container_1671022279734_0001_01_000016	RESOURCE=<memory:1024, vCores:1>	QUEUENAME=default
2022-12-14 12:55:12,654 INFO org.apache.hadoop.yarn.server.resourcemanager.scheduler.capacity.ParentQueue: assignedContainer queue=root usedCapacity=0.82225686 absoluteUsedCapacity=0.82225686 used=<memory:17408, vCores:16> cluster=<memory:21171, vCores:6>
2022-12-14 12:55:12,654 INFO org.apache.hadoop.yarn.server.resourcemanager.scheduler.capacity.CapacityScheduler: Allocation proposal accepted
2022-12-14 12:55:12,654 INFO org.apache.hadoop.yarn.server.resourcemanager.scheduler.capacity.allocator.AbstractContainerAllocator: assignedContainer application attempt=appattempt_1671022279734_0001_000001 container=null queue=default clusterResource=<memory:21171, vCores:6> type=NODE_LOCAL requestedPartition=
2022-12-14 12:55:12,655 INFO org.apache.hadoop.yarn.server.resourcemanager.rmcontainer.RMContainerImpl: container_1671022279734_0001_01_000017 Container Transitioned from NEW to ALLOCATED
2022-12-14 12:55:12,655 INFO org.apache.hadoop.yarn.server.resourcemanager.scheduler.common.fica.FiCaSchedulerNode: Assigned container container_1671022279734_0001_01_000017 of capacity <memory:1024, vCores:1> on host adh-test-00-mnode2.ru-central1.internal:8041, which has 5 containers, <memory:6144, vCores:5> used and <memory:913, vCores:-3> available after allocation
2022-12-14 12:55:12,655 INFO org.apache.hadoop.yarn.server.resourcemanager.RMAuditLogger: USER=yarn	OPERATION=AM Allocated Container	TARGET=SchedulerApp	RESULT=SUCCESS	APPID=application_1671022279734_0001	CONTAINERID=container_1671022279734_0001_01_000017	RESOURCE=<memory:1024, vCores:1>	QUEUENAME=default
2022-12-14 12:55:12,656 INFO org.apache.hadoop.yarn.server.resourcemanager.scheduler.capacity.ParentQueue: assignedContainer queue=root usedCapacity=0.8706249 absoluteUsedCapacity=0.8706249 used=<memory:18432, vCores:17> cluster=<memory:21171, vCores:6>
2022-12-14 12:55:12,656 INFO org.apache.hadoop.yarn.server.resourcemanager.scheduler.capacity.CapacityScheduler: Allocation proposal accepted
2022-12-14 12:55:12,738 INFO org.apache.hadoop.yarn.server.resourcemanager.security.NMTokenSecretManagerInRM: Sending NMToken for nodeId : adh-test-00-mnode3.ru-central1.internal:8041 for container : container_1671022279734_0001_01_000002
2022-12-14 12:55:12,739 INFO org.apache.hadoop.yarn.server.resourcemanager.rmcontainer.RMContainerImpl: container_1671022279734_0001_01_000002 Container Transitioned from ALLOCATED to ACQUIRED
2022-12-14 12:55:12,741 INFO org.apache.hadoop.yarn.server.resourcemanager.rmcontainer.RMContainerImpl: container_1671022279734_0001_01_000003 Container Transitioned from ALLOCATED to ACQUIRED
2022-12-14 12:55:12,744 INFO org.apache.hadoop.yarn.server.resourcemanager.rmcontainer.RMContainerImpl: container_1671022279734_0001_01_000004 Container Transitioned from ALLOCATED to ACQUIRED
2022-12-14 12:55:12,746 INFO org.apache.hadoop.yarn.server.resourcemanager.rmcontainer.RMContainerImpl: container_1671022279734_0001_01_000005 Container Transitioned from ALLOCATED to ACQUIRED
2022-12-14 12:55:12,748 INFO org.apache.hadoop.yarn.server.resourcemanager.rmcontainer.RMContainerImpl: container_1671022279734_0001_01_000006 Container Transitioned from ALLOCATED to ACQUIRED
2022-12-14 12:55:12,749 INFO org.apache.hadoop.yarn.server.resourcemanager.rmcontainer.RMContainerImpl: container_1671022279734_0001_01_000007 Container Transitioned from ALLOCATED to ACQUIRED
2022-12-14 12:55:12,757 INFO org.apache.hadoop.yarn.server.resourcemanager.security.NMTokenSecretManagerInRM: Sending NMToken for nodeId : adh-test-00-mnode1.ru-central1.internal:8041 for container : container_1671022279734_0001_01_000008
2022-12-14 12:55:12,758 INFO org.apache.hadoop.yarn.server.resourcemanager.rmcontainer.RMContainerImpl: container_1671022279734_0001_01_000008 Container Transitioned from ALLOCATED to ACQUIRED
2022-12-14 12:55:12,760 INFO org.apache.hadoop.yarn.server.resourcemanager.rmcontainer.RMContainerImpl: container_1671022279734_0001_01_000009 Container Transitioned from ALLOCATED to ACQUIRED
2022-12-14 12:55:12,761 INFO org.apache.hadoop.yarn.server.resourcemanager.rmcontainer.RMContainerImpl: container_1671022279734_0001_01_000010 Container Transitioned from ALLOCATED to ACQUIRED
2022-12-14 12:55:12,762 INFO org.apache.hadoop.yarn.server.resourcemanager.rmcontainer.RMContainerImpl: container_1671022279734_0001_01_000011 Container Transitioned from ALLOCATED to ACQUIRED
2022-12-14 12:55:12,763 INFO org.apache.hadoop.yarn.server.resourcemanager.rmcontainer.RMContainerImpl: container_1671022279734_0001_01_000012 Container Transitioned from ALLOCATED to ACQUIRED
2022-12-14 12:55:12,764 INFO org.apache.hadoop.yarn.server.resourcemanager.rmcontainer.RMContainerImpl: container_1671022279734_0001_01_000013 Container Transitioned from ALLOCATED to ACQUIRED
2022-12-14 12:55:12,765 INFO org.apache.hadoop.yarn.server.resourcemanager.security.NMTokenSecretManagerInRM: Sending NMToken for nodeId : adh-test-00-mnode2.ru-central1.internal:8041 for container : container_1671022279734_0001_01_000014
2022-12-14 12:55:12,766 INFO org.apache.hadoop.yarn.server.resourcemanager.rmcontainer.RMContainerImpl: container_1671022279734_0001_01_000014 Container Transitioned from ALLOCATED to ACQUIRED
2022-12-14 12:55:12,768 INFO org.apache.hadoop.yarn.server.resourcemanager.rmcontainer.RMContainerImpl: container_1671022279734_0001_01_000015 Container Transitioned from ALLOCATED to ACQUIRED
2022-12-14 12:55:12,769 INFO org.apache.hadoop.yarn.server.resourcemanager.rmcontainer.RMContainerImpl: container_1671022279734_0001_01_000016 Container Transitioned from ALLOCATED to ACQUIRED
2022-12-14 12:55:12,770 INFO org.apache.hadoop.yarn.server.resourcemanager.rmcontainer.RMContainerImpl: container_1671022279734_0001_01_000017 Container Transitioned from ALLOCATED to ACQUIRED
2022-12-14 12:55:13,660 INFO org.apache.hadoop.yarn.server.resourcemanager.rmcontainer.RMContainerImpl: container_1671022279734_0001_01_000014 Container Transitioned from ACQUIRED to RUNNING
2022-12-14 12:55:13,661 INFO org.apache.hadoop.yarn.server.resourcemanager.rmcontainer.RMContainerImpl: container_1671022279734_0001_01_000015 Container Transitioned from ACQUIRED to RUNNING
2022-12-14 12:55:13,662 INFO org.apache.hadoop.yarn.server.resourcemanager.rmcontainer.RMContainerImpl: container_1671022279734_0001_01_000016 Container Transitioned from ACQUIRED to RUNNING
2022-12-14 12:55:13,662 INFO org.apache.hadoop.yarn.server.resourcemanager.rmcontainer.RMContainerImpl: container_1671022279734_0001_01_000017 Container Transitioned from ACQUIRED to RUNNING
2022-12-14 12:55:13,812 INFO org.apache.hadoop.yarn.server.resourcemanager.scheduler.AppSchedulingInfo: checking for deactivate of application :application_1671022279734_0001
2022-12-14 12:55:13,974 INFO org.apache.hadoop.yarn.server.resourcemanager.rmcontainer.RMContainerImpl: container_1671022279734_0001_01_000002 Container Transitioned from ACQUIRED to RUNNING
2022-12-14 12:55:13,975 INFO org.apache.hadoop.yarn.server.resourcemanager.rmcontainer.RMContainerImpl: container_1671022279734_0001_01_000003 Container Transitioned from ACQUIRED to RUNNING
2022-12-14 12:55:13,975 INFO org.apache.hadoop.yarn.server.resourcemanager.rmcontainer.RMContainerImpl: container_1671022279734_0001_01_000004 Container Transitioned from ACQUIRED to RUNNING
2022-12-14 12:55:13,975 INFO org.apache.hadoop.yarn.server.resourcemanager.rmcontainer.RMContainerImpl: container_1671022279734_0001_01_000005 Container Transitioned from ACQUIRED to RUNNING
2022-12-14 12:55:13,976 INFO org.apache.hadoop.yarn.server.resourcemanager.rmcontainer.RMContainerImpl: container_1671022279734_0001_01_000006 Container Transitioned from ACQUIRED to RUNNING
2022-12-14 12:55:13,976 INFO org.apache.hadoop.yarn.server.resourcemanager.rmcontainer.RMContainerImpl: container_1671022279734_0001_01_000007 Container Transitioned from ACQUIRED to RUNNING
2022-12-14 12:55:14,229 INFO org.apache.hadoop.yarn.server.resourcemanager.rmcontainer.RMContainerImpl: container_1671022279734_0001_01_000008 Container Transitioned from ACQUIRED to RUNNING
2022-12-14 12:55:14,230 INFO org.apache.hadoop.yarn.server.resourcemanager.rmcontainer.RMContainerImpl: container_1671022279734_0001_01_000009 Container Transitioned from ACQUIRED to RUNNING
2022-12-14 12:55:14,231 INFO org.apache.hadoop.yarn.server.resourcemanager.rmcontainer.RMContainerImpl: container_1671022279734_0001_01_000010 Container Transitioned from ACQUIRED to RUNNING
2022-12-14 12:55:14,231 INFO org.apache.hadoop.yarn.server.resourcemanager.rmcontainer.RMContainerImpl: container_1671022279734_0001_01_000011 Container Transitioned from ACQUIRED to RUNNING
2022-12-14 12:55:14,231 INFO org.apache.hadoop.yarn.server.resourcemanager.rmcontainer.RMContainerImpl: container_1671022279734_0001_01_000012 Container Transitioned from ACQUIRED to RUNNING
2022-12-14 12:55:14,232 INFO org.apache.hadoop.yarn.server.resourcemanager.rmcontainer.RMContainerImpl: container_1671022279734_0001_01_000013 Container Transitioned from ACQUIRED to RUNNING
2022-12-14 12:55:19,066 INFO org.apache.hadoop.yarn.server.resourcemanager.rmcontainer.RMContainerImpl: container_1671022279734_0001_01_000014 Container Transitioned from RUNNING to COMPLETED
2022-12-14 12:55:19,066 INFO org.apache.hadoop.yarn.server.resourcemanager.RMAuditLogger: USER=yarn	OPERATION=AM Released Container	TARGET=SchedulerApp	RESULT=SUCCESS	APPID=application_1671022279734_0001	CONTAINERID=container_1671022279734_0001_01_000014	RESOURCE=<memory:1024, vCores:1>	QUEUENAME=default
2022-12-14 12:55:19,307 INFO org.apache.hadoop.yarn.server.resourcemanager.rmcontainer.RMContainerImpl: container_1671022279734_0001_01_000017 Container Transitioned from RUNNING to COMPLETED
2022-12-14 12:55:19,307 INFO org.apache.hadoop.yarn.server.resourcemanager.RMAuditLogger: USER=yarn	OPERATION=AM Released Container	TARGET=SchedulerApp	RESULT=SUCCESS	APPID=application_1671022279734_0001	CONTAINERID=container_1671022279734_0001_01_000017	RESOURCE=<memory:1024, vCores:1>	QUEUENAME=default
2022-12-14 12:55:19,348 INFO org.apache.hadoop.yarn.server.resourcemanager.rmcontainer.RMContainerImpl: container_1671022279734_0001_01_000015 Container Transitioned from RUNNING to COMPLETED
2022-12-14 12:55:19,348 INFO org.apache.hadoop.yarn.server.resourcemanager.RMAuditLogger: USER=yarn	OPERATION=AM Released Container	TARGET=SchedulerApp	RESULT=SUCCESS	APPID=application_1671022279734_0001	CONTAINERID=container_1671022279734_0001_01_000015	RESOURCE=<memory:1024, vCores:1>	QUEUENAME=default
2022-12-14 12:55:20,388 INFO org.apache.hadoop.yarn.server.resourcemanager.rmcontainer.RMContainerImpl: container_1671022279734_0001_01_000016 Container Transitioned from RUNNING to COMPLETED
2022-12-14 12:55:20,388 INFO org.apache.hadoop.yarn.server.resourcemanager.RMAuditLogger: USER=yarn	OPERATION=AM Released Container	TARGET=SchedulerApp	RESULT=SUCCESS	APPID=application_1671022279734_0001	CONTAINERID=container_1671022279734_0001_01_000016	RESOURCE=<memory:1024, vCores:1>	QUEUENAME=default
2022-12-14 12:55:20,390 INFO org.apache.hadoop.yarn.server.resourcemanager.scheduler.capacity.allocator.AbstractContainerAllocator: assignedContainer application attempt=appattempt_1671022279734_0001_000001 container=null queue=default clusterResource=<memory:21171, vCores:6> type=OFF_SWITCH requestedPartition=
2022-12-14 12:55:20,391 INFO org.apache.hadoop.yarn.server.resourcemanager.rmcontainer.RMContainerImpl: container_1671022279734_0001_01_000018 Container Transitioned from NEW to ALLOCATED
2022-12-14 12:55:20,391 INFO org.apache.hadoop.yarn.server.resourcemanager.scheduler.common.fica.FiCaSchedulerNode: Assigned container container_1671022279734_0001_01_000018 of capacity <memory:1024, vCores:1> on host adh-test-00-mnode2.ru-central1.internal:8041, which has 2 containers, <memory:3072, vCores:2> used and <memory:3985, vCores:0> available after allocation
2022-12-14 12:55:20,391 INFO org.apache.hadoop.yarn.server.resourcemanager.RMAuditLogger: USER=yarn	OPERATION=AM Allocated Container	TARGET=SchedulerApp	RESULT=SUCCESS	APPID=application_1671022279734_0001	CONTAINERID=container_1671022279734_0001_01_000018	RESOURCE=<memory:1024, vCores:1>	QUEUENAME=default
2022-12-14 12:55:20,391 INFO org.apache.hadoop.yarn.server.resourcemanager.scheduler.capacity.ParentQueue: assignedContainer queue=root usedCapacity=0.72552073 absoluteUsedCapacity=0.72552073 used=<memory:15360, vCores:14> cluster=<memory:21171, vCores:6>
2022-12-14 12:55:20,391 INFO org.apache.hadoop.yarn.server.resourcemanager.scheduler.capacity.CapacityScheduler: Allocation proposal accepted
2022-12-14 12:55:21,136 INFO org.apache.hadoop.yarn.server.resourcemanager.rmcontainer.RMContainerImpl: container_1671022279734_0001_01_000018 Container Transitioned from ALLOCATED to ACQUIRED
2022-12-14 12:55:21,407 INFO org.apache.hadoop.yarn.server.resourcemanager.rmcontainer.RMContainerImpl: container_1671022279734_0001_01_000018 Container Transitioned from ACQUIRED to RUNNING
2022-12-14 12:55:22,166 INFO org.apache.hadoop.yarn.server.resourcemanager.scheduler.AppSchedulingInfo: checking for deactivate of application :application_1671022279734_0001
2022-12-14 12:55:23,342 INFO org.apache.hadoop.yarn.server.resourcemanager.rmcontainer.RMContainerImpl: container_1671022279734_0001_01_000002 Container Transitioned from RUNNING to COMPLETED
2022-12-14 12:55:23,342 INFO org.apache.hadoop.yarn.server.resourcemanager.RMAuditLogger: USER=yarn	OPERATION=AM Released Container	TARGET=SchedulerApp	RESULT=SUCCESS	APPID=application_1671022279734_0001	CONTAINERID=container_1671022279734_0001_01_000002	RESOURCE=<memory:1024, vCores:1>	QUEUENAME=default
2022-12-14 12:55:23,389 INFO org.apache.hadoop.yarn.server.resourcemanager.rmcontainer.RMContainerImpl: container_1671022279734_0001_01_000005 Container Transitioned from RUNNING to COMPLETED
2022-12-14 12:55:23,389 INFO org.apache.hadoop.yarn.server.resourcemanager.RMAuditLogger: USER=yarn	OPERATION=AM Released Container	TARGET=SchedulerApp	RESULT=SUCCESS	APPID=application_1671022279734_0001	CONTAINERID=container_1671022279734_0001_01_000005	RESOURCE=<memory:1024, vCores:1>	QUEUENAME=default
2022-12-14 12:55:23,444 INFO org.apache.hadoop.yarn.server.resourcemanager.rmcontainer.RMContainerImpl: container_1671022279734_0001_01_000007 Container Transitioned from RUNNING to COMPLETED
2022-12-14 12:55:23,444 INFO org.apache.hadoop.yarn.server.resourcemanager.RMAuditLogger: USER=yarn	OPERATION=AM Released Container	TARGET=SchedulerApp	RESULT=SUCCESS	APPID=application_1671022279734_0001	CONTAINERID=container_1671022279734_0001_01_000007	RESOURCE=<memory:1024, vCores:1>	QUEUENAME=default
2022-12-14 12:55:23,484 INFO org.apache.hadoop.yarn.server.resourcemanager.rmcontainer.RMContainerImpl: container_1671022279734_0001_01_000004 Container Transitioned from RUNNING to COMPLETED
2022-12-14 12:55:23,484 INFO org.apache.hadoop.yarn.server.resourcemanager.RMAuditLogger: USER=yarn	OPERATION=AM Released Container	TARGET=SchedulerApp	RESULT=SUCCESS	APPID=application_1671022279734_0001	CONTAINERID=container_1671022279734_0001_01_000004	RESOURCE=<memory:1024, vCores:1>	QUEUENAME=default
2022-12-14 12:55:23,582 INFO org.apache.hadoop.yarn.server.resourcemanager.rmcontainer.RMContainerImpl: container_1671022279734_0001_01_000006 Container Transitioned from RUNNING to COMPLETED
2022-12-14 12:55:23,582 INFO org.apache.hadoop.yarn.server.resourcemanager.RMAuditLogger: USER=yarn	OPERATION=AM Released Container	TARGET=SchedulerApp	RESULT=SUCCESS	APPID=application_1671022279734_0001	CONTAINERID=container_1671022279734_0001_01_000006	RESOURCE=<memory:1024, vCores:1>	QUEUENAME=default
2022-12-14 12:55:23,674 INFO org.apache.hadoop.yarn.server.resourcemanager.rmcontainer.RMContainerImpl: container_1671022279734_0001_01_000003 Container Transitioned from RUNNING to COMPLETED
2022-12-14 12:55:23,675 INFO org.apache.hadoop.yarn.server.resourcemanager.RMAuditLogger: USER=yarn	OPERATION=AM Released Container	TARGET=SchedulerApp	RESULT=SUCCESS	APPID=application_1671022279734_0001	CONTAINERID=container_1671022279734_0001_01_000003	RESOURCE=<memory:1024, vCores:1>	QUEUENAME=default
2022-12-14 12:55:24,060 INFO org.apache.hadoop.yarn.server.resourcemanager.rmcontainer.RMContainerImpl: container_1671022279734_0001_01_000013 Container Transitioned from RUNNING to COMPLETED
2022-12-14 12:55:24,060 INFO org.apache.hadoop.yarn.server.resourcemanager.RMAuditLogger: USER=yarn	OPERATION=AM Released Container	TARGET=SchedulerApp	RESULT=SUCCESS	APPID=application_1671022279734_0001	CONTAINERID=container_1671022279734_0001_01_000013	RESOURCE=<memory:1024, vCores:1>	QUEUENAME=default
2022-12-14 12:55:24,062 INFO org.apache.hadoop.yarn.server.resourcemanager.rmcontainer.RMContainerImpl: container_1671022279734_0001_01_000011 Container Transitioned from RUNNING to COMPLETED
2022-12-14 12:55:24,062 INFO org.apache.hadoop.yarn.server.resourcemanager.RMAuditLogger: USER=yarn	OPERATION=AM Released Container	TARGET=SchedulerApp	RESULT=SUCCESS	APPID=application_1671022279734_0001	CONTAINERID=container_1671022279734_0001_01_000011	RESOURCE=<memory:1024, vCores:1>	QUEUENAME=default
2022-12-14 12:55:24,329 INFO org.apache.hadoop.yarn.server.resourcemanager.rmcontainer.RMContainerImpl: container_1671022279734_0001_01_000009 Container Transitioned from RUNNING to COMPLETED
2022-12-14 12:55:24,329 INFO org.apache.hadoop.yarn.server.resourcemanager.RMAuditLogger: USER=yarn	OPERATION=AM Released Container	TARGET=SchedulerApp	RESULT=SUCCESS	APPID=application_1671022279734_0001	CONTAINERID=container_1671022279734_0001_01_000009	RESOURCE=<memory:1024, vCores:1>	QUEUENAME=default
2022-12-14 12:55:24,355 INFO org.apache.hadoop.yarn.server.resourcemanager.rmcontainer.RMContainerImpl: container_1671022279734_0001_01_000010 Container Transitioned from RUNNING to COMPLETED
2022-12-14 12:55:24,355 INFO org.apache.hadoop.yarn.server.resourcemanager.RMAuditLogger: USER=yarn	OPERATION=AM Released Container	TARGET=SchedulerApp	RESULT=SUCCESS	APPID=application_1671022279734_0001	CONTAINERID=container_1671022279734_0001_01_000010	RESOURCE=<memory:1024, vCores:1>	QUEUENAME=default
2022-12-14 12:55:24,388 INFO org.apache.hadoop.yarn.server.resourcemanager.rmcontainer.RMContainerImpl: container_1671022279734_0001_01_000012 Container Transitioned from RUNNING to COMPLETED
2022-12-14 12:55:24,388 INFO org.apache.hadoop.yarn.server.resourcemanager.RMAuditLogger: USER=yarn	OPERATION=AM Released Container	TARGET=SchedulerApp	RESULT=SUCCESS	APPID=application_1671022279734_0001	CONTAINERID=container_1671022279734_0001_01_000012	RESOURCE=<memory:1024, vCores:1>	QUEUENAME=default
2022-12-14 12:55:24,412 INFO org.apache.hadoop.yarn.server.resourcemanager.rmcontainer.RMContainerImpl: container_1671022279734_0001_01_000008 Container Transitioned from RUNNING to COMPLETED
2022-12-14 12:55:24,412 INFO org.apache.hadoop.yarn.server.resourcemanager.RMAuditLogger: USER=yarn	OPERATION=AM Released Container	TARGET=SchedulerApp	RESULT=SUCCESS	APPID=application_1671022279734_0001	CONTAINERID=container_1671022279734_0001_01_000008	RESOURCE=<memory:1024, vCores:1>	QUEUENAME=default
2022-12-14 12:55:24,544 INFO org.apache.hadoop.yarn.server.resourcemanager.rmcontainer.RMContainerImpl: container_1671022279734_0001_01_000018 Container Transitioned from RUNNING to COMPLETED
2022-12-14 12:55:24,544 INFO org.apache.hadoop.yarn.server.resourcemanager.RMAuditLogger: USER=yarn	OPERATION=AM Released Container	TARGET=SchedulerApp	RESULT=SUCCESS	APPID=application_1671022279734_0001	CONTAINERID=container_1671022279734_0001_01_000018	RESOURCE=<memory:1024, vCores:1>	QUEUENAME=default
2022-12-14 12:55:24,606 INFO org.apache.hadoop.yarn.server.resourcemanager.rmapp.attempt.RMAppAttemptImpl: Updating application attempt appattempt_1671022279734_0001_000001 with final state: FINISHING, and exit status: -1000
2022-12-14 12:55:24,607 INFO org.apache.hadoop.yarn.server.resourcemanager.rmapp.attempt.RMAppAttemptImpl: appattempt_1671022279734_0001_000001 State change from RUNNING to FINAL_SAVING on event = UNREGISTERED
2022-12-14 12:55:24,607 INFO org.apache.hadoop.yarn.server.resourcemanager.rmapp.RMAppImpl: Updating application application_1671022279734_0001 with final state: FINISHING
2022-12-14 12:55:24,608 INFO org.apache.hadoop.yarn.server.resourcemanager.rmapp.RMAppImpl: application_1671022279734_0001 State change from RUNNING to FINAL_SAVING on event = ATTEMPT_UNREGISTERED
2022-12-14 12:55:24,608 INFO org.apache.hadoop.yarn.server.resourcemanager.recovery.RMStateStore: Updating info for app: application_1671022279734_0001
2022-12-14 12:55:24,608 INFO org.apache.hadoop.yarn.server.resourcemanager.rmapp.attempt.RMAppAttemptImpl: appattempt_1671022279734_0001_000001 State change from FINAL_SAVING to FINISHING on event = ATTEMPT_UPDATE_SAVED
2022-12-14 12:55:24,608 INFO org.apache.hadoop.yarn.server.resourcemanager.rmapp.RMAppImpl: application_1671022279734_0001 State change from FINAL_SAVING to FINISHING on event = APP_UPDATE_SAVED
2022-12-14 12:55:25,608 INFO org.apache.hadoop.yarn.server.resourcemanager.ApplicationMasterService: application_1671022279734_0001 unregistered successfully. 
2022-12-14 12:55:30,984 INFO org.apache.hadoop.yarn.server.resourcemanager.rmcontainer.RMContainerImpl: container_1671022279734_0001_01_000001 Container Transitioned from RUNNING to COMPLETED
2022-12-14 12:55:30,984 INFO org.apache.hadoop.yarn.server.resourcemanager.ApplicationMasterService: Unregistering app attempt : appattempt_1671022279734_0001_000001
2022-12-14 12:55:30,985 INFO org.apache.hadoop.yarn.server.resourcemanager.RMAuditLogger: USER=yarn	OPERATION=AM Released Container	TARGET=SchedulerApp	RESULT=SUCCESS	APPID=application_1671022279734_0001	CONTAINERID=container_1671022279734_0001_01_000001	RESOURCE=<memory:2048, vCores:1>	QUEUENAME=default
2022-12-14 12:55:30,986 INFO org.apache.hadoop.yarn.server.resourcemanager.security.AMRMTokenSecretManager: Application finished, removing password for appattempt_1671022279734_0001_000001
2022-12-14 12:55:30,988 INFO org.apache.hadoop.yarn.server.resourcemanager.rmapp.attempt.RMAppAttemptImpl: appattempt_1671022279734_0001_000001 State change from FINISHING to FINISHED on event = CONTAINER_FINISHED
2022-12-14 12:55:30,991 INFO org.apache.hadoop.yarn.server.resourcemanager.rmapp.RMAppImpl: application_1671022279734_0001 State change from FINISHING to FINISHED on event = ATTEMPT_FINISHED
2022-12-14 12:55:30,991 INFO org.apache.hadoop.yarn.server.resourcemanager.scheduler.capacity.CapacityScheduler: Application Attempt appattempt_1671022279734_0001_000001 is done. finalState=FINISHED
2022-12-14 12:55:30,991 INFO org.apache.hadoop.yarn.server.resourcemanager.scheduler.AppSchedulingInfo: Application application_1671022279734_0001 requests cleared
2022-12-14 12:55:30,992 INFO org.apache.hadoop.yarn.server.resourcemanager.amlauncher.AMLauncher: Cleaning master appattempt_1671022279734_0001_000001
2022-12-14 12:55:30,993 INFO org.apache.hadoop.yarn.server.resourcemanager.RMAuditLogger: USER=yarn	OPERATION=Application Finished - Succeeded	TARGET=RMAppManager	RESULT=SUCCESS	APPID=application_1671022279734_0001
2022-12-14 12:55:30,995 INFO org.apache.hadoop.yarn.server.resourcemanager.scheduler.capacity.LeafQueue: Application removed - appId: application_1671022279734_0001 user: yarn queue: default #user-pending-applications: 0 #user-active-applications: 0 #queue-pending-applications: 0 #queue-active-applications: 0
2022-12-14 12:55:30,995 INFO org.apache.hadoop.yarn.server.resourcemanager.scheduler.capacity.ParentQueue: Application removed - appId: application_1671022279734_0001 user: yarn leaf-queue of parent: root #applications: 0
2022-12-14 12:55:30,995 INFO org.apache.hadoop.yarn.server.resourcemanager.RMAppManager$ApplicationSummary: appId=application_1671022279734_0001,name=QuasiMonteCarlo,user=yarn,queue=default,state=FINISHED,trackingUrl=http://adh-test-00-mnode1.ru-central1.internal:8088/proxy/application_1671022279734_0001/,appMasterHost=adh-test-00-mnode2.ru-central1.internal,submitTime=1671022505181,startTime=1671022505266,finishTime=1671022524607,finalStatus=SUCCEEDED,memorySeconds=229187,vcoreSeconds=190,preemptedMemorySeconds=0,preemptedVcoreSeconds=0,preemptedAMContainers=0,preemptedNonAMContainers=0,preemptedResources=<memory:0\, vCores:0>,applicationType=MAPREDUCE,resourceSeconds=229187 MB-seconds\, 190 vcore-seconds,preemptedResourceSeconds=0 MB-seconds\, 0 vcore-seconds
2022-12-14 13:01:17,274 INFO org.apache.hadoop.yarn.server.resourcemanager.scheduler.AbstractYarnScheduler: Release request cache is cleaned up
2022-12-14 13:14:35,386 INFO org.apache.hadoop.yarn.server.resourcemanager.ClientRMService: Allocated new applicationId: 2
2022-12-14 13:14:36,043 INFO org.apache.hadoop.yarn.server.resourcemanager.scheduler.capacity.CapacityScheduler: Application 'application_1671022279734_0002' is submitted without priority hence considering default queue/cluster priority: 0
2022-12-14 13:14:36,043 INFO org.apache.hadoop.yarn.server.resourcemanager.scheduler.capacity.CapacityScheduler: Priority '0' is acceptable in queue : default for application: application_1671022279734_0002
2022-12-14 13:14:36,044 INFO org.apache.hadoop.yarn.server.resourcemanager.ClientRMService: Application with id 2 submitted by user hdfs
2022-12-14 13:14:36,044 INFO org.apache.hadoop.yarn.server.resourcemanager.RMAuditLogger: USER=hdfs	IP=10.130.0.4	OPERATION=Submit Application Request	TARGET=ClientRMService	RESULT=SUCCESS	APPID=application_1671022279734_0002	CALLERCONTEXT=CLI	QUEUENAME=default
2022-12-14 13:14:36,044 INFO org.apache.hadoop.yarn.server.resourcemanager.rmapp.RMAppImpl: Storing application with id application_1671022279734_0002
2022-12-14 13:14:36,045 INFO org.apache.hadoop.yarn.server.resourcemanager.recovery.RMStateStore: Storing info for app: application_1671022279734_0002
2022-12-14 13:14:36,045 INFO org.apache.hadoop.yarn.server.resourcemanager.rmapp.RMAppImpl: application_1671022279734_0002 State change from NEW to NEW_SAVING on event = START
2022-12-14 13:14:36,046 INFO org.apache.hadoop.yarn.server.resourcemanager.rmapp.RMAppImpl: application_1671022279734_0002 State change from NEW_SAVING to SUBMITTED on event = APP_NEW_SAVED
2022-12-14 13:14:36,049 INFO org.apache.hadoop.yarn.server.resourcemanager.scheduler.capacity.ParentQueue: Application added - appId: application_1671022279734_0002 user: hdfs leaf-queue of parent: root #applications: 1
2022-12-14 13:14:36,049 INFO org.apache.hadoop.yarn.server.resourcemanager.scheduler.capacity.CapacityScheduler: Accepted application application_1671022279734_0002 from user: hdfs, in queue: default
2022-12-14 13:14:36,049 INFO org.apache.hadoop.yarn.server.resourcemanager.rmapp.RMAppImpl: application_1671022279734_0002 State change from SUBMITTED to ACCEPTED on event = APP_ACCEPTED
2022-12-14 13:14:36,049 INFO org.apache.hadoop.yarn.server.resourcemanager.ApplicationMasterService: Registering app attempt : appattempt_1671022279734_0002_000001
2022-12-14 13:14:36,049 INFO org.apache.hadoop.yarn.server.resourcemanager.rmapp.attempt.RMAppAttemptImpl: appattempt_1671022279734_0002_000001 State change from NEW to SUBMITTED on event = START
2022-12-14 13:14:36,050 INFO org.apache.hadoop.yarn.server.resourcemanager.scheduler.capacity.LeafQueue: Application application_1671022279734_0002 from user: hdfs activated in queue: default
2022-12-14 13:14:36,050 INFO org.apache.hadoop.yarn.server.resourcemanager.scheduler.capacity.LeafQueue: Application added - appId: application_1671022279734_0002 user: hdfs, leaf-queue: default #user-pending-applications: 0 #user-active-applications: 1 #queue-pending-applications: 0 #queue-active-applications: 1
2022-12-14 13:14:36,050 INFO org.apache.hadoop.yarn.server.resourcemanager.scheduler.capacity.CapacityScheduler: Added Application Attempt appattempt_1671022279734_0002_000001 to scheduler from user hdfs in queue default
2022-12-14 13:14:36,053 INFO org.apache.hadoop.yarn.server.resourcemanager.rmapp.attempt.RMAppAttemptImpl: appattempt_1671022279734_0002_000001 State change from SUBMITTED to SCHEDULED on event = ATTEMPT_ADDED
2022-12-14 13:14:36,055 INFO org.apache.hadoop.yarn.server.resourcemanager.scheduler.capacity.allocator.AbstractContainerAllocator: assignedContainer application attempt=appattempt_1671022279734_0002_000001 container=null queue=default clusterResource=<memory:21171, vCores:6> type=OFF_SWITCH requestedPartition=
2022-12-14 13:14:36,057 INFO org.apache.hadoop.yarn.server.resourcemanager.rmcontainer.RMContainerImpl: container_1671022279734_0002_01_000001 Container Transitioned from NEW to ALLOCATED
2022-12-14 13:14:36,058 INFO org.apache.hadoop.yarn.server.resourcemanager.scheduler.common.fica.FiCaSchedulerNode: Assigned container container_1671022279734_0002_01_000001 of capacity <memory:2048, vCores:1> on host adh-test-00-mnode2.ru-central1.internal:8041, which has 1 containers, <memory:2048, vCores:1> used and <memory:5009, vCores:1> available after allocation
2022-12-14 13:14:36,058 INFO org.apache.hadoop.yarn.server.resourcemanager.RMAuditLogger: USER=hdfs	OPERATION=AM Allocated Container	TARGET=SchedulerApp	RESULT=SUCCESS	APPID=application_1671022279734_0002	CONTAINERID=container_1671022279734_0002_01_000001	RESOURCE=<memory:2048, vCores:1>	QUEUENAME=default
2022-12-14 13:14:36,059 INFO org.apache.hadoop.yarn.server.resourcemanager.security.NMTokenSecretManagerInRM: Sending NMToken for nodeId : adh-test-00-mnode2.ru-central1.internal:8041 for container : container_1671022279734_0002_01_000001
2022-12-14 13:14:36,063 INFO org.apache.hadoop.yarn.server.resourcemanager.rmcontainer.RMContainerImpl: container_1671022279734_0002_01_000001 Container Transitioned from ALLOCATED to ACQUIRED
2022-12-14 13:14:36,063 INFO org.apache.hadoop.yarn.server.resourcemanager.security.NMTokenSecretManagerInRM: Clear node set for appattempt_1671022279734_0002_000001
2022-12-14 13:14:36,063 INFO org.apache.hadoop.yarn.server.resourcemanager.rmapp.attempt.RMAppAttemptImpl: Storing attempt: AppId: application_1671022279734_0002 AttemptId: appattempt_1671022279734_0002_000001 MasterContainer: Container: [ContainerId: container_1671022279734_0002_01_000001, AllocationRequestId: -1, Version: 0, NodeId: adh-test-00-mnode2.ru-central1.internal:8041, NodeHttpAddress: adh-test-00-mnode2.ru-central1.internal:8042, Resource: <memory:2048, vCores:1>, Priority: 0, Token: Token { kind: ContainerToken, service: 10.130.0.5:8041 }, ExecutionType: GUARANTEED, ]
2022-12-14 13:14:36,064 INFO org.apache.hadoop.yarn.server.resourcemanager.scheduler.capacity.ParentQueue: assignedContainer queue=root usedCapacity=0.0967361 absoluteUsedCapacity=0.0967361 used=<memory:2048, vCores:1> cluster=<memory:21171, vCores:6>
2022-12-14 13:14:36,064 INFO org.apache.hadoop.yarn.server.resourcemanager.scheduler.capacity.CapacityScheduler: Allocation proposal accepted
2022-12-14 13:14:36,064 INFO org.apache.hadoop.yarn.server.resourcemanager.rmapp.attempt.RMAppAttemptImpl: appattempt_1671022279734_0002_000001 State change from SCHEDULED to ALLOCATED_SAVING on event = CONTAINER_ALLOCATED
2022-12-14 13:14:36,066 INFO org.apache.hadoop.yarn.server.resourcemanager.rmapp.attempt.RMAppAttemptImpl: appattempt_1671022279734_0002_000001 State change from ALLOCATED_SAVING to ALLOCATED on event = ATTEMPT_NEW_SAVED
2022-12-14 13:14:36,067 INFO org.apache.hadoop.yarn.server.resourcemanager.amlauncher.AMLauncher: Launching masterappattempt_1671022279734_0002_000001
2022-12-14 13:14:36,070 INFO org.apache.hadoop.yarn.server.resourcemanager.amlauncher.AMLauncher: Setting up container Container: [ContainerId: container_1671022279734_0002_01_000001, AllocationRequestId: -1, Version: 0, NodeId: adh-test-00-mnode2.ru-central1.internal:8041, NodeHttpAddress: adh-test-00-mnode2.ru-central1.internal:8042, Resource: <memory:2048, vCores:1>, Priority: 0, Token: Token { kind: ContainerToken, service: 10.130.0.5:8041 }, ExecutionType: GUARANTEED, ] for AM appattempt_1671022279734_0002_000001
2022-12-14 13:14:36,071 INFO org.apache.hadoop.yarn.server.resourcemanager.security.AMRMTokenSecretManager: Create AMRMToken for ApplicationAttempt: appattempt_1671022279734_0002_000001
2022-12-14 13:14:36,071 INFO org.apache.hadoop.yarn.server.resourcemanager.security.AMRMTokenSecretManager: Creating password for appattempt_1671022279734_0002_000001
2022-12-14 13:14:36,114 INFO org.apache.hadoop.yarn.server.resourcemanager.amlauncher.AMLauncher: Done launching container Container: [ContainerId: container_1671022279734_0002_01_000001, AllocationRequestId: -1, Version: 0, NodeId: adh-test-00-mnode2.ru-central1.internal:8041, NodeHttpAddress: adh-test-00-mnode2.ru-central1.internal:8042, Resource: <memory:2048, vCores:1>, Priority: 0, Token: Token { kind: ContainerToken, service: 10.130.0.5:8041 }, ExecutionType: GUARANTEED, ] for AM appattempt_1671022279734_0002_000001
2022-12-14 13:14:36,114 INFO org.apache.hadoop.yarn.server.resourcemanager.rmapp.attempt.RMAppAttemptImpl: appattempt_1671022279734_0002_000001 State change from ALLOCATED to LAUNCHED on event = LAUNCHED
2022-12-14 13:14:37,058 INFO org.apache.hadoop.yarn.server.resourcemanager.rmcontainer.RMContainerImpl: container_1671022279734_0002_01_000001 Container Transitioned from ACQUIRED to RUNNING
2022-12-14 13:14:39,654 INFO SecurityLogger.org.apache.hadoop.ipc.Server: Auth successful for appattempt_1671022279734_0002_000001 (auth:SIMPLE)
2022-12-14 13:14:39,658 INFO org.apache.hadoop.yarn.server.resourcemanager.DefaultAMSProcessor: AM registration appattempt_1671022279734_0002_000001
2022-12-14 13:14:39,659 INFO org.apache.hadoop.yarn.server.resourcemanager.RMAuditLogger: USER=hdfs	IP=10.130.0.5	OPERATION=Register App Master	TARGET=ApplicationMasterService	RESULT=SUCCESS	APPID=application_1671022279734_0002	APPATTEMPTID=appattempt_1671022279734_0002_000001
2022-12-14 13:14:39,659 INFO org.apache.hadoop.yarn.server.resourcemanager.rmapp.attempt.RMAppAttemptImpl: appattempt_1671022279734_0002_000001 State change from LAUNCHED to RUNNING on event = REGISTERED
2022-12-14 13:14:39,659 INFO org.apache.hadoop.yarn.server.resourcemanager.rmapp.RMAppImpl: application_1671022279734_0002 State change from ACCEPTED to RUNNING on event = ATTEMPT_REGISTERED
2022-12-14 13:14:40,870 INFO org.apache.hadoop.yarn.server.resourcemanager.scheduler.capacity.allocator.AbstractContainerAllocator: assignedContainer application attempt=appattempt_1671022279734_0002_000001 container=null queue=default clusterResource=<memory:21171, vCores:6> type=NODE_LOCAL requestedPartition=
2022-12-14 13:14:40,871 INFO org.apache.hadoop.yarn.server.resourcemanager.rmcontainer.RMContainerImpl: container_1671022279734_0002_01_000002 Container Transitioned from NEW to ALLOCATED
2022-12-14 13:14:40,871 INFO org.apache.hadoop.yarn.server.resourcemanager.scheduler.common.fica.FiCaSchedulerNode: Assigned container container_1671022279734_0002_01_000002 of capacity <memory:1024, vCores:1> on host adh-test-00-mnode3.ru-central1.internal:8041, which has 1 containers, <memory:1024, vCores:1> used and <memory:6033, vCores:1> available after allocation
2022-12-14 13:14:40,871 INFO org.apache.hadoop.yarn.server.resourcemanager.RMAuditLogger: USER=hdfs	OPERATION=AM Allocated Container	TARGET=SchedulerApp	RESULT=SUCCESS	APPID=application_1671022279734_0002	CONTAINERID=container_1671022279734_0002_01_000002	RESOURCE=<memory:1024, vCores:1>	QUEUENAME=default
2022-12-14 13:14:40,871 INFO org.apache.hadoop.yarn.server.resourcemanager.scheduler.capacity.ParentQueue: assignedContainer queue=root usedCapacity=0.14510415 absoluteUsedCapacity=0.14510415 used=<memory:3072, vCores:2> cluster=<memory:21171, vCores:6>
2022-12-14 13:14:40,871 INFO org.apache.hadoop.yarn.server.resourcemanager.scheduler.capacity.CapacityScheduler: Allocation proposal accepted
2022-12-14 13:14:40,871 INFO org.apache.hadoop.yarn.server.resourcemanager.scheduler.capacity.allocator.AbstractContainerAllocator: assignedContainer application attempt=appattempt_1671022279734_0002_000001 container=null queue=default clusterResource=<memory:21171, vCores:6> type=NODE_LOCAL requestedPartition=
2022-12-14 13:14:40,872 INFO org.apache.hadoop.yarn.server.resourcemanager.rmcontainer.RMContainerImpl: container_1671022279734_0002_01_000003 Container Transitioned from NEW to ALLOCATED
2022-12-14 13:14:40,872 INFO org.apache.hadoop.yarn.server.resourcemanager.scheduler.common.fica.FiCaSchedulerNode: Assigned container container_1671022279734_0002_01_000003 of capacity <memory:1024, vCores:1> on host adh-test-00-mnode3.ru-central1.internal:8041, which has 2 containers, <memory:2048, vCores:2> used and <memory:5009, vCores:0> available after allocation
2022-12-14 13:14:40,872 INFO org.apache.hadoop.yarn.server.resourcemanager.RMAuditLogger: USER=hdfs	OPERATION=AM Allocated Container	TARGET=SchedulerApp	RESULT=SUCCESS	APPID=application_1671022279734_0002	CONTAINERID=container_1671022279734_0002_01_000003	RESOURCE=<memory:1024, vCores:1>	QUEUENAME=default
2022-12-14 13:14:40,872 INFO org.apache.hadoop.yarn.server.resourcemanager.scheduler.capacity.ParentQueue: assignedContainer queue=root usedCapacity=0.1934722 absoluteUsedCapacity=0.1934722 used=<memory:4096, vCores:3> cluster=<memory:21171, vCores:6>
2022-12-14 13:14:40,872 INFO org.apache.hadoop.yarn.server.resourcemanager.scheduler.capacity.CapacityScheduler: Allocation proposal accepted
2022-12-14 13:14:40,872 INFO org.apache.hadoop.yarn.server.resourcemanager.scheduler.capacity.allocator.AbstractContainerAllocator: assignedContainer application attempt=appattempt_1671022279734_0002_000001 container=null queue=default clusterResource=<memory:21171, vCores:6> type=NODE_LOCAL requestedPartition=
2022-12-14 13:14:40,872 INFO org.apache.hadoop.yarn.server.resourcemanager.rmcontainer.RMContainerImpl: container_1671022279734_0002_01_000004 Container Transitioned from NEW to ALLOCATED
2022-12-14 13:14:40,872 INFO org.apache.hadoop.yarn.server.resourcemanager.scheduler.common.fica.FiCaSchedulerNode: Assigned container container_1671022279734_0002_01_000004 of capacity <memory:1024, vCores:1> on host adh-test-00-mnode3.ru-central1.internal:8041, which has 3 containers, <memory:3072, vCores:3> used and <memory:3985, vCores:-1> available after allocation
2022-12-14 13:14:40,872 INFO org.apache.hadoop.yarn.server.resourcemanager.RMAuditLogger: USER=hdfs	OPERATION=AM Allocated Container	TARGET=SchedulerApp	RESULT=SUCCESS	APPID=application_1671022279734_0002	CONTAINERID=container_1671022279734_0002_01_000004	RESOURCE=<memory:1024, vCores:1>	QUEUENAME=default
2022-12-14 13:14:40,872 INFO org.apache.hadoop.yarn.server.resourcemanager.scheduler.capacity.ParentQueue: assignedContainer queue=root usedCapacity=0.24184026 absoluteUsedCapacity=0.24184026 used=<memory:5120, vCores:4> cluster=<memory:21171, vCores:6>
2022-12-14 13:14:40,872 INFO org.apache.hadoop.yarn.server.resourcemanager.scheduler.capacity.CapacityScheduler: Allocation proposal accepted
2022-12-14 13:14:40,872 INFO org.apache.hadoop.yarn.server.resourcemanager.scheduler.capacity.allocator.AbstractContainerAllocator: assignedContainer application attempt=appattempt_1671022279734_0002_000001 container=null queue=default clusterResource=<memory:21171, vCores:6> type=NODE_LOCAL requestedPartition=
2022-12-14 13:14:40,873 INFO org.apache.hadoop.yarn.server.resourcemanager.rmcontainer.RMContainerImpl: container_1671022279734_0002_01_000005 Container Transitioned from NEW to ALLOCATED
2022-12-14 13:14:40,873 INFO org.apache.hadoop.yarn.server.resourcemanager.scheduler.common.fica.FiCaSchedulerNode: Assigned container container_1671022279734_0002_01_000005 of capacity <memory:1024, vCores:1> on host adh-test-00-mnode3.ru-central1.internal:8041, which has 4 containers, <memory:4096, vCores:4> used and <memory:2961, vCores:-2> available after allocation
2022-12-14 13:14:40,873 INFO org.apache.hadoop.yarn.server.resourcemanager.RMAuditLogger: USER=hdfs	OPERATION=AM Allocated Container	TARGET=SchedulerApp	RESULT=SUCCESS	APPID=application_1671022279734_0002	CONTAINERID=container_1671022279734_0002_01_000005	RESOURCE=<memory:1024, vCores:1>	QUEUENAME=default
2022-12-14 13:14:40,873 INFO org.apache.hadoop.yarn.server.resourcemanager.scheduler.capacity.ParentQueue: assignedContainer queue=root usedCapacity=0.2902083 absoluteUsedCapacity=0.2902083 used=<memory:6144, vCores:5> cluster=<memory:21171, vCores:6>
2022-12-14 13:14:40,873 INFO org.apache.hadoop.yarn.server.resourcemanager.scheduler.capacity.CapacityScheduler: Allocation proposal accepted
2022-12-14 13:14:40,873 INFO org.apache.hadoop.yarn.server.resourcemanager.scheduler.capacity.allocator.AbstractContainerAllocator: assignedContainer application attempt=appattempt_1671022279734_0002_000001 container=null queue=default clusterResource=<memory:21171, vCores:6> type=NODE_LOCAL requestedPartition=
2022-12-14 13:14:40,873 INFO org.apache.hadoop.yarn.server.resourcemanager.rmcontainer.RMContainerImpl: container_1671022279734_0002_01_000006 Container Transitioned from NEW to ALLOCATED
2022-12-14 13:14:40,873 INFO org.apache.hadoop.yarn.server.resourcemanager.scheduler.common.fica.FiCaSchedulerNode: Assigned container container_1671022279734_0002_01_000006 of capacity <memory:1024, vCores:1> on host adh-test-00-mnode3.ru-central1.internal:8041, which has 5 containers, <memory:5120, vCores:5> used and <memory:1937, vCores:-3> available after allocation
2022-12-14 13:14:40,873 INFO org.apache.hadoop.yarn.server.resourcemanager.RMAuditLogger: USER=hdfs	OPERATION=AM Allocated Container	TARGET=SchedulerApp	RESULT=SUCCESS	APPID=application_1671022279734_0002	CONTAINERID=container_1671022279734_0002_01_000006	RESOURCE=<memory:1024, vCores:1>	QUEUENAME=default
2022-12-14 13:14:40,873 INFO org.apache.hadoop.yarn.server.resourcemanager.scheduler.capacity.ParentQueue: assignedContainer queue=root usedCapacity=0.33857635 absoluteUsedCapacity=0.33857635 used=<memory:7168, vCores:6> cluster=<memory:21171, vCores:6>
2022-12-14 13:14:40,873 INFO org.apache.hadoop.yarn.server.resourcemanager.scheduler.capacity.CapacityScheduler: Allocation proposal accepted
2022-12-14 13:14:40,873 INFO org.apache.hadoop.yarn.server.resourcemanager.scheduler.capacity.allocator.AbstractContainerAllocator: assignedContainer application attempt=appattempt_1671022279734_0002_000001 container=null queue=default clusterResource=<memory:21171, vCores:6> type=NODE_LOCAL requestedPartition=
2022-12-14 13:14:40,874 INFO org.apache.hadoop.yarn.server.resourcemanager.rmcontainer.RMContainerImpl: container_1671022279734_0002_01_000007 Container Transitioned from NEW to ALLOCATED
2022-12-14 13:14:40,874 INFO org.apache.hadoop.yarn.server.resourcemanager.scheduler.common.fica.FiCaSchedulerNode: Assigned container container_1671022279734_0002_01_000007 of capacity <memory:1024, vCores:1> on host adh-test-00-mnode3.ru-central1.internal:8041, which has 6 containers, <memory:6144, vCores:6> used and <memory:913, vCores:-4> available after allocation
2022-12-14 13:14:40,874 INFO org.apache.hadoop.yarn.server.resourcemanager.RMAuditLogger: USER=hdfs	OPERATION=AM Allocated Container	TARGET=SchedulerApp	RESULT=SUCCESS	APPID=application_1671022279734_0002	CONTAINERID=container_1671022279734_0002_01_000007	RESOURCE=<memory:1024, vCores:1>	QUEUENAME=default
2022-12-14 13:14:40,874 INFO org.apache.hadoop.yarn.server.resourcemanager.scheduler.capacity.ParentQueue: assignedContainer queue=root usedCapacity=0.3869444 absoluteUsedCapacity=0.3869444 used=<memory:8192, vCores:7> cluster=<memory:21171, vCores:6>
2022-12-14 13:14:40,874 INFO org.apache.hadoop.yarn.server.resourcemanager.scheduler.capacity.CapacityScheduler: Allocation proposal accepted
2022-12-14 13:14:40,960 INFO org.apache.hadoop.yarn.server.resourcemanager.scheduler.capacity.allocator.AbstractContainerAllocator: assignedContainer application attempt=appattempt_1671022279734_0002_000001 container=null queue=default clusterResource=<memory:21171, vCores:6> type=NODE_LOCAL requestedPartition=
2022-12-14 13:14:40,960 INFO org.apache.hadoop.yarn.server.resourcemanager.rmcontainer.RMContainerImpl: container_1671022279734_0002_01_000008 Container Transitioned from NEW to ALLOCATED
2022-12-14 13:14:40,960 INFO org.apache.hadoop.yarn.server.resourcemanager.scheduler.common.fica.FiCaSchedulerNode: Assigned container container_1671022279734_0002_01_000008 of capacity <memory:1024, vCores:1> on host adh-test-00-mnode1.ru-central1.internal:8041, which has 1 containers, <memory:1024, vCores:1> used and <memory:6033, vCores:1> available after allocation
2022-12-14 13:14:40,960 INFO org.apache.hadoop.yarn.server.resourcemanager.RMAuditLogger: USER=hdfs	OPERATION=AM Allocated Container	TARGET=SchedulerApp	RESULT=SUCCESS	APPID=application_1671022279734_0002	CONTAINERID=container_1671022279734_0002_01_000008	RESOURCE=<memory:1024, vCores:1>	QUEUENAME=default
2022-12-14 13:14:40,960 INFO org.apache.hadoop.yarn.server.resourcemanager.scheduler.capacity.ParentQueue: assignedContainer queue=root usedCapacity=0.43531245 absoluteUsedCapacity=0.43531245 used=<memory:9216, vCores:8> cluster=<memory:21171, vCores:6>
2022-12-14 13:14:40,961 INFO org.apache.hadoop.yarn.server.resourcemanager.scheduler.capacity.CapacityScheduler: Allocation proposal accepted
2022-12-14 13:14:40,961 INFO org.apache.hadoop.yarn.server.resourcemanager.scheduler.capacity.allocator.AbstractContainerAllocator: assignedContainer application attempt=appattempt_1671022279734_0002_000001 container=null queue=default clusterResource=<memory:21171, vCores:6> type=NODE_LOCAL requestedPartition=
2022-12-14 13:14:40,961 INFO org.apache.hadoop.yarn.server.resourcemanager.rmcontainer.RMContainerImpl: container_1671022279734_0002_01_000009 Container Transitioned from NEW to ALLOCATED
2022-12-14 13:14:40,961 INFO org.apache.hadoop.yarn.server.resourcemanager.scheduler.common.fica.FiCaSchedulerNode: Assigned container container_1671022279734_0002_01_000009 of capacity <memory:1024, vCores:1> on host adh-test-00-mnode1.ru-central1.internal:8041, which has 2 containers, <memory:2048, vCores:2> used and <memory:5009, vCores:0> available after allocation
2022-12-14 13:14:40,961 INFO org.apache.hadoop.yarn.server.resourcemanager.RMAuditLogger: USER=hdfs	OPERATION=AM Allocated Container	TARGET=SchedulerApp	RESULT=SUCCESS	APPID=application_1671022279734_0002	CONTAINERID=container_1671022279734_0002_01_000009	RESOURCE=<memory:1024, vCores:1>	QUEUENAME=default
2022-12-14 13:14:40,961 INFO org.apache.hadoop.yarn.server.resourcemanager.scheduler.capacity.ParentQueue: assignedContainer queue=root usedCapacity=0.48368052 absoluteUsedCapacity=0.48368052 used=<memory:10240, vCores:9> cluster=<memory:21171, vCores:6>
2022-12-14 13:14:40,961 INFO org.apache.hadoop.yarn.server.resourcemanager.scheduler.capacity.CapacityScheduler: Allocation proposal accepted
2022-12-14 13:14:40,961 INFO org.apache.hadoop.yarn.server.resourcemanager.scheduler.capacity.allocator.AbstractContainerAllocator: assignedContainer application attempt=appattempt_1671022279734_0002_000001 container=null queue=default clusterResource=<memory:21171, vCores:6> type=NODE_LOCAL requestedPartition=
2022-12-14 13:14:40,961 INFO org.apache.hadoop.yarn.server.resourcemanager.rmcontainer.RMContainerImpl: container_1671022279734_0002_01_000010 Container Transitioned from NEW to ALLOCATED
2022-12-14 13:14:40,961 INFO org.apache.hadoop.yarn.server.resourcemanager.scheduler.common.fica.FiCaSchedulerNode: Assigned container container_1671022279734_0002_01_000010 of capacity <memory:1024, vCores:1> on host adh-test-00-mnode1.ru-central1.internal:8041, which has 3 containers, <memory:3072, vCores:3> used and <memory:3985, vCores:-1> available after allocation
2022-12-14 13:14:40,962 INFO org.apache.hadoop.yarn.server.resourcemanager.RMAuditLogger: USER=hdfs	OPERATION=AM Allocated Container	TARGET=SchedulerApp	RESULT=SUCCESS	APPID=application_1671022279734_0002	CONTAINERID=container_1671022279734_0002_01_000010	RESOURCE=<memory:1024, vCores:1>	QUEUENAME=default
2022-12-14 13:14:40,962 INFO org.apache.hadoop.yarn.server.resourcemanager.scheduler.capacity.ParentQueue: assignedContainer queue=root usedCapacity=0.5320486 absoluteUsedCapacity=0.5320486 used=<memory:11264, vCores:10> cluster=<memory:21171, vCores:6>
2022-12-14 13:14:40,962 INFO org.apache.hadoop.yarn.server.resourcemanager.scheduler.capacity.CapacityScheduler: Allocation proposal accepted
2022-12-14 13:14:40,962 INFO org.apache.hadoop.yarn.server.resourcemanager.scheduler.capacity.allocator.AbstractContainerAllocator: assignedContainer application attempt=appattempt_1671022279734_0002_000001 container=null queue=default clusterResource=<memory:21171, vCores:6> type=NODE_LOCAL requestedPartition=
2022-12-14 13:14:40,962 INFO org.apache.hadoop.yarn.server.resourcemanager.rmcontainer.RMContainerImpl: container_1671022279734_0002_01_000011 Container Transitioned from NEW to ALLOCATED
2022-12-14 13:14:40,962 INFO org.apache.hadoop.yarn.server.resourcemanager.scheduler.common.fica.FiCaSchedulerNode: Assigned container container_1671022279734_0002_01_000011 of capacity <memory:1024, vCores:1> on host adh-test-00-mnode1.ru-central1.internal:8041, which has 4 containers, <memory:4096, vCores:4> used and <memory:2961, vCores:-2> available after allocation
2022-12-14 13:14:40,962 INFO org.apache.hadoop.yarn.server.resourcemanager.RMAuditLogger: USER=hdfs	OPERATION=AM Allocated Container	TARGET=SchedulerApp	RESULT=SUCCESS	APPID=application_1671022279734_0002	CONTAINERID=container_1671022279734_0002_01_000011	RESOURCE=<memory:1024, vCores:1>	QUEUENAME=default
2022-12-14 13:14:40,962 INFO org.apache.hadoop.yarn.server.resourcemanager.scheduler.capacity.ParentQueue: assignedContainer queue=root usedCapacity=0.5804166 absoluteUsedCapacity=0.5804166 used=<memory:12288, vCores:11> cluster=<memory:21171, vCores:6>
2022-12-14 13:14:40,962 INFO org.apache.hadoop.yarn.server.resourcemanager.scheduler.capacity.CapacityScheduler: Allocation proposal accepted
2022-12-14 13:14:40,962 INFO org.apache.hadoop.yarn.server.resourcemanager.scheduler.capacity.allocator.AbstractContainerAllocator: assignedContainer application attempt=appattempt_1671022279734_0002_000001 container=null queue=default clusterResource=<memory:21171, vCores:6> type=NODE_LOCAL requestedPartition=
2022-12-14 13:14:40,963 INFO org.apache.hadoop.yarn.server.resourcemanager.rmcontainer.RMContainerImpl: container_1671022279734_0002_01_000012 Container Transitioned from NEW to ALLOCATED
2022-12-14 13:14:40,963 INFO org.apache.hadoop.yarn.server.resourcemanager.scheduler.common.fica.FiCaSchedulerNode: Assigned container container_1671022279734_0002_01_000012 of capacity <memory:1024, vCores:1> on host adh-test-00-mnode1.ru-central1.internal:8041, which has 5 containers, <memory:5120, vCores:5> used and <memory:1937, vCores:-3> available after allocation
2022-12-14 13:14:40,963 INFO org.apache.hadoop.yarn.server.resourcemanager.RMAuditLogger: USER=hdfs	OPERATION=AM Allocated Container	TARGET=SchedulerApp	RESULT=SUCCESS	APPID=application_1671022279734_0002	CONTAINERID=container_1671022279734_0002_01_000012	RESOURCE=<memory:1024, vCores:1>	QUEUENAME=default
2022-12-14 13:14:40,963 INFO org.apache.hadoop.yarn.server.resourcemanager.scheduler.capacity.ParentQueue: assignedContainer queue=root usedCapacity=0.62878466 absoluteUsedCapacity=0.62878466 used=<memory:13312, vCores:12> cluster=<memory:21171, vCores:6>
2022-12-14 13:14:40,963 INFO org.apache.hadoop.yarn.server.resourcemanager.scheduler.capacity.CapacityScheduler: Allocation proposal accepted
2022-12-14 13:14:40,963 INFO org.apache.hadoop.yarn.server.resourcemanager.scheduler.capacity.allocator.AbstractContainerAllocator: assignedContainer application attempt=appattempt_1671022279734_0002_000001 container=null queue=default clusterResource=<memory:21171, vCores:6> type=NODE_LOCAL requestedPartition=
2022-12-14 13:14:40,963 INFO org.apache.hadoop.yarn.server.resourcemanager.rmcontainer.RMContainerImpl: container_1671022279734_0002_01_000013 Container Transitioned from NEW to ALLOCATED
2022-12-14 13:14:40,963 INFO org.apache.hadoop.yarn.server.resourcemanager.scheduler.common.fica.FiCaSchedulerNode: Assigned container container_1671022279734_0002_01_000013 of capacity <memory:1024, vCores:1> on host adh-test-00-mnode1.ru-central1.internal:8041, which has 6 containers, <memory:6144, vCores:6> used and <memory:913, vCores:-4> available after allocation
2022-12-14 13:14:40,963 INFO org.apache.hadoop.yarn.server.resourcemanager.RMAuditLogger: USER=hdfs	OPERATION=AM Allocated Container	TARGET=SchedulerApp	RESULT=SUCCESS	APPID=application_1671022279734_0002	CONTAINERID=container_1671022279734_0002_01_000013	RESOURCE=<memory:1024, vCores:1>	QUEUENAME=default
2022-12-14 13:14:40,963 INFO org.apache.hadoop.yarn.server.resourcemanager.scheduler.capacity.ParentQueue: assignedContainer queue=root usedCapacity=0.6771527 absoluteUsedCapacity=0.6771527 used=<memory:14336, vCores:13> cluster=<memory:21171, vCores:6>
2022-12-14 13:14:40,963 INFO org.apache.hadoop.yarn.server.resourcemanager.scheduler.capacity.CapacityScheduler: Allocation proposal accepted
2022-12-14 13:14:41,065 INFO org.apache.hadoop.yarn.server.resourcemanager.scheduler.capacity.allocator.AbstractContainerAllocator: assignedContainer application attempt=appattempt_1671022279734_0002_000001 container=null queue=default clusterResource=<memory:21171, vCores:6> type=NODE_LOCAL requestedPartition=
2022-12-14 13:14:41,065 INFO org.apache.hadoop.yarn.server.resourcemanager.rmcontainer.RMContainerImpl: container_1671022279734_0002_01_000014 Container Transitioned from NEW to ALLOCATED
2022-12-14 13:14:41,066 INFO org.apache.hadoop.yarn.server.resourcemanager.scheduler.common.fica.FiCaSchedulerNode: Assigned container container_1671022279734_0002_01_000014 of capacity <memory:1024, vCores:1> on host adh-test-00-mnode2.ru-central1.internal:8041, which has 2 containers, <memory:3072, vCores:2> used and <memory:3985, vCores:0> available after allocation
2022-12-14 13:14:41,066 INFO org.apache.hadoop.yarn.server.resourcemanager.RMAuditLogger: USER=hdfs	OPERATION=AM Allocated Container	TARGET=SchedulerApp	RESULT=SUCCESS	APPID=application_1671022279734_0002	CONTAINERID=container_1671022279734_0002_01_000014	RESOURCE=<memory:1024, vCores:1>	QUEUENAME=default
2022-12-14 13:14:41,066 INFO org.apache.hadoop.yarn.server.resourcemanager.scheduler.capacity.ParentQueue: assignedContainer queue=root usedCapacity=0.72552073 absoluteUsedCapacity=0.72552073 used=<memory:15360, vCores:14> cluster=<memory:21171, vCores:6>
2022-12-14 13:14:41,066 INFO org.apache.hadoop.yarn.server.resourcemanager.scheduler.capacity.CapacityScheduler: Allocation proposal accepted
2022-12-14 13:14:41,066 INFO org.apache.hadoop.yarn.server.resourcemanager.scheduler.capacity.allocator.AbstractContainerAllocator: assignedContainer application attempt=appattempt_1671022279734_0002_000001 container=null queue=default clusterResource=<memory:21171, vCores:6> type=NODE_LOCAL requestedPartition=
2022-12-14 13:14:41,066 INFO org.apache.hadoop.yarn.server.resourcemanager.rmcontainer.RMContainerImpl: container_1671022279734_0002_01_000015 Container Transitioned from NEW to ALLOCATED
2022-12-14 13:14:41,066 INFO org.apache.hadoop.yarn.server.resourcemanager.scheduler.common.fica.FiCaSchedulerNode: Assigned container container_1671022279734_0002_01_000015 of capacity <memory:1024, vCores:1> on host adh-test-00-mnode2.ru-central1.internal:8041, which has 3 containers, <memory:4096, vCores:3> used and <memory:2961, vCores:-1> available after allocation
2022-12-14 13:14:41,066 INFO org.apache.hadoop.yarn.server.resourcemanager.RMAuditLogger: USER=hdfs	OPERATION=AM Allocated Container	TARGET=SchedulerApp	RESULT=SUCCESS	APPID=application_1671022279734_0002	CONTAINERID=container_1671022279734_0002_01_000015	RESOURCE=<memory:1024, vCores:1>	QUEUENAME=default
2022-12-14 13:14:41,066 INFO org.apache.hadoop.yarn.server.resourcemanager.scheduler.capacity.ParentQueue: assignedContainer queue=root usedCapacity=0.7738888 absoluteUsedCapacity=0.7738888 used=<memory:16384, vCores:15> cluster=<memory:21171, vCores:6>
2022-12-14 13:14:41,066 INFO org.apache.hadoop.yarn.server.resourcemanager.scheduler.capacity.CapacityScheduler: Allocation proposal accepted
2022-12-14 13:14:41,067 INFO org.apache.hadoop.yarn.server.resourcemanager.scheduler.capacity.allocator.AbstractContainerAllocator: assignedContainer application attempt=appattempt_1671022279734_0002_000001 container=null queue=default clusterResource=<memory:21171, vCores:6> type=NODE_LOCAL requestedPartition=
2022-12-14 13:14:41,067 INFO org.apache.hadoop.yarn.server.resourcemanager.rmcontainer.RMContainerImpl: container_1671022279734_0002_01_000016 Container Transitioned from NEW to ALLOCATED
2022-12-14 13:14:41,067 INFO org.apache.hadoop.yarn.server.resourcemanager.scheduler.common.fica.FiCaSchedulerNode: Assigned container container_1671022279734_0002_01_000016 of capacity <memory:1024, vCores:1> on host adh-test-00-mnode2.ru-central1.internal:8041, which has 4 containers, <memory:5120, vCores:4> used and <memory:1937, vCores:-2> available after allocation
2022-12-14 13:14:41,067 INFO org.apache.hadoop.yarn.server.resourcemanager.RMAuditLogger: USER=hdfs	OPERATION=AM Allocated Container	TARGET=SchedulerApp	RESULT=SUCCESS	APPID=application_1671022279734_0002	CONTAINERID=container_1671022279734_0002_01_000016	RESOURCE=<memory:1024, vCores:1>	QUEUENAME=default
2022-12-14 13:14:41,067 INFO org.apache.hadoop.yarn.server.resourcemanager.scheduler.capacity.ParentQueue: assignedContainer queue=root usedCapacity=0.82225686 absoluteUsedCapacity=0.82225686 used=<memory:17408, vCores:16> cluster=<memory:21171, vCores:6>
2022-12-14 13:14:41,067 INFO org.apache.hadoop.yarn.server.resourcemanager.scheduler.capacity.CapacityScheduler: Allocation proposal accepted
2022-12-14 13:14:41,067 INFO org.apache.hadoop.yarn.server.resourcemanager.scheduler.capacity.allocator.AbstractContainerAllocator: assignedContainer application attempt=appattempt_1671022279734_0002_000001 container=null queue=default clusterResource=<memory:21171, vCores:6> type=NODE_LOCAL requestedPartition=
2022-12-14 13:14:41,067 INFO org.apache.hadoop.yarn.server.resourcemanager.rmcontainer.RMContainerImpl: container_1671022279734_0002_01_000017 Container Transitioned from NEW to ALLOCATED
2022-12-14 13:14:41,068 INFO org.apache.hadoop.yarn.server.resourcemanager.scheduler.common.fica.FiCaSchedulerNode: Assigned container container_1671022279734_0002_01_000017 of capacity <memory:1024, vCores:1> on host adh-test-00-mnode2.ru-central1.internal:8041, which has 5 containers, <memory:6144, vCores:5> used and <memory:913, vCores:-3> available after allocation
2022-12-14 13:14:41,068 INFO org.apache.hadoop.yarn.server.resourcemanager.RMAuditLogger: USER=hdfs	OPERATION=AM Allocated Container	TARGET=SchedulerApp	RESULT=SUCCESS	APPID=application_1671022279734_0002	CONTAINERID=container_1671022279734_0002_01_000017	RESOURCE=<memory:1024, vCores:1>	QUEUENAME=default
2022-12-14 13:14:41,068 INFO org.apache.hadoop.yarn.server.resourcemanager.scheduler.capacity.ParentQueue: assignedContainer queue=root usedCapacity=0.8706249 absoluteUsedCapacity=0.8706249 used=<memory:18432, vCores:17> cluster=<memory:21171, vCores:6>
2022-12-14 13:14:41,068 INFO org.apache.hadoop.yarn.server.resourcemanager.scheduler.capacity.CapacityScheduler: Allocation proposal accepted
2022-12-14 13:14:41,720 INFO org.apache.hadoop.yarn.server.resourcemanager.security.NMTokenSecretManagerInRM: Sending NMToken for nodeId : adh-test-00-mnode3.ru-central1.internal:8041 for container : container_1671022279734_0002_01_000002
2022-12-14 13:14:41,721 INFO org.apache.hadoop.yarn.server.resourcemanager.rmcontainer.RMContainerImpl: container_1671022279734_0002_01_000002 Container Transitioned from ALLOCATED to ACQUIRED
2022-12-14 13:14:41,723 INFO org.apache.hadoop.yarn.server.resourcemanager.rmcontainer.RMContainerImpl: container_1671022279734_0002_01_000003 Container Transitioned from ALLOCATED to ACQUIRED
2022-12-14 13:14:41,727 INFO org.apache.hadoop.yarn.server.resourcemanager.rmcontainer.RMContainerImpl: container_1671022279734_0002_01_000004 Container Transitioned from ALLOCATED to ACQUIRED
2022-12-14 13:14:41,728 INFO org.apache.hadoop.yarn.server.resourcemanager.rmcontainer.RMContainerImpl: container_1671022279734_0002_01_000005 Container Transitioned from ALLOCATED to ACQUIRED
2022-12-14 13:14:41,730 INFO org.apache.hadoop.yarn.server.resourcemanager.rmcontainer.RMContainerImpl: container_1671022279734_0002_01_000006 Container Transitioned from ALLOCATED to ACQUIRED
2022-12-14 13:14:41,731 INFO org.apache.hadoop.yarn.server.resourcemanager.rmcontainer.RMContainerImpl: container_1671022279734_0002_01_000007 Container Transitioned from ALLOCATED to ACQUIRED
2022-12-14 13:14:41,731 INFO org.apache.hadoop.yarn.server.resourcemanager.security.NMTokenSecretManagerInRM: Sending NMToken for nodeId : adh-test-00-mnode1.ru-central1.internal:8041 for container : container_1671022279734_0002_01_000008
2022-12-14 13:14:41,732 INFO org.apache.hadoop.yarn.server.resourcemanager.rmcontainer.RMContainerImpl: container_1671022279734_0002_01_000008 Container Transitioned from ALLOCATED to ACQUIRED
2022-12-14 13:14:41,733 INFO org.apache.hadoop.yarn.server.resourcemanager.rmcontainer.RMContainerImpl: container_1671022279734_0002_01_000009 Container Transitioned from ALLOCATED to ACQUIRED
2022-12-14 13:14:41,734 INFO org.apache.hadoop.yarn.server.resourcemanager.rmcontainer.RMContainerImpl: container_1671022279734_0002_01_000010 Container Transitioned from ALLOCATED to ACQUIRED
2022-12-14 13:14:41,735 INFO org.apache.hadoop.yarn.server.resourcemanager.rmcontainer.RMContainerImpl: container_1671022279734_0002_01_000011 Container Transitioned from ALLOCATED to ACQUIRED
2022-12-14 13:14:41,736 INFO org.apache.hadoop.yarn.server.resourcemanager.rmcontainer.RMContainerImpl: container_1671022279734_0002_01_000012 Container Transitioned from ALLOCATED to ACQUIRED
2022-12-14 13:14:41,737 INFO org.apache.hadoop.yarn.server.resourcemanager.rmcontainer.RMContainerImpl: container_1671022279734_0002_01_000013 Container Transitioned from ALLOCATED to ACQUIRED
2022-12-14 13:14:41,738 INFO org.apache.hadoop.yarn.server.resourcemanager.security.NMTokenSecretManagerInRM: Sending NMToken for nodeId : adh-test-00-mnode2.ru-central1.internal:8041 for container : container_1671022279734_0002_01_000014
2022-12-14 13:14:41,739 INFO org.apache.hadoop.yarn.server.resourcemanager.rmcontainer.RMContainerImpl: container_1671022279734_0002_01_000014 Container Transitioned from ALLOCATED to ACQUIRED
2022-12-14 13:14:41,740 INFO org.apache.hadoop.yarn.server.resourcemanager.rmcontainer.RMContainerImpl: container_1671022279734_0002_01_000015 Container Transitioned from ALLOCATED to ACQUIRED
2022-12-14 13:14:41,741 INFO org.apache.hadoop.yarn.server.resourcemanager.rmcontainer.RMContainerImpl: container_1671022279734_0002_01_000016 Container Transitioned from ALLOCATED to ACQUIRED
2022-12-14 13:14:41,743 INFO org.apache.hadoop.yarn.server.resourcemanager.rmcontainer.RMContainerImpl: container_1671022279734_0002_01_000017 Container Transitioned from ALLOCATED to ACQUIRED
2022-12-14 13:14:42,917 INFO org.apache.hadoop.yarn.server.resourcemanager.rmcontainer.RMContainerImpl: container_1671022279734_0002_01_000002 Container Transitioned from ACQUIRED to RUNNING
2022-12-14 13:14:42,918 INFO org.apache.hadoop.yarn.server.resourcemanager.rmcontainer.RMContainerImpl: container_1671022279734_0002_01_000003 Container Transitioned from ACQUIRED to RUNNING
2022-12-14 13:14:42,919 INFO org.apache.hadoop.yarn.server.resourcemanager.rmcontainer.RMContainerImpl: container_1671022279734_0002_01_000004 Container Transitioned from ACQUIRED to RUNNING
2022-12-14 13:14:42,919 INFO org.apache.hadoop.yarn.server.resourcemanager.rmcontainer.RMContainerImpl: container_1671022279734_0002_01_000005 Container Transitioned from ACQUIRED to RUNNING
2022-12-14 13:14:42,919 INFO org.apache.hadoop.yarn.server.resourcemanager.rmcontainer.RMContainerImpl: container_1671022279734_0002_01_000006 Container Transitioned from ACQUIRED to RUNNING
2022-12-14 13:14:42,920 INFO org.apache.hadoop.yarn.server.resourcemanager.rmcontainer.RMContainerImpl: container_1671022279734_0002_01_000007 Container Transitioned from ACQUIRED to RUNNING
2022-12-14 13:14:42,985 INFO org.apache.hadoop.yarn.server.resourcemanager.rmcontainer.RMContainerImpl: container_1671022279734_0002_01_000008 Container Transitioned from ACQUIRED to RUNNING
2022-12-14 13:14:42,986 INFO org.apache.hadoop.yarn.server.resourcemanager.rmcontainer.RMContainerImpl: container_1671022279734_0002_01_000009 Container Transitioned from ACQUIRED to RUNNING
2022-12-14 13:14:42,986 INFO org.apache.hadoop.yarn.server.resourcemanager.rmcontainer.RMContainerImpl: container_1671022279734_0002_01_000010 Container Transitioned from ACQUIRED to RUNNING
2022-12-14 13:14:42,987 INFO org.apache.hadoop.yarn.server.resourcemanager.rmcontainer.RMContainerImpl: container_1671022279734_0002_01_000011 Container Transitioned from ACQUIRED to RUNNING
2022-12-14 13:14:42,987 INFO org.apache.hadoop.yarn.server.resourcemanager.rmcontainer.RMContainerImpl: container_1671022279734_0002_01_000012 Container Transitioned from ACQUIRED to RUNNING
2022-12-14 13:14:42,987 INFO org.apache.hadoop.yarn.server.resourcemanager.rmcontainer.RMContainerImpl: container_1671022279734_0002_01_000013 Container Transitioned from ACQUIRED to RUNNING
2022-12-14 13:14:43,108 INFO org.apache.hadoop.yarn.server.resourcemanager.rmcontainer.RMContainerImpl: container_1671022279734_0002_01_000014 Container Transitioned from ACQUIRED to RUNNING
2022-12-14 13:14:43,109 INFO org.apache.hadoop.yarn.server.resourcemanager.rmcontainer.RMContainerImpl: container_1671022279734_0002_01_000015 Container Transitioned from ACQUIRED to RUNNING
2022-12-14 13:14:43,109 INFO org.apache.hadoop.yarn.server.resourcemanager.rmcontainer.RMContainerImpl: container_1671022279734_0002_01_000016 Container Transitioned from ACQUIRED to RUNNING
2022-12-14 13:14:43,109 INFO org.apache.hadoop.yarn.server.resourcemanager.rmcontainer.RMContainerImpl: container_1671022279734_0002_01_000017 Container Transitioned from ACQUIRED to RUNNING
2022-12-14 13:14:47,834 INFO org.apache.hadoop.yarn.server.resourcemanager.rmcontainer.RMContainerImpl: container_1671022279734_0002_01_000015 Container Transitioned from RUNNING to COMPLETED
2022-12-14 13:14:47,834 INFO org.apache.hadoop.yarn.server.resourcemanager.RMAuditLogger: USER=hdfs	OPERATION=AM Released Container	TARGET=SchedulerApp	RESULT=SUCCESS	APPID=application_1671022279734_0002	CONTAINERID=container_1671022279734_0002_01_000015	RESOURCE=<memory:1024, vCores:1>	QUEUENAME=default
2022-12-14 13:14:47,835 INFO org.apache.hadoop.yarn.server.resourcemanager.scheduler.capacity.allocator.AbstractContainerAllocator: assignedContainer application attempt=appattempt_1671022279734_0002_000001 container=null queue=default clusterResource=<memory:21171, vCores:6> type=NODE_LOCAL requestedPartition=
2022-12-14 13:14:47,835 INFO org.apache.hadoop.yarn.server.resourcemanager.rmcontainer.RMContainerImpl: container_1671022279734_0002_01_000018 Container Transitioned from NEW to ALLOCATED
2022-12-14 13:14:47,835 INFO org.apache.hadoop.yarn.server.resourcemanager.scheduler.common.fica.FiCaSchedulerNode: Assigned container container_1671022279734_0002_01_000018 of capacity <memory:1024, vCores:1> on host adh-test-00-mnode2.ru-central1.internal:8041, which has 5 containers, <memory:6144, vCores:5> used and <memory:913, vCores:-3> available after allocation
2022-12-14 13:14:47,835 INFO org.apache.hadoop.yarn.server.resourcemanager.RMAuditLogger: USER=hdfs	OPERATION=AM Allocated Container	TARGET=SchedulerApp	RESULT=SUCCESS	APPID=application_1671022279734_0002	CONTAINERID=container_1671022279734_0002_01_000018	RESOURCE=<memory:1024, vCores:1>	QUEUENAME=default
2022-12-14 13:14:47,836 INFO org.apache.hadoop.yarn.server.resourcemanager.scheduler.capacity.ParentQueue: assignedContainer queue=root usedCapacity=0.8706249 absoluteUsedCapacity=0.8706249 used=<memory:18432, vCores:17> cluster=<memory:21171, vCores:6>
2022-12-14 13:14:47,836 INFO org.apache.hadoop.yarn.server.resourcemanager.scheduler.capacity.CapacityScheduler: Allocation proposal accepted
2022-12-14 13:14:47,961 INFO org.apache.hadoop.yarn.server.resourcemanager.rmcontainer.RMContainerImpl: container_1671022279734_0002_01_000016 Container Transitioned from RUNNING to COMPLETED
2022-12-14 13:14:47,962 INFO org.apache.hadoop.yarn.server.resourcemanager.RMAuditLogger: USER=hdfs	OPERATION=AM Released Container	TARGET=SchedulerApp	RESULT=SUCCESS	APPID=application_1671022279734_0002	CONTAINERID=container_1671022279734_0002_01_000016	RESOURCE=<memory:1024, vCores:1>	QUEUENAME=default
2022-12-14 13:14:47,962 INFO org.apache.hadoop.yarn.server.resourcemanager.scheduler.capacity.allocator.AbstractContainerAllocator: assignedContainer application attempt=appattempt_1671022279734_0002_000001 container=null queue=default clusterResource=<memory:21171, vCores:6> type=NODE_LOCAL requestedPartition=
2022-12-14 13:14:47,962 INFO org.apache.hadoop.yarn.server.resourcemanager.rmcontainer.RMContainerImpl: container_1671022279734_0002_01_000019 Container Transitioned from NEW to ALLOCATED
2022-12-14 13:14:47,963 INFO org.apache.hadoop.yarn.server.resourcemanager.scheduler.common.fica.FiCaSchedulerNode: Assigned container container_1671022279734_0002_01_000019 of capacity <memory:1024, vCores:1> on host adh-test-00-mnode2.ru-central1.internal:8041, which has 5 containers, <memory:6144, vCores:5> used and <memory:913, vCores:-3> available after allocation
2022-12-14 13:14:47,963 INFO org.apache.hadoop.yarn.server.resourcemanager.RMAuditLogger: USER=hdfs	OPERATION=AM Allocated Container	TARGET=SchedulerApp	RESULT=SUCCESS	APPID=application_1671022279734_0002	CONTAINERID=container_1671022279734_0002_01_000019	RESOURCE=<memory:1024, vCores:1>	QUEUENAME=default
2022-12-14 13:14:47,963 INFO org.apache.hadoop.yarn.server.resourcemanager.scheduler.capacity.ParentQueue: assignedContainer queue=root usedCapacity=0.8706249 absoluteUsedCapacity=0.8706249 used=<memory:18432, vCores:17> cluster=<memory:21171, vCores:6>
2022-12-14 13:14:47,963 INFO org.apache.hadoop.yarn.server.resourcemanager.scheduler.capacity.CapacityScheduler: Allocation proposal accepted
2022-12-14 13:14:48,055 INFO org.apache.hadoop.yarn.server.resourcemanager.rmcontainer.RMContainerImpl: container_1671022279734_0002_01_000017 Container Transitioned from RUNNING to COMPLETED
2022-12-14 13:14:48,055 INFO org.apache.hadoop.yarn.server.resourcemanager.RMAuditLogger: USER=hdfs	OPERATION=AM Released Container	TARGET=SchedulerApp	RESULT=SUCCESS	APPID=application_1671022279734_0002	CONTAINERID=container_1671022279734_0002_01_000017	RESOURCE=<memory:1024, vCores:1>	QUEUENAME=default
2022-12-14 13:14:48,056 INFO org.apache.hadoop.yarn.server.resourcemanager.scheduler.capacity.allocator.AbstractContainerAllocator: assignedContainer application attempt=appattempt_1671022279734_0002_000001 container=null queue=default clusterResource=<memory:21171, vCores:6> type=NODE_LOCAL requestedPartition=
2022-12-14 13:14:48,056 INFO org.apache.hadoop.yarn.server.resourcemanager.rmcontainer.RMContainerImpl: container_1671022279734_0002_01_000020 Container Transitioned from NEW to ALLOCATED
2022-12-14 13:14:48,056 INFO org.apache.hadoop.yarn.server.resourcemanager.scheduler.common.fica.FiCaSchedulerNode: Assigned container container_1671022279734_0002_01_000020 of capacity <memory:1024, vCores:1> on host adh-test-00-mnode2.ru-central1.internal:8041, which has 5 containers, <memory:6144, vCores:5> used and <memory:913, vCores:-3> available after allocation
2022-12-14 13:14:48,056 INFO org.apache.hadoop.yarn.server.resourcemanager.RMAuditLogger: USER=hdfs	OPERATION=AM Allocated Container	TARGET=SchedulerApp	RESULT=SUCCESS	APPID=application_1671022279734_0002	CONTAINERID=container_1671022279734_0002_01_000020	RESOURCE=<memory:1024, vCores:1>	QUEUENAME=default
2022-12-14 13:14:48,057 INFO org.apache.hadoop.yarn.server.resourcemanager.scheduler.capacity.ParentQueue: assignedContainer queue=root usedCapacity=0.8706249 absoluteUsedCapacity=0.8706249 used=<memory:18432, vCores:17> cluster=<memory:21171, vCores:6>
2022-12-14 13:14:48,057 INFO org.apache.hadoop.yarn.server.resourcemanager.scheduler.capacity.CapacityScheduler: Allocation proposal accepted
2022-12-14 13:14:48,102 INFO org.apache.hadoop.yarn.server.resourcemanager.rmcontainer.RMContainerImpl: container_1671022279734_0002_01_000018 Container Transitioned from ALLOCATED to ACQUIRED
2022-12-14 13:14:48,103 INFO org.apache.hadoop.yarn.server.resourcemanager.rmcontainer.RMContainerImpl: container_1671022279734_0002_01_000019 Container Transitioned from ALLOCATED to ACQUIRED
2022-12-14 13:14:48,104 INFO org.apache.hadoop.yarn.server.resourcemanager.rmcontainer.RMContainerImpl: container_1671022279734_0002_01_000020 Container Transitioned from ALLOCATED to ACQUIRED
2022-12-14 13:14:48,104 INFO org.apache.hadoop.yarn.server.resourcemanager.rmcontainer.RMContainerImpl: container_1671022279734_0002_01_000014 Container Transitioned from RUNNING to COMPLETED
2022-12-14 13:14:48,104 INFO org.apache.hadoop.yarn.server.resourcemanager.RMAuditLogger: USER=hdfs	OPERATION=AM Released Container	TARGET=SchedulerApp	RESULT=SUCCESS	APPID=application_1671022279734_0002	CONTAINERID=container_1671022279734_0002_01_000014	RESOURCE=<memory:1024, vCores:1>	QUEUENAME=default
2022-12-14 13:14:48,105 INFO org.apache.hadoop.yarn.server.resourcemanager.scheduler.capacity.allocator.AbstractContainerAllocator: assignedContainer application attempt=appattempt_1671022279734_0002_000001 container=null queue=default clusterResource=<memory:21171, vCores:6> type=NODE_LOCAL requestedPartition=
2022-12-14 13:14:48,114 INFO org.apache.hadoop.yarn.server.resourcemanager.rmcontainer.RMContainerImpl: container_1671022279734_0002_01_000021 Container Transitioned from NEW to ALLOCATED
2022-12-14 13:14:48,114 INFO org.apache.hadoop.yarn.server.resourcemanager.scheduler.common.fica.FiCaSchedulerNode: Assigned container container_1671022279734_0002_01_000021 of capacity <memory:1024, vCores:1> on host adh-test-00-mnode2.ru-central1.internal:8041, which has 5 containers, <memory:6144, vCores:5> used and <memory:913, vCores:-3> available after allocation
2022-12-14 13:14:48,114 INFO org.apache.hadoop.yarn.server.resourcemanager.RMAuditLogger: USER=hdfs	OPERATION=AM Allocated Container	TARGET=SchedulerApp	RESULT=SUCCESS	APPID=application_1671022279734_0002	CONTAINERID=container_1671022279734_0002_01_000021	RESOURCE=<memory:1024, vCores:1>	QUEUENAME=default
2022-12-14 13:14:48,114 INFO org.apache.hadoop.yarn.server.resourcemanager.scheduler.capacity.ParentQueue: assignedContainer queue=root usedCapacity=0.8706249 absoluteUsedCapacity=0.8706249 used=<memory:18432, vCores:17> cluster=<memory:21171, vCores:6>
2022-12-14 13:14:48,114 INFO org.apache.hadoop.yarn.server.resourcemanager.scheduler.capacity.CapacityScheduler: Allocation proposal accepted
2022-12-14 13:14:49,115 INFO org.apache.hadoop.yarn.server.resourcemanager.rmcontainer.RMContainerImpl: container_1671022279734_0002_01_000018 Container Transitioned from ACQUIRED to RUNNING
2022-12-14 13:14:49,116 INFO org.apache.hadoop.yarn.server.resourcemanager.rmcontainer.RMContainerImpl: container_1671022279734_0002_01_000019 Container Transitioned from ACQUIRED to RUNNING
2022-12-14 13:14:49,116 INFO org.apache.hadoop.yarn.server.resourcemanager.rmcontainer.RMContainerImpl: container_1671022279734_0002_01_000020 Container Transitioned from ACQUIRED to RUNNING
2022-12-14 13:14:49,193 INFO org.apache.hadoop.yarn.server.resourcemanager.rmcontainer.RMContainerImpl: container_1671022279734_0002_01_000021 Container Transitioned from ALLOCATED to ACQUIRED
2022-12-14 13:14:50,149 INFO org.apache.hadoop.yarn.server.resourcemanager.rmcontainer.RMContainerImpl: container_1671022279734_0002_01_000021 Container Transitioned from ACQUIRED to RUNNING
2022-12-14 13:14:50,244 INFO org.apache.hadoop.yarn.server.resourcemanager.scheduler.AppSchedulingInfo: checking for deactivate of application :application_1671022279734_0002
2022-12-14 13:14:51,200 INFO org.apache.hadoop.yarn.server.resourcemanager.rmcontainer.RMContainerImpl: container_1671022279734_0002_01_000007 Container Transitioned from RUNNING to COMPLETED
2022-12-14 13:14:51,200 INFO org.apache.hadoop.yarn.server.resourcemanager.RMAuditLogger: USER=hdfs	OPERATION=AM Released Container	TARGET=SchedulerApp	RESULT=SUCCESS	APPID=application_1671022279734_0002	CONTAINERID=container_1671022279734_0002_01_000007	RESOURCE=<memory:1024, vCores:1>	QUEUENAME=default
2022-12-14 13:14:51,202 INFO org.apache.hadoop.yarn.server.resourcemanager.scheduler.capacity.allocator.AbstractContainerAllocator: assignedContainer application attempt=appattempt_1671022279734_0002_000001 container=null queue=default clusterResource=<memory:21171, vCores:6> type=OFF_SWITCH requestedPartition=
2022-12-14 13:14:51,202 INFO org.apache.hadoop.yarn.server.resourcemanager.rmcontainer.RMContainerImpl: container_1671022279734_0002_01_000022 Container Transitioned from NEW to ALLOCATED
2022-12-14 13:14:51,202 INFO org.apache.hadoop.yarn.server.resourcemanager.scheduler.common.fica.FiCaSchedulerNode: Assigned container container_1671022279734_0002_01_000022 of capacity <memory:1024, vCores:1> on host adh-test-00-mnode3.ru-central1.internal:8041, which has 6 containers, <memory:6144, vCores:6> used and <memory:913, vCores:-4> available after allocation
2022-12-14 13:14:51,202 INFO org.apache.hadoop.yarn.server.resourcemanager.RMAuditLogger: USER=hdfs	OPERATION=AM Allocated Container	TARGET=SchedulerApp	RESULT=SUCCESS	APPID=application_1671022279734_0002	CONTAINERID=container_1671022279734_0002_01_000022	RESOURCE=<memory:1024, vCores:1>	QUEUENAME=default
2022-12-14 13:14:51,203 INFO org.apache.hadoop.yarn.server.resourcemanager.scheduler.capacity.ParentQueue: assignedContainer queue=root usedCapacity=0.8706249 absoluteUsedCapacity=0.8706249 used=<memory:18432, vCores:17> cluster=<memory:21171, vCores:6>
2022-12-14 13:14:51,203 INFO org.apache.hadoop.yarn.server.resourcemanager.scheduler.capacity.CapacityScheduler: Allocation proposal accepted
2022-12-14 13:14:51,295 INFO org.apache.hadoop.yarn.server.resourcemanager.rmcontainer.RMContainerImpl: container_1671022279734_0002_01_000022 Container Transitioned from ALLOCATED to ACQUIRED
2022-12-14 13:14:51,306 INFO org.apache.hadoop.yarn.server.resourcemanager.rmcontainer.RMContainerImpl: container_1671022279734_0002_01_000005 Container Transitioned from RUNNING to COMPLETED
2022-12-14 13:14:51,306 INFO org.apache.hadoop.yarn.server.resourcemanager.RMAuditLogger: USER=hdfs	OPERATION=AM Released Container	TARGET=SchedulerApp	RESULT=SUCCESS	APPID=application_1671022279734_0002	CONTAINERID=container_1671022279734_0002_01_000005	RESOURCE=<memory:1024, vCores:1>	QUEUENAME=default
2022-12-14 13:14:51,319 INFO org.apache.hadoop.yarn.server.resourcemanager.rmcontainer.RMContainerImpl: container_1671022279734_0002_01_000002 Container Transitioned from RUNNING to COMPLETED
2022-12-14 13:14:51,319 INFO org.apache.hadoop.yarn.server.resourcemanager.RMAuditLogger: USER=hdfs	OPERATION=AM Released Container	TARGET=SchedulerApp	RESULT=SUCCESS	APPID=application_1671022279734_0002	CONTAINERID=container_1671022279734_0002_01_000002	RESOURCE=<memory:1024, vCores:1>	QUEUENAME=default
2022-12-14 13:14:51,340 INFO org.apache.hadoop.yarn.server.resourcemanager.rmcontainer.RMContainerImpl: container_1671022279734_0002_01_000006 Container Transitioned from RUNNING to COMPLETED
2022-12-14 13:14:51,340 INFO org.apache.hadoop.yarn.server.resourcemanager.RMAuditLogger: USER=hdfs	OPERATION=AM Released Container	TARGET=SchedulerApp	RESULT=SUCCESS	APPID=application_1671022279734_0002	CONTAINERID=container_1671022279734_0002_01_000006	RESOURCE=<memory:1024, vCores:1>	QUEUENAME=default
2022-12-14 13:14:51,400 INFO org.apache.hadoop.yarn.server.resourcemanager.rmcontainer.RMContainerImpl: container_1671022279734_0002_01_000004 Container Transitioned from RUNNING to COMPLETED
2022-12-14 13:14:51,400 INFO org.apache.hadoop.yarn.server.resourcemanager.RMAuditLogger: USER=hdfs	OPERATION=AM Released Container	TARGET=SchedulerApp	RESULT=SUCCESS	APPID=application_1671022279734_0002	CONTAINERID=container_1671022279734_0002_01_000004	RESOURCE=<memory:1024, vCores:1>	QUEUENAME=default
2022-12-14 13:14:51,637 INFO org.apache.hadoop.yarn.server.resourcemanager.rmcontainer.RMContainerImpl: container_1671022279734_0002_01_000012 Container Transitioned from RUNNING to COMPLETED
2022-12-14 13:14:51,637 INFO org.apache.hadoop.yarn.server.resourcemanager.RMAuditLogger: USER=hdfs	OPERATION=AM Released Container	TARGET=SchedulerApp	RESULT=SUCCESS	APPID=application_1671022279734_0002	CONTAINERID=container_1671022279734_0002_01_000012	RESOURCE=<memory:1024, vCores:1>	QUEUENAME=default
2022-12-14 13:14:51,822 INFO org.apache.hadoop.yarn.server.resourcemanager.rmcontainer.RMContainerImpl: container_1671022279734_0002_01_000011 Container Transitioned from RUNNING to COMPLETED
2022-12-14 13:14:51,822 INFO org.apache.hadoop.yarn.server.resourcemanager.RMAuditLogger: USER=hdfs	OPERATION=AM Released Container	TARGET=SchedulerApp	RESULT=SUCCESS	APPID=application_1671022279734_0002	CONTAINERID=container_1671022279734_0002_01_000011	RESOURCE=<memory:1024, vCores:1>	QUEUENAME=default
2022-12-14 13:14:52,010 INFO org.apache.hadoop.yarn.server.resourcemanager.rmcontainer.RMContainerImpl: container_1671022279734_0002_01_000009 Container Transitioned from RUNNING to COMPLETED
2022-12-14 13:14:52,011 INFO org.apache.hadoop.yarn.server.resourcemanager.RMAuditLogger: USER=hdfs	OPERATION=AM Released Container	TARGET=SchedulerApp	RESULT=SUCCESS	APPID=application_1671022279734_0002	CONTAINERID=container_1671022279734_0002_01_000009	RESOURCE=<memory:1024, vCores:1>	QUEUENAME=default
2022-12-14 13:14:52,075 INFO org.apache.hadoop.yarn.server.resourcemanager.rmcontainer.RMContainerImpl: container_1671022279734_0002_01_000010 Container Transitioned from RUNNING to COMPLETED
2022-12-14 13:14:52,075 INFO org.apache.hadoop.yarn.server.resourcemanager.RMAuditLogger: USER=hdfs	OPERATION=AM Released Container	TARGET=SchedulerApp	RESULT=SUCCESS	APPID=application_1671022279734_0002	CONTAINERID=container_1671022279734_0002_01_000010	RESOURCE=<memory:1024, vCores:1>	QUEUENAME=default
2022-12-14 13:14:52,094 INFO org.apache.hadoop.yarn.server.resourcemanager.rmcontainer.RMContainerImpl: container_1671022279734_0002_01_000013 Container Transitioned from RUNNING to COMPLETED
2022-12-14 13:14:52,094 INFO org.apache.hadoop.yarn.server.resourcemanager.RMAuditLogger: USER=hdfs	OPERATION=AM Released Container	TARGET=SchedulerApp	RESULT=SUCCESS	APPID=application_1671022279734_0002	CONTAINERID=container_1671022279734_0002_01_000013	RESOURCE=<memory:1024, vCores:1>	QUEUENAME=default
2022-12-14 13:14:52,127 INFO org.apache.hadoop.yarn.server.resourcemanager.rmcontainer.RMContainerImpl: container_1671022279734_0002_01_000008 Container Transitioned from RUNNING to COMPLETED
2022-12-14 13:14:52,127 INFO org.apache.hadoop.yarn.server.resourcemanager.RMAuditLogger: USER=hdfs	OPERATION=AM Released Container	TARGET=SchedulerApp	RESULT=SUCCESS	APPID=application_1671022279734_0002	CONTAINERID=container_1671022279734_0002_01_000008	RESOURCE=<memory:1024, vCores:1>	QUEUENAME=default
2022-12-14 13:14:52,344 INFO org.apache.hadoop.yarn.server.resourcemanager.scheduler.AppSchedulingInfo: checking for deactivate of application :application_1671022279734_0002
2022-12-14 13:14:52,408 INFO org.apache.hadoop.yarn.server.resourcemanager.rmcontainer.RMContainerImpl: container_1671022279734_0002_01_000022 Container Transitioned from ACQUIRED to RUNNING
2022-12-14 13:14:52,408 INFO org.apache.hadoop.yarn.server.resourcemanager.rmcontainer.RMContainerImpl: container_1671022279734_0002_01_000003 Container Transitioned from RUNNING to COMPLETED
2022-12-14 13:14:52,408 INFO org.apache.hadoop.yarn.server.resourcemanager.RMAuditLogger: USER=hdfs	OPERATION=AM Released Container	TARGET=SchedulerApp	RESULT=SUCCESS	APPID=application_1671022279734_0002	CONTAINERID=container_1671022279734_0002_01_000003	RESOURCE=<memory:1024, vCores:1>	QUEUENAME=default
2022-12-14 13:14:53,718 INFO org.apache.hadoop.yarn.server.resourcemanager.rmcontainer.RMContainerImpl: container_1671022279734_0002_01_000018 Container Transitioned from RUNNING to COMPLETED
2022-12-14 13:14:53,718 INFO org.apache.hadoop.yarn.server.resourcemanager.RMAuditLogger: USER=hdfs	OPERATION=AM Released Container	TARGET=SchedulerApp	RESULT=SUCCESS	APPID=application_1671022279734_0002	CONTAINERID=container_1671022279734_0002_01_000018	RESOURCE=<memory:1024, vCores:1>	QUEUENAME=default
2022-12-14 13:14:53,886 INFO org.apache.hadoop.yarn.server.resourcemanager.rmcontainer.RMContainerImpl: container_1671022279734_0002_01_000019 Container Transitioned from RUNNING to COMPLETED
2022-12-14 13:14:53,886 INFO org.apache.hadoop.yarn.server.resourcemanager.RMAuditLogger: USER=hdfs	OPERATION=AM Released Container	TARGET=SchedulerApp	RESULT=SUCCESS	APPID=application_1671022279734_0002	CONTAINERID=container_1671022279734_0002_01_000019	RESOURCE=<memory:1024, vCores:1>	QUEUENAME=default
2022-12-14 13:14:54,155 INFO org.apache.hadoop.yarn.server.resourcemanager.rmcontainer.RMContainerImpl: container_1671022279734_0002_01_000020 Container Transitioned from RUNNING to COMPLETED
2022-12-14 13:14:54,155 INFO org.apache.hadoop.yarn.server.resourcemanager.RMAuditLogger: USER=hdfs	OPERATION=AM Released Container	TARGET=SchedulerApp	RESULT=SUCCESS	APPID=application_1671022279734_0002	CONTAINERID=container_1671022279734_0002_01_000020	RESOURCE=<memory:1024, vCores:1>	QUEUENAME=default
2022-12-14 13:14:54,404 INFO org.apache.hadoop.yarn.server.resourcemanager.rmcontainer.RMContainerImpl: container_1671022279734_0002_01_000021 Container Transitioned from RUNNING to COMPLETED
2022-12-14 13:14:54,404 INFO org.apache.hadoop.yarn.server.resourcemanager.RMAuditLogger: USER=hdfs	OPERATION=AM Released Container	TARGET=SchedulerApp	RESULT=SUCCESS	APPID=application_1671022279734_0002	CONTAINERID=container_1671022279734_0002_01_000021	RESOURCE=<memory:1024, vCores:1>	QUEUENAME=default
2022-12-14 13:14:54,897 INFO org.apache.hadoop.yarn.server.resourcemanager.rmapp.attempt.RMAppAttemptImpl: Updating application attempt appattempt_1671022279734_0002_000001 with final state: FINISHING, and exit status: -1000
2022-12-14 13:14:54,897 INFO org.apache.hadoop.yarn.server.resourcemanager.rmapp.attempt.RMAppAttemptImpl: appattempt_1671022279734_0002_000001 State change from RUNNING to FINAL_SAVING on event = UNREGISTERED
2022-12-14 13:14:54,897 INFO org.apache.hadoop.yarn.server.resourcemanager.rmapp.RMAppImpl: Updating application application_1671022279734_0002 with final state: FINISHING
2022-12-14 13:14:54,897 INFO org.apache.hadoop.yarn.server.resourcemanager.rmapp.RMAppImpl: application_1671022279734_0002 State change from RUNNING to FINAL_SAVING on event = ATTEMPT_UNREGISTERED
2022-12-14 13:14:54,898 INFO org.apache.hadoop.yarn.server.resourcemanager.recovery.RMStateStore: Updating info for app: application_1671022279734_0002
2022-12-14 13:14:54,898 INFO org.apache.hadoop.yarn.server.resourcemanager.rmapp.attempt.RMAppAttemptImpl: appattempt_1671022279734_0002_000001 State change from FINAL_SAVING to FINISHING on event = ATTEMPT_UPDATE_SAVED
2022-12-14 13:14:54,898 INFO org.apache.hadoop.yarn.server.resourcemanager.rmapp.RMAppImpl: application_1671022279734_0002 State change from FINAL_SAVING to FINISHING on event = APP_UPDATE_SAVED
2022-12-14 13:14:54,899 INFO org.apache.hadoop.yarn.server.resourcemanager.rmcontainer.RMContainerImpl: container_1671022279734_0002_01_000022 Container Transitioned from RUNNING to COMPLETED
2022-12-14 13:14:54,899 INFO org.apache.hadoop.yarn.server.resourcemanager.RMAuditLogger: USER=hdfs	OPERATION=AM Released Container	TARGET=SchedulerApp	RESULT=SUCCESS	APPID=application_1671022279734_0002	CONTAINERID=container_1671022279734_0002_01_000022	RESOURCE=<memory:1024, vCores:1>	QUEUENAME=default
2022-12-14 13:14:55,899 INFO org.apache.hadoop.yarn.server.resourcemanager.ApplicationMasterService: application_1671022279734_0002 unregistered successfully. 
2022-12-14 13:15:01,304 INFO org.apache.hadoop.yarn.server.resourcemanager.ApplicationMasterService: Unregistering app attempt : appattempt_1671022279734_0002_000001
2022-12-14 13:15:01,304 INFO org.apache.hadoop.yarn.server.resourcemanager.rmcontainer.RMContainerImpl: container_1671022279734_0002_01_000001 Container Transitioned from RUNNING to COMPLETED
2022-12-14 13:15:01,304 INFO org.apache.hadoop.yarn.server.resourcemanager.security.AMRMTokenSecretManager: Application finished, removing password for appattempt_1671022279734_0002_000001
2022-12-14 13:15:01,304 INFO org.apache.hadoop.yarn.server.resourcemanager.RMAuditLogger: USER=hdfs	OPERATION=AM Released Container	TARGET=SchedulerApp	RESULT=SUCCESS	APPID=application_1671022279734_0002	CONTAINERID=container_1671022279734_0002_01_000001	RESOURCE=<memory:2048, vCores:1>	QUEUENAME=default
2022-12-14 13:15:01,305 INFO org.apache.hadoop.yarn.server.resourcemanager.rmapp.attempt.RMAppAttemptImpl: appattempt_1671022279734_0002_000001 State change from FINISHING to FINISHED on event = CONTAINER_FINISHED
2022-12-14 13:15:01,306 INFO org.apache.hadoop.yarn.server.resourcemanager.rmapp.RMAppImpl: application_1671022279734_0002 State change from FINISHING to FINISHED on event = ATTEMPT_FINISHED
2022-12-14 13:15:01,306 INFO org.apache.hadoop.yarn.server.resourcemanager.scheduler.capacity.CapacityScheduler: Application Attempt appattempt_1671022279734_0002_000001 is done. finalState=FINISHED
2022-12-14 13:15:01,306 INFO org.apache.hadoop.yarn.server.resourcemanager.RMAuditLogger: USER=hdfs	OPERATION=Application Finished - Succeeded	TARGET=RMAppManager	RESULT=SUCCESS	APPID=application_1671022279734_0002
2022-12-14 13:15:01,306 INFO org.apache.hadoop.yarn.server.resourcemanager.scheduler.AppSchedulingInfo: Application application_1671022279734_0002 requests cleared
2022-12-14 13:15:01,306 INFO org.apache.hadoop.yarn.server.resourcemanager.scheduler.capacity.LeafQueue: Application removed - appId: application_1671022279734_0002 user: hdfs queue: default #user-pending-applications: 0 #user-active-applications: 0 #queue-pending-applications: 0 #queue-active-applications: 0
2022-12-14 13:15:01,306 INFO org.apache.hadoop.yarn.server.resourcemanager.scheduler.capacity.ParentQueue: Application removed - appId: application_1671022279734_0002 user: hdfs leaf-queue of parent: root #applications: 0
2022-12-14 13:15:01,306 INFO org.apache.hadoop.yarn.server.resourcemanager.amlauncher.AMLauncher: Cleaning master appattempt_1671022279734_0002_000001
2022-12-14 13:15:01,306 INFO org.apache.hadoop.yarn.server.resourcemanager.RMAppManager$ApplicationSummary: appId=application_1671022279734_0002,name=QuasiMonteCarlo,user=hdfs,queue=default,state=FINISHED,trackingUrl=http://adh-test-00-mnode1.ru-central1.internal:8088/proxy/application_1671022279734_0002/,appMasterHost=adh-test-00-mnode2.ru-central1.internal,submitTime=1671023676043,startTime=1671023676044,finishTime=1671023694897,finalStatus=SUCCEEDED,memorySeconds=241475,vcoreSeconds=200,preemptedMemorySeconds=0,preemptedVcoreSeconds=0,preemptedAMContainers=0,preemptedNonAMContainers=0,preemptedResources=<memory:0\, vCores:0>,applicationType=MAPREDUCE,resourceSeconds=241475 MB-seconds\, 200 vcore-seconds,preemptedResourceSeconds=0 MB-seconds\, 0 vcore-seconds
2022-12-14 13:51:19,887 INFO org.apache.hadoop.yarn.server.resourcemanager.recovery.LeveldbRMStateStore: Starting full compaction cycle
2022-12-14 13:51:19,900 INFO org.apache.hadoop.yarn.server.resourcemanager.recovery.LeveldbRMStateStore: Full compaction cycle completed in 13 msec
2022-12-14 14:51:19,887 INFO org.apache.hadoop.yarn.server.resourcemanager.recovery.LeveldbRMStateStore: Starting full compaction cycle
2022-12-14 14:51:19,900 INFO org.apache.hadoop.yarn.server.resourcemanager.recovery.LeveldbRMStateStore: Full compaction cycle completed in 13 msec
2022-12-14 15:51:19,887 INFO org.apache.hadoop.yarn.server.resourcemanager.recovery.LeveldbRMStateStore: Starting full compaction cycle
2022-12-14 15:51:19,900 INFO org.apache.hadoop.yarn.server.resourcemanager.recovery.LeveldbRMStateStore: Full compaction cycle completed in 13 msec
2022-12-14 16:51:19,887 INFO org.apache.hadoop.yarn.server.resourcemanager.recovery.LeveldbRMStateStore: Starting full compaction cycle
2022-12-14 16:51:19,902 INFO org.apache.hadoop.yarn.server.resourcemanager.recovery.LeveldbRMStateStore: Full compaction cycle completed in 14 msec
2022-12-14 17:51:19,887 INFO org.apache.hadoop.yarn.server.resourcemanager.recovery.LeveldbRMStateStore: Starting full compaction cycle
2022-12-14 17:51:19,898 INFO org.apache.hadoop.yarn.server.resourcemanager.recovery.LeveldbRMStateStore: Full compaction cycle completed in 11 msec
2022-12-14 18:51:19,887 INFO org.apache.hadoop.yarn.server.resourcemanager.recovery.LeveldbRMStateStore: Starting full compaction cycle
2022-12-14 18:51:19,891 INFO org.apache.hadoop.yarn.server.resourcemanager.recovery.LeveldbRMStateStore: Full compaction cycle completed in 4 msec
2022-12-14 19:51:19,887 INFO org.apache.hadoop.yarn.server.resourcemanager.recovery.LeveldbRMStateStore: Starting full compaction cycle
2022-12-14 19:51:19,896 INFO org.apache.hadoop.yarn.server.resourcemanager.recovery.LeveldbRMStateStore: Full compaction cycle completed in 9 msec
2022-12-14 20:51:19,887 INFO org.apache.hadoop.yarn.server.resourcemanager.recovery.LeveldbRMStateStore: Starting full compaction cycle
2022-12-14 20:51:19,890 INFO org.apache.hadoop.yarn.server.resourcemanager.recovery.LeveldbRMStateStore: Full compaction cycle completed in 3 msec
2022-12-14 21:51:19,887 INFO org.apache.hadoop.yarn.server.resourcemanager.recovery.LeveldbRMStateStore: Starting full compaction cycle
2022-12-14 21:51:19,890 INFO org.apache.hadoop.yarn.server.resourcemanager.recovery.LeveldbRMStateStore: Full compaction cycle completed in 3 msec
2022-12-14 22:51:19,887 INFO org.apache.hadoop.yarn.server.resourcemanager.recovery.LeveldbRMStateStore: Starting full compaction cycle
2022-12-14 22:51:19,899 INFO org.apache.hadoop.yarn.server.resourcemanager.recovery.LeveldbRMStateStore: Full compaction cycle completed in 12 msec
2022-12-14 23:51:19,887 INFO org.apache.hadoop.yarn.server.resourcemanager.recovery.LeveldbRMStateStore: Starting full compaction cycle
2022-12-14 23:51:19,899 INFO org.apache.hadoop.yarn.server.resourcemanager.recovery.LeveldbRMStateStore: Full compaction cycle completed in 11 msec
2022-12-15 00:51:19,887 INFO org.apache.hadoop.yarn.server.resourcemanager.recovery.LeveldbRMStateStore: Starting full compaction cycle
2022-12-15 00:51:19,891 INFO org.apache.hadoop.yarn.server.resourcemanager.recovery.LeveldbRMStateStore: Full compaction cycle completed in 4 msec
2022-12-15 01:51:19,887 INFO org.apache.hadoop.yarn.server.resourcemanager.recovery.LeveldbRMStateStore: Starting full compaction cycle
2022-12-15 01:51:19,905 INFO org.apache.hadoop.yarn.server.resourcemanager.recovery.LeveldbRMStateStore: Full compaction cycle completed in 18 msec
2022-12-15 02:51:19,887 INFO org.apache.hadoop.yarn.server.resourcemanager.recovery.LeveldbRMStateStore: Starting full compaction cycle
2022-12-15 02:51:19,909 INFO org.apache.hadoop.yarn.server.resourcemanager.recovery.LeveldbRMStateStore: Full compaction cycle completed in 22 msec
2022-12-15 03:51:19,887 INFO org.apache.hadoop.yarn.server.resourcemanager.recovery.LeveldbRMStateStore: Starting full compaction cycle
2022-12-15 03:51:19,894 INFO org.apache.hadoop.yarn.server.resourcemanager.recovery.LeveldbRMStateStore: Full compaction cycle completed in 7 msec
2022-12-15 04:51:19,888 INFO org.apache.hadoop.yarn.server.resourcemanager.recovery.LeveldbRMStateStore: Starting full compaction cycle
2022-12-15 04:51:19,893 INFO org.apache.hadoop.yarn.server.resourcemanager.recovery.LeveldbRMStateStore: Full compaction cycle completed in 5 msec
2022-12-15 05:51:19,889 INFO org.apache.hadoop.yarn.server.resourcemanager.recovery.LeveldbRMStateStore: Starting full compaction cycle
2022-12-15 05:51:19,899 INFO org.apache.hadoop.yarn.server.resourcemanager.recovery.LeveldbRMStateStore: Full compaction cycle completed in 10 msec
2022-12-15 06:51:19,889 INFO org.apache.hadoop.yarn.server.resourcemanager.recovery.LeveldbRMStateStore: Starting full compaction cycle
2022-12-15 06:51:19,904 INFO org.apache.hadoop.yarn.server.resourcemanager.recovery.LeveldbRMStateStore: Full compaction cycle completed in 15 msec
2022-12-15 07:51:19,889 INFO org.apache.hadoop.yarn.server.resourcemanager.recovery.LeveldbRMStateStore: Starting full compaction cycle
2022-12-15 07:51:19,909 INFO org.apache.hadoop.yarn.server.resourcemanager.recovery.LeveldbRMStateStore: Full compaction cycle completed in 20 msec
2022-12-15 08:51:19,889 INFO org.apache.hadoop.yarn.server.resourcemanager.recovery.LeveldbRMStateStore: Starting full compaction cycle
2022-12-15 08:51:19,905 INFO org.apache.hadoop.yarn.server.resourcemanager.recovery.LeveldbRMStateStore: Full compaction cycle completed in 16 msec
2022-12-15 09:51:19,889 INFO org.apache.hadoop.yarn.server.resourcemanager.recovery.LeveldbRMStateStore: Starting full compaction cycle
2022-12-15 09:51:19,893 INFO org.apache.hadoop.yarn.server.resourcemanager.recovery.LeveldbRMStateStore: Full compaction cycle completed in 4 msec
2022-12-15 10:51:19,889 INFO org.apache.hadoop.yarn.server.resourcemanager.recovery.LeveldbRMStateStore: Starting full compaction cycle
2022-12-15 10:51:19,900 INFO org.apache.hadoop.yarn.server.resourcemanager.recovery.LeveldbRMStateStore: Full compaction cycle completed in 11 msec
2022-12-15 11:51:19,889 INFO org.apache.hadoop.yarn.server.resourcemanager.recovery.LeveldbRMStateStore: Starting full compaction cycle
2022-12-15 11:51:19,906 INFO org.apache.hadoop.yarn.server.resourcemanager.recovery.LeveldbRMStateStore: Full compaction cycle completed in 17 msec
2022-12-15 19:01:05,592 INFO org.apache.hadoop.yarn.server.resourcemanager.ResourceManager: STARTUP_MSG: 
/************************************************************
STARTUP_MSG: Starting ResourceManager
STARTUP_MSG:   host = adh-test-00-mnode1.ru-central1.internal/10.130.0.4
STARTUP_MSG:   args = []
STARTUP_MSG:   version = 3.1.2
STARTUP_MSG:   build = git@ssh.gitlab.adsw.io:arenadata/infrastructure/code/ci/prj_adh.git -r 15525ac41ebda8bc83c285e9b6ea7fb9921fd7fd; compiled by 'jenkins' on 2022-09-08T14:33Z
STARTUP_MSG:   java = 1.8.0_352
************************************************************/
2022-12-15 19:01:05,645 INFO org.apache.hadoop.yarn.server.resourcemanager.ResourceManager: registered UNIX signal handlers for [TERM, HUP, INT]
2022-12-15 19:01:06,107 INFO org.apache.hadoop.conf.Configuration: found resource core-site.xml at file:/etc/hadoop/conf/core-site.xml
2022-12-15 19:01:06,385 INFO org.apache.hadoop.conf.Configuration: resource-types.xml not found
2022-12-15 19:01:06,385 INFO org.apache.hadoop.yarn.util.resource.ResourceUtils: Unable to find 'resource-types.xml'.
2022-12-15 19:01:06,628 INFO org.apache.hadoop.conf.Configuration: found resource yarn-site.xml at file:/etc/hadoop/conf/yarn-site.xml
2022-12-15 19:01:06,688 INFO org.apache.hadoop.yarn.event.AsyncDispatcher: Registering class org.apache.hadoop.yarn.server.resourcemanager.RMFatalEventType for class org.apache.hadoop.yarn.server.resourcemanager.ResourceManager$RMFatalEventDispatcher
2022-12-15 19:01:06,747 INFO org.apache.hadoop.yarn.server.resourcemanager.security.NMTokenSecretManagerInRM: NMTokenKeyRollingInterval: 86400000ms and NMTokenKeyActivationDelay: 900000ms
2022-12-15 19:01:06,752 INFO org.apache.hadoop.yarn.server.resourcemanager.security.RMContainerTokenSecretManager: ContainerTokenKeyRollingInterval: 86400000ms and ContainerTokenKeyActivationDelay: 900000ms
2022-12-15 19:01:06,760 INFO org.apache.hadoop.yarn.server.resourcemanager.security.AMRMTokenSecretManager: AMRMTokenKeyRollingInterval: 86400000ms and AMRMTokenKeyActivationDelay: 900000 ms
2022-12-15 19:01:06,873 INFO org.apache.hadoop.yarn.server.resourcemanager.recovery.RMStateStoreFactory: Using RMStateStore implementation - class org.apache.hadoop.yarn.server.resourcemanager.recovery.LeveldbRMStateStore
2022-12-15 19:01:06,875 INFO org.apache.hadoop.yarn.event.AsyncDispatcher: Registering class org.apache.hadoop.yarn.server.resourcemanager.recovery.RMStateStoreEventType for class org.apache.hadoop.yarn.server.resourcemanager.recovery.RMStateStore$ForwardingEventHandler
2022-12-15 19:01:06,881 INFO org.apache.hadoop.yarn.event.AsyncDispatcher: Registering class org.apache.hadoop.yarn.server.resourcemanager.NodesListManagerEventType for class org.apache.hadoop.yarn.server.resourcemanager.NodesListManager
2022-12-15 19:01:06,881 INFO org.apache.hadoop.yarn.server.resourcemanager.ResourceManager: Using Scheduler: org.apache.hadoop.yarn.server.resourcemanager.scheduler.capacity.CapacityScheduler
2022-12-15 19:01:06,958 INFO org.apache.hadoop.yarn.event.AsyncDispatcher: Registering class org.apache.hadoop.yarn.server.resourcemanager.scheduler.event.SchedulerEventType for class org.apache.hadoop.yarn.event.EventDispatcher
2022-12-15 19:01:06,960 INFO org.apache.hadoop.yarn.event.AsyncDispatcher: Registering class org.apache.hadoop.yarn.server.resourcemanager.rmapp.RMAppEventType for class org.apache.hadoop.yarn.server.resourcemanager.ResourceManager$ApplicationEventDispatcher
2022-12-15 19:01:06,961 INFO org.apache.hadoop.yarn.event.AsyncDispatcher: Registering class org.apache.hadoop.yarn.server.resourcemanager.rmapp.attempt.RMAppAttemptEventType for class org.apache.hadoop.yarn.server.resourcemanager.ResourceManager$ApplicationAttemptEventDispatcher
2022-12-15 19:01:06,962 INFO org.apache.hadoop.yarn.event.AsyncDispatcher: Registering class org.apache.hadoop.yarn.server.resourcemanager.rmnode.RMNodeEventType for class org.apache.hadoop.yarn.server.resourcemanager.ResourceManager$NodeEventDispatcher
2022-12-15 19:01:07,126 WARN org.apache.hadoop.metrics2.impl.MetricsConfig: Cannot locate configuration: tried hadoop-metrics2-resourcemanager.properties,hadoop-metrics2.properties
2022-12-15 19:01:07,148 INFO org.apache.hadoop.metrics2.impl.MetricsSystemImpl: Scheduled Metric snapshot period at 10 second(s).
2022-12-15 19:01:07,148 INFO org.apache.hadoop.metrics2.impl.MetricsSystemImpl: ResourceManager metrics system started
2022-12-15 19:01:07,168 INFO org.apache.hadoop.yarn.security.YarnAuthorizationProvider: org.apache.hadoop.yarn.security.ConfiguredYarnAuthorizer is instantiated.
2022-12-15 19:01:07,171 INFO org.apache.hadoop.yarn.event.AsyncDispatcher: Registering class org.apache.hadoop.yarn.server.resourcemanager.RMAppManagerEventType for class org.apache.hadoop.yarn.server.resourcemanager.RMAppManager
2022-12-15 19:01:07,183 INFO org.apache.hadoop.yarn.event.AsyncDispatcher: Registering class org.apache.hadoop.yarn.server.resourcemanager.amlauncher.AMLauncherEventType for class org.apache.hadoop.yarn.server.resourcemanager.amlauncher.ApplicationMasterLauncher
2022-12-15 19:01:07,216 INFO org.apache.hadoop.yarn.server.resourcemanager.RMNMInfo: Registered RMNMInfo MBean
2022-12-15 19:01:07,217 INFO org.apache.hadoop.yarn.server.resourcemanager.rmapp.monitor.RMAppLifetimeMonitor: Application lifelime monitor interval set to 3000 ms.
2022-12-15 19:01:07,240 INFO org.apache.hadoop.util.HostsFileReader: Refreshing hosts (include/exclude) list
2022-12-15 19:01:07,251 INFO org.apache.hadoop.util.HostsFileReader: Adding a node "adh-test-00-mnode1.ru-central1.internal" to the list of included hosts from /etc/hadoop/conf/include-path
2022-12-15 19:01:07,252 INFO org.apache.hadoop.util.HostsFileReader: Adding a node "adh-test-00-mnode2.ru-central1.internal" to the list of included hosts from /etc/hadoop/conf/include-path
2022-12-15 19:01:07,252 INFO org.apache.hadoop.util.HostsFileReader: Adding a node "adh-test-00-mnode3.ru-central1.internal" to the list of included hosts from /etc/hadoop/conf/include-path
2022-12-15 19:01:07,609 INFO org.apache.hadoop.conf.Configuration: found resource capacity-scheduler.xml at file:/etc/hadoop/conf/capacity-scheduler.xml
2022-12-15 19:01:07,650 INFO org.apache.hadoop.yarn.server.resourcemanager.scheduler.AbstractYarnScheduler: Minimum allocation = <memory:1024, vCores:1>
2022-12-15 19:01:07,650 INFO org.apache.hadoop.yarn.server.resourcemanager.scheduler.AbstractYarnScheduler: Maximum allocation = <memory:4096, vCores:2>
2022-12-15 19:01:07,702 INFO org.apache.hadoop.yarn.server.resourcemanager.scheduler.capacity.CapacitySchedulerConfiguration: max alloc mb per queue for root is undefined
2022-12-15 19:01:07,702 INFO org.apache.hadoop.yarn.server.resourcemanager.scheduler.capacity.CapacitySchedulerConfiguration: max alloc vcore per queue for root is undefined
2022-12-15 19:01:07,721 INFO org.apache.hadoop.yarn.server.resourcemanager.scheduler.capacity.ParentQueue: root, capacity=1.0, absoluteCapacity=1.0, maxCapacity=1.0, absoluteMaxCapacity=1.0, state=RUNNING, acls=SUBMIT_APP:*ADMINISTER_QUEUE:*, labels=*,
, reservationsContinueLooking=true, orderingPolicy=utilization, priority=0
2022-12-15 19:01:07,721 INFO org.apache.hadoop.yarn.server.resourcemanager.scheduler.capacity.ParentQueue: Initialized parent-queue root name=root, fullname=root
2022-12-15 19:01:07,748 INFO org.apache.hadoop.yarn.server.resourcemanager.scheduler.capacity.CapacitySchedulerConfiguration: max alloc mb per queue for root.default is undefined
2022-12-15 19:01:07,749 INFO org.apache.hadoop.yarn.server.resourcemanager.scheduler.capacity.CapacitySchedulerConfiguration: max alloc vcore per queue for root.default is undefined
2022-12-15 19:01:07,754 INFO org.apache.hadoop.yarn.server.resourcemanager.scheduler.capacity.LeafQueue: Initializing default
capacity = 1.0 [= (float) configuredCapacity / 100 ]
absoluteCapacity = 1.0 [= parentAbsoluteCapacity * capacity ]
maxCapacity = 1.0 [= configuredMaxCapacity ]
absoluteMaxCapacity = 1.0 [= 1.0 maximumCapacity undefined, (parentAbsoluteMaxCapacity * maximumCapacity) / 100 otherwise ]
effectiveMinResource=<memory:0, vCores:0>
 , effectiveMaxResource=<memory:0, vCores:0>
userLimit = 100 [= configuredUserLimit ]
userLimitFactor = 1.0 [= configuredUserLimitFactor ]
maxApplications = 10000 [= configuredMaximumSystemApplicationsPerQueue or (int)(configuredMaximumSystemApplications * absoluteCapacity)]
maxApplicationsPerUser = 10000 [= (int)(maxApplications * (userLimit / 100.0f) * userLimitFactor) ]
usedCapacity = 0.0 [= usedResourcesMemory / (clusterResourceMemory * absoluteCapacity)]
absoluteUsedCapacity = 0.0 [= usedResourcesMemory / clusterResourceMemory]
maxAMResourcePerQueuePercent = 0.2 [= configuredMaximumAMResourcePercent ]
minimumAllocationFactor = 0.75 [= (float)(maximumAllocationMemory - minimumAllocationMemory) / maximumAllocationMemory ]
maximumAllocation = <memory:4096, vCores:2> [= configuredMaxAllocation ]
numContainers = 0 [= currentNumContainers ]
state = RUNNING [= configuredState ]
acls = SUBMIT_APP:*ADMINISTER_QUEUE:* [= configuredAcls ]
nodeLocalityDelay = 40
rackLocalityAdditionalDelay = -1
labels=*,
reservationsContinueLooking = true
preemptionDisabled = true
defaultAppPriorityPerQueue = 0
priority = 0
maxLifetime = -1 seconds
defaultLifetime = -1 seconds
2022-12-15 19:01:07,755 INFO org.apache.hadoop.yarn.server.resourcemanager.scheduler.capacity.CapacitySchedulerQueueManager: Initialized queue: default: capacity=1.0, absoluteCapacity=1.0, usedResources=<memory:0, vCores:0>, usedCapacity=0.0, absoluteUsedCapacity=0.0, numApps=0, numContainers=0, effectiveMinResource=<memory:0, vCores:0> , effectiveMaxResource=<memory:0, vCores:0>
2022-12-15 19:01:07,755 INFO org.apache.hadoop.yarn.server.resourcemanager.scheduler.capacity.CapacitySchedulerQueueManager: Initialized queue: root: numChildQueue= 1, capacity=1.0, absoluteCapacity=1.0, usedResources=<memory:0, vCores:0>usedCapacity=0.0, numApps=0, numContainers=0
2022-12-15 19:01:07,784 INFO org.apache.hadoop.yarn.server.resourcemanager.scheduler.capacity.CapacitySchedulerQueueManager: Initialized root queue root: numChildQueue= 1, capacity=1.0, absoluteCapacity=1.0, usedResources=<memory:0, vCores:0>usedCapacity=0.0, numApps=0, numContainers=0
2022-12-15 19:01:07,785 INFO org.apache.hadoop.yarn.server.resourcemanager.placement.UserGroupMappingPlacementRule: Initialized queue mappings, override: false
2022-12-15 19:01:07,786 INFO org.apache.hadoop.yarn.server.resourcemanager.scheduler.capacity.CapacityScheduler: Initialized CapacityScheduler with calculator=class org.apache.hadoop.yarn.util.resource.DefaultResourceCalculator, minimumAllocation=<<memory:1024, vCores:1>>, maximumAllocation=<<memory:4096, vCores:2>>, asynchronousScheduling=false, asyncScheduleInterval=5ms
2022-12-15 19:01:07,790 INFO org.apache.hadoop.conf.Configuration: dynamic-resources.xml not found
2022-12-15 19:01:07,796 INFO org.apache.hadoop.yarn.server.resourcemanager.AMSProcessingChain: Initializing AMS Processing chain. Root Processor=[org.apache.hadoop.yarn.server.resourcemanager.DefaultAMSProcessor].
2022-12-15 19:01:07,796 INFO org.apache.hadoop.yarn.server.resourcemanager.ApplicationMasterService: disabled placement handler will be used, all scheduling requests will be rejected.
2022-12-15 19:01:07,800 INFO org.apache.hadoop.yarn.server.resourcemanager.AMSProcessingChain: Adding [org.apache.hadoop.yarn.server.resourcemanager.scheduler.constraint.processor.DisabledPlacementProcessor] tp top of AMS Processing chain. 
2022-12-15 19:01:08,225 INFO org.apache.hadoop.yarn.client.api.impl.TimelineClientImpl: Timeline service address: adh-test-00-mnode2.ru-central1.internal:8188
2022-12-15 19:01:08,650 INFO org.apache.hadoop.yarn.event.AsyncDispatcher: Registering class org.apache.hadoop.yarn.server.resourcemanager.metrics.AbstractSystemMetricsPublisher$SystemMetricsEventType for class org.apache.hadoop.yarn.server.resourcemanager.metrics.TimelineServiceV1Publisher$TimelineV1EventHandler
2022-12-15 19:01:08,650 INFO org.apache.hadoop.yarn.event.AsyncDispatcher: Registering class org.apache.hadoop.yarn.server.resourcemanager.metrics.AbstractSystemMetricsPublisher$SystemMetricsEventType for class org.apache.hadoop.yarn.server.resourcemanager.metrics.TimelineServiceV1Publisher$TimelineV1EventHandler
2022-12-15 19:01:08,650 INFO org.apache.hadoop.yarn.event.AsyncDispatcher: Registering class org.apache.hadoop.yarn.server.resourcemanager.metrics.AbstractSystemMetricsPublisher$SystemMetricsEventType for class org.apache.hadoop.yarn.server.resourcemanager.metrics.TimelineServiceV1Publisher$TimelineV1EventHandler
2022-12-15 19:01:08,650 INFO org.apache.hadoop.yarn.event.AsyncDispatcher: Registering class org.apache.hadoop.yarn.server.resourcemanager.metrics.AbstractSystemMetricsPublisher$SystemMetricsEventType for class org.apache.hadoop.yarn.server.resourcemanager.metrics.TimelineServiceV1Publisher$TimelineV1EventHandler
2022-12-15 19:01:08,650 INFO org.apache.hadoop.yarn.event.AsyncDispatcher: Registering class org.apache.hadoop.yarn.server.resourcemanager.metrics.AbstractSystemMetricsPublisher$SystemMetricsEventType for class org.apache.hadoop.yarn.server.resourcemanager.metrics.TimelineServiceV1Publisher$TimelineV1EventHandler
2022-12-15 19:01:08,650 INFO org.apache.hadoop.yarn.event.AsyncDispatcher: Registering class org.apache.hadoop.yarn.server.resourcemanager.metrics.AbstractSystemMetricsPublisher$SystemMetricsEventType for class org.apache.hadoop.yarn.server.resourcemanager.metrics.TimelineServiceV1Publisher$TimelineV1EventHandler
2022-12-15 19:01:08,650 INFO org.apache.hadoop.yarn.event.AsyncDispatcher: Registering class org.apache.hadoop.yarn.server.resourcemanager.metrics.AbstractSystemMetricsPublisher$SystemMetricsEventType for class org.apache.hadoop.yarn.server.resourcemanager.metrics.TimelineServiceV1Publisher$TimelineV1EventHandler
2022-12-15 19:01:08,650 INFO org.apache.hadoop.yarn.event.AsyncDispatcher: Registering class org.apache.hadoop.yarn.server.resourcemanager.metrics.AbstractSystemMetricsPublisher$SystemMetricsEventType for class org.apache.hadoop.yarn.server.resourcemanager.metrics.TimelineServiceV1Publisher$TimelineV1EventHandler
2022-12-15 19:01:08,650 INFO org.apache.hadoop.yarn.event.AsyncDispatcher: Registering class org.apache.hadoop.yarn.server.resourcemanager.metrics.AbstractSystemMetricsPublisher$SystemMetricsEventType for class org.apache.hadoop.yarn.server.resourcemanager.metrics.TimelineServiceV1Publisher$TimelineV1EventHandler
2022-12-15 19:01:08,650 INFO org.apache.hadoop.yarn.event.AsyncDispatcher: Registering class org.apache.hadoop.yarn.server.resourcemanager.metrics.AbstractSystemMetricsPublisher$SystemMetricsEventType for class org.apache.hadoop.yarn.server.resourcemanager.metrics.TimelineServiceV1Publisher$TimelineV1EventHandler
2022-12-15 19:01:08,704 INFO org.eclipse.jetty.util.log: Logging initialized @17463ms
2022-12-15 19:01:08,752 INFO org.apache.hadoop.yarn.server.resourcemanager.ResourceManager: Using webapps at: file:/usr/lib/hadoop-yarn/webapps/ui2
2022-12-15 19:01:08,797 INFO org.apache.hadoop.security.authentication.server.AuthenticationFilter: Unable to initialize FileSignerSecretProvider, falling back to use random secrets.
2022-12-15 19:01:08,804 INFO org.apache.hadoop.http.HttpRequestLog: Http request log for http.requests.resourcemanager is not defined
2022-12-15 19:01:08,808 INFO org.apache.hadoop.http.HttpServer2: Added global filter 'safety' (class=org.apache.hadoop.http.HttpServer2$QuotingInputFilter)
2022-12-15 19:01:08,811 INFO org.apache.hadoop.http.HttpServer2: Added filter RMAuthenticationFilter (class=org.apache.hadoop.yarn.server.security.http.RMAuthenticationFilter) to context cluster
2022-12-15 19:01:08,812 INFO org.apache.hadoop.http.HttpServer2: Added filter RMAuthenticationFilter (class=org.apache.hadoop.yarn.server.security.http.RMAuthenticationFilter) to context logs
2022-12-15 19:01:08,812 INFO org.apache.hadoop.http.HttpServer2: Added filter RMAuthenticationFilter (class=org.apache.hadoop.yarn.server.security.http.RMAuthenticationFilter) to context static
2022-12-15 19:01:08,812 INFO org.apache.hadoop.http.HttpServer2: Added filter static_user_filter (class=org.apache.hadoop.http.lib.StaticUserWebFilter$StaticUserFilter) to context cluster
2022-12-15 19:01:08,814 INFO org.apache.hadoop.http.HttpServer2: Added filter static_user_filter (class=org.apache.hadoop.http.lib.StaticUserWebFilter$StaticUserFilter) to context logs
2022-12-15 19:01:08,814 INFO org.apache.hadoop.http.HttpServer2: Added filter static_user_filter (class=org.apache.hadoop.http.lib.StaticUserWebFilter$StaticUserFilter) to context static
2022-12-15 19:01:08,817 INFO org.apache.hadoop.http.HttpServer2: adding path spec: /cluster/*
2022-12-15 19:01:08,817 INFO org.apache.hadoop.http.HttpServer2: adding path spec: /ws/*
2022-12-15 19:01:08,817 INFO org.apache.hadoop.http.HttpServer2: adding path spec: /app/*
2022-12-15 19:01:09,295 INFO org.apache.hadoop.yarn.webapp.WebApps: Registered webapp guice modules
2022-12-15 19:01:09,303 INFO org.apache.hadoop.http.HttpServer2: Jetty bound to port 8088
2022-12-15 19:01:09,304 INFO org.eclipse.jetty.server.Server: jetty-9.3.24.v20180605, build timestamp: 2018-06-05T17:11:56Z, git hash: 84205aa28f11a4f31f2a3b86d1bba2cc8ab69827
2022-12-15 19:01:09,344 INFO org.apache.hadoop.security.authentication.server.AuthenticationFilter: Unable to initialize FileSignerSecretProvider, falling back to use random secrets.
2022-12-15 19:01:09,382 INFO org.apache.hadoop.security.token.delegation.AbstractDelegationTokenSecretManager: Updating the current master key for generating delegation tokens
2022-12-15 19:01:09,387 INFO org.eclipse.jetty.server.handler.ContextHandler: Started o.e.j.s.ServletContextHandler@569bf9eb{/logs,file:///var/log/hadoop-yarn/,AVAILABLE}
2022-12-15 19:01:09,388 INFO org.apache.hadoop.security.token.delegation.AbstractDelegationTokenSecretManager: Starting expired delegation token remover thread, tokenRemoverScanInterval=60 min(s)
2022-12-15 19:01:09,388 INFO org.eclipse.jetty.server.handler.ContextHandler: Started o.e.j.s.ServletContextHandler@eb6449b{/static,jar:file:/usr/lib/hadoop-yarn/hadoop-yarn-common-3.1.2.jar!/webapps/static,AVAILABLE}
2022-12-15 19:01:09,406 INFO org.apache.hadoop.security.token.delegation.AbstractDelegationTokenSecretManager: Updating the current master key for generating delegation tokens
2022-12-15 19:01:11,097 INFO org.eclipse.jetty.server.handler.ContextHandler: Started o.e.j.w.WebAppContext@ebd06a9{/,file:///tmp/jetty-0.0.0.0-8088-cluster-_-any-1366849252542494468.dir/webapp/,AVAILABLE}{/cluster}
2022-12-15 19:01:11,148 INFO org.eclipse.jetty.webapp.StandardDescriptorProcessor: NO JSP Support for /ui2, did not find org.eclipse.jetty.jsp.JettyJspServlet
2022-12-15 19:01:11,156 INFO org.eclipse.jetty.server.handler.ContextHandler: Started o.e.j.w.WebAppContext@a7ad6e5{/ui2,file:///usr/lib/hadoop-yarn/webapps/ui2/,AVAILABLE}
2022-12-15 19:01:11,163 INFO org.eclipse.jetty.server.AbstractConnector: Started ServerConnector@1b5c3e5f{HTTP/1.1,[http/1.1]}{0.0.0.0:8088}
2022-12-15 19:01:11,163 INFO org.eclipse.jetty.server.Server: Started @19924ms
2022-12-15 19:01:11,163 INFO org.apache.hadoop.yarn.webapp.WebApps: Web app cluster started at 8088
2022-12-15 19:01:11,333 INFO org.apache.hadoop.ipc.CallQueueManager: Using callQueue: class java.util.concurrent.LinkedBlockingQueue queueCapacity: 100 scheduler: class org.apache.hadoop.ipc.DefaultRpcScheduler
2022-12-15 19:01:11,344 INFO org.apache.hadoop.ipc.Server: Starting Socket Reader #1 for port 8033
2022-12-15 19:01:11,374 INFO org.apache.hadoop.yarn.factories.impl.pb.RpcServerFactoryPBImpl: Adding protocol org.apache.hadoop.yarn.server.api.ResourceManagerAdministrationProtocolPB to the server
2022-12-15 19:01:11,375 INFO org.apache.hadoop.ipc.Server: IPC Server Responder: starting
2022-12-15 19:01:11,376 INFO org.apache.hadoop.ipc.Server: IPC Server listener on 8033: starting
2022-12-15 19:01:11,382 INFO org.apache.hadoop.yarn.server.resourcemanager.ResourceManager: Transitioning to active state
2022-12-15 19:01:11,568 INFO org.apache.hadoop.yarn.server.resourcemanager.recovery.LeveldbRMStateStore: Using state database at /srv/hadoop-yarn/leveldb-state-store/yarn-rm-state for recovery
2022-12-15 19:01:11,814 INFO org.apache.hadoop.yarn.server.resourcemanager.ResourceManager: Recovery started
2022-12-15 19:01:11,832 INFO org.apache.hadoop.yarn.server.resourcemanager.recovery.RMStateStore: Loaded RM state version info 1.1
2022-12-15 19:01:11,857 INFO org.apache.hadoop.yarn.server.resourcemanager.recovery.LeveldbRMStateStore: Recovered 2 RM delegation token master keys
2022-12-15 19:01:11,857 INFO org.apache.hadoop.yarn.server.resourcemanager.recovery.LeveldbRMStateStore: Recovered 0 RM delegation tokens
2022-12-15 19:01:11,952 INFO org.apache.hadoop.yarn.server.resourcemanager.recovery.LeveldbRMStateStore: Recovered 2 applications and 2 application attempts
2022-12-15 19:01:11,958 INFO org.apache.hadoop.yarn.server.resourcemanager.recovery.LeveldbRMStateStore: Recovered 0 reservations
2022-12-15 19:01:11,958 INFO org.apache.hadoop.yarn.server.resourcemanager.security.RMDelegationTokenSecretManager: recovering RMDelegationTokenSecretManager.
2022-12-15 19:01:11,961 INFO org.apache.hadoop.yarn.server.resourcemanager.RMAppManager: Recovering 2 applications
2022-12-15 19:01:12,032 WARN org.apache.hadoop.yarn.server.resourcemanager.rmapp.RMAppImpl: The specific max attempts: 0 for application: 1 is invalid, because it is out of the range [1, 2]. Use the global max attempts instead.
2022-12-15 19:01:12,070 INFO org.apache.hadoop.yarn.server.resourcemanager.RMAuditLogger: USER=yarn	OPERATION=Application Finished - Succeeded	TARGET=RMAppManager	RESULT=SUCCESS	APPID=application_1671022279734_0001
2022-12-15 19:01:12,073 INFO org.apache.hadoop.yarn.server.resourcemanager.RMAppManager$ApplicationSummary: appId=application_1671022279734_0001,name=QuasiMonteCarlo,user=yarn,queue=default,state=FINISHED,trackingUrl=http://adh-test-00-mnode1.ru-central1.internal:8088/proxy/application_1671022279734_0001/,appMasterHost=N/A,submitTime=1671022505181,startTime=1671022505266,finishTime=1671022524607,finalStatus=SUCCEEDED,memorySeconds=216125,vcoreSeconds=183,preemptedMemorySeconds=216125,preemptedVcoreSeconds=183,preemptedAMContainers=0,preemptedNonAMContainers=0,preemptedResources=<memory:0\, vCores:0>,applicationType=MAPREDUCE,resourceSeconds=216125 MB-seconds\, 183 vcore-seconds,preemptedResourceSeconds=216125 MB-seconds\, 183 vcore-seconds
2022-12-15 19:01:12,073 WARN org.apache.hadoop.yarn.server.resourcemanager.rmapp.RMAppImpl: The specific max attempts: 0 for application: 2 is invalid, because it is out of the range [1, 2]. Use the global max attempts instead.
2022-12-15 19:01:12,075 INFO org.apache.hadoop.yarn.server.resourcemanager.RMAppManager: Successfully recovered 2 out of 2 applications
2022-12-15 19:01:12,075 INFO org.apache.hadoop.yarn.server.resourcemanager.ResourceManager: Recovery ended
2022-12-15 19:01:12,075 INFO org.apache.hadoop.yarn.server.resourcemanager.security.RMContainerTokenSecretManager: Rolling master-key for container-tokens
2022-12-15 19:01:12,076 INFO org.apache.hadoop.yarn.server.resourcemanager.RMAuditLogger: USER=hdfs	OPERATION=Application Finished - Succeeded	TARGET=RMAppManager	RESULT=SUCCESS	APPID=application_1671022279734_0002
2022-12-15 19:01:12,078 INFO org.apache.hadoop.yarn.server.resourcemanager.security.NMTokenSecretManagerInRM: Rolling master-key for nm-tokens
2022-12-15 19:01:12,078 INFO org.apache.hadoop.security.token.delegation.AbstractDelegationTokenSecretManager: Updating the current master key for generating delegation tokens
2022-12-15 19:01:12,078 INFO org.apache.hadoop.yarn.server.resourcemanager.security.RMDelegationTokenSecretManager: storing master key with keyID 3
2022-12-15 19:01:12,078 INFO org.apache.hadoop.yarn.server.resourcemanager.recovery.RMStateStore: Storing RMDTMasterKey.
2022-12-15 19:01:12,080 INFO org.apache.hadoop.security.token.delegation.AbstractDelegationTokenSecretManager: Starting expired delegation token remover thread, tokenRemoverScanInterval=60 min(s)
2022-12-15 19:01:12,080 INFO org.apache.hadoop.security.token.delegation.AbstractDelegationTokenSecretManager: Updating the current master key for generating delegation tokens
2022-12-15 19:01:12,087 INFO org.apache.hadoop.yarn.server.resourcemanager.security.RMDelegationTokenSecretManager: storing master key with keyID 4
2022-12-15 19:01:12,087 INFO org.apache.hadoop.yarn.server.resourcemanager.recovery.RMStateStore: Storing RMDTMasterKey.
2022-12-15 19:01:12,088 INFO org.apache.hadoop.yarn.server.resourcemanager.RMAppManager$ApplicationSummary: appId=application_1671022279734_0002,name=QuasiMonteCarlo,user=hdfs,queue=default,state=FINISHED,trackingUrl=http://adh-test-00-mnode1.ru-central1.internal:8088/proxy/application_1671022279734_0002/,appMasterHost=N/A,submitTime=1671023676043,startTime=1671023676044,finishTime=1671023694897,finalStatus=SUCCEEDED,memorySeconds=228352,vcoreSeconds=193,preemptedMemorySeconds=228352,preemptedVcoreSeconds=193,preemptedAMContainers=0,preemptedNonAMContainers=0,preemptedResources=<memory:0\, vCores:0>,applicationType=MAPREDUCE,resourceSeconds=228352 MB-seconds\, 193 vcore-seconds,preemptedResourceSeconds=228352 MB-seconds\, 193 vcore-seconds
2022-12-15 19:01:12,656 INFO org.apache.hadoop.service.AbstractService: Service org.apache.hadoop.yarn.nodelabels.CommonNodeLabelsManager failed in state STARTED
org.apache.hadoop.hdfs.server.namenode.SafeModeException: Cannot create directory /system/yarn/node-labels. Name node is in safe mode.
The reported blocks 0 needs additional 11 blocks to reach the threshold 0.9990 of total blocks 12.
The number of live datanodes 0 has reached the minimum number 0. Safe mode will be turned off automatically once the thresholds have been reached. NamenodeHostName:adh-test-00-mnode1.ru-central1.internal
	at org.apache.hadoop.hdfs.server.namenode.FSNamesystem.newSafemodeException(FSNamesystem.java:1461)
	at org.apache.hadoop.hdfs.server.namenode.FSNamesystem.checkNameNodeSafeMode(FSNamesystem.java:1448)
	at org.apache.hadoop.hdfs.server.namenode.FSNamesystem.mkdirs(FSNamesystem.java:3145)
	at org.apache.hadoop.hdfs.server.namenode.NameNodeRpcServer.mkdirs(NameNodeRpcServer.java:1126)
	at org.apache.hadoop.hdfs.protocolPB.ClientNamenodeProtocolServerSideTranslatorPB.mkdirs(ClientNamenodeProtocolServerSideTranslatorPB.java:707)
	at org.apache.hadoop.hdfs.protocol.proto.ClientNamenodeProtocolProtos$ClientNamenodeProtocol$2.callBlockingMethod(ClientNamenodeProtocolProtos.java)
	at org.apache.hadoop.ipc.ProtobufRpcEngine$Server$ProtoBufRpcInvoker.call(ProtobufRpcEngine.java:523)
	at org.apache.hadoop.ipc.RPC$Server.call(RPC.java:991)
	at org.apache.hadoop.ipc.Server$RpcCall.run(Server.java:872)
	at org.apache.hadoop.ipc.Server$RpcCall.run(Server.java:818)
	at java.security.AccessController.doPrivileged(Native Method)
	at javax.security.auth.Subject.doAs(Subject.java:422)
	at org.apache.hadoop.security.UserGroupInformation.doAs(UserGroupInformation.java:1729)
	at org.apache.hadoop.ipc.Server$Handler.run(Server.java:2678)

	at sun.reflect.NativeConstructorAccessorImpl.newInstance0(Native Method)
	at sun.reflect.NativeConstructorAccessorImpl.newInstance(NativeConstructorAccessorImpl.java:62)
	at sun.reflect.DelegatingConstructorAccessorImpl.newInstance(DelegatingConstructorAccessorImpl.java:45)
	at java.lang.reflect.Constructor.newInstance(Constructor.java:423)
	at org.apache.hadoop.ipc.RemoteException.instantiateException(RemoteException.java:121)
	at org.apache.hadoop.ipc.RemoteException.unwrapRemoteException(RemoteException.java:88)
	at org.apache.hadoop.hdfs.DFSClient.primitiveMkdir(DFSClient.java:2421)
	at org.apache.hadoop.hdfs.DFSClient.mkdirs(DFSClient.java:2395)
	at org.apache.hadoop.hdfs.DistributedFileSystem$27.doCall(DistributedFileSystem.java:1325)
	at org.apache.hadoop.hdfs.DistributedFileSystem$27.doCall(DistributedFileSystem.java:1322)
	at org.apache.hadoop.fs.FileSystemLinkResolver.resolve(FileSystemLinkResolver.java:81)
	at org.apache.hadoop.hdfs.DistributedFileSystem.mkdirsInternal(DistributedFileSystem.java:1339)
	at org.apache.hadoop.hdfs.DistributedFileSystem.mkdirs(DistributedFileSystem.java:1314)
	at org.apache.hadoop.fs.FileSystem.mkdirs(FileSystem.java:2275)
	at org.apache.hadoop.yarn.nodelabels.FileSystemNodeLabelsStore.init(FileSystemNodeLabelsStore.java:87)
	at org.apache.hadoop.yarn.nodelabels.CommonNodeLabelsManager.initNodeLabelStore(CommonNodeLabelsManager.java:253)
	at org.apache.hadoop.yarn.nodelabels.CommonNodeLabelsManager.serviceStart(CommonNodeLabelsManager.java:268)
	at org.apache.hadoop.service.AbstractService.start(AbstractService.java:194)
	at org.apache.hadoop.service.CompositeService.serviceStart(CompositeService.java:121)
	at org.apache.hadoop.yarn.server.resourcemanager.ResourceManager$RMActiveServices.serviceStart(ResourceManager.java:869)
	at org.apache.hadoop.service.AbstractService.start(AbstractService.java:194)
	at org.apache.hadoop.yarn.server.resourcemanager.ResourceManager.startActiveServices(ResourceManager.java:1228)
	at org.apache.hadoop.yarn.server.resourcemanager.ResourceManager$1.run(ResourceManager.java:1269)
	at org.apache.hadoop.yarn.server.resourcemanager.ResourceManager$1.run(ResourceManager.java:1265)
	at java.security.AccessController.doPrivileged(Native Method)
	at javax.security.auth.Subject.doAs(Subject.java:422)
	at org.apache.hadoop.security.UserGroupInformation.doAs(UserGroupInformation.java:1729)
	at org.apache.hadoop.yarn.server.resourcemanager.ResourceManager.transitionToActive(ResourceManager.java:1265)
	at org.apache.hadoop.yarn.server.resourcemanager.ResourceManager.serviceStart(ResourceManager.java:1316)
	at org.apache.hadoop.service.AbstractService.start(AbstractService.java:194)
	at org.apache.hadoop.yarn.server.resourcemanager.ResourceManager.main(ResourceManager.java:1501)
Caused by: org.apache.hadoop.ipc.RemoteException(org.apache.hadoop.hdfs.server.namenode.SafeModeException): Cannot create directory /system/yarn/node-labels. Name node is in safe mode.
The reported blocks 0 needs additional 11 blocks to reach the threshold 0.9990 of total blocks 12.
The number of live datanodes 0 has reached the minimum number 0. Safe mode will be turned off automatically once the thresholds have been reached. NamenodeHostName:adh-test-00-mnode1.ru-central1.internal
	at org.apache.hadoop.hdfs.server.namenode.FSNamesystem.newSafemodeException(FSNamesystem.java:1461)
	at org.apache.hadoop.hdfs.server.namenode.FSNamesystem.checkNameNodeSafeMode(FSNamesystem.java:1448)
	at org.apache.hadoop.hdfs.server.namenode.FSNamesystem.mkdirs(FSNamesystem.java:3145)
	at org.apache.hadoop.hdfs.server.namenode.NameNodeRpcServer.mkdirs(NameNodeRpcServer.java:1126)
	at org.apache.hadoop.hdfs.protocolPB.ClientNamenodeProtocolServerSideTranslatorPB.mkdirs(ClientNamenodeProtocolServerSideTranslatorPB.java:707)
	at org.apache.hadoop.hdfs.protocol.proto.ClientNamenodeProtocolProtos$ClientNamenodeProtocol$2.callBlockingMethod(ClientNamenodeProtocolProtos.java)
	at org.apache.hadoop.ipc.ProtobufRpcEngine$Server$ProtoBufRpcInvoker.call(ProtobufRpcEngine.java:523)
	at org.apache.hadoop.ipc.RPC$Server.call(RPC.java:991)
	at org.apache.hadoop.ipc.Server$RpcCall.run(Server.java:872)
	at org.apache.hadoop.ipc.Server$RpcCall.run(Server.java:818)
	at java.security.AccessController.doPrivileged(Native Method)
	at javax.security.auth.Subject.doAs(Subject.java:422)
	at org.apache.hadoop.security.UserGroupInformation.doAs(UserGroupInformation.java:1729)
	at org.apache.hadoop.ipc.Server$Handler.run(Server.java:2678)

	at org.apache.hadoop.ipc.Client.getRpcResponse(Client.java:1511)
	at org.apache.hadoop.ipc.Client.call(Client.java:1457)
	at org.apache.hadoop.ipc.Client.call(Client.java:1367)
	at org.apache.hadoop.ipc.ProtobufRpcEngine$Invoker.invoke(ProtobufRpcEngine.java:228)
	at org.apache.hadoop.ipc.ProtobufRpcEngine$Invoker.invoke(ProtobufRpcEngine.java:116)
	at com.sun.proxy.$Proxy89.mkdirs(Unknown Source)
	at org.apache.hadoop.hdfs.protocolPB.ClientNamenodeProtocolTranslatorPB.mkdirs(ClientNamenodeProtocolTranslatorPB.java:653)
	at sun.reflect.NativeMethodAccessorImpl.invoke0(Native Method)
	at sun.reflect.NativeMethodAccessorImpl.invoke(NativeMethodAccessorImpl.java:62)
	at sun.reflect.DelegatingMethodAccessorImpl.invoke(DelegatingMethodAccessorImpl.java:43)
	at java.lang.reflect.Method.invoke(Method.java:498)
	at org.apache.hadoop.io.retry.RetryInvocationHandler.invokeMethod(RetryInvocationHandler.java:422)
	at org.apache.hadoop.io.retry.RetryInvocationHandler$Call.invokeMethod(RetryInvocationHandler.java:165)
	at org.apache.hadoop.io.retry.RetryInvocationHandler$Call.invoke(RetryInvocationHandler.java:157)
	at org.apache.hadoop.io.retry.RetryInvocationHandler$Call.invokeOnce(RetryInvocationHandler.java:95)
	at org.apache.hadoop.io.retry.RetryInvocationHandler.invoke(RetryInvocationHandler.java:359)
	at com.sun.proxy.$Proxy90.mkdirs(Unknown Source)
	at org.apache.hadoop.hdfs.DFSClient.primitiveMkdir(DFSClient.java:2419)
	... 24 more
2022-12-15 19:01:12,762 INFO org.apache.hadoop.service.AbstractService: Service RMActiveServices failed in state STARTED
org.apache.hadoop.service.ServiceStateException: org.apache.hadoop.hdfs.server.namenode.SafeModeException: Cannot create directory /system/yarn/node-labels. Name node is in safe mode.
The reported blocks 0 needs additional 11 blocks to reach the threshold 0.9990 of total blocks 12.
The number of live datanodes 0 has reached the minimum number 0. Safe mode will be turned off automatically once the thresholds have been reached. NamenodeHostName:adh-test-00-mnode1.ru-central1.internal
	at org.apache.hadoop.hdfs.server.namenode.FSNamesystem.newSafemodeException(FSNamesystem.java:1461)
	at org.apache.hadoop.hdfs.server.namenode.FSNamesystem.checkNameNodeSafeMode(FSNamesystem.java:1448)
	at org.apache.hadoop.hdfs.server.namenode.FSNamesystem.mkdirs(FSNamesystem.java:3145)
	at org.apache.hadoop.hdfs.server.namenode.NameNodeRpcServer.mkdirs(NameNodeRpcServer.java:1126)
	at org.apache.hadoop.hdfs.protocolPB.ClientNamenodeProtocolServerSideTranslatorPB.mkdirs(ClientNamenodeProtocolServerSideTranslatorPB.java:707)
	at org.apache.hadoop.hdfs.protocol.proto.ClientNamenodeProtocolProtos$ClientNamenodeProtocol$2.callBlockingMethod(ClientNamenodeProtocolProtos.java)
	at org.apache.hadoop.ipc.ProtobufRpcEngine$Server$ProtoBufRpcInvoker.call(ProtobufRpcEngine.java:523)
	at org.apache.hadoop.ipc.RPC$Server.call(RPC.java:991)
	at org.apache.hadoop.ipc.Server$RpcCall.run(Server.java:872)
	at org.apache.hadoop.ipc.Server$RpcCall.run(Server.java:818)
	at java.security.AccessController.doPrivileged(Native Method)
	at javax.security.auth.Subject.doAs(Subject.java:422)
	at org.apache.hadoop.security.UserGroupInformation.doAs(UserGroupInformation.java:1729)
	at org.apache.hadoop.ipc.Server$Handler.run(Server.java:2678)

	at org.apache.hadoop.service.ServiceStateException.convert(ServiceStateException.java:105)
	at org.apache.hadoop.service.AbstractService.start(AbstractService.java:203)
	at org.apache.hadoop.service.CompositeService.serviceStart(CompositeService.java:121)
	at org.apache.hadoop.yarn.server.resourcemanager.ResourceManager$RMActiveServices.serviceStart(ResourceManager.java:869)
	at org.apache.hadoop.service.AbstractService.start(AbstractService.java:194)
	at org.apache.hadoop.yarn.server.resourcemanager.ResourceManager.startActiveServices(ResourceManager.java:1228)
	at org.apache.hadoop.yarn.server.resourcemanager.ResourceManager$1.run(ResourceManager.java:1269)
	at org.apache.hadoop.yarn.server.resourcemanager.ResourceManager$1.run(ResourceManager.java:1265)
	at java.security.AccessController.doPrivileged(Native Method)
	at javax.security.auth.Subject.doAs(Subject.java:422)
	at org.apache.hadoop.security.UserGroupInformation.doAs(UserGroupInformation.java:1729)
	at org.apache.hadoop.yarn.server.resourcemanager.ResourceManager.transitionToActive(ResourceManager.java:1265)
	at org.apache.hadoop.yarn.server.resourcemanager.ResourceManager.serviceStart(ResourceManager.java:1316)
	at org.apache.hadoop.service.AbstractService.start(AbstractService.java:194)
	at org.apache.hadoop.yarn.server.resourcemanager.ResourceManager.main(ResourceManager.java:1501)
Caused by: org.apache.hadoop.hdfs.server.namenode.SafeModeException: Cannot create directory /system/yarn/node-labels. Name node is in safe mode.
The reported blocks 0 needs additional 11 blocks to reach the threshold 0.9990 of total blocks 12.
The number of live datanodes 0 has reached the minimum number 0. Safe mode will be turned off automatically once the thresholds have been reached. NamenodeHostName:adh-test-00-mnode1.ru-central1.internal
	at org.apache.hadoop.hdfs.server.namenode.FSNamesystem.newSafemodeException(FSNamesystem.java:1461)
	at org.apache.hadoop.hdfs.server.namenode.FSNamesystem.checkNameNodeSafeMode(FSNamesystem.java:1448)
	at org.apache.hadoop.hdfs.server.namenode.FSNamesystem.mkdirs(FSNamesystem.java:3145)
	at org.apache.hadoop.hdfs.server.namenode.NameNodeRpcServer.mkdirs(NameNodeRpcServer.java:1126)
	at org.apache.hadoop.hdfs.protocolPB.ClientNamenodeProtocolServerSideTranslatorPB.mkdirs(ClientNamenodeProtocolServerSideTranslatorPB.java:707)
	at org.apache.hadoop.hdfs.protocol.proto.ClientNamenodeProtocolProtos$ClientNamenodeProtocol$2.callBlockingMethod(ClientNamenodeProtocolProtos.java)
	at org.apache.hadoop.ipc.ProtobufRpcEngine$Server$ProtoBufRpcInvoker.call(ProtobufRpcEngine.java:523)
	at org.apache.hadoop.ipc.RPC$Server.call(RPC.java:991)
	at org.apache.hadoop.ipc.Server$RpcCall.run(Server.java:872)
	at org.apache.hadoop.ipc.Server$RpcCall.run(Server.java:818)
	at java.security.AccessController.doPrivileged(Native Method)
	at javax.security.auth.Subject.doAs(Subject.java:422)
	at org.apache.hadoop.security.UserGroupInformation.doAs(UserGroupInformation.java:1729)
	at org.apache.hadoop.ipc.Server$Handler.run(Server.java:2678)

	at sun.reflect.NativeConstructorAccessorImpl.newInstance0(Native Method)
	at sun.reflect.NativeConstructorAccessorImpl.newInstance(NativeConstructorAccessorImpl.java:62)
	at sun.reflect.DelegatingConstructorAccessorImpl.newInstance(DelegatingConstructorAccessorImpl.java:45)
	at java.lang.reflect.Constructor.newInstance(Constructor.java:423)
	at org.apache.hadoop.ipc.RemoteException.instantiateException(RemoteException.java:121)
	at org.apache.hadoop.ipc.RemoteException.unwrapRemoteException(RemoteException.java:88)
	at org.apache.hadoop.hdfs.DFSClient.primitiveMkdir(DFSClient.java:2421)
	at org.apache.hadoop.hdfs.DFSClient.mkdirs(DFSClient.java:2395)
	at org.apache.hadoop.hdfs.DistributedFileSystem$27.doCall(DistributedFileSystem.java:1325)
	at org.apache.hadoop.hdfs.DistributedFileSystem$27.doCall(DistributedFileSystem.java:1322)
	at org.apache.hadoop.fs.FileSystemLinkResolver.resolve(FileSystemLinkResolver.java:81)
	at org.apache.hadoop.hdfs.DistributedFileSystem.mkdirsInternal(DistributedFileSystem.java:1339)
	at org.apache.hadoop.hdfs.DistributedFileSystem.mkdirs(DistributedFileSystem.java:1314)
	at org.apache.hadoop.fs.FileSystem.mkdirs(FileSystem.java:2275)
	at org.apache.hadoop.yarn.nodelabels.FileSystemNodeLabelsStore.init(FileSystemNodeLabelsStore.java:87)
	at org.apache.hadoop.yarn.nodelabels.CommonNodeLabelsManager.initNodeLabelStore(CommonNodeLabelsManager.java:253)
	at org.apache.hadoop.yarn.nodelabels.CommonNodeLabelsManager.serviceStart(CommonNodeLabelsManager.java:268)
	at org.apache.hadoop.service.AbstractService.start(AbstractService.java:194)
	... 13 more
Caused by: org.apache.hadoop.ipc.RemoteException(org.apache.hadoop.hdfs.server.namenode.SafeModeException): Cannot create directory /system/yarn/node-labels. Name node is in safe mode.
The reported blocks 0 needs additional 11 blocks to reach the threshold 0.9990 of total blocks 12.
The number of live datanodes 0 has reached the minimum number 0. Safe mode will be turned off automatically once the thresholds have been reached. NamenodeHostName:adh-test-00-mnode1.ru-central1.internal
	at org.apache.hadoop.hdfs.server.namenode.FSNamesystem.newSafemodeException(FSNamesystem.java:1461)
	at org.apache.hadoop.hdfs.server.namenode.FSNamesystem.checkNameNodeSafeMode(FSNamesystem.java:1448)
	at org.apache.hadoop.hdfs.server.namenode.FSNamesystem.mkdirs(FSNamesystem.java:3145)
	at org.apache.hadoop.hdfs.server.namenode.NameNodeRpcServer.mkdirs(NameNodeRpcServer.java:1126)
	at org.apache.hadoop.hdfs.protocolPB.ClientNamenodeProtocolServerSideTranslatorPB.mkdirs(ClientNamenodeProtocolServerSideTranslatorPB.java:707)
	at org.apache.hadoop.hdfs.protocol.proto.ClientNamenodeProtocolProtos$ClientNamenodeProtocol$2.callBlockingMethod(ClientNamenodeProtocolProtos.java)
	at org.apache.hadoop.ipc.ProtobufRpcEngine$Server$ProtoBufRpcInvoker.call(ProtobufRpcEngine.java:523)
	at org.apache.hadoop.ipc.RPC$Server.call(RPC.java:991)
	at org.apache.hadoop.ipc.Server$RpcCall.run(Server.java:872)
	at org.apache.hadoop.ipc.Server$RpcCall.run(Server.java:818)
	at java.security.AccessController.doPrivileged(Native Method)
	at javax.security.auth.Subject.doAs(Subject.java:422)
	at org.apache.hadoop.security.UserGroupInformation.doAs(UserGroupInformation.java:1729)
	at org.apache.hadoop.ipc.Server$Handler.run(Server.java:2678)

	at org.apache.hadoop.ipc.Client.getRpcResponse(Client.java:1511)
	at org.apache.hadoop.ipc.Client.call(Client.java:1457)
	at org.apache.hadoop.ipc.Client.call(Client.java:1367)
	at org.apache.hadoop.ipc.ProtobufRpcEngine$Invoker.invoke(ProtobufRpcEngine.java:228)
	at org.apache.hadoop.ipc.ProtobufRpcEngine$Invoker.invoke(ProtobufRpcEngine.java:116)
	at com.sun.proxy.$Proxy89.mkdirs(Unknown Source)
	at org.apache.hadoop.hdfs.protocolPB.ClientNamenodeProtocolTranslatorPB.mkdirs(ClientNamenodeProtocolTranslatorPB.java:653)
	at sun.reflect.NativeMethodAccessorImpl.invoke0(Native Method)
	at sun.reflect.NativeMethodAccessorImpl.invoke(NativeMethodAccessorImpl.java:62)
	at sun.reflect.DelegatingMethodAccessorImpl.invoke(DelegatingMethodAccessorImpl.java:43)
	at java.lang.reflect.Method.invoke(Method.java:498)
	at org.apache.hadoop.io.retry.RetryInvocationHandler.invokeMethod(RetryInvocationHandler.java:422)
	at org.apache.hadoop.io.retry.RetryInvocationHandler$Call.invokeMethod(RetryInvocationHandler.java:165)
	at org.apache.hadoop.io.retry.RetryInvocationHandler$Call.invoke(RetryInvocationHandler.java:157)
	at org.apache.hadoop.io.retry.RetryInvocationHandler$Call.invokeOnce(RetryInvocationHandler.java:95)
	at org.apache.hadoop.io.retry.RetryInvocationHandler.invoke(RetryInvocationHandler.java:359)
	at com.sun.proxy.$Proxy90.mkdirs(Unknown Source)
	at org.apache.hadoop.hdfs.DFSClient.primitiveMkdir(DFSClient.java:2419)
	... 24 more
2022-12-15 19:01:12,764 INFO org.apache.hadoop.yarn.util.AbstractLivelinessMonitor: AMLivelinessMonitor thread interrupted
2022-12-15 19:01:12,765 INFO org.apache.hadoop.yarn.util.AbstractLivelinessMonitor: org.apache.hadoop.yarn.server.resourcemanager.rmapp.monitor.RMAppLifetimeMonitor thread interrupted
2022-12-15 19:01:12,765 INFO org.apache.hadoop.yarn.util.AbstractLivelinessMonitor: org.apache.hadoop.yarn.server.resourcemanager.rmcontainer.ContainerAllocationExpirer thread interrupted
2022-12-15 19:01:12,765 INFO org.apache.hadoop.yarn.util.AbstractLivelinessMonitor: AMLivelinessMonitor thread interrupted
2022-12-15 19:01:12,764 ERROR org.apache.hadoop.security.token.delegation.AbstractDelegationTokenSecretManager: ExpiredTokenRemover received java.lang.InterruptedException: sleep interrupted
2022-12-15 19:01:12,770 INFO org.apache.hadoop.metrics2.impl.MetricsSystemImpl: Stopping ResourceManager metrics system...
2022-12-15 19:01:12,770 INFO org.apache.hadoop.metrics2.impl.MetricsSystemImpl: ResourceManager metrics system stopped.
2022-12-15 19:01:12,770 INFO org.apache.hadoop.metrics2.impl.MetricsSystemImpl: ResourceManager metrics system shutdown complete.
2022-12-15 19:01:12,770 INFO org.apache.hadoop.yarn.event.AsyncDispatcher: AsyncDispatcher is draining to stop, ignoring any new events.
2022-12-15 19:01:12,774 INFO org.apache.hadoop.yarn.event.AsyncDispatcher: Registering class org.apache.hadoop.yarn.server.resourcemanager.RMFatalEventType for class org.apache.hadoop.yarn.server.resourcemanager.ResourceManager$RMFatalEventDispatcher
2022-12-15 19:01:12,774 INFO org.apache.hadoop.yarn.server.resourcemanager.security.NMTokenSecretManagerInRM: NMTokenKeyRollingInterval: 86400000ms and NMTokenKeyActivationDelay: 900000ms
2022-12-15 19:01:12,775 INFO org.apache.hadoop.yarn.server.resourcemanager.security.RMContainerTokenSecretManager: ContainerTokenKeyRollingInterval: 86400000ms and ContainerTokenKeyActivationDelay: 900000ms
2022-12-15 19:01:12,775 INFO org.apache.hadoop.yarn.server.resourcemanager.security.AMRMTokenSecretManager: AMRMTokenKeyRollingInterval: 86400000ms and AMRMTokenKeyActivationDelay: 900000 ms
2022-12-15 19:01:12,775 INFO org.apache.hadoop.yarn.server.resourcemanager.recovery.RMStateStoreFactory: Using RMStateStore implementation - class org.apache.hadoop.yarn.server.resourcemanager.recovery.LeveldbRMStateStore
2022-12-15 19:01:12,775 INFO org.apache.hadoop.yarn.event.AsyncDispatcher: Registering class org.apache.hadoop.yarn.server.resourcemanager.recovery.RMStateStoreEventType for class org.apache.hadoop.yarn.server.resourcemanager.recovery.RMStateStore$ForwardingEventHandler
2022-12-15 19:01:12,775 INFO org.apache.hadoop.yarn.event.AsyncDispatcher: Registering class org.apache.hadoop.yarn.server.resourcemanager.NodesListManagerEventType for class org.apache.hadoop.yarn.server.resourcemanager.NodesListManager
2022-12-15 19:01:12,775 INFO org.apache.hadoop.yarn.server.resourcemanager.ResourceManager: Using Scheduler: org.apache.hadoop.yarn.server.resourcemanager.scheduler.capacity.CapacityScheduler
2022-12-15 19:01:12,775 INFO org.apache.hadoop.yarn.event.AsyncDispatcher: Registering class org.apache.hadoop.yarn.server.resourcemanager.scheduler.event.SchedulerEventType for class org.apache.hadoop.yarn.event.EventDispatcher
2022-12-15 19:01:12,775 INFO org.apache.hadoop.yarn.event.AsyncDispatcher: Registering class org.apache.hadoop.yarn.server.resourcemanager.rmapp.RMAppEventType for class org.apache.hadoop.yarn.server.resourcemanager.ResourceManager$ApplicationEventDispatcher
2022-12-15 19:01:12,775 INFO org.apache.hadoop.yarn.event.AsyncDispatcher: Registering class org.apache.hadoop.yarn.server.resourcemanager.rmapp.attempt.RMAppAttemptEventType for class org.apache.hadoop.yarn.server.resourcemanager.ResourceManager$ApplicationAttemptEventDispatcher
2022-12-15 19:01:12,775 INFO org.apache.hadoop.yarn.event.AsyncDispatcher: Registering class org.apache.hadoop.yarn.server.resourcemanager.rmnode.RMNodeEventType for class org.apache.hadoop.yarn.server.resourcemanager.ResourceManager$NodeEventDispatcher
2022-12-15 19:01:12,779 WARN org.apache.hadoop.metrics2.impl.MetricsConfig: Cannot locate configuration: tried hadoop-metrics2-resourcemanager.properties,hadoop-metrics2.properties
2022-12-15 19:01:12,782 INFO org.apache.hadoop.metrics2.impl.MetricsSystemImpl: Scheduled Metric snapshot period at 10 second(s).
2022-12-15 19:01:12,782 INFO org.apache.hadoop.metrics2.impl.MetricsSystemImpl: ResourceManager metrics system started
2022-12-15 19:01:12,784 INFO org.apache.hadoop.yarn.event.AsyncDispatcher: Registering class org.apache.hadoop.yarn.server.resourcemanager.RMAppManagerEventType for class org.apache.hadoop.yarn.server.resourcemanager.RMAppManager
2022-12-15 19:01:12,784 INFO org.apache.hadoop.yarn.event.AsyncDispatcher: Registering class org.apache.hadoop.yarn.server.resourcemanager.amlauncher.AMLauncherEventType for class org.apache.hadoop.yarn.server.resourcemanager.amlauncher.ApplicationMasterLauncher
2022-12-15 19:01:12,784 WARN org.apache.hadoop.metrics2.util.MBeans: Failed to register MBean "Hadoop:service=ResourceManager,name=RMNMInfo": Instance already exists.
2022-12-15 19:01:12,784 INFO org.apache.hadoop.yarn.server.resourcemanager.RMNMInfo: Registered RMNMInfo MBean
2022-12-15 19:01:12,784 INFO org.apache.hadoop.yarn.server.resourcemanager.rmapp.monitor.RMAppLifetimeMonitor: Application lifelime monitor interval set to 3000 ms.
2022-12-15 19:01:12,784 INFO org.apache.hadoop.util.HostsFileReader: Refreshing hosts (include/exclude) list
2022-12-15 19:01:12,784 INFO org.apache.hadoop.util.HostsFileReader: Adding a node "adh-test-00-mnode1.ru-central1.internal" to the list of included hosts from /etc/hadoop/conf/include-path
2022-12-15 19:01:12,784 INFO org.apache.hadoop.util.HostsFileReader: Adding a node "adh-test-00-mnode2.ru-central1.internal" to the list of included hosts from /etc/hadoop/conf/include-path
2022-12-15 19:01:12,784 INFO org.apache.hadoop.util.HostsFileReader: Adding a node "adh-test-00-mnode3.ru-central1.internal" to the list of included hosts from /etc/hadoop/conf/include-path
2022-12-15 19:01:12,787 INFO org.apache.hadoop.conf.Configuration: found resource capacity-scheduler.xml at file:/etc/hadoop/conf/capacity-scheduler.xml
2022-12-15 19:01:12,798 INFO org.apache.hadoop.yarn.server.resourcemanager.scheduler.AbstractYarnScheduler: Minimum allocation = <memory:1024, vCores:1>
2022-12-15 19:01:12,798 INFO org.apache.hadoop.yarn.server.resourcemanager.scheduler.AbstractYarnScheduler: Maximum allocation = <memory:4096, vCores:2>
2022-12-15 19:01:12,803 INFO org.apache.hadoop.yarn.server.resourcemanager.scheduler.capacity.CapacitySchedulerConfiguration: max alloc mb per queue for root is undefined
2022-12-15 19:01:12,803 INFO org.apache.hadoop.yarn.server.resourcemanager.scheduler.capacity.CapacitySchedulerConfiguration: max alloc vcore per queue for root is undefined
2022-12-15 19:01:12,804 INFO org.apache.hadoop.yarn.server.resourcemanager.scheduler.capacity.ParentQueue: root, capacity=1.0, absoluteCapacity=1.0, maxCapacity=1.0, absoluteMaxCapacity=1.0, state=RUNNING, acls=SUBMIT_APP:*ADMINISTER_QUEUE:*, labels=*,
, reservationsContinueLooking=true, orderingPolicy=utilization, priority=0
2022-12-15 19:01:12,804 INFO org.apache.hadoop.yarn.server.resourcemanager.scheduler.capacity.ParentQueue: Initialized parent-queue root name=root, fullname=root
2022-12-15 19:01:12,807 INFO org.apache.hadoop.yarn.server.resourcemanager.scheduler.capacity.CapacitySchedulerConfiguration: max alloc mb per queue for root.default is undefined
2022-12-15 19:01:12,807 INFO org.apache.hadoop.yarn.server.resourcemanager.scheduler.capacity.CapacitySchedulerConfiguration: max alloc vcore per queue for root.default is undefined
2022-12-15 19:01:12,809 INFO org.apache.hadoop.yarn.server.resourcemanager.scheduler.capacity.LeafQueue: Initializing default
capacity = 1.0 [= (float) configuredCapacity / 100 ]
absoluteCapacity = 1.0 [= parentAbsoluteCapacity * capacity ]
maxCapacity = 1.0 [= configuredMaxCapacity ]
absoluteMaxCapacity = 1.0 [= 1.0 maximumCapacity undefined, (parentAbsoluteMaxCapacity * maximumCapacity) / 100 otherwise ]
effectiveMinResource=<memory:0, vCores:0>
 , effectiveMaxResource=<memory:0, vCores:0>
userLimit = 100 [= configuredUserLimit ]
userLimitFactor = 1.0 [= configuredUserLimitFactor ]
maxApplications = 10000 [= configuredMaximumSystemApplicationsPerQueue or (int)(configuredMaximumSystemApplications * absoluteCapacity)]
maxApplicationsPerUser = 10000 [= (int)(maxApplications * (userLimit / 100.0f) * userLimitFactor) ]
usedCapacity = 0.0 [= usedResourcesMemory / (clusterResourceMemory * absoluteCapacity)]
absoluteUsedCapacity = 0.0 [= usedResourcesMemory / clusterResourceMemory]
maxAMResourcePerQueuePercent = 0.2 [= configuredMaximumAMResourcePercent ]
minimumAllocationFactor = 0.75 [= (float)(maximumAllocationMemory - minimumAllocationMemory) / maximumAllocationMemory ]
maximumAllocation = <memory:4096, vCores:2> [= configuredMaxAllocation ]
numContainers = 0 [= currentNumContainers ]
state = RUNNING [= configuredState ]
acls = SUBMIT_APP:*ADMINISTER_QUEUE:* [= configuredAcls ]
nodeLocalityDelay = 40
rackLocalityAdditionalDelay = -1
labels=*,
reservationsContinueLooking = true
preemptionDisabled = true
defaultAppPriorityPerQueue = 0
priority = 0
maxLifetime = -1 seconds
defaultLifetime = -1 seconds
2022-12-15 19:01:12,809 INFO org.apache.hadoop.yarn.server.resourcemanager.scheduler.capacity.CapacitySchedulerQueueManager: Initialized queue: default: capacity=1.0, absoluteCapacity=1.0, usedResources=<memory:0, vCores:0>, usedCapacity=0.0, absoluteUsedCapacity=0.0, numApps=0, numContainers=0, effectiveMinResource=<memory:0, vCores:0> , effectiveMaxResource=<memory:0, vCores:0>
2022-12-15 19:01:12,809 INFO org.apache.hadoop.yarn.server.resourcemanager.scheduler.capacity.CapacitySchedulerQueueManager: Initialized queue: root: numChildQueue= 1, capacity=1.0, absoluteCapacity=1.0, usedResources=<memory:0, vCores:0>usedCapacity=0.0, numApps=0, numContainers=0
2022-12-15 19:01:12,809 INFO org.apache.hadoop.yarn.server.resourcemanager.scheduler.capacity.CapacitySchedulerQueueManager: Initialized root queue root: numChildQueue= 1, capacity=1.0, absoluteCapacity=1.0, usedResources=<memory:0, vCores:0>usedCapacity=0.0, numApps=0, numContainers=0
2022-12-15 19:01:12,810 INFO org.apache.hadoop.yarn.server.resourcemanager.placement.UserGroupMappingPlacementRule: Initialized queue mappings, override: false
2022-12-15 19:01:12,810 INFO org.apache.hadoop.yarn.server.resourcemanager.scheduler.capacity.CapacityScheduler: Initialized CapacityScheduler with calculator=class org.apache.hadoop.yarn.util.resource.DefaultResourceCalculator, minimumAllocation=<<memory:1024, vCores:1>>, maximumAllocation=<<memory:4096, vCores:2>>, asynchronousScheduling=false, asyncScheduleInterval=5ms
2022-12-15 19:01:12,810 INFO org.apache.hadoop.conf.Configuration: dynamic-resources.xml not found
2022-12-15 19:01:12,811 INFO org.apache.hadoop.yarn.server.resourcemanager.AMSProcessingChain: Initializing AMS Processing chain. Root Processor=[org.apache.hadoop.yarn.server.resourcemanager.DefaultAMSProcessor].
2022-12-15 19:01:12,811 INFO org.apache.hadoop.yarn.server.resourcemanager.ApplicationMasterService: disabled placement handler will be used, all scheduling requests will be rejected.
2022-12-15 19:01:12,811 INFO org.apache.hadoop.yarn.server.resourcemanager.AMSProcessingChain: Adding [org.apache.hadoop.yarn.server.resourcemanager.scheduler.constraint.processor.DisabledPlacementProcessor] tp top of AMS Processing chain. 
2022-12-15 19:01:12,812 INFO org.apache.hadoop.service.AbstractService: Service ResourceManager failed in state STARTED
org.apache.hadoop.service.ServiceStateException: org.apache.hadoop.hdfs.server.namenode.SafeModeException: Cannot create directory /system/yarn/node-labels. Name node is in safe mode.
The reported blocks 0 needs additional 11 blocks to reach the threshold 0.9990 of total blocks 12.
The number of live datanodes 0 has reached the minimum number 0. Safe mode will be turned off automatically once the thresholds have been reached. NamenodeHostName:adh-test-00-mnode1.ru-central1.internal
	at org.apache.hadoop.hdfs.server.namenode.FSNamesystem.newSafemodeException(FSNamesystem.java:1461)
	at org.apache.hadoop.hdfs.server.namenode.FSNamesystem.checkNameNodeSafeMode(FSNamesystem.java:1448)
	at org.apache.hadoop.hdfs.server.namenode.FSNamesystem.mkdirs(FSNamesystem.java:3145)
	at org.apache.hadoop.hdfs.server.namenode.NameNodeRpcServer.mkdirs(NameNodeRpcServer.java:1126)
	at org.apache.hadoop.hdfs.protocolPB.ClientNamenodeProtocolServerSideTranslatorPB.mkdirs(ClientNamenodeProtocolServerSideTranslatorPB.java:707)
	at org.apache.hadoop.hdfs.protocol.proto.ClientNamenodeProtocolProtos$ClientNamenodeProtocol$2.callBlockingMethod(ClientNamenodeProtocolProtos.java)
	at org.apache.hadoop.ipc.ProtobufRpcEngine$Server$ProtoBufRpcInvoker.call(ProtobufRpcEngine.java:523)
	at org.apache.hadoop.ipc.RPC$Server.call(RPC.java:991)
	at org.apache.hadoop.ipc.Server$RpcCall.run(Server.java:872)
	at org.apache.hadoop.ipc.Server$RpcCall.run(Server.java:818)
	at java.security.AccessController.doPrivileged(Native Method)
	at javax.security.auth.Subject.doAs(Subject.java:422)
	at org.apache.hadoop.security.UserGroupInformation.doAs(UserGroupInformation.java:1729)
	at org.apache.hadoop.ipc.Server$Handler.run(Server.java:2678)

	at org.apache.hadoop.service.ServiceStateException.convert(ServiceStateException.java:105)
	at org.apache.hadoop.service.AbstractService.start(AbstractService.java:203)
	at org.apache.hadoop.service.CompositeService.serviceStart(CompositeService.java:121)
	at org.apache.hadoop.yarn.server.resourcemanager.ResourceManager$RMActiveServices.serviceStart(ResourceManager.java:869)
	at org.apache.hadoop.service.AbstractService.start(AbstractService.java:194)
	at org.apache.hadoop.yarn.server.resourcemanager.ResourceManager.startActiveServices(ResourceManager.java:1228)
	at org.apache.hadoop.yarn.server.resourcemanager.ResourceManager$1.run(ResourceManager.java:1269)
	at org.apache.hadoop.yarn.server.resourcemanager.ResourceManager$1.run(ResourceManager.java:1265)
	at java.security.AccessController.doPrivileged(Native Method)
	at javax.security.auth.Subject.doAs(Subject.java:422)
	at org.apache.hadoop.security.UserGroupInformation.doAs(UserGroupInformation.java:1729)
	at org.apache.hadoop.yarn.server.resourcemanager.ResourceManager.transitionToActive(ResourceManager.java:1265)
	at org.apache.hadoop.yarn.server.resourcemanager.ResourceManager.serviceStart(ResourceManager.java:1316)
	at org.apache.hadoop.service.AbstractService.start(AbstractService.java:194)
	at org.apache.hadoop.yarn.server.resourcemanager.ResourceManager.main(ResourceManager.java:1501)
Caused by: org.apache.hadoop.hdfs.server.namenode.SafeModeException: Cannot create directory /system/yarn/node-labels. Name node is in safe mode.
The reported blocks 0 needs additional 11 blocks to reach the threshold 0.9990 of total blocks 12.
The number of live datanodes 0 has reached the minimum number 0. Safe mode will be turned off automatically once the thresholds have been reached. NamenodeHostName:adh-test-00-mnode1.ru-central1.internal
	at org.apache.hadoop.hdfs.server.namenode.FSNamesystem.newSafemodeException(FSNamesystem.java:1461)
	at org.apache.hadoop.hdfs.server.namenode.FSNamesystem.checkNameNodeSafeMode(FSNamesystem.java:1448)
	at org.apache.hadoop.hdfs.server.namenode.FSNamesystem.mkdirs(FSNamesystem.java:3145)
	at org.apache.hadoop.hdfs.server.namenode.NameNodeRpcServer.mkdirs(NameNodeRpcServer.java:1126)
	at org.apache.hadoop.hdfs.protocolPB.ClientNamenodeProtocolServerSideTranslatorPB.mkdirs(ClientNamenodeProtocolServerSideTranslatorPB.java:707)
	at org.apache.hadoop.hdfs.protocol.proto.ClientNamenodeProtocolProtos$ClientNamenodeProtocol$2.callBlockingMethod(ClientNamenodeProtocolProtos.java)
	at org.apache.hadoop.ipc.ProtobufRpcEngine$Server$ProtoBufRpcInvoker.call(ProtobufRpcEngine.java:523)
	at org.apache.hadoop.ipc.RPC$Server.call(RPC.java:991)
	at org.apache.hadoop.ipc.Server$RpcCall.run(Server.java:872)
	at org.apache.hadoop.ipc.Server$RpcCall.run(Server.java:818)
	at java.security.AccessController.doPrivileged(Native Method)
	at javax.security.auth.Subject.doAs(Subject.java:422)
	at org.apache.hadoop.security.UserGroupInformation.doAs(UserGroupInformation.java:1729)
	at org.apache.hadoop.ipc.Server$Handler.run(Server.java:2678)

	at sun.reflect.NativeConstructorAccessorImpl.newInstance0(Native Method)
	at sun.reflect.NativeConstructorAccessorImpl.newInstance(NativeConstructorAccessorImpl.java:62)
	at sun.reflect.DelegatingConstructorAccessorImpl.newInstance(DelegatingConstructorAccessorImpl.java:45)
	at java.lang.reflect.Constructor.newInstance(Constructor.java:423)
	at org.apache.hadoop.ipc.RemoteException.instantiateException(RemoteException.java:121)
	at org.apache.hadoop.ipc.RemoteException.unwrapRemoteException(RemoteException.java:88)
	at org.apache.hadoop.hdfs.DFSClient.primitiveMkdir(DFSClient.java:2421)
	at org.apache.hadoop.hdfs.DFSClient.mkdirs(DFSClient.java:2395)
	at org.apache.hadoop.hdfs.DistributedFileSystem$27.doCall(DistributedFileSystem.java:1325)
	at org.apache.hadoop.hdfs.DistributedFileSystem$27.doCall(DistributedFileSystem.java:1322)
	at org.apache.hadoop.fs.FileSystemLinkResolver.resolve(FileSystemLinkResolver.java:81)
	at org.apache.hadoop.hdfs.DistributedFileSystem.mkdirsInternal(DistributedFileSystem.java:1339)
	at org.apache.hadoop.hdfs.DistributedFileSystem.mkdirs(DistributedFileSystem.java:1314)
	at org.apache.hadoop.fs.FileSystem.mkdirs(FileSystem.java:2275)
	at org.apache.hadoop.yarn.nodelabels.FileSystemNodeLabelsStore.init(FileSystemNodeLabelsStore.java:87)
	at org.apache.hadoop.yarn.nodelabels.CommonNodeLabelsManager.initNodeLabelStore(CommonNodeLabelsManager.java:253)
	at org.apache.hadoop.yarn.nodelabels.CommonNodeLabelsManager.serviceStart(CommonNodeLabelsManager.java:268)
	at org.apache.hadoop.service.AbstractService.start(AbstractService.java:194)
	... 13 more
Caused by: org.apache.hadoop.ipc.RemoteException(org.apache.hadoop.hdfs.server.namenode.SafeModeException): Cannot create directory /system/yarn/node-labels. Name node is in safe mode.
The reported blocks 0 needs additional 11 blocks to reach the threshold 0.9990 of total blocks 12.
The number of live datanodes 0 has reached the minimum number 0. Safe mode will be turned off automatically once the thresholds have been reached. NamenodeHostName:adh-test-00-mnode1.ru-central1.internal
	at org.apache.hadoop.hdfs.server.namenode.FSNamesystem.newSafemodeException(FSNamesystem.java:1461)
	at org.apache.hadoop.hdfs.server.namenode.FSNamesystem.checkNameNodeSafeMode(FSNamesystem.java:1448)
	at org.apache.hadoop.hdfs.server.namenode.FSNamesystem.mkdirs(FSNamesystem.java:3145)
	at org.apache.hadoop.hdfs.server.namenode.NameNodeRpcServer.mkdirs(NameNodeRpcServer.java:1126)
	at org.apache.hadoop.hdfs.protocolPB.ClientNamenodeProtocolServerSideTranslatorPB.mkdirs(ClientNamenodeProtocolServerSideTranslatorPB.java:707)
	at org.apache.hadoop.hdfs.protocol.proto.ClientNamenodeProtocolProtos$ClientNamenodeProtocol$2.callBlockingMethod(ClientNamenodeProtocolProtos.java)
	at org.apache.hadoop.ipc.ProtobufRpcEngine$Server$ProtoBufRpcInvoker.call(ProtobufRpcEngine.java:523)
	at org.apache.hadoop.ipc.RPC$Server.call(RPC.java:991)
	at org.apache.hadoop.ipc.Server$RpcCall.run(Server.java:872)
	at org.apache.hadoop.ipc.Server$RpcCall.run(Server.java:818)
	at java.security.AccessController.doPrivileged(Native Method)
	at javax.security.auth.Subject.doAs(Subject.java:422)
	at org.apache.hadoop.security.UserGroupInformation.doAs(UserGroupInformation.java:1729)
	at org.apache.hadoop.ipc.Server$Handler.run(Server.java:2678)

	at org.apache.hadoop.ipc.Client.getRpcResponse(Client.java:1511)
	at org.apache.hadoop.ipc.Client.call(Client.java:1457)
	at org.apache.hadoop.ipc.Client.call(Client.java:1367)
	at org.apache.hadoop.ipc.ProtobufRpcEngine$Invoker.invoke(ProtobufRpcEngine.java:228)
	at org.apache.hadoop.ipc.ProtobufRpcEngine$Invoker.invoke(ProtobufRpcEngine.java:116)
	at com.sun.proxy.$Proxy89.mkdirs(Unknown Source)
	at org.apache.hadoop.hdfs.protocolPB.ClientNamenodeProtocolTranslatorPB.mkdirs(ClientNamenodeProtocolTranslatorPB.java:653)
	at sun.reflect.NativeMethodAccessorImpl.invoke0(Native Method)
	at sun.reflect.NativeMethodAccessorImpl.invoke(NativeMethodAccessorImpl.java:62)
	at sun.reflect.DelegatingMethodAccessorImpl.invoke(DelegatingMethodAccessorImpl.java:43)
	at java.lang.reflect.Method.invoke(Method.java:498)
	at org.apache.hadoop.io.retry.RetryInvocationHandler.invokeMethod(RetryInvocationHandler.java:422)
	at org.apache.hadoop.io.retry.RetryInvocationHandler$Call.invokeMethod(RetryInvocationHandler.java:165)
	at org.apache.hadoop.io.retry.RetryInvocationHandler$Call.invoke(RetryInvocationHandler.java:157)
	at org.apache.hadoop.io.retry.RetryInvocationHandler$Call.invokeOnce(RetryInvocationHandler.java:95)
	at org.apache.hadoop.io.retry.RetryInvocationHandler.invoke(RetryInvocationHandler.java:359)
	at com.sun.proxy.$Proxy90.mkdirs(Unknown Source)
	at org.apache.hadoop.hdfs.DFSClient.primitiveMkdir(DFSClient.java:2419)
	... 24 more
2022-12-15 19:01:12,816 ERROR org.apache.hadoop.security.token.delegation.AbstractDelegationTokenSecretManager: ExpiredTokenRemover received java.lang.InterruptedException: sleep interrupted
2022-12-15 19:01:12,818 INFO org.eclipse.jetty.server.handler.ContextHandler: Stopped o.e.j.w.WebAppContext@ebd06a9{/,null,UNAVAILABLE}{/cluster}
2022-12-15 19:01:12,827 INFO org.eclipse.jetty.server.AbstractConnector: Stopped ServerConnector@1b5c3e5f{HTTP/1.1,[http/1.1]}{0.0.0.0:8088}
2022-12-15 19:01:12,829 INFO org.eclipse.jetty.server.handler.ContextHandler: Stopped o.e.j.w.WebAppContext@a7ad6e5{/ui2,file:///usr/lib/hadoop-yarn/webapps/ui2/,UNAVAILABLE}
2022-12-15 19:01:12,829 INFO org.eclipse.jetty.server.handler.ContextHandler: Stopped o.e.j.s.ServletContextHandler@eb6449b{/static,jar:file:/usr/lib/hadoop-yarn/hadoop-yarn-common-3.1.2.jar!/webapps/static,UNAVAILABLE}
2022-12-15 19:01:12,830 INFO org.eclipse.jetty.server.handler.ContextHandler: Stopped o.e.j.s.ServletContextHandler@569bf9eb{/logs,file:///var/log/hadoop-yarn/,UNAVAILABLE}
2022-12-15 19:01:12,837 INFO org.apache.hadoop.yarn.event.AsyncDispatcher: AsyncDispatcher is draining to stop, ignoring any new events.
2022-12-15 19:01:12,837 INFO org.apache.hadoop.yarn.event.AsyncDispatcher: AsyncDispatcher is draining to stop, ignoring any new events.
2022-12-15 19:01:12,938 INFO org.apache.hadoop.yarn.event.AsyncDispatcher: Waiting for AsyncDispatcher to drain. Thread state is :RUNNABLE
2022-12-15 19:01:13,038 INFO org.apache.hadoop.yarn.event.AsyncDispatcher: Waiting for AsyncDispatcher to drain. Thread state is :RUNNABLE
2022-12-15 19:01:13,138 INFO org.apache.hadoop.yarn.event.AsyncDispatcher: Waiting for AsyncDispatcher to drain. Thread state is :RUNNABLE
2022-12-15 19:01:13,240 INFO org.apache.hadoop.yarn.event.AsyncDispatcher: Waiting for AsyncDispatcher to drain. Thread state is :RUNNABLE
2022-12-15 19:01:13,340 INFO org.apache.hadoop.yarn.event.AsyncDispatcher: Waiting for AsyncDispatcher to drain. Thread state is :RUNNABLE
2022-12-15 19:01:13,441 INFO org.apache.hadoop.yarn.event.AsyncDispatcher: Waiting for AsyncDispatcher to drain. Thread state is :RUNNABLE
2022-12-15 19:01:13,541 INFO org.apache.hadoop.yarn.event.AsyncDispatcher: Waiting for AsyncDispatcher to drain. Thread state is :RUNNABLE
2022-12-15 19:01:13,642 INFO org.apache.hadoop.yarn.event.AsyncDispatcher: Waiting for AsyncDispatcher to drain. Thread state is :RUNNABLE
2022-12-15 19:01:13,742 INFO org.apache.hadoop.yarn.event.AsyncDispatcher: Waiting for AsyncDispatcher to drain. Thread state is :RUNNABLE
2022-12-15 19:01:13,842 INFO org.apache.hadoop.yarn.event.AsyncDispatcher: Waiting for AsyncDispatcher to drain. Thread state is :RUNNABLE
2022-12-15 19:01:13,942 INFO org.apache.hadoop.yarn.event.AsyncDispatcher: Waiting for AsyncDispatcher to drain. Thread state is :RUNNABLE
2022-12-15 19:01:14,043 INFO org.apache.hadoop.yarn.event.AsyncDispatcher: Waiting for AsyncDispatcher to drain. Thread state is :RUNNABLE
2022-12-15 19:01:14,143 INFO org.apache.hadoop.yarn.event.AsyncDispatcher: Waiting for AsyncDispatcher to drain. Thread state is :RUNNABLE
2022-12-15 19:01:14,243 INFO org.apache.hadoop.yarn.event.AsyncDispatcher: Waiting for AsyncDispatcher to drain. Thread state is :RUNNABLE
2022-12-15 19:01:14,344 INFO org.apache.hadoop.yarn.event.AsyncDispatcher: Waiting for AsyncDispatcher to drain. Thread state is :RUNNABLE
2022-12-15 19:01:14,444 INFO org.apache.hadoop.yarn.event.AsyncDispatcher: Waiting for AsyncDispatcher to drain. Thread state is :RUNNABLE
2022-12-15 19:01:14,544 INFO org.apache.hadoop.yarn.event.AsyncDispatcher: Waiting for AsyncDispatcher to drain. Thread state is :RUNNABLE
2022-12-15 19:01:14,644 INFO org.apache.hadoop.yarn.event.AsyncDispatcher: Waiting for AsyncDispatcher to drain. Thread state is :RUNNABLE
2022-12-15 19:01:14,745 INFO org.apache.hadoop.yarn.event.AsyncDispatcher: Waiting for AsyncDispatcher to drain. Thread state is :RUNNABLE
2022-12-15 19:01:14,845 INFO org.apache.hadoop.yarn.event.AsyncDispatcher: Waiting for AsyncDispatcher to drain. Thread state is :RUNNABLE
2022-12-15 19:01:14,945 INFO org.apache.hadoop.yarn.event.AsyncDispatcher: Waiting for AsyncDispatcher to drain. Thread state is :RUNNABLE
2022-12-15 19:01:15,046 INFO org.apache.hadoop.yarn.event.AsyncDispatcher: Waiting for AsyncDispatcher to drain. Thread state is :RUNNABLE
2022-12-15 19:01:15,146 INFO org.apache.hadoop.yarn.event.AsyncDispatcher: Waiting for AsyncDispatcher to drain. Thread state is :RUNNABLE
2022-12-15 19:01:15,246 INFO org.apache.hadoop.yarn.event.AsyncDispatcher: Waiting for AsyncDispatcher to drain. Thread state is :RUNNABLE
2022-12-15 19:01:15,346 INFO org.apache.hadoop.yarn.event.AsyncDispatcher: Waiting for AsyncDispatcher to drain. Thread state is :RUNNABLE
2022-12-15 19:01:15,447 INFO org.apache.hadoop.yarn.event.AsyncDispatcher: Waiting for AsyncDispatcher to drain. Thread state is :RUNNABLE
2022-12-15 19:01:15,547 INFO org.apache.hadoop.yarn.event.AsyncDispatcher: Waiting for AsyncDispatcher to drain. Thread state is :RUNNABLE
2022-12-15 19:01:15,647 INFO org.apache.hadoop.yarn.event.AsyncDispatcher: Waiting for AsyncDispatcher to drain. Thread state is :RUNNABLE
2022-12-15 19:01:15,747 INFO org.apache.hadoop.yarn.event.AsyncDispatcher: Waiting for AsyncDispatcher to drain. Thread state is :RUNNABLE
2022-12-15 19:01:15,847 INFO org.apache.hadoop.yarn.event.AsyncDispatcher: Waiting for AsyncDispatcher to drain. Thread state is :RUNNABLE
2022-12-15 19:01:15,948 INFO org.apache.hadoop.yarn.event.AsyncDispatcher: Waiting for AsyncDispatcher to drain. Thread state is :RUNNABLE
2022-12-15 19:01:16,048 INFO org.apache.hadoop.yarn.event.AsyncDispatcher: Waiting for AsyncDispatcher to drain. Thread state is :RUNNABLE
2022-12-15 19:01:16,148 INFO org.apache.hadoop.yarn.event.AsyncDispatcher: Waiting for AsyncDispatcher to drain. Thread state is :RUNNABLE
2022-12-15 19:01:16,248 INFO org.apache.hadoop.yarn.event.AsyncDispatcher: Waiting for AsyncDispatcher to drain. Thread state is :RUNNABLE
2022-12-15 19:01:16,349 INFO org.apache.hadoop.yarn.event.AsyncDispatcher: Waiting for AsyncDispatcher to drain. Thread state is :RUNNABLE
2022-12-15 19:01:16,449 INFO org.apache.hadoop.yarn.event.AsyncDispatcher: Waiting for AsyncDispatcher to drain. Thread state is :RUNNABLE
2022-12-15 19:01:16,549 INFO org.apache.hadoop.yarn.event.AsyncDispatcher: Waiting for AsyncDispatcher to drain. Thread state is :RUNNABLE
2022-12-15 19:01:16,650 INFO org.apache.hadoop.yarn.event.AsyncDispatcher: Waiting for AsyncDispatcher to drain. Thread state is :RUNNABLE
2022-12-15 19:01:16,750 INFO org.apache.hadoop.yarn.event.AsyncDispatcher: Waiting for AsyncDispatcher to drain. Thread state is :RUNNABLE
2022-12-15 19:01:16,850 INFO org.apache.hadoop.yarn.event.AsyncDispatcher: Waiting for AsyncDispatcher to drain. Thread state is :RUNNABLE
2022-12-15 19:01:16,951 INFO org.apache.hadoop.yarn.event.AsyncDispatcher: Waiting for AsyncDispatcher to drain. Thread state is :RUNNABLE
2022-12-15 19:01:17,051 INFO org.apache.hadoop.yarn.event.AsyncDispatcher: Waiting for AsyncDispatcher to drain. Thread state is :RUNNABLE
2022-12-15 19:01:17,151 INFO org.apache.hadoop.yarn.event.AsyncDispatcher: Waiting for AsyncDispatcher to drain. Thread state is :RUNNABLE
2022-12-15 19:01:17,252 INFO org.apache.hadoop.yarn.event.AsyncDispatcher: Waiting for AsyncDispatcher to drain. Thread state is :RUNNABLE
2022-12-15 19:01:17,352 INFO org.apache.hadoop.yarn.event.AsyncDispatcher: Waiting for AsyncDispatcher to drain. Thread state is :RUNNABLE
2022-12-15 19:01:17,453 INFO org.apache.hadoop.yarn.event.AsyncDispatcher: Waiting for AsyncDispatcher to drain. Thread state is :RUNNABLE
2022-12-15 19:01:17,553 INFO org.apache.hadoop.yarn.event.AsyncDispatcher: Waiting for AsyncDispatcher to drain. Thread state is :RUNNABLE
2022-12-15 19:01:17,654 INFO org.apache.hadoop.yarn.event.AsyncDispatcher: Waiting for AsyncDispatcher to drain. Thread state is :RUNNABLE
2022-12-15 19:01:17,754 INFO org.apache.hadoop.yarn.event.AsyncDispatcher: Waiting for AsyncDispatcher to drain. Thread state is :RUNNABLE
2022-12-15 19:01:17,854 INFO org.apache.hadoop.yarn.event.AsyncDispatcher: Waiting for AsyncDispatcher to drain. Thread state is :RUNNABLE
2022-12-15 19:01:17,954 INFO org.apache.hadoop.yarn.event.AsyncDispatcher: Waiting for AsyncDispatcher to drain. Thread state is :RUNNABLE
2022-12-15 19:01:18,054 INFO org.apache.hadoop.yarn.event.AsyncDispatcher: Waiting for AsyncDispatcher to drain. Thread state is :RUNNABLE
2022-12-15 19:01:18,155 INFO org.apache.hadoop.yarn.event.AsyncDispatcher: Waiting for AsyncDispatcher to drain. Thread state is :RUNNABLE
2022-12-15 19:01:18,255 INFO org.apache.hadoop.yarn.event.AsyncDispatcher: Waiting for AsyncDispatcher to drain. Thread state is :RUNNABLE
2022-12-15 19:01:18,355 INFO org.apache.hadoop.yarn.event.AsyncDispatcher: Waiting for AsyncDispatcher to drain. Thread state is :RUNNABLE
2022-12-15 19:01:18,456 INFO org.apache.hadoop.yarn.event.AsyncDispatcher: Waiting for AsyncDispatcher to drain. Thread state is :RUNNABLE
2022-12-15 19:01:18,556 INFO org.apache.hadoop.yarn.event.AsyncDispatcher: Waiting for AsyncDispatcher to drain. Thread state is :RUNNABLE
2022-12-15 19:01:18,656 INFO org.apache.hadoop.yarn.event.AsyncDispatcher: Waiting for AsyncDispatcher to drain. Thread state is :RUNNABLE
2022-12-15 19:01:18,756 INFO org.apache.hadoop.yarn.event.AsyncDispatcher: Waiting for AsyncDispatcher to drain. Thread state is :RUNNABLE
2022-12-15 19:01:18,857 INFO org.apache.hadoop.yarn.event.AsyncDispatcher: Waiting for AsyncDispatcher to drain. Thread state is :RUNNABLE
2022-12-15 19:01:18,957 INFO org.apache.hadoop.yarn.event.AsyncDispatcher: Waiting for AsyncDispatcher to drain. Thread state is :RUNNABLE
2022-12-15 19:01:19,058 INFO org.apache.hadoop.yarn.event.AsyncDispatcher: Waiting for AsyncDispatcher to drain. Thread state is :RUNNABLE
2022-12-15 19:01:19,158 INFO org.apache.hadoop.yarn.event.AsyncDispatcher: Waiting for AsyncDispatcher to drain. Thread state is :RUNNABLE
2022-12-15 19:01:19,258 INFO org.apache.hadoop.yarn.event.AsyncDispatcher: Waiting for AsyncDispatcher to drain. Thread state is :RUNNABLE
2022-12-15 19:01:19,359 INFO org.apache.hadoop.yarn.event.AsyncDispatcher: Waiting for AsyncDispatcher to drain. Thread state is :RUNNABLE
2022-12-15 19:01:19,459 INFO org.apache.hadoop.yarn.event.AsyncDispatcher: Waiting for AsyncDispatcher to drain. Thread state is :RUNNABLE
2022-12-15 19:01:19,559 INFO org.apache.hadoop.yarn.event.AsyncDispatcher: Waiting for AsyncDispatcher to drain. Thread state is :RUNNABLE
2022-12-15 19:01:19,659 INFO org.apache.hadoop.yarn.event.AsyncDispatcher: Waiting for AsyncDispatcher to drain. Thread state is :RUNNABLE
2022-12-15 19:01:19,760 INFO org.apache.hadoop.yarn.event.AsyncDispatcher: Waiting for AsyncDispatcher to drain. Thread state is :RUNNABLE
2022-12-15 19:01:19,860 INFO org.apache.hadoop.yarn.event.AsyncDispatcher: Waiting for AsyncDispatcher to drain. Thread state is :RUNNABLE
2022-12-15 19:01:19,960 INFO org.apache.hadoop.yarn.event.AsyncDispatcher: Waiting for AsyncDispatcher to drain. Thread state is :RUNNABLE
2022-12-15 19:01:20,061 INFO org.apache.hadoop.yarn.event.AsyncDispatcher: Waiting for AsyncDispatcher to drain. Thread state is :RUNNABLE
2022-12-15 19:01:20,163 INFO org.apache.hadoop.yarn.event.AsyncDispatcher: Waiting for AsyncDispatcher to drain. Thread state is :RUNNABLE
2022-12-15 19:01:20,263 INFO org.apache.hadoop.yarn.event.AsyncDispatcher: Waiting for AsyncDispatcher to drain. Thread state is :RUNNABLE
2022-12-15 19:01:20,363 INFO org.apache.hadoop.yarn.event.AsyncDispatcher: Waiting for AsyncDispatcher to drain. Thread state is :RUNNABLE
2022-12-15 19:01:20,463 INFO org.apache.hadoop.yarn.event.AsyncDispatcher: Waiting for AsyncDispatcher to drain. Thread state is :RUNNABLE
2022-12-15 19:01:20,564 INFO org.apache.hadoop.yarn.event.AsyncDispatcher: Waiting for AsyncDispatcher to drain. Thread state is :RUNNABLE
2022-12-15 19:01:20,664 INFO org.apache.hadoop.yarn.event.AsyncDispatcher: Waiting for AsyncDispatcher to drain. Thread state is :RUNNABLE
2022-12-15 19:01:20,764 INFO org.apache.hadoop.yarn.event.AsyncDispatcher: Waiting for AsyncDispatcher to drain. Thread state is :RUNNABLE
2022-12-15 19:01:20,864 INFO org.apache.hadoop.yarn.event.AsyncDispatcher: Waiting for AsyncDispatcher to drain. Thread state is :RUNNABLE
2022-12-15 19:01:20,965 INFO org.apache.hadoop.yarn.event.AsyncDispatcher: Waiting for AsyncDispatcher to drain. Thread state is :RUNNABLE
2022-12-15 19:01:21,065 INFO org.apache.hadoop.yarn.event.AsyncDispatcher: Waiting for AsyncDispatcher to drain. Thread state is :RUNNABLE
2022-12-15 19:01:21,165 INFO org.apache.hadoop.yarn.event.AsyncDispatcher: Waiting for AsyncDispatcher to drain. Thread state is :RUNNABLE
2022-12-15 19:01:21,265 INFO org.apache.hadoop.yarn.event.AsyncDispatcher: Waiting for AsyncDispatcher to drain. Thread state is :RUNNABLE
2022-12-15 19:01:21,366 INFO org.apache.hadoop.yarn.event.AsyncDispatcher: Waiting for AsyncDispatcher to drain. Thread state is :RUNNABLE
2022-12-15 19:01:21,466 INFO org.apache.hadoop.yarn.event.AsyncDispatcher: Waiting for AsyncDispatcher to drain. Thread state is :RUNNABLE
2022-12-15 19:01:21,566 INFO org.apache.hadoop.yarn.event.AsyncDispatcher: Waiting for AsyncDispatcher to drain. Thread state is :RUNNABLE
2022-12-15 19:01:21,666 INFO org.apache.hadoop.yarn.event.AsyncDispatcher: Waiting for AsyncDispatcher to drain. Thread state is :RUNNABLE
2022-12-15 19:01:21,767 INFO org.apache.hadoop.yarn.event.AsyncDispatcher: Waiting for AsyncDispatcher to drain. Thread state is :RUNNABLE
2022-12-15 19:01:21,867 INFO org.apache.hadoop.yarn.event.AsyncDispatcher: Waiting for AsyncDispatcher to drain. Thread state is :RUNNABLE
2022-12-15 19:01:21,967 INFO org.apache.hadoop.yarn.event.AsyncDispatcher: Waiting for AsyncDispatcher to drain. Thread state is :RUNNABLE
2022-12-15 19:01:22,067 INFO org.apache.hadoop.yarn.event.AsyncDispatcher: Waiting for AsyncDispatcher to drain. Thread state is :RUNNABLE
2022-12-15 19:01:22,168 INFO org.apache.hadoop.yarn.event.AsyncDispatcher: Waiting for AsyncDispatcher to drain. Thread state is :RUNNABLE
2022-12-15 19:01:22,268 INFO org.apache.hadoop.yarn.event.AsyncDispatcher: Waiting for AsyncDispatcher to drain. Thread state is :RUNNABLE
2022-12-15 19:01:22,368 INFO org.apache.hadoop.yarn.event.AsyncDispatcher: Waiting for AsyncDispatcher to drain. Thread state is :RUNNABLE
2022-12-15 19:01:22,469 INFO org.apache.hadoop.yarn.event.AsyncDispatcher: Waiting for AsyncDispatcher to drain. Thread state is :RUNNABLE
2022-12-15 19:01:22,569 INFO org.apache.hadoop.yarn.event.AsyncDispatcher: Waiting for AsyncDispatcher to drain. Thread state is :RUNNABLE
2022-12-15 19:01:22,669 INFO org.apache.hadoop.yarn.event.AsyncDispatcher: Waiting for AsyncDispatcher to drain. Thread state is :RUNNABLE
2022-12-15 19:01:22,769 INFO org.apache.hadoop.yarn.event.AsyncDispatcher: Waiting for AsyncDispatcher to drain. Thread state is :RUNNABLE
2022-12-15 19:01:22,870 INFO org.apache.hadoop.yarn.event.AsyncDispatcher: Waiting for AsyncDispatcher to drain. Thread state is :RUNNABLE
2022-12-15 19:01:22,970 INFO org.apache.hadoop.yarn.event.AsyncDispatcher: Waiting for AsyncDispatcher to drain. Thread state is :RUNNABLE
2022-12-15 19:01:23,070 INFO org.apache.hadoop.yarn.event.AsyncDispatcher: Waiting for AsyncDispatcher to drain. Thread state is :RUNNABLE
2022-12-15 19:01:23,170 INFO org.apache.hadoop.yarn.event.AsyncDispatcher: Waiting for AsyncDispatcher to drain. Thread state is :RUNNABLE
2022-12-15 19:01:23,271 INFO org.apache.hadoop.yarn.event.AsyncDispatcher: Waiting for AsyncDispatcher to drain. Thread state is :RUNNABLE
2022-12-15 19:01:23,371 INFO org.apache.hadoop.yarn.event.AsyncDispatcher: Waiting for AsyncDispatcher to drain. Thread state is :RUNNABLE
2022-12-15 19:01:23,471 INFO org.apache.hadoop.yarn.event.AsyncDispatcher: Waiting for AsyncDispatcher to drain. Thread state is :RUNNABLE
2022-12-15 19:01:23,571 INFO org.apache.hadoop.yarn.event.AsyncDispatcher: Waiting for AsyncDispatcher to drain. Thread state is :RUNNABLE
2022-12-15 19:01:23,672 INFO org.apache.hadoop.yarn.event.AsyncDispatcher: Waiting for AsyncDispatcher to drain. Thread state is :RUNNABLE
2022-12-15 19:01:23,772 INFO org.apache.hadoop.yarn.event.AsyncDispatcher: Waiting for AsyncDispatcher to drain. Thread state is :RUNNABLE
2022-12-15 19:01:23,872 INFO org.apache.hadoop.yarn.event.AsyncDispatcher: Waiting for AsyncDispatcher to drain. Thread state is :RUNNABLE
2022-12-15 19:01:23,972 INFO org.apache.hadoop.yarn.event.AsyncDispatcher: Waiting for AsyncDispatcher to drain. Thread state is :RUNNABLE
2022-12-15 19:01:24,073 INFO org.apache.hadoop.yarn.event.AsyncDispatcher: Waiting for AsyncDispatcher to drain. Thread state is :RUNNABLE
2022-12-15 19:01:24,173 INFO org.apache.hadoop.yarn.event.AsyncDispatcher: Waiting for AsyncDispatcher to drain. Thread state is :RUNNABLE
2022-12-15 19:01:24,273 INFO org.apache.hadoop.yarn.event.AsyncDispatcher: Waiting for AsyncDispatcher to drain. Thread state is :RUNNABLE
2022-12-15 19:01:24,374 INFO org.apache.hadoop.yarn.event.AsyncDispatcher: Waiting for AsyncDispatcher to drain. Thread state is :RUNNABLE
2022-12-15 19:01:24,474 INFO org.apache.hadoop.yarn.event.AsyncDispatcher: Waiting for AsyncDispatcher to drain. Thread state is :RUNNABLE
2022-12-15 19:01:24,574 INFO org.apache.hadoop.yarn.event.AsyncDispatcher: Waiting for AsyncDispatcher to drain. Thread state is :RUNNABLE
2022-12-15 19:01:24,674 INFO org.apache.hadoop.yarn.event.AsyncDispatcher: Waiting for AsyncDispatcher to drain. Thread state is :RUNNABLE
2022-12-15 19:01:24,775 INFO org.apache.hadoop.yarn.event.AsyncDispatcher: Waiting for AsyncDispatcher to drain. Thread state is :RUNNABLE
2022-12-15 19:01:24,875 INFO org.apache.hadoop.yarn.event.AsyncDispatcher: Waiting for AsyncDispatcher to drain. Thread state is :RUNNABLE
2022-12-15 19:01:24,975 INFO org.apache.hadoop.yarn.event.AsyncDispatcher: Waiting for AsyncDispatcher to drain. Thread state is :RUNNABLE
2022-12-15 19:01:25,075 INFO org.apache.hadoop.yarn.event.AsyncDispatcher: Waiting for AsyncDispatcher to drain. Thread state is :RUNNABLE
2022-12-15 19:01:25,176 INFO org.apache.hadoop.yarn.event.AsyncDispatcher: Waiting for AsyncDispatcher to drain. Thread state is :RUNNABLE
2022-12-15 19:01:25,276 INFO org.apache.hadoop.yarn.event.AsyncDispatcher: Waiting for AsyncDispatcher to drain. Thread state is :RUNNABLE
2022-12-15 19:01:25,376 INFO org.apache.hadoop.yarn.event.AsyncDispatcher: Waiting for AsyncDispatcher to drain. Thread state is :RUNNABLE
2022-12-15 19:01:25,476 INFO org.apache.hadoop.yarn.event.AsyncDispatcher: Waiting for AsyncDispatcher to drain. Thread state is :RUNNABLE
2022-12-15 19:01:25,577 INFO org.apache.hadoop.yarn.event.AsyncDispatcher: Waiting for AsyncDispatcher to drain. Thread state is :RUNNABLE
2022-12-15 19:01:25,677 INFO org.apache.hadoop.yarn.event.AsyncDispatcher: Waiting for AsyncDispatcher to drain. Thread state is :RUNNABLE
2022-12-15 19:01:25,777 INFO org.apache.hadoop.yarn.event.AsyncDispatcher: Waiting for AsyncDispatcher to drain. Thread state is :RUNNABLE
2022-12-15 19:01:25,877 INFO org.apache.hadoop.yarn.event.AsyncDispatcher: Waiting for AsyncDispatcher to drain. Thread state is :RUNNABLE
2022-12-15 19:01:25,978 INFO org.apache.hadoop.yarn.event.AsyncDispatcher: Waiting for AsyncDispatcher to drain. Thread state is :RUNNABLE
2022-12-15 19:01:26,078 INFO org.apache.hadoop.yarn.event.AsyncDispatcher: Waiting for AsyncDispatcher to drain. Thread state is :RUNNABLE
2022-12-15 19:01:26,178 INFO org.apache.hadoop.yarn.event.AsyncDispatcher: Waiting for AsyncDispatcher to drain. Thread state is :RUNNABLE
2022-12-15 19:01:26,278 INFO org.apache.hadoop.yarn.event.AsyncDispatcher: Waiting for AsyncDispatcher to drain. Thread state is :RUNNABLE
2022-12-15 19:01:26,379 INFO org.apache.hadoop.yarn.event.AsyncDispatcher: Waiting for AsyncDispatcher to drain. Thread state is :RUNNABLE
2022-12-15 19:01:26,479 INFO org.apache.hadoop.yarn.event.AsyncDispatcher: Waiting for AsyncDispatcher to drain. Thread state is :RUNNABLE
2022-12-15 19:01:26,579 INFO org.apache.hadoop.yarn.event.AsyncDispatcher: Waiting for AsyncDispatcher to drain. Thread state is :RUNNABLE
2022-12-15 19:01:26,679 INFO org.apache.hadoop.yarn.event.AsyncDispatcher: Waiting for AsyncDispatcher to drain. Thread state is :RUNNABLE
2022-12-15 19:01:26,780 INFO org.apache.hadoop.yarn.event.AsyncDispatcher: Waiting for AsyncDispatcher to drain. Thread state is :RUNNABLE
2022-12-15 19:01:26,880 INFO org.apache.hadoop.yarn.event.AsyncDispatcher: Waiting for AsyncDispatcher to drain. Thread state is :RUNNABLE
2022-12-15 19:01:26,980 INFO org.apache.hadoop.yarn.event.AsyncDispatcher: Waiting for AsyncDispatcher to drain. Thread state is :RUNNABLE
2022-12-15 19:01:27,080 INFO org.apache.hadoop.yarn.event.AsyncDispatcher: Waiting for AsyncDispatcher to drain. Thread state is :RUNNABLE
2022-12-15 19:01:27,180 INFO org.apache.hadoop.yarn.event.AsyncDispatcher: Waiting for AsyncDispatcher to drain. Thread state is :RUNNABLE
2022-12-15 19:01:27,281 INFO org.apache.hadoop.yarn.event.AsyncDispatcher: Waiting for AsyncDispatcher to drain. Thread state is :RUNNABLE
2022-12-15 19:01:27,381 INFO org.apache.hadoop.yarn.event.AsyncDispatcher: Waiting for AsyncDispatcher to drain. Thread state is :RUNNABLE
2022-12-15 19:01:27,481 INFO org.apache.hadoop.yarn.event.AsyncDispatcher: Waiting for AsyncDispatcher to drain. Thread state is :RUNNABLE
2022-12-15 19:01:27,582 INFO org.apache.hadoop.yarn.event.AsyncDispatcher: Waiting for AsyncDispatcher to drain. Thread state is :RUNNABLE
2022-12-15 19:01:27,682 INFO org.apache.hadoop.yarn.event.AsyncDispatcher: Waiting for AsyncDispatcher to drain. Thread state is :RUNNABLE
2022-12-15 19:01:27,782 INFO org.apache.hadoop.yarn.event.AsyncDispatcher: Waiting for AsyncDispatcher to drain. Thread state is :RUNNABLE
2022-12-15 19:01:27,882 INFO org.apache.hadoop.yarn.event.AsyncDispatcher: Waiting for AsyncDispatcher to drain. Thread state is :RUNNABLE
2022-12-15 19:01:27,983 INFO org.apache.hadoop.yarn.event.AsyncDispatcher: Waiting for AsyncDispatcher to drain. Thread state is :RUNNABLE
2022-12-15 19:01:28,083 INFO org.apache.hadoop.yarn.event.AsyncDispatcher: Waiting for AsyncDispatcher to drain. Thread state is :RUNNABLE
2022-12-15 19:01:28,183 INFO org.apache.hadoop.yarn.event.AsyncDispatcher: Waiting for AsyncDispatcher to drain. Thread state is :RUNNABLE
2022-12-15 19:01:28,283 INFO org.apache.hadoop.yarn.event.AsyncDispatcher: Waiting for AsyncDispatcher to drain. Thread state is :RUNNABLE
2022-12-15 19:01:28,384 INFO org.apache.hadoop.yarn.event.AsyncDispatcher: Waiting for AsyncDispatcher to drain. Thread state is :RUNNABLE
2022-12-15 19:01:28,484 INFO org.apache.hadoop.yarn.event.AsyncDispatcher: Waiting for AsyncDispatcher to drain. Thread state is :RUNNABLE
2022-12-15 19:01:28,584 INFO org.apache.hadoop.yarn.event.AsyncDispatcher: Waiting for AsyncDispatcher to drain. Thread state is :RUNNABLE
2022-12-15 19:01:28,685 INFO org.apache.hadoop.yarn.event.AsyncDispatcher: Waiting for AsyncDispatcher to drain. Thread state is :RUNNABLE
2022-12-15 19:01:28,785 INFO org.apache.hadoop.yarn.event.AsyncDispatcher: Waiting for AsyncDispatcher to drain. Thread state is :RUNNABLE
2022-12-15 19:01:28,885 INFO org.apache.hadoop.yarn.event.AsyncDispatcher: Waiting for AsyncDispatcher to drain. Thread state is :RUNNABLE
2022-12-15 19:01:28,985 INFO org.apache.hadoop.yarn.event.AsyncDispatcher: Waiting for AsyncDispatcher to drain. Thread state is :RUNNABLE
2022-12-15 19:01:29,086 INFO org.apache.hadoop.yarn.event.AsyncDispatcher: Waiting for AsyncDispatcher to drain. Thread state is :RUNNABLE
2022-12-15 19:01:29,186 INFO org.apache.hadoop.yarn.event.AsyncDispatcher: Waiting for AsyncDispatcher to drain. Thread state is :RUNNABLE
2022-12-15 19:01:29,286 INFO org.apache.hadoop.yarn.event.AsyncDispatcher: Waiting for AsyncDispatcher to drain. Thread state is :RUNNABLE
2022-12-15 19:01:29,387 INFO org.apache.hadoop.yarn.event.AsyncDispatcher: Waiting for AsyncDispatcher to drain. Thread state is :RUNNABLE
2022-12-15 19:01:29,487 INFO org.apache.hadoop.yarn.event.AsyncDispatcher: Waiting for AsyncDispatcher to drain. Thread state is :RUNNABLE
2022-12-15 19:01:29,587 INFO org.apache.hadoop.yarn.event.AsyncDispatcher: Waiting for AsyncDispatcher to drain. Thread state is :RUNNABLE
2022-12-15 19:01:29,687 INFO org.apache.hadoop.yarn.event.AsyncDispatcher: Waiting for AsyncDispatcher to drain. Thread state is :RUNNABLE
2022-12-15 19:01:29,788 INFO org.apache.hadoop.yarn.event.AsyncDispatcher: Waiting for AsyncDispatcher to drain. Thread state is :RUNNABLE
2022-12-15 19:01:29,888 INFO org.apache.hadoop.yarn.event.AsyncDispatcher: Waiting for AsyncDispatcher to drain. Thread state is :RUNNABLE
2022-12-15 19:01:29,988 INFO org.apache.hadoop.yarn.event.AsyncDispatcher: Waiting for AsyncDispatcher to drain. Thread state is :RUNNABLE
2022-12-15 19:01:30,088 INFO org.apache.hadoop.yarn.event.AsyncDispatcher: Waiting for AsyncDispatcher to drain. Thread state is :RUNNABLE
2022-12-15 19:01:30,189 INFO org.apache.hadoop.yarn.event.AsyncDispatcher: Waiting for AsyncDispatcher to drain. Thread state is :RUNNABLE
2022-12-15 19:01:30,289 INFO org.apache.hadoop.yarn.event.AsyncDispatcher: Waiting for AsyncDispatcher to drain. Thread state is :RUNNABLE
2022-12-15 19:01:30,389 INFO org.apache.hadoop.yarn.event.AsyncDispatcher: Waiting for AsyncDispatcher to drain. Thread state is :RUNNABLE
2022-12-15 19:01:30,489 INFO org.apache.hadoop.yarn.event.AsyncDispatcher: Waiting for AsyncDispatcher to drain. Thread state is :RUNNABLE
2022-12-15 19:01:30,590 INFO org.apache.hadoop.yarn.event.AsyncDispatcher: Waiting for AsyncDispatcher to drain. Thread state is :RUNNABLE
2022-12-15 19:01:30,690 INFO org.apache.hadoop.yarn.event.AsyncDispatcher: Waiting for AsyncDispatcher to drain. Thread state is :RUNNABLE
2022-12-15 19:01:30,790 INFO org.apache.hadoop.yarn.event.AsyncDispatcher: Waiting for AsyncDispatcher to drain. Thread state is :RUNNABLE
2022-12-15 19:01:30,890 INFO org.apache.hadoop.yarn.event.AsyncDispatcher: Waiting for AsyncDispatcher to drain. Thread state is :RUNNABLE
2022-12-15 19:01:30,991 INFO org.apache.hadoop.yarn.event.AsyncDispatcher: Waiting for AsyncDispatcher to drain. Thread state is :RUNNABLE
2022-12-15 19:01:31,091 INFO org.apache.hadoop.yarn.event.AsyncDispatcher: Waiting for AsyncDispatcher to drain. Thread state is :RUNNABLE
2022-12-15 19:01:31,191 INFO org.apache.hadoop.yarn.event.AsyncDispatcher: Waiting for AsyncDispatcher to drain. Thread state is :RUNNABLE
2022-12-15 19:01:31,292 INFO org.apache.hadoop.yarn.event.AsyncDispatcher: Waiting for AsyncDispatcher to drain. Thread state is :RUNNABLE
2022-12-15 19:01:31,392 INFO org.apache.hadoop.yarn.event.AsyncDispatcher: Waiting for AsyncDispatcher to drain. Thread state is :RUNNABLE
2022-12-15 19:01:31,492 INFO org.apache.hadoop.yarn.event.AsyncDispatcher: Waiting for AsyncDispatcher to drain. Thread state is :RUNNABLE
2022-12-15 19:01:31,592 INFO org.apache.hadoop.yarn.event.AsyncDispatcher: Waiting for AsyncDispatcher to drain. Thread state is :RUNNABLE
2022-12-15 19:01:31,693 INFO org.apache.hadoop.yarn.event.AsyncDispatcher: Waiting for AsyncDispatcher to drain. Thread state is :RUNNABLE
2022-12-15 19:01:31,793 INFO org.apache.hadoop.yarn.event.AsyncDispatcher: Waiting for AsyncDispatcher to drain. Thread state is :RUNNABLE
2022-12-15 19:01:31,893 INFO org.apache.hadoop.yarn.event.AsyncDispatcher: Waiting for AsyncDispatcher to drain. Thread state is :RUNNABLE
2022-12-15 19:01:31,993 INFO org.apache.hadoop.yarn.event.AsyncDispatcher: Waiting for AsyncDispatcher to drain. Thread state is :RUNNABLE
2022-12-15 19:01:32,094 INFO org.apache.hadoop.yarn.event.AsyncDispatcher: Waiting for AsyncDispatcher to drain. Thread state is :RUNNABLE
2022-12-15 19:01:32,194 INFO org.apache.hadoop.yarn.event.AsyncDispatcher: Waiting for AsyncDispatcher to drain. Thread state is :RUNNABLE
2022-12-15 19:01:32,294 INFO org.apache.hadoop.yarn.event.AsyncDispatcher: Waiting for AsyncDispatcher to drain. Thread state is :RUNNABLE
2022-12-15 19:01:32,394 INFO org.apache.hadoop.yarn.event.AsyncDispatcher: Waiting for AsyncDispatcher to drain. Thread state is :RUNNABLE
2022-12-15 19:01:32,495 INFO org.apache.hadoop.yarn.event.AsyncDispatcher: Waiting for AsyncDispatcher to drain. Thread state is :RUNNABLE
2022-12-15 19:01:32,595 INFO org.apache.hadoop.yarn.event.AsyncDispatcher: Waiting for AsyncDispatcher to drain. Thread state is :RUNNABLE
2022-12-15 19:01:32,695 INFO org.apache.hadoop.yarn.event.AsyncDispatcher: Waiting for AsyncDispatcher to drain. Thread state is :RUNNABLE
2022-12-15 19:01:32,796 INFO org.apache.hadoop.yarn.event.AsyncDispatcher: Waiting for AsyncDispatcher to drain. Thread state is :RUNNABLE
2022-12-15 19:01:32,896 INFO org.apache.hadoop.yarn.event.AsyncDispatcher: Waiting for AsyncDispatcher to drain. Thread state is :RUNNABLE
2022-12-15 19:01:32,996 INFO org.apache.hadoop.yarn.event.AsyncDispatcher: Waiting for AsyncDispatcher to drain. Thread state is :RUNNABLE
2022-12-15 19:01:33,096 INFO org.apache.hadoop.yarn.event.AsyncDispatcher: Waiting for AsyncDispatcher to drain. Thread state is :RUNNABLE
2022-12-15 19:01:33,197 INFO org.apache.hadoop.yarn.event.AsyncDispatcher: Waiting for AsyncDispatcher to drain. Thread state is :RUNNABLE
2022-12-15 19:01:33,297 INFO org.apache.hadoop.yarn.event.AsyncDispatcher: Waiting for AsyncDispatcher to drain. Thread state is :RUNNABLE
2022-12-15 19:01:33,397 INFO org.apache.hadoop.yarn.event.AsyncDispatcher: Waiting for AsyncDispatcher to drain. Thread state is :RUNNABLE
2022-12-15 19:01:33,497 INFO org.apache.hadoop.yarn.event.AsyncDispatcher: Waiting for AsyncDispatcher to drain. Thread state is :RUNNABLE
2022-12-15 19:01:33,598 INFO org.apache.hadoop.yarn.event.AsyncDispatcher: Waiting for AsyncDispatcher to drain. Thread state is :RUNNABLE
2022-12-15 19:01:33,698 INFO org.apache.hadoop.yarn.event.AsyncDispatcher: Waiting for AsyncDispatcher to drain. Thread state is :RUNNABLE
2022-12-15 19:01:33,798 INFO org.apache.hadoop.yarn.event.AsyncDispatcher: Waiting for AsyncDispatcher to drain. Thread state is :RUNNABLE
2022-12-15 19:01:33,898 INFO org.apache.hadoop.yarn.event.AsyncDispatcher: Waiting for AsyncDispatcher to drain. Thread state is :RUNNABLE
2022-12-15 19:01:33,998 INFO org.apache.hadoop.yarn.event.AsyncDispatcher: Waiting for AsyncDispatcher to drain. Thread state is :RUNNABLE
2022-12-15 19:01:34,099 INFO org.apache.hadoop.yarn.event.AsyncDispatcher: Waiting for AsyncDispatcher to drain. Thread state is :RUNNABLE
2022-12-15 19:01:34,199 INFO org.apache.hadoop.yarn.event.AsyncDispatcher: Waiting for AsyncDispatcher to drain. Thread state is :RUNNABLE
2022-12-15 19:01:34,299 INFO org.apache.hadoop.yarn.event.AsyncDispatcher: Waiting for AsyncDispatcher to drain. Thread state is :RUNNABLE
2022-12-15 19:01:34,399 INFO org.apache.hadoop.yarn.event.AsyncDispatcher: Waiting for AsyncDispatcher to drain. Thread state is :RUNNABLE
2022-12-15 19:01:34,499 INFO org.apache.hadoop.yarn.event.AsyncDispatcher: Waiting for AsyncDispatcher to drain. Thread state is :RUNNABLE
2022-12-15 19:01:34,599 INFO org.apache.hadoop.yarn.event.AsyncDispatcher: Waiting for AsyncDispatcher to drain. Thread state is :RUNNABLE
2022-12-15 19:01:34,700 INFO org.apache.hadoop.yarn.event.AsyncDispatcher: Waiting for AsyncDispatcher to drain. Thread state is :RUNNABLE
2022-12-15 19:01:34,800 INFO org.apache.hadoop.yarn.event.AsyncDispatcher: Waiting for AsyncDispatcher to drain. Thread state is :RUNNABLE
2022-12-15 19:01:34,900 INFO org.apache.hadoop.yarn.event.AsyncDispatcher: Waiting for AsyncDispatcher to drain. Thread state is :RUNNABLE
2022-12-15 19:01:35,000 INFO org.apache.hadoop.yarn.event.AsyncDispatcher: Waiting for AsyncDispatcher to drain. Thread state is :RUNNABLE
2022-12-15 19:01:35,100 INFO org.apache.hadoop.yarn.event.AsyncDispatcher: Waiting for AsyncDispatcher to drain. Thread state is :RUNNABLE
2022-12-15 19:01:35,201 INFO org.apache.hadoop.yarn.event.AsyncDispatcher: Waiting for AsyncDispatcher to drain. Thread state is :RUNNABLE
2022-12-15 19:01:35,301 INFO org.apache.hadoop.yarn.event.AsyncDispatcher: Waiting for AsyncDispatcher to drain. Thread state is :RUNNABLE
2022-12-15 19:01:35,401 INFO org.apache.hadoop.yarn.event.AsyncDispatcher: Waiting for AsyncDispatcher to drain. Thread state is :RUNNABLE
2022-12-15 19:01:35,501 INFO org.apache.hadoop.yarn.event.AsyncDispatcher: Waiting for AsyncDispatcher to drain. Thread state is :RUNNABLE
2022-12-15 19:01:35,601 INFO org.apache.hadoop.yarn.event.AsyncDispatcher: Waiting for AsyncDispatcher to drain. Thread state is :RUNNABLE
2022-12-15 19:01:35,702 INFO org.apache.hadoop.yarn.event.AsyncDispatcher: Waiting for AsyncDispatcher to drain. Thread state is :RUNNABLE
2022-12-15 19:01:35,802 INFO org.apache.hadoop.yarn.event.AsyncDispatcher: Waiting for AsyncDispatcher to drain. Thread state is :RUNNABLE
2022-12-15 19:01:35,902 INFO org.apache.hadoop.yarn.event.AsyncDispatcher: Waiting for AsyncDispatcher to drain. Thread state is :RUNNABLE
2022-12-15 19:01:36,002 INFO org.apache.hadoop.yarn.event.AsyncDispatcher: Waiting for AsyncDispatcher to drain. Thread state is :RUNNABLE
2022-12-15 19:01:36,103 INFO org.apache.hadoop.yarn.event.AsyncDispatcher: Waiting for AsyncDispatcher to drain. Thread state is :RUNNABLE
2022-12-15 19:01:36,203 INFO org.apache.hadoop.yarn.event.AsyncDispatcher: Waiting for AsyncDispatcher to drain. Thread state is :RUNNABLE
2022-12-15 19:01:36,303 INFO org.apache.hadoop.yarn.event.AsyncDispatcher: Waiting for AsyncDispatcher to drain. Thread state is :RUNNABLE
2022-12-15 19:01:36,404 INFO org.apache.hadoop.yarn.event.AsyncDispatcher: Waiting for AsyncDispatcher to drain. Thread state is :RUNNABLE
2022-12-15 19:01:36,504 INFO org.apache.hadoop.yarn.event.AsyncDispatcher: Waiting for AsyncDispatcher to drain. Thread state is :RUNNABLE
2022-12-15 19:01:36,604 INFO org.apache.hadoop.yarn.event.AsyncDispatcher: Waiting for AsyncDispatcher to drain. Thread state is :RUNNABLE
2022-12-15 19:01:36,704 INFO org.apache.hadoop.yarn.event.AsyncDispatcher: Waiting for AsyncDispatcher to drain. Thread state is :RUNNABLE
2022-12-15 19:01:36,804 INFO org.apache.hadoop.yarn.event.AsyncDispatcher: Waiting for AsyncDispatcher to drain. Thread state is :RUNNABLE
2022-12-15 19:01:36,905 INFO org.apache.hadoop.yarn.event.AsyncDispatcher: Waiting for AsyncDispatcher to drain. Thread state is :RUNNABLE
2022-12-15 19:01:37,005 INFO org.apache.hadoop.yarn.event.AsyncDispatcher: Waiting for AsyncDispatcher to drain. Thread state is :RUNNABLE
2022-12-15 19:01:37,105 INFO org.apache.hadoop.yarn.event.AsyncDispatcher: Waiting for AsyncDispatcher to drain. Thread state is :RUNNABLE
2022-12-15 19:01:37,206 INFO org.apache.hadoop.yarn.event.AsyncDispatcher: Waiting for AsyncDispatcher to drain. Thread state is :RUNNABLE
2022-12-15 19:01:37,306 INFO org.apache.hadoop.yarn.event.AsyncDispatcher: Waiting for AsyncDispatcher to drain. Thread state is :RUNNABLE
2022-12-15 19:01:37,406 INFO org.apache.hadoop.yarn.event.AsyncDispatcher: Waiting for AsyncDispatcher to drain. Thread state is :RUNNABLE
2022-12-15 19:01:37,506 INFO org.apache.hadoop.yarn.event.AsyncDispatcher: Waiting for AsyncDispatcher to drain. Thread state is :RUNNABLE
2022-12-15 19:01:37,607 INFO org.apache.hadoop.yarn.event.AsyncDispatcher: Waiting for AsyncDispatcher to drain. Thread state is :RUNNABLE
2022-12-15 19:01:37,707 INFO org.apache.hadoop.yarn.event.AsyncDispatcher: Waiting for AsyncDispatcher to drain. Thread state is :RUNNABLE
2022-12-15 19:01:37,807 INFO org.apache.hadoop.yarn.event.AsyncDispatcher: Waiting for AsyncDispatcher to drain. Thread state is :RUNNABLE
2022-12-15 19:01:37,907 INFO org.apache.hadoop.yarn.event.AsyncDispatcher: Waiting for AsyncDispatcher to drain. Thread state is :RUNNABLE
2022-12-15 19:01:38,008 INFO org.apache.hadoop.yarn.event.AsyncDispatcher: Waiting for AsyncDispatcher to drain. Thread state is :RUNNABLE
2022-12-15 19:01:38,108 INFO org.apache.hadoop.yarn.event.AsyncDispatcher: Waiting for AsyncDispatcher to drain. Thread state is :RUNNABLE
2022-12-15 19:01:38,208 INFO org.apache.hadoop.yarn.event.AsyncDispatcher: Waiting for AsyncDispatcher to drain. Thread state is :RUNNABLE
2022-12-15 19:01:38,309 INFO org.apache.hadoop.yarn.event.AsyncDispatcher: Waiting for AsyncDispatcher to drain. Thread state is :RUNNABLE
2022-12-15 19:01:38,409 INFO org.apache.hadoop.yarn.event.AsyncDispatcher: Waiting for AsyncDispatcher to drain. Thread state is :RUNNABLE
2022-12-15 19:01:38,509 INFO org.apache.hadoop.yarn.event.AsyncDispatcher: Waiting for AsyncDispatcher to drain. Thread state is :RUNNABLE
2022-12-15 19:01:38,609 INFO org.apache.hadoop.yarn.event.AsyncDispatcher: Waiting for AsyncDispatcher to drain. Thread state is :RUNNABLE
2022-12-15 19:01:38,710 INFO org.apache.hadoop.yarn.event.AsyncDispatcher: Waiting for AsyncDispatcher to drain. Thread state is :RUNNABLE
2022-12-15 19:01:38,810 INFO org.apache.hadoop.yarn.event.AsyncDispatcher: Waiting for AsyncDispatcher to drain. Thread state is :RUNNABLE
2022-12-15 19:01:38,910 INFO org.apache.hadoop.yarn.event.AsyncDispatcher: Waiting for AsyncDispatcher to drain. Thread state is :RUNNABLE
2022-12-15 19:01:39,010 INFO org.apache.hadoop.yarn.event.AsyncDispatcher: Waiting for AsyncDispatcher to drain. Thread state is :RUNNABLE
2022-12-15 19:01:39,111 INFO org.apache.hadoop.yarn.event.AsyncDispatcher: Waiting for AsyncDispatcher to drain. Thread state is :RUNNABLE
2022-12-15 19:01:39,211 INFO org.apache.hadoop.yarn.event.AsyncDispatcher: Waiting for AsyncDispatcher to drain. Thread state is :RUNNABLE
2022-12-15 19:01:39,311 INFO org.apache.hadoop.yarn.event.AsyncDispatcher: Waiting for AsyncDispatcher to drain. Thread state is :RUNNABLE
2022-12-15 19:01:39,412 INFO org.apache.hadoop.yarn.event.AsyncDispatcher: Waiting for AsyncDispatcher to drain. Thread state is :RUNNABLE
2022-12-15 19:01:39,512 INFO org.apache.hadoop.yarn.event.AsyncDispatcher: Waiting for AsyncDispatcher to drain. Thread state is :RUNNABLE
2022-12-15 19:01:39,612 INFO org.apache.hadoop.yarn.event.AsyncDispatcher: Waiting for AsyncDispatcher to drain. Thread state is :RUNNABLE
2022-12-15 19:01:39,712 INFO org.apache.hadoop.yarn.event.AsyncDispatcher: Waiting for AsyncDispatcher to drain. Thread state is :RUNNABLE
2022-12-15 19:01:39,812 INFO org.apache.hadoop.yarn.event.AsyncDispatcher: Waiting for AsyncDispatcher to drain. Thread state is :RUNNABLE
2022-12-15 19:01:39,913 INFO org.apache.hadoop.yarn.event.AsyncDispatcher: Waiting for AsyncDispatcher to drain. Thread state is :RUNNABLE
2022-12-15 19:01:40,013 INFO org.apache.hadoop.yarn.event.AsyncDispatcher: Waiting for AsyncDispatcher to drain. Thread state is :RUNNABLE
2022-12-15 19:01:40,113 INFO org.apache.hadoop.yarn.event.AsyncDispatcher: Waiting for AsyncDispatcher to drain. Thread state is :RUNNABLE
2022-12-15 19:01:40,213 INFO org.apache.hadoop.yarn.event.AsyncDispatcher: Waiting for AsyncDispatcher to drain. Thread state is :RUNNABLE
2022-12-15 19:01:40,314 INFO org.apache.hadoop.yarn.event.AsyncDispatcher: Waiting for AsyncDispatcher to drain. Thread state is :RUNNABLE
2022-12-15 19:01:40,414 INFO org.apache.hadoop.yarn.event.AsyncDispatcher: Waiting for AsyncDispatcher to drain. Thread state is :RUNNABLE
2022-12-15 19:01:40,514 INFO org.apache.hadoop.yarn.event.AsyncDispatcher: Waiting for AsyncDispatcher to drain. Thread state is :RUNNABLE
2022-12-15 19:01:40,614 INFO org.apache.hadoop.yarn.event.AsyncDispatcher: Waiting for AsyncDispatcher to drain. Thread state is :RUNNABLE
2022-12-15 19:01:40,715 INFO org.apache.hadoop.yarn.event.AsyncDispatcher: Waiting for AsyncDispatcher to drain. Thread state is :RUNNABLE
2022-12-15 19:01:40,815 INFO org.apache.hadoop.yarn.event.AsyncDispatcher: Waiting for AsyncDispatcher to drain. Thread state is :RUNNABLE
2022-12-15 19:01:40,915 INFO org.apache.hadoop.yarn.event.AsyncDispatcher: Waiting for AsyncDispatcher to drain. Thread state is :RUNNABLE
2022-12-15 19:01:41,015 INFO org.apache.hadoop.yarn.event.AsyncDispatcher: Waiting for AsyncDispatcher to drain. Thread state is :RUNNABLE
2022-12-15 19:01:41,116 INFO org.apache.hadoop.yarn.event.AsyncDispatcher: Waiting for AsyncDispatcher to drain. Thread state is :RUNNABLE
2022-12-15 19:01:41,216 INFO org.apache.hadoop.yarn.event.AsyncDispatcher: Waiting for AsyncDispatcher to drain. Thread state is :RUNNABLE
2022-12-15 19:01:41,316 INFO org.apache.hadoop.yarn.event.AsyncDispatcher: Waiting for AsyncDispatcher to drain. Thread state is :RUNNABLE
2022-12-15 19:01:41,416 INFO org.apache.hadoop.yarn.event.AsyncDispatcher: Waiting for AsyncDispatcher to drain. Thread state is :RUNNABLE
2022-12-15 19:01:41,516 INFO org.apache.hadoop.yarn.event.AsyncDispatcher: Waiting for AsyncDispatcher to drain. Thread state is :RUNNABLE
2022-12-15 19:01:41,617 INFO org.apache.hadoop.yarn.event.AsyncDispatcher: Waiting for AsyncDispatcher to drain. Thread state is :RUNNABLE
2022-12-15 19:01:41,717 INFO org.apache.hadoop.yarn.event.AsyncDispatcher: Waiting for AsyncDispatcher to drain. Thread state is :RUNNABLE
2022-12-15 19:01:41,817 INFO org.apache.hadoop.yarn.event.AsyncDispatcher: Waiting for AsyncDispatcher to drain. Thread state is :RUNNABLE
2022-12-15 19:01:41,917 INFO org.apache.hadoop.yarn.event.AsyncDispatcher: Waiting for AsyncDispatcher to drain. Thread state is :RUNNABLE
2022-12-15 19:01:42,018 INFO org.apache.hadoop.yarn.event.AsyncDispatcher: Waiting for AsyncDispatcher to drain. Thread state is :RUNNABLE
2022-12-15 19:01:42,118 INFO org.apache.hadoop.yarn.event.AsyncDispatcher: Waiting for AsyncDispatcher to drain. Thread state is :RUNNABLE
2022-12-15 19:01:42,218 INFO org.apache.hadoop.yarn.event.AsyncDispatcher: Waiting for AsyncDispatcher to drain. Thread state is :RUNNABLE
2022-12-15 19:01:42,318 INFO org.apache.hadoop.yarn.event.AsyncDispatcher: Waiting for AsyncDispatcher to drain. Thread state is :RUNNABLE
2022-12-15 19:01:42,419 INFO org.apache.hadoop.yarn.event.AsyncDispatcher: Waiting for AsyncDispatcher to drain. Thread state is :RUNNABLE
2022-12-15 19:01:42,519 INFO org.apache.hadoop.yarn.event.AsyncDispatcher: Waiting for AsyncDispatcher to drain. Thread state is :RUNNABLE
2022-12-15 19:01:42,619 INFO org.apache.hadoop.yarn.event.AsyncDispatcher: Waiting for AsyncDispatcher to drain. Thread state is :RUNNABLE
2022-12-15 19:01:42,719 INFO org.apache.hadoop.yarn.event.AsyncDispatcher: Waiting for AsyncDispatcher to drain. Thread state is :RUNNABLE
2022-12-15 19:01:42,820 INFO org.apache.hadoop.yarn.event.AsyncDispatcher: Waiting for AsyncDispatcher to drain. Thread state is :RUNNABLE
2022-12-15 19:01:42,920 INFO org.apache.hadoop.yarn.event.AsyncDispatcher: Waiting for AsyncDispatcher to drain. Thread state is :RUNNABLE
2022-12-15 19:01:43,020 INFO org.apache.hadoop.yarn.event.AsyncDispatcher: Waiting for AsyncDispatcher to drain. Thread state is :RUNNABLE
2022-12-15 19:01:43,120 INFO org.apache.hadoop.yarn.event.AsyncDispatcher: Waiting for AsyncDispatcher to drain. Thread state is :RUNNABLE
2022-12-15 19:01:43,221 INFO org.apache.hadoop.yarn.event.AsyncDispatcher: Waiting for AsyncDispatcher to drain. Thread state is :RUNNABLE
2022-12-15 19:01:43,321 INFO org.apache.hadoop.yarn.event.AsyncDispatcher: Waiting for AsyncDispatcher to drain. Thread state is :RUNNABLE
2022-12-15 19:01:43,421 INFO org.apache.hadoop.yarn.event.AsyncDispatcher: Waiting for AsyncDispatcher to drain. Thread state is :RUNNABLE
2022-12-15 19:01:43,521 INFO org.apache.hadoop.yarn.event.AsyncDispatcher: Waiting for AsyncDispatcher to drain. Thread state is :RUNNABLE
2022-12-15 19:01:43,622 INFO org.apache.hadoop.yarn.event.AsyncDispatcher: Waiting for AsyncDispatcher to drain. Thread state is :RUNNABLE
2022-12-15 19:01:43,722 INFO org.apache.hadoop.yarn.event.AsyncDispatcher: Waiting for AsyncDispatcher to drain. Thread state is :RUNNABLE
2022-12-15 19:01:43,822 INFO org.apache.hadoop.yarn.event.AsyncDispatcher: Waiting for AsyncDispatcher to drain. Thread state is :RUNNABLE
2022-12-15 19:01:43,922 INFO org.apache.hadoop.yarn.event.AsyncDispatcher: Waiting for AsyncDispatcher to drain. Thread state is :RUNNABLE
2022-12-15 19:01:44,023 INFO org.apache.hadoop.yarn.event.AsyncDispatcher: Waiting for AsyncDispatcher to drain. Thread state is :RUNNABLE
2022-12-15 19:01:44,123 INFO org.apache.hadoop.yarn.event.AsyncDispatcher: Waiting for AsyncDispatcher to drain. Thread state is :RUNNABLE
2022-12-15 19:01:44,223 INFO org.apache.hadoop.yarn.event.AsyncDispatcher: Waiting for AsyncDispatcher to drain. Thread state is :RUNNABLE
2022-12-15 19:01:44,324 INFO org.apache.hadoop.yarn.event.AsyncDispatcher: Waiting for AsyncDispatcher to drain. Thread state is :RUNNABLE
2022-12-15 19:01:44,424 INFO org.apache.hadoop.yarn.event.AsyncDispatcher: Waiting for AsyncDispatcher to drain. Thread state is :RUNNABLE
2022-12-15 19:01:44,524 INFO org.apache.hadoop.yarn.event.AsyncDispatcher: Waiting for AsyncDispatcher to drain. Thread state is :RUNNABLE
2022-12-15 19:01:44,624 INFO org.apache.hadoop.yarn.event.AsyncDispatcher: Waiting for AsyncDispatcher to drain. Thread state is :RUNNABLE
2022-12-15 19:01:44,725 INFO org.apache.hadoop.yarn.event.AsyncDispatcher: Waiting for AsyncDispatcher to drain. Thread state is :RUNNABLE
2022-12-15 19:01:44,825 INFO org.apache.hadoop.yarn.event.AsyncDispatcher: Waiting for AsyncDispatcher to drain. Thread state is :RUNNABLE
2022-12-15 19:01:44,925 INFO org.apache.hadoop.yarn.event.AsyncDispatcher: Waiting for AsyncDispatcher to drain. Thread state is :RUNNABLE
2022-12-15 19:01:45,025 INFO org.apache.hadoop.yarn.event.AsyncDispatcher: Waiting for AsyncDispatcher to drain. Thread state is :RUNNABLE
2022-12-15 19:01:45,126 INFO org.apache.hadoop.yarn.event.AsyncDispatcher: Waiting for AsyncDispatcher to drain. Thread state is :RUNNABLE
2022-12-15 19:01:45,226 INFO org.apache.hadoop.yarn.event.AsyncDispatcher: Waiting for AsyncDispatcher to drain. Thread state is :RUNNABLE
2022-12-15 19:01:45,326 INFO org.apache.hadoop.yarn.event.AsyncDispatcher: Waiting for AsyncDispatcher to drain. Thread state is :RUNNABLE
2022-12-15 19:01:45,426 INFO org.apache.hadoop.yarn.event.AsyncDispatcher: Waiting for AsyncDispatcher to drain. Thread state is :RUNNABLE
2022-12-15 19:01:45,527 INFO org.apache.hadoop.yarn.event.AsyncDispatcher: Waiting for AsyncDispatcher to drain. Thread state is :RUNNABLE
2022-12-15 19:01:45,627 INFO org.apache.hadoop.yarn.event.AsyncDispatcher: Waiting for AsyncDispatcher to drain. Thread state is :RUNNABLE
2022-12-15 19:01:45,727 INFO org.apache.hadoop.yarn.event.AsyncDispatcher: Waiting for AsyncDispatcher to drain. Thread state is :RUNNABLE
2022-12-15 19:01:45,827 INFO org.apache.hadoop.yarn.event.AsyncDispatcher: Waiting for AsyncDispatcher to drain. Thread state is :RUNNABLE
2022-12-15 19:01:45,928 INFO org.apache.hadoop.yarn.event.AsyncDispatcher: Waiting for AsyncDispatcher to drain. Thread state is :RUNNABLE
2022-12-15 19:01:46,028 INFO org.apache.hadoop.yarn.event.AsyncDispatcher: Waiting for AsyncDispatcher to drain. Thread state is :RUNNABLE
2022-12-15 19:01:46,128 INFO org.apache.hadoop.yarn.event.AsyncDispatcher: Waiting for AsyncDispatcher to drain. Thread state is :RUNNABLE
2022-12-15 19:01:46,229 INFO org.apache.hadoop.yarn.event.AsyncDispatcher: Waiting for AsyncDispatcher to drain. Thread state is :RUNNABLE
2022-12-15 19:01:46,329 INFO org.apache.hadoop.yarn.event.AsyncDispatcher: Waiting for AsyncDispatcher to drain. Thread state is :RUNNABLE
2022-12-15 19:01:46,429 INFO org.apache.hadoop.yarn.event.AsyncDispatcher: Waiting for AsyncDispatcher to drain. Thread state is :RUNNABLE
2022-12-15 19:01:46,529 INFO org.apache.hadoop.yarn.event.AsyncDispatcher: Waiting for AsyncDispatcher to drain. Thread state is :RUNNABLE
2022-12-15 19:01:46,629 INFO org.apache.hadoop.yarn.event.AsyncDispatcher: Waiting for AsyncDispatcher to drain. Thread state is :RUNNABLE
2022-12-15 19:01:46,730 INFO org.apache.hadoop.yarn.event.AsyncDispatcher: Waiting for AsyncDispatcher to drain. Thread state is :RUNNABLE
2022-12-15 19:01:46,830 INFO org.apache.hadoop.yarn.event.AsyncDispatcher: Waiting for AsyncDispatcher to drain. Thread state is :RUNNABLE
2022-12-15 19:01:46,930 INFO org.apache.hadoop.yarn.event.AsyncDispatcher: Waiting for AsyncDispatcher to drain. Thread state is :RUNNABLE
2022-12-15 19:01:47,030 INFO org.apache.hadoop.yarn.event.AsyncDispatcher: Waiting for AsyncDispatcher to drain. Thread state is :RUNNABLE
2022-12-15 19:01:47,131 INFO org.apache.hadoop.yarn.event.AsyncDispatcher: Waiting for AsyncDispatcher to drain. Thread state is :RUNNABLE
2022-12-15 19:01:47,231 INFO org.apache.hadoop.yarn.event.AsyncDispatcher: Waiting for AsyncDispatcher to drain. Thread state is :RUNNABLE
2022-12-15 19:01:47,331 INFO org.apache.hadoop.yarn.event.AsyncDispatcher: Waiting for AsyncDispatcher to drain. Thread state is :RUNNABLE
2022-12-15 19:01:47,431 INFO org.apache.hadoop.yarn.event.AsyncDispatcher: Waiting for AsyncDispatcher to drain. Thread state is :RUNNABLE
2022-12-15 19:01:47,532 INFO org.apache.hadoop.yarn.event.AsyncDispatcher: Waiting for AsyncDispatcher to drain. Thread state is :RUNNABLE
2022-12-15 19:01:47,632 INFO org.apache.hadoop.yarn.event.AsyncDispatcher: Waiting for AsyncDispatcher to drain. Thread state is :RUNNABLE
2022-12-15 19:01:47,732 INFO org.apache.hadoop.yarn.event.AsyncDispatcher: Waiting for AsyncDispatcher to drain. Thread state is :RUNNABLE
2022-12-15 19:01:47,832 INFO org.apache.hadoop.yarn.event.AsyncDispatcher: Waiting for AsyncDispatcher to drain. Thread state is :RUNNABLE
2022-12-15 19:01:47,933 INFO org.apache.hadoop.yarn.event.AsyncDispatcher: Waiting for AsyncDispatcher to drain. Thread state is :RUNNABLE
2022-12-15 19:01:48,033 INFO org.apache.hadoop.yarn.event.AsyncDispatcher: Waiting for AsyncDispatcher to drain. Thread state is :RUNNABLE
2022-12-15 19:01:48,133 INFO org.apache.hadoop.yarn.event.AsyncDispatcher: Waiting for AsyncDispatcher to drain. Thread state is :RUNNABLE
2022-12-15 19:01:48,233 INFO org.apache.hadoop.yarn.event.AsyncDispatcher: Waiting for AsyncDispatcher to drain. Thread state is :RUNNABLE
2022-12-15 19:01:48,333 INFO org.apache.hadoop.yarn.event.AsyncDispatcher: Waiting for AsyncDispatcher to drain. Thread state is :RUNNABLE
2022-12-15 19:01:48,433 INFO org.apache.hadoop.yarn.event.AsyncDispatcher: Waiting for AsyncDispatcher to drain. Thread state is :RUNNABLE
2022-12-15 19:01:48,534 INFO org.apache.hadoop.yarn.event.AsyncDispatcher: Waiting for AsyncDispatcher to drain. Thread state is :RUNNABLE
2022-12-15 19:01:48,634 INFO org.apache.hadoop.yarn.event.AsyncDispatcher: Waiting for AsyncDispatcher to drain. Thread state is :RUNNABLE
2022-12-15 19:01:48,734 INFO org.apache.hadoop.yarn.event.AsyncDispatcher: Waiting for AsyncDispatcher to drain. Thread state is :RUNNABLE
2022-12-15 19:01:48,834 INFO org.apache.hadoop.yarn.event.AsyncDispatcher: Waiting for AsyncDispatcher to drain. Thread state is :RUNNABLE
2022-12-15 19:01:48,935 INFO org.apache.hadoop.yarn.event.AsyncDispatcher: Waiting for AsyncDispatcher to drain. Thread state is :RUNNABLE
2022-12-15 19:01:49,035 INFO org.apache.hadoop.yarn.event.AsyncDispatcher: Waiting for AsyncDispatcher to drain. Thread state is :RUNNABLE
2022-12-15 19:01:49,135 INFO org.apache.hadoop.yarn.event.AsyncDispatcher: Waiting for AsyncDispatcher to drain. Thread state is :RUNNABLE
2022-12-15 19:01:49,235 INFO org.apache.hadoop.yarn.event.AsyncDispatcher: Waiting for AsyncDispatcher to drain. Thread state is :RUNNABLE
2022-12-15 19:01:49,336 INFO org.apache.hadoop.yarn.event.AsyncDispatcher: Waiting for AsyncDispatcher to drain. Thread state is :RUNNABLE
2022-12-15 19:01:49,436 INFO org.apache.hadoop.yarn.event.AsyncDispatcher: Waiting for AsyncDispatcher to drain. Thread state is :RUNNABLE
2022-12-15 19:01:49,536 INFO org.apache.hadoop.yarn.event.AsyncDispatcher: Waiting for AsyncDispatcher to drain. Thread state is :RUNNABLE
2022-12-15 19:01:49,636 INFO org.apache.hadoop.yarn.event.AsyncDispatcher: Waiting for AsyncDispatcher to drain. Thread state is :RUNNABLE
2022-12-15 19:01:49,737 INFO org.apache.hadoop.yarn.event.AsyncDispatcher: Waiting for AsyncDispatcher to drain. Thread state is :RUNNABLE
2022-12-15 19:01:49,837 INFO org.apache.hadoop.yarn.event.AsyncDispatcher: Waiting for AsyncDispatcher to drain. Thread state is :RUNNABLE
2022-12-15 19:01:49,937 INFO org.apache.hadoop.yarn.event.AsyncDispatcher: Waiting for AsyncDispatcher to drain. Thread state is :RUNNABLE
2022-12-15 19:01:50,037 INFO org.apache.hadoop.yarn.event.AsyncDispatcher: Waiting for AsyncDispatcher to drain. Thread state is :RUNNABLE
2022-12-15 19:01:50,138 INFO org.apache.hadoop.yarn.event.AsyncDispatcher: Waiting for AsyncDispatcher to drain. Thread state is :RUNNABLE
2022-12-15 19:01:50,238 INFO org.apache.hadoop.yarn.event.AsyncDispatcher: Waiting for AsyncDispatcher to drain. Thread state is :RUNNABLE
2022-12-15 19:01:50,338 INFO org.apache.hadoop.yarn.event.AsyncDispatcher: Waiting for AsyncDispatcher to drain. Thread state is :RUNNABLE
2022-12-15 19:01:50,438 INFO org.apache.hadoop.yarn.event.AsyncDispatcher: Waiting for AsyncDispatcher to drain. Thread state is :RUNNABLE
2022-12-15 19:01:50,539 INFO org.apache.hadoop.yarn.event.AsyncDispatcher: Waiting for AsyncDispatcher to drain. Thread state is :RUNNABLE
2022-12-15 19:01:50,639 INFO org.apache.hadoop.yarn.event.AsyncDispatcher: Waiting for AsyncDispatcher to drain. Thread state is :RUNNABLE
2022-12-15 19:01:50,739 INFO org.apache.hadoop.yarn.event.AsyncDispatcher: Waiting for AsyncDispatcher to drain. Thread state is :RUNNABLE
2022-12-15 19:01:50,839 INFO org.apache.hadoop.yarn.event.AsyncDispatcher: Waiting for AsyncDispatcher to drain. Thread state is :RUNNABLE
2022-12-15 19:01:50,939 INFO org.apache.hadoop.yarn.event.AsyncDispatcher: Waiting for AsyncDispatcher to drain. Thread state is :RUNNABLE
2022-12-15 19:01:51,040 INFO org.apache.hadoop.yarn.event.AsyncDispatcher: Waiting for AsyncDispatcher to drain. Thread state is :RUNNABLE
2022-12-15 19:01:51,140 INFO org.apache.hadoop.yarn.event.AsyncDispatcher: Waiting for AsyncDispatcher to drain. Thread state is :RUNNABLE
2022-12-15 19:01:51,240 INFO org.apache.hadoop.yarn.event.AsyncDispatcher: Waiting for AsyncDispatcher to drain. Thread state is :RUNNABLE
2022-12-15 19:01:51,340 INFO org.apache.hadoop.yarn.event.AsyncDispatcher: Waiting for AsyncDispatcher to drain. Thread state is :RUNNABLE
2022-12-15 19:01:51,440 INFO org.apache.hadoop.yarn.event.AsyncDispatcher: Waiting for AsyncDispatcher to drain. Thread state is :RUNNABLE
2022-12-15 19:01:51,541 INFO org.apache.hadoop.yarn.event.AsyncDispatcher: Waiting for AsyncDispatcher to drain. Thread state is :RUNNABLE
2022-12-15 19:01:51,641 INFO org.apache.hadoop.yarn.event.AsyncDispatcher: Waiting for AsyncDispatcher to drain. Thread state is :RUNNABLE
2022-12-15 19:01:51,741 INFO org.apache.hadoop.yarn.event.AsyncDispatcher: Waiting for AsyncDispatcher to drain. Thread state is :RUNNABLE
2022-12-15 19:01:51,841 INFO org.apache.hadoop.yarn.event.AsyncDispatcher: Waiting for AsyncDispatcher to drain. Thread state is :RUNNABLE
2022-12-15 19:01:51,942 INFO org.apache.hadoop.yarn.event.AsyncDispatcher: Waiting for AsyncDispatcher to drain. Thread state is :RUNNABLE
2022-12-15 19:01:52,042 INFO org.apache.hadoop.yarn.event.AsyncDispatcher: Waiting for AsyncDispatcher to drain. Thread state is :RUNNABLE
2022-12-15 19:01:52,142 INFO org.apache.hadoop.yarn.event.AsyncDispatcher: Waiting for AsyncDispatcher to drain. Thread state is :RUNNABLE
2022-12-15 19:01:52,242 INFO org.apache.hadoop.yarn.event.AsyncDispatcher: Waiting for AsyncDispatcher to drain. Thread state is :RUNNABLE
2022-12-15 19:01:52,343 INFO org.apache.hadoop.yarn.event.AsyncDispatcher: Waiting for AsyncDispatcher to drain. Thread state is :RUNNABLE
2022-12-15 19:01:52,443 INFO org.apache.hadoop.yarn.event.AsyncDispatcher: Waiting for AsyncDispatcher to drain. Thread state is :RUNNABLE
2022-12-15 19:01:52,543 INFO org.apache.hadoop.yarn.event.AsyncDispatcher: Waiting for AsyncDispatcher to drain. Thread state is :RUNNABLE
2022-12-15 19:01:52,643 INFO org.apache.hadoop.yarn.event.AsyncDispatcher: Waiting for AsyncDispatcher to drain. Thread state is :RUNNABLE
2022-12-15 19:01:52,743 INFO org.apache.hadoop.yarn.event.AsyncDispatcher: Waiting for AsyncDispatcher to drain. Thread state is :RUNNABLE
2022-12-15 19:01:52,844 INFO org.apache.hadoop.yarn.event.AsyncDispatcher: Waiting for AsyncDispatcher to drain. Thread state is :RUNNABLE
2022-12-15 19:01:52,944 INFO org.apache.hadoop.yarn.event.AsyncDispatcher: Waiting for AsyncDispatcher to drain. Thread state is :RUNNABLE
2022-12-15 19:01:53,044 INFO org.apache.hadoop.yarn.event.AsyncDispatcher: Waiting for AsyncDispatcher to drain. Thread state is :RUNNABLE
2022-12-15 19:01:53,144 INFO org.apache.hadoop.yarn.event.AsyncDispatcher: Waiting for AsyncDispatcher to drain. Thread state is :RUNNABLE
2022-12-15 19:01:53,245 INFO org.apache.hadoop.yarn.event.AsyncDispatcher: Waiting for AsyncDispatcher to drain. Thread state is :RUNNABLE
2022-12-15 19:01:53,345 INFO org.apache.hadoop.yarn.event.AsyncDispatcher: Waiting for AsyncDispatcher to drain. Thread state is :RUNNABLE
2022-12-15 19:01:53,445 INFO org.apache.hadoop.yarn.event.AsyncDispatcher: Waiting for AsyncDispatcher to drain. Thread state is :RUNNABLE
2022-12-15 19:01:53,545 INFO org.apache.hadoop.yarn.event.AsyncDispatcher: Waiting for AsyncDispatcher to drain. Thread state is :RUNNABLE
2022-12-15 19:01:53,646 INFO org.apache.hadoop.yarn.event.AsyncDispatcher: Waiting for AsyncDispatcher to drain. Thread state is :RUNNABLE
2022-12-15 19:01:53,746 INFO org.apache.hadoop.yarn.event.AsyncDispatcher: Waiting for AsyncDispatcher to drain. Thread state is :RUNNABLE
2022-12-15 19:01:53,846 INFO org.apache.hadoop.yarn.event.AsyncDispatcher: Waiting for AsyncDispatcher to drain. Thread state is :RUNNABLE
2022-12-15 19:01:53,946 INFO org.apache.hadoop.yarn.event.AsyncDispatcher: Waiting for AsyncDispatcher to drain. Thread state is :RUNNABLE
2022-12-15 19:01:54,047 INFO org.apache.hadoop.yarn.event.AsyncDispatcher: Waiting for AsyncDispatcher to drain. Thread state is :RUNNABLE
2022-12-15 19:01:54,147 INFO org.apache.hadoop.yarn.event.AsyncDispatcher: Waiting for AsyncDispatcher to drain. Thread state is :RUNNABLE
2022-12-15 19:01:54,247 INFO org.apache.hadoop.yarn.event.AsyncDispatcher: Waiting for AsyncDispatcher to drain. Thread state is :RUNNABLE
2022-12-15 19:01:54,347 INFO org.apache.hadoop.yarn.event.AsyncDispatcher: Waiting for AsyncDispatcher to drain. Thread state is :RUNNABLE
2022-12-15 19:01:54,448 INFO org.apache.hadoop.yarn.event.AsyncDispatcher: Waiting for AsyncDispatcher to drain. Thread state is :RUNNABLE
2022-12-15 19:01:54,548 INFO org.apache.hadoop.yarn.event.AsyncDispatcher: Waiting for AsyncDispatcher to drain. Thread state is :RUNNABLE
2022-12-15 19:01:54,648 INFO org.apache.hadoop.yarn.event.AsyncDispatcher: Waiting for AsyncDispatcher to drain. Thread state is :RUNNABLE
2022-12-15 19:01:54,748 INFO org.apache.hadoop.yarn.event.AsyncDispatcher: Waiting for AsyncDispatcher to drain. Thread state is :RUNNABLE
2022-12-15 19:01:54,849 INFO org.apache.hadoop.yarn.event.AsyncDispatcher: Waiting for AsyncDispatcher to drain. Thread state is :RUNNABLE
2022-12-15 19:01:54,949 INFO org.apache.hadoop.yarn.event.AsyncDispatcher: Waiting for AsyncDispatcher to drain. Thread state is :RUNNABLE
2022-12-15 19:01:55,049 INFO org.apache.hadoop.yarn.event.AsyncDispatcher: Waiting for AsyncDispatcher to drain. Thread state is :RUNNABLE
2022-12-15 19:01:55,149 INFO org.apache.hadoop.yarn.event.AsyncDispatcher: Waiting for AsyncDispatcher to drain. Thread state is :RUNNABLE
2022-12-15 19:01:55,249 INFO org.apache.hadoop.yarn.event.AsyncDispatcher: Waiting for AsyncDispatcher to drain. Thread state is :RUNNABLE
2022-12-15 19:01:55,350 INFO org.apache.hadoop.yarn.event.AsyncDispatcher: Waiting for AsyncDispatcher to drain. Thread state is :RUNNABLE
2022-12-15 19:01:55,450 INFO org.apache.hadoop.yarn.event.AsyncDispatcher: Waiting for AsyncDispatcher to drain. Thread state is :RUNNABLE
2022-12-15 19:01:55,550 INFO org.apache.hadoop.yarn.event.AsyncDispatcher: Waiting for AsyncDispatcher to drain. Thread state is :RUNNABLE
2022-12-15 19:01:55,651 INFO org.apache.hadoop.yarn.event.AsyncDispatcher: Waiting for AsyncDispatcher to drain. Thread state is :RUNNABLE
2022-12-15 19:01:55,751 INFO org.apache.hadoop.yarn.event.AsyncDispatcher: Waiting for AsyncDispatcher to drain. Thread state is :RUNNABLE
2022-12-15 19:01:55,851 INFO org.apache.hadoop.yarn.event.AsyncDispatcher: Waiting for AsyncDispatcher to drain. Thread state is :RUNNABLE
2022-12-15 19:01:55,951 INFO org.apache.hadoop.yarn.event.AsyncDispatcher: Waiting for AsyncDispatcher to drain. Thread state is :RUNNABLE
2022-12-15 19:01:56,051 INFO org.apache.hadoop.yarn.event.AsyncDispatcher: Waiting for AsyncDispatcher to drain. Thread state is :RUNNABLE
2022-12-15 19:01:56,152 INFO org.apache.hadoop.yarn.event.AsyncDispatcher: Waiting for AsyncDispatcher to drain. Thread state is :RUNNABLE
2022-12-15 19:01:56,252 INFO org.apache.hadoop.yarn.event.AsyncDispatcher: Waiting for AsyncDispatcher to drain. Thread state is :RUNNABLE
2022-12-15 19:01:56,352 INFO org.apache.hadoop.yarn.event.AsyncDispatcher: Waiting for AsyncDispatcher to drain. Thread state is :RUNNABLE
2022-12-15 19:01:56,452 INFO org.apache.hadoop.yarn.event.AsyncDispatcher: Waiting for AsyncDispatcher to drain. Thread state is :RUNNABLE
2022-12-15 19:01:56,553 INFO org.apache.hadoop.yarn.event.AsyncDispatcher: Waiting for AsyncDispatcher to drain. Thread state is :RUNNABLE
2022-12-15 19:01:56,653 INFO org.apache.hadoop.yarn.event.AsyncDispatcher: Waiting for AsyncDispatcher to drain. Thread state is :RUNNABLE
2022-12-15 19:01:56,753 INFO org.apache.hadoop.yarn.event.AsyncDispatcher: Waiting for AsyncDispatcher to drain. Thread state is :RUNNABLE
2022-12-15 19:01:56,853 INFO org.apache.hadoop.yarn.event.AsyncDispatcher: Waiting for AsyncDispatcher to drain. Thread state is :RUNNABLE
2022-12-15 19:01:56,954 INFO org.apache.hadoop.yarn.event.AsyncDispatcher: Waiting for AsyncDispatcher to drain. Thread state is :RUNNABLE
2022-12-15 19:01:57,054 INFO org.apache.hadoop.yarn.event.AsyncDispatcher: Waiting for AsyncDispatcher to drain. Thread state is :RUNNABLE
2022-12-15 19:01:57,154 INFO org.apache.hadoop.yarn.event.AsyncDispatcher: Waiting for AsyncDispatcher to drain. Thread state is :RUNNABLE
2022-12-15 19:01:57,254 INFO org.apache.hadoop.yarn.event.AsyncDispatcher: Waiting for AsyncDispatcher to drain. Thread state is :RUNNABLE
2022-12-15 19:01:57,355 INFO org.apache.hadoop.yarn.event.AsyncDispatcher: Waiting for AsyncDispatcher to drain. Thread state is :RUNNABLE
2022-12-15 19:01:57,455 INFO org.apache.hadoop.yarn.event.AsyncDispatcher: Waiting for AsyncDispatcher to drain. Thread state is :RUNNABLE
2022-12-15 19:01:57,555 INFO org.apache.hadoop.yarn.event.AsyncDispatcher: Waiting for AsyncDispatcher to drain. Thread state is :RUNNABLE
2022-12-15 19:01:57,655 INFO org.apache.hadoop.yarn.event.AsyncDispatcher: Waiting for AsyncDispatcher to drain. Thread state is :RUNNABLE
2022-12-15 19:01:57,755 INFO org.apache.hadoop.yarn.event.AsyncDispatcher: Waiting for AsyncDispatcher to drain. Thread state is :RUNNABLE
2022-12-15 19:01:57,856 INFO org.apache.hadoop.yarn.event.AsyncDispatcher: Waiting for AsyncDispatcher to drain. Thread state is :RUNNABLE
2022-12-15 19:01:57,956 INFO org.apache.hadoop.yarn.event.AsyncDispatcher: Waiting for AsyncDispatcher to drain. Thread state is :RUNNABLE
2022-12-15 19:01:58,056 INFO org.apache.hadoop.yarn.event.AsyncDispatcher: Waiting for AsyncDispatcher to drain. Thread state is :RUNNABLE
2022-12-15 19:01:58,156 INFO org.apache.hadoop.yarn.event.AsyncDispatcher: Waiting for AsyncDispatcher to drain. Thread state is :RUNNABLE
2022-12-15 19:01:58,257 INFO org.apache.hadoop.yarn.event.AsyncDispatcher: Waiting for AsyncDispatcher to drain. Thread state is :RUNNABLE
2022-12-15 19:01:58,357 INFO org.apache.hadoop.yarn.event.AsyncDispatcher: Waiting for AsyncDispatcher to drain. Thread state is :RUNNABLE
2022-12-15 19:01:58,457 INFO org.apache.hadoop.yarn.event.AsyncDispatcher: Waiting for AsyncDispatcher to drain. Thread state is :RUNNABLE
2022-12-15 19:01:58,557 INFO org.apache.hadoop.yarn.event.AsyncDispatcher: Waiting for AsyncDispatcher to drain. Thread state is :RUNNABLE
2022-12-15 19:01:58,658 INFO org.apache.hadoop.yarn.event.AsyncDispatcher: Waiting for AsyncDispatcher to drain. Thread state is :RUNNABLE
2022-12-15 19:01:58,758 INFO org.apache.hadoop.yarn.event.AsyncDispatcher: Waiting for AsyncDispatcher to drain. Thread state is :RUNNABLE
2022-12-15 19:01:58,858 INFO org.apache.hadoop.yarn.event.AsyncDispatcher: Waiting for AsyncDispatcher to drain. Thread state is :RUNNABLE
2022-12-15 19:01:58,958 INFO org.apache.hadoop.yarn.event.AsyncDispatcher: Waiting for AsyncDispatcher to drain. Thread state is :RUNNABLE
2022-12-15 19:01:59,059 INFO org.apache.hadoop.yarn.event.AsyncDispatcher: Waiting for AsyncDispatcher to drain. Thread state is :RUNNABLE
2022-12-15 19:01:59,159 INFO org.apache.hadoop.yarn.event.AsyncDispatcher: Waiting for AsyncDispatcher to drain. Thread state is :RUNNABLE
2022-12-15 19:01:59,259 INFO org.apache.hadoop.yarn.event.AsyncDispatcher: Waiting for AsyncDispatcher to drain. Thread state is :RUNNABLE
2022-12-15 19:01:59,359 INFO org.apache.hadoop.yarn.event.AsyncDispatcher: Waiting for AsyncDispatcher to drain. Thread state is :RUNNABLE
2022-12-15 19:01:59,459 INFO org.apache.hadoop.yarn.event.AsyncDispatcher: Waiting for AsyncDispatcher to drain. Thread state is :RUNNABLE
2022-12-15 19:01:59,560 INFO org.apache.hadoop.yarn.event.AsyncDispatcher: Waiting for AsyncDispatcher to drain. Thread state is :RUNNABLE
2022-12-15 19:01:59,660 INFO org.apache.hadoop.yarn.event.AsyncDispatcher: Waiting for AsyncDispatcher to drain. Thread state is :RUNNABLE
2022-12-15 19:01:59,760 INFO org.apache.hadoop.yarn.event.AsyncDispatcher: Waiting for AsyncDispatcher to drain. Thread state is :RUNNABLE
2022-12-15 19:01:59,861 INFO org.apache.hadoop.yarn.event.AsyncDispatcher: Waiting for AsyncDispatcher to drain. Thread state is :RUNNABLE
2022-12-15 19:01:59,961 INFO org.apache.hadoop.yarn.event.AsyncDispatcher: Waiting for AsyncDispatcher to drain. Thread state is :RUNNABLE
2022-12-15 19:02:00,061 INFO org.apache.hadoop.yarn.event.AsyncDispatcher: Waiting for AsyncDispatcher to drain. Thread state is :RUNNABLE
2022-12-15 19:02:00,161 INFO org.apache.hadoop.yarn.event.AsyncDispatcher: Waiting for AsyncDispatcher to drain. Thread state is :RUNNABLE
2022-12-15 19:02:00,261 INFO org.apache.hadoop.yarn.event.AsyncDispatcher: Waiting for AsyncDispatcher to drain. Thread state is :RUNNABLE
2022-12-15 19:02:00,362 INFO org.apache.hadoop.yarn.event.AsyncDispatcher: Waiting for AsyncDispatcher to drain. Thread state is :RUNNABLE
2022-12-15 19:02:00,462 INFO org.apache.hadoop.yarn.event.AsyncDispatcher: Waiting for AsyncDispatcher to drain. Thread state is :RUNNABLE
2022-12-15 19:02:00,562 INFO org.apache.hadoop.yarn.event.AsyncDispatcher: Waiting for AsyncDispatcher to drain. Thread state is :RUNNABLE
2022-12-15 19:02:00,662 INFO org.apache.hadoop.yarn.event.AsyncDispatcher: Waiting for AsyncDispatcher to drain. Thread state is :RUNNABLE
2022-12-15 19:02:00,762 INFO org.apache.hadoop.yarn.event.AsyncDispatcher: Waiting for AsyncDispatcher to drain. Thread state is :RUNNABLE
2022-12-15 19:02:00,863 INFO org.apache.hadoop.yarn.event.AsyncDispatcher: Waiting for AsyncDispatcher to drain. Thread state is :RUNNABLE
2022-12-15 19:02:00,963 INFO org.apache.hadoop.yarn.event.AsyncDispatcher: Waiting for AsyncDispatcher to drain. Thread state is :RUNNABLE
2022-12-15 19:02:01,063 INFO org.apache.hadoop.yarn.event.AsyncDispatcher: Waiting for AsyncDispatcher to drain. Thread state is :RUNNABLE
2022-12-15 19:02:01,163 INFO org.apache.hadoop.yarn.event.AsyncDispatcher: Waiting for AsyncDispatcher to drain. Thread state is :RUNNABLE
2022-12-15 19:02:01,264 INFO org.apache.hadoop.yarn.event.AsyncDispatcher: Waiting for AsyncDispatcher to drain. Thread state is :RUNNABLE
2022-12-15 19:02:01,364 INFO org.apache.hadoop.yarn.event.AsyncDispatcher: Waiting for AsyncDispatcher to drain. Thread state is :RUNNABLE
2022-12-15 19:02:01,464 INFO org.apache.hadoop.yarn.event.AsyncDispatcher: Waiting for AsyncDispatcher to drain. Thread state is :RUNNABLE
2022-12-15 19:02:01,564 INFO org.apache.hadoop.yarn.event.AsyncDispatcher: Waiting for AsyncDispatcher to drain. Thread state is :RUNNABLE
2022-12-15 19:02:01,665 INFO org.apache.hadoop.yarn.event.AsyncDispatcher: Waiting for AsyncDispatcher to drain. Thread state is :RUNNABLE
2022-12-15 19:02:01,765 INFO org.apache.hadoop.yarn.event.AsyncDispatcher: Waiting for AsyncDispatcher to drain. Thread state is :RUNNABLE
2022-12-15 19:02:01,865 INFO org.apache.hadoop.yarn.event.AsyncDispatcher: Waiting for AsyncDispatcher to drain. Thread state is :RUNNABLE
2022-12-15 19:02:01,965 INFO org.apache.hadoop.yarn.event.AsyncDispatcher: Waiting for AsyncDispatcher to drain. Thread state is :RUNNABLE
2022-12-15 19:02:02,066 INFO org.apache.hadoop.yarn.event.AsyncDispatcher: Waiting for AsyncDispatcher to drain. Thread state is :RUNNABLE
2022-12-15 19:02:02,166 INFO org.apache.hadoop.yarn.event.AsyncDispatcher: Waiting for AsyncDispatcher to drain. Thread state is :RUNNABLE
2022-12-15 19:02:02,266 INFO org.apache.hadoop.yarn.event.AsyncDispatcher: Waiting for AsyncDispatcher to drain. Thread state is :RUNNABLE
2022-12-15 19:02:02,367 INFO org.apache.hadoop.yarn.event.AsyncDispatcher: Waiting for AsyncDispatcher to drain. Thread state is :RUNNABLE
2022-12-15 19:02:02,467 INFO org.apache.hadoop.yarn.event.AsyncDispatcher: Waiting for AsyncDispatcher to drain. Thread state is :RUNNABLE
2022-12-15 19:02:02,567 INFO org.apache.hadoop.yarn.event.AsyncDispatcher: Waiting for AsyncDispatcher to drain. Thread state is :RUNNABLE
2022-12-15 19:02:02,667 INFO org.apache.hadoop.yarn.event.AsyncDispatcher: Waiting for AsyncDispatcher to drain. Thread state is :RUNNABLE
2022-12-15 19:02:02,768 INFO org.apache.hadoop.yarn.event.AsyncDispatcher: Waiting for AsyncDispatcher to drain. Thread state is :RUNNABLE
2022-12-15 19:02:02,868 INFO org.apache.hadoop.yarn.event.AsyncDispatcher: Waiting for AsyncDispatcher to drain. Thread state is :RUNNABLE
2022-12-15 19:02:02,968 INFO org.apache.hadoop.yarn.event.AsyncDispatcher: Waiting for AsyncDispatcher to drain. Thread state is :RUNNABLE
2022-12-15 19:02:03,068 INFO org.apache.hadoop.yarn.event.AsyncDispatcher: Waiting for AsyncDispatcher to drain. Thread state is :RUNNABLE
2022-12-15 19:02:03,169 INFO org.apache.hadoop.yarn.event.AsyncDispatcher: Waiting for AsyncDispatcher to drain. Thread state is :RUNNABLE
2022-12-15 19:02:03,269 INFO org.apache.hadoop.yarn.event.AsyncDispatcher: Waiting for AsyncDispatcher to drain. Thread state is :RUNNABLE
2022-12-15 19:02:03,369 INFO org.apache.hadoop.yarn.event.AsyncDispatcher: Waiting for AsyncDispatcher to drain. Thread state is :RUNNABLE
2022-12-15 19:02:03,469 INFO org.apache.hadoop.yarn.event.AsyncDispatcher: Waiting for AsyncDispatcher to drain. Thread state is :RUNNABLE
2022-12-15 19:02:03,569 INFO org.apache.hadoop.yarn.event.AsyncDispatcher: Waiting for AsyncDispatcher to drain. Thread state is :RUNNABLE
2022-12-15 19:02:03,670 INFO org.apache.hadoop.yarn.event.AsyncDispatcher: Waiting for AsyncDispatcher to drain. Thread state is :RUNNABLE
2022-12-15 19:02:03,770 INFO org.apache.hadoop.yarn.event.AsyncDispatcher: Waiting for AsyncDispatcher to drain. Thread state is :RUNNABLE
2022-12-15 19:02:03,870 INFO org.apache.hadoop.yarn.event.AsyncDispatcher: Waiting for AsyncDispatcher to drain. Thread state is :RUNNABLE
2022-12-15 19:02:03,970 INFO org.apache.hadoop.yarn.event.AsyncDispatcher: Waiting for AsyncDispatcher to drain. Thread state is :RUNNABLE
2022-12-15 19:02:04,071 INFO org.apache.hadoop.yarn.event.AsyncDispatcher: Waiting for AsyncDispatcher to drain. Thread state is :RUNNABLE
2022-12-15 19:02:04,171 INFO org.apache.hadoop.yarn.event.AsyncDispatcher: Waiting for AsyncDispatcher to drain. Thread state is :RUNNABLE
2022-12-15 19:02:04,271 INFO org.apache.hadoop.yarn.event.AsyncDispatcher: Waiting for AsyncDispatcher to drain. Thread state is :RUNNABLE
2022-12-15 19:02:04,371 INFO org.apache.hadoop.yarn.event.AsyncDispatcher: Waiting for AsyncDispatcher to drain. Thread state is :RUNNABLE
2022-12-15 19:02:04,472 INFO org.apache.hadoop.yarn.event.AsyncDispatcher: Waiting for AsyncDispatcher to drain. Thread state is :RUNNABLE
2022-12-15 19:02:04,572 INFO org.apache.hadoop.yarn.event.AsyncDispatcher: Waiting for AsyncDispatcher to drain. Thread state is :RUNNABLE
2022-12-15 19:02:04,672 INFO org.apache.hadoop.yarn.event.AsyncDispatcher: Waiting for AsyncDispatcher to drain. Thread state is :RUNNABLE
2022-12-15 19:02:04,772 INFO org.apache.hadoop.yarn.event.AsyncDispatcher: Waiting for AsyncDispatcher to drain. Thread state is :RUNNABLE
2022-12-15 19:02:04,873 INFO org.apache.hadoop.yarn.event.AsyncDispatcher: Waiting for AsyncDispatcher to drain. Thread state is :RUNNABLE
2022-12-15 19:02:04,973 INFO org.apache.hadoop.yarn.event.AsyncDispatcher: Waiting for AsyncDispatcher to drain. Thread state is :RUNNABLE
2022-12-15 19:02:05,073 INFO org.apache.hadoop.yarn.event.AsyncDispatcher: Waiting for AsyncDispatcher to drain. Thread state is :RUNNABLE
2022-12-15 19:02:05,173 INFO org.apache.hadoop.yarn.event.AsyncDispatcher: Waiting for AsyncDispatcher to drain. Thread state is :RUNNABLE
2022-12-15 19:02:05,274 INFO org.apache.hadoop.yarn.event.AsyncDispatcher: Waiting for AsyncDispatcher to drain. Thread state is :RUNNABLE
2022-12-15 19:02:05,374 INFO org.apache.hadoop.yarn.event.AsyncDispatcher: Waiting for AsyncDispatcher to drain. Thread state is :RUNNABLE
2022-12-15 19:02:05,474 INFO org.apache.hadoop.yarn.event.AsyncDispatcher: Waiting for AsyncDispatcher to drain. Thread state is :RUNNABLE
2022-12-15 19:02:05,574 INFO org.apache.hadoop.yarn.event.AsyncDispatcher: Waiting for AsyncDispatcher to drain. Thread state is :RUNNABLE
2022-12-15 19:02:05,674 INFO org.apache.hadoop.yarn.event.AsyncDispatcher: Waiting for AsyncDispatcher to drain. Thread state is :RUNNABLE
2022-12-15 19:02:05,775 INFO org.apache.hadoop.yarn.event.AsyncDispatcher: Waiting for AsyncDispatcher to drain. Thread state is :RUNNABLE
2022-12-15 19:02:05,875 INFO org.apache.hadoop.yarn.event.AsyncDispatcher: Waiting for AsyncDispatcher to drain. Thread state is :RUNNABLE
2022-12-15 19:02:05,975 INFO org.apache.hadoop.yarn.event.AsyncDispatcher: Waiting for AsyncDispatcher to drain. Thread state is :RUNNABLE
2022-12-15 19:02:06,075 INFO org.apache.hadoop.yarn.event.AsyncDispatcher: Waiting for AsyncDispatcher to drain. Thread state is :RUNNABLE
2022-12-15 19:02:06,175 INFO org.apache.hadoop.yarn.event.AsyncDispatcher: Waiting for AsyncDispatcher to drain. Thread state is :RUNNABLE
2022-12-15 19:02:06,275 INFO org.apache.hadoop.yarn.event.AsyncDispatcher: Waiting for AsyncDispatcher to drain. Thread state is :RUNNABLE
2022-12-15 19:02:06,376 INFO org.apache.hadoop.yarn.event.AsyncDispatcher: Waiting for AsyncDispatcher to drain. Thread state is :RUNNABLE
2022-12-15 19:02:06,476 INFO org.apache.hadoop.yarn.event.AsyncDispatcher: Waiting for AsyncDispatcher to drain. Thread state is :RUNNABLE
2022-12-15 19:02:06,576 INFO org.apache.hadoop.yarn.event.AsyncDispatcher: Waiting for AsyncDispatcher to drain. Thread state is :RUNNABLE
2022-12-15 19:02:06,676 INFO org.apache.hadoop.yarn.event.AsyncDispatcher: Waiting for AsyncDispatcher to drain. Thread state is :RUNNABLE
2022-12-15 19:02:06,777 INFO org.apache.hadoop.yarn.event.AsyncDispatcher: Waiting for AsyncDispatcher to drain. Thread state is :RUNNABLE
2022-12-15 19:02:06,877 INFO org.apache.hadoop.yarn.event.AsyncDispatcher: Waiting for AsyncDispatcher to drain. Thread state is :RUNNABLE
2022-12-15 19:02:06,977 INFO org.apache.hadoop.yarn.event.AsyncDispatcher: Waiting for AsyncDispatcher to drain. Thread state is :RUNNABLE
2022-12-15 19:02:07,077 INFO org.apache.hadoop.yarn.event.AsyncDispatcher: Waiting for AsyncDispatcher to drain. Thread state is :RUNNABLE
2022-12-15 19:02:07,178 INFO org.apache.hadoop.yarn.event.AsyncDispatcher: Waiting for AsyncDispatcher to drain. Thread state is :RUNNABLE
2022-12-15 19:02:07,278 INFO org.apache.hadoop.yarn.event.AsyncDispatcher: Waiting for AsyncDispatcher to drain. Thread state is :RUNNABLE
2022-12-15 19:02:07,378 INFO org.apache.hadoop.yarn.event.AsyncDispatcher: Waiting for AsyncDispatcher to drain. Thread state is :RUNNABLE
2022-12-15 19:02:07,478 INFO org.apache.hadoop.yarn.event.AsyncDispatcher: Waiting for AsyncDispatcher to drain. Thread state is :RUNNABLE
2022-12-15 19:02:07,578 INFO org.apache.hadoop.yarn.event.AsyncDispatcher: Waiting for AsyncDispatcher to drain. Thread state is :RUNNABLE
2022-12-15 19:02:07,679 INFO org.apache.hadoop.yarn.event.AsyncDispatcher: Waiting for AsyncDispatcher to drain. Thread state is :RUNNABLE
2022-12-15 19:02:07,779 INFO org.apache.hadoop.yarn.event.AsyncDispatcher: Waiting for AsyncDispatcher to drain. Thread state is :RUNNABLE
2022-12-15 19:02:07,879 INFO org.apache.hadoop.yarn.event.AsyncDispatcher: Waiting for AsyncDispatcher to drain. Thread state is :RUNNABLE
2022-12-15 19:02:07,980 INFO org.apache.hadoop.yarn.event.AsyncDispatcher: Waiting for AsyncDispatcher to drain. Thread state is :RUNNABLE
2022-12-15 19:02:08,080 INFO org.apache.hadoop.yarn.event.AsyncDispatcher: Waiting for AsyncDispatcher to drain. Thread state is :RUNNABLE
2022-12-15 19:02:08,180 INFO org.apache.hadoop.yarn.event.AsyncDispatcher: Waiting for AsyncDispatcher to drain. Thread state is :RUNNABLE
2022-12-15 19:02:08,280 INFO org.apache.hadoop.yarn.event.AsyncDispatcher: Waiting for AsyncDispatcher to drain. Thread state is :RUNNABLE
2022-12-15 19:02:08,380 INFO org.apache.hadoop.yarn.event.AsyncDispatcher: Waiting for AsyncDispatcher to drain. Thread state is :RUNNABLE
2022-12-15 19:02:08,481 INFO org.apache.hadoop.yarn.event.AsyncDispatcher: Waiting for AsyncDispatcher to drain. Thread state is :RUNNABLE
2022-12-15 19:02:08,581 INFO org.apache.hadoop.yarn.event.AsyncDispatcher: Waiting for AsyncDispatcher to drain. Thread state is :RUNNABLE
2022-12-15 19:02:08,681 INFO org.apache.hadoop.yarn.event.AsyncDispatcher: Waiting for AsyncDispatcher to drain. Thread state is :RUNNABLE
2022-12-15 19:02:08,781 INFO org.apache.hadoop.yarn.event.AsyncDispatcher: Waiting for AsyncDispatcher to drain. Thread state is :RUNNABLE
2022-12-15 19:02:08,881 INFO org.apache.hadoop.yarn.event.AsyncDispatcher: Waiting for AsyncDispatcher to drain. Thread state is :RUNNABLE
2022-12-15 19:02:08,981 INFO org.apache.hadoop.yarn.event.AsyncDispatcher: Waiting for AsyncDispatcher to drain. Thread state is :RUNNABLE
2022-12-15 19:02:09,082 INFO org.apache.hadoop.yarn.event.AsyncDispatcher: Waiting for AsyncDispatcher to drain. Thread state is :RUNNABLE
2022-12-15 19:02:09,182 INFO org.apache.hadoop.yarn.event.AsyncDispatcher: Waiting for AsyncDispatcher to drain. Thread state is :RUNNABLE
2022-12-15 19:02:09,282 INFO org.apache.hadoop.yarn.event.AsyncDispatcher: Waiting for AsyncDispatcher to drain. Thread state is :RUNNABLE
2022-12-15 19:02:09,382 INFO org.apache.hadoop.yarn.event.AsyncDispatcher: Waiting for AsyncDispatcher to drain. Thread state is :RUNNABLE
2022-12-15 19:02:09,483 INFO org.apache.hadoop.yarn.event.AsyncDispatcher: Waiting for AsyncDispatcher to drain. Thread state is :RUNNABLE
2022-12-15 19:02:09,583 INFO org.apache.hadoop.yarn.event.AsyncDispatcher: Waiting for AsyncDispatcher to drain. Thread state is :RUNNABLE
2022-12-15 19:02:09,683 INFO org.apache.hadoop.yarn.event.AsyncDispatcher: Waiting for AsyncDispatcher to drain. Thread state is :RUNNABLE
2022-12-15 19:02:09,783 INFO org.apache.hadoop.yarn.event.AsyncDispatcher: Waiting for AsyncDispatcher to drain. Thread state is :RUNNABLE
2022-12-15 19:02:09,884 INFO org.apache.hadoop.yarn.event.AsyncDispatcher: Waiting for AsyncDispatcher to drain. Thread state is :RUNNABLE
2022-12-15 19:02:09,984 INFO org.apache.hadoop.yarn.event.AsyncDispatcher: Waiting for AsyncDispatcher to drain. Thread state is :RUNNABLE
2022-12-15 19:02:10,084 INFO org.apache.hadoop.yarn.event.AsyncDispatcher: Waiting for AsyncDispatcher to drain. Thread state is :RUNNABLE
2022-12-15 19:02:10,184 INFO org.apache.hadoop.yarn.event.AsyncDispatcher: Waiting for AsyncDispatcher to drain. Thread state is :RUNNABLE
2022-12-15 19:02:10,284 INFO org.apache.hadoop.yarn.event.AsyncDispatcher: Waiting for AsyncDispatcher to drain. Thread state is :RUNNABLE
2022-12-15 19:02:10,385 INFO org.apache.hadoop.yarn.event.AsyncDispatcher: Waiting for AsyncDispatcher to drain. Thread state is :RUNNABLE
2022-12-15 19:02:10,485 INFO org.apache.hadoop.yarn.event.AsyncDispatcher: Waiting for AsyncDispatcher to drain. Thread state is :RUNNABLE
2022-12-15 19:02:10,585 INFO org.apache.hadoop.yarn.event.AsyncDispatcher: Waiting for AsyncDispatcher to drain. Thread state is :RUNNABLE
2022-12-15 19:02:10,685 INFO org.apache.hadoop.yarn.event.AsyncDispatcher: Waiting for AsyncDispatcher to drain. Thread state is :RUNNABLE
2022-12-15 19:02:10,786 INFO org.apache.hadoop.yarn.event.AsyncDispatcher: Waiting for AsyncDispatcher to drain. Thread state is :RUNNABLE
2022-12-15 19:02:10,886 INFO org.apache.hadoop.yarn.event.AsyncDispatcher: Waiting for AsyncDispatcher to drain. Thread state is :RUNNABLE
2022-12-15 19:02:10,986 INFO org.apache.hadoop.yarn.event.AsyncDispatcher: Waiting for AsyncDispatcher to drain. Thread state is :RUNNABLE
2022-12-15 19:02:11,086 INFO org.apache.hadoop.yarn.event.AsyncDispatcher: Waiting for AsyncDispatcher to drain. Thread state is :RUNNABLE
2022-12-15 19:02:11,186 INFO org.apache.hadoop.yarn.event.AsyncDispatcher: Waiting for AsyncDispatcher to drain. Thread state is :RUNNABLE
2022-12-15 19:02:11,287 INFO org.apache.hadoop.yarn.event.AsyncDispatcher: Waiting for AsyncDispatcher to drain. Thread state is :RUNNABLE
2022-12-15 19:02:11,387 INFO org.apache.hadoop.yarn.event.AsyncDispatcher: Waiting for AsyncDispatcher to drain. Thread state is :RUNNABLE
2022-12-15 19:02:11,487 INFO org.apache.hadoop.yarn.event.AsyncDispatcher: Waiting for AsyncDispatcher to drain. Thread state is :RUNNABLE
2022-12-15 19:02:11,587 INFO org.apache.hadoop.yarn.event.AsyncDispatcher: Waiting for AsyncDispatcher to drain. Thread state is :RUNNABLE
2022-12-15 19:02:11,688 INFO org.apache.hadoop.yarn.event.AsyncDispatcher: Waiting for AsyncDispatcher to drain. Thread state is :RUNNABLE
2022-12-15 19:02:11,788 INFO org.apache.hadoop.yarn.event.AsyncDispatcher: Waiting for AsyncDispatcher to drain. Thread state is :RUNNABLE
2022-12-15 19:02:11,888 INFO org.apache.hadoop.yarn.event.AsyncDispatcher: Waiting for AsyncDispatcher to drain. Thread state is :RUNNABLE
2022-12-15 19:02:11,988 INFO org.apache.hadoop.yarn.event.AsyncDispatcher: Waiting for AsyncDispatcher to drain. Thread state is :RUNNABLE
2022-12-15 19:02:12,088 INFO org.apache.hadoop.yarn.event.AsyncDispatcher: Waiting for AsyncDispatcher to drain. Thread state is :RUNNABLE
2022-12-15 19:02:12,113 INFO org.apache.hadoop.yarn.client.api.impl.TimelineConnector: Exception caught by TimelineClientConnectionRetry, will try 30 more time(s).
Message: java.net.SocketTimeoutException: Call From null to adh-test-00-mnode2.ru-central1.internal:8188 failed on socket timeout exception: java.net.SocketTimeoutException: connect timed out; For more details see:  http://wiki.apache.org/hadoop/SocketTimeout
2022-12-15 19:02:12,142 INFO org.apache.hadoop.yarn.client.api.impl.TimelineConnector: Exception caught by TimelineClientConnectionRetry, will try 30 more time(s).
Message: java.net.SocketTimeoutException: Call From null to adh-test-00-mnode2.ru-central1.internal:8188 failed on socket timeout exception: java.net.SocketTimeoutException: connect timed out; For more details see:  http://wiki.apache.org/hadoop/SocketTimeout
2022-12-15 19:02:12,188 INFO org.apache.hadoop.yarn.event.AsyncDispatcher: Waiting for AsyncDispatcher to drain. Thread state is :TIMED_WAITING
2022-12-15 19:02:12,288 INFO org.apache.hadoop.yarn.event.AsyncDispatcher: Waiting for AsyncDispatcher to drain. Thread state is :TIMED_WAITING
2022-12-15 19:02:12,389 INFO org.apache.hadoop.yarn.event.AsyncDispatcher: Waiting for AsyncDispatcher to drain. Thread state is :TIMED_WAITING
2022-12-15 19:02:12,489 INFO org.apache.hadoop.yarn.event.AsyncDispatcher: Waiting for AsyncDispatcher to drain. Thread state is :TIMED_WAITING
2022-12-15 19:02:12,589 INFO org.apache.hadoop.yarn.event.AsyncDispatcher: Waiting for AsyncDispatcher to drain. Thread state is :TIMED_WAITING
2022-12-15 19:02:12,689 INFO org.apache.hadoop.yarn.event.AsyncDispatcher: Waiting for AsyncDispatcher to drain. Thread state is :TIMED_WAITING
2022-12-15 19:02:12,789 INFO org.apache.hadoop.yarn.event.AsyncDispatcher: Waiting for AsyncDispatcher to drain. Thread state is :TIMED_WAITING
2022-12-15 19:02:12,890 INFO org.apache.hadoop.yarn.event.AsyncDispatcher: Waiting for AsyncDispatcher to drain. Thread state is :TIMED_WAITING
2022-12-15 19:02:12,990 INFO org.apache.hadoop.yarn.event.AsyncDispatcher: Waiting for AsyncDispatcher to drain. Thread state is :TIMED_WAITING
2022-12-15 19:02:13,090 INFO org.apache.hadoop.yarn.event.AsyncDispatcher: Waiting for AsyncDispatcher to drain. Thread state is :TIMED_WAITING
2022-12-15 19:02:13,190 INFO org.apache.hadoop.yarn.event.AsyncDispatcher: Waiting for AsyncDispatcher to drain. Thread state is :RUNNABLE
2022-12-15 19:02:13,291 INFO org.apache.hadoop.yarn.event.AsyncDispatcher: Waiting for AsyncDispatcher to drain. Thread state is :RUNNABLE
2022-12-15 19:02:13,391 INFO org.apache.hadoop.yarn.event.AsyncDispatcher: Waiting for AsyncDispatcher to drain. Thread state is :RUNNABLE
2022-12-15 19:02:13,491 INFO org.apache.hadoop.yarn.event.AsyncDispatcher: Waiting for AsyncDispatcher to drain. Thread state is :RUNNABLE
2022-12-15 19:02:13,591 INFO org.apache.hadoop.yarn.event.AsyncDispatcher: Waiting for AsyncDispatcher to drain. Thread state is :RUNNABLE
2022-12-15 19:02:13,691 INFO org.apache.hadoop.yarn.event.AsyncDispatcher: Waiting for AsyncDispatcher to drain. Thread state is :RUNNABLE
2022-12-15 19:02:13,792 INFO org.apache.hadoop.yarn.event.AsyncDispatcher: Waiting for AsyncDispatcher to drain. Thread state is :RUNNABLE
2022-12-15 19:02:13,892 INFO org.apache.hadoop.yarn.event.AsyncDispatcher: Waiting for AsyncDispatcher to drain. Thread state is :RUNNABLE
2022-12-15 19:02:13,992 INFO org.apache.hadoop.yarn.event.AsyncDispatcher: Waiting for AsyncDispatcher to drain. Thread state is :RUNNABLE
2022-12-15 19:02:14,092 INFO org.apache.hadoop.yarn.event.AsyncDispatcher: Waiting for AsyncDispatcher to drain. Thread state is :RUNNABLE
2022-12-15 19:02:14,193 INFO org.apache.hadoop.yarn.event.AsyncDispatcher: Waiting for AsyncDispatcher to drain. Thread state is :RUNNABLE
2022-12-15 19:02:14,293 INFO org.apache.hadoop.yarn.event.AsyncDispatcher: Waiting for AsyncDispatcher to drain. Thread state is :RUNNABLE
2022-12-15 19:02:14,393 INFO org.apache.hadoop.yarn.event.AsyncDispatcher: Waiting for AsyncDispatcher to drain. Thread state is :RUNNABLE
2022-12-15 19:02:14,493 INFO org.apache.hadoop.yarn.event.AsyncDispatcher: Waiting for AsyncDispatcher to drain. Thread state is :RUNNABLE
2022-12-15 19:02:14,594 INFO org.apache.hadoop.yarn.event.AsyncDispatcher: Waiting for AsyncDispatcher to drain. Thread state is :RUNNABLE
2022-12-15 19:02:14,694 INFO org.apache.hadoop.yarn.event.AsyncDispatcher: Waiting for AsyncDispatcher to drain. Thread state is :RUNNABLE
2022-12-15 19:02:14,794 INFO org.apache.hadoop.yarn.event.AsyncDispatcher: Waiting for AsyncDispatcher to drain. Thread state is :RUNNABLE
2022-12-15 19:02:14,894 INFO org.apache.hadoop.yarn.event.AsyncDispatcher: Waiting for AsyncDispatcher to drain. Thread state is :RUNNABLE
2022-12-15 19:02:14,995 INFO org.apache.hadoop.yarn.event.AsyncDispatcher: Waiting for AsyncDispatcher to drain. Thread state is :RUNNABLE
2022-12-15 19:02:15,095 INFO org.apache.hadoop.yarn.event.AsyncDispatcher: Waiting for AsyncDispatcher to drain. Thread state is :RUNNABLE
2022-12-15 19:02:15,195 INFO org.apache.hadoop.yarn.event.AsyncDispatcher: Waiting for AsyncDispatcher to drain. Thread state is :RUNNABLE
2022-12-15 19:02:15,295 INFO org.apache.hadoop.yarn.event.AsyncDispatcher: Waiting for AsyncDispatcher to drain. Thread state is :RUNNABLE
2022-12-15 19:02:15,395 INFO org.apache.hadoop.yarn.event.AsyncDispatcher: Waiting for AsyncDispatcher to drain. Thread state is :RUNNABLE
2022-12-15 19:02:15,496 INFO org.apache.hadoop.yarn.event.AsyncDispatcher: Waiting for AsyncDispatcher to drain. Thread state is :RUNNABLE
2022-12-15 19:02:15,596 INFO org.apache.hadoop.yarn.event.AsyncDispatcher: Waiting for AsyncDispatcher to drain. Thread state is :RUNNABLE
2022-12-15 19:02:15,696 INFO org.apache.hadoop.yarn.event.AsyncDispatcher: Waiting for AsyncDispatcher to drain. Thread state is :RUNNABLE
2022-12-15 19:02:15,796 INFO org.apache.hadoop.yarn.event.AsyncDispatcher: Waiting for AsyncDispatcher to drain. Thread state is :RUNNABLE
2022-12-15 19:02:15,897 INFO org.apache.hadoop.yarn.event.AsyncDispatcher: Waiting for AsyncDispatcher to drain. Thread state is :RUNNABLE
2022-12-15 19:02:15,997 INFO org.apache.hadoop.yarn.event.AsyncDispatcher: Waiting for AsyncDispatcher to drain. Thread state is :RUNNABLE
2022-12-15 19:02:16,097 INFO org.apache.hadoop.yarn.event.AsyncDispatcher: Waiting for AsyncDispatcher to drain. Thread state is :RUNNABLE
2022-12-15 19:02:16,197 INFO org.apache.hadoop.yarn.event.AsyncDispatcher: Waiting for AsyncDispatcher to drain. Thread state is :RUNNABLE
2022-12-15 19:02:16,297 INFO org.apache.hadoop.yarn.event.AsyncDispatcher: Waiting for AsyncDispatcher to drain. Thread state is :RUNNABLE
2022-12-15 19:02:16,398 INFO org.apache.hadoop.yarn.event.AsyncDispatcher: Waiting for AsyncDispatcher to drain. Thread state is :RUNNABLE
2022-12-15 19:02:16,498 INFO org.apache.hadoop.yarn.event.AsyncDispatcher: Waiting for AsyncDispatcher to drain. Thread state is :RUNNABLE
2022-12-15 19:02:16,598 INFO org.apache.hadoop.yarn.event.AsyncDispatcher: Waiting for AsyncDispatcher to drain. Thread state is :RUNNABLE
2022-12-15 19:02:16,698 INFO org.apache.hadoop.yarn.event.AsyncDispatcher: Waiting for AsyncDispatcher to drain. Thread state is :RUNNABLE
2022-12-15 19:02:16,798 INFO org.apache.hadoop.yarn.event.AsyncDispatcher: Waiting for AsyncDispatcher to drain. Thread state is :RUNNABLE
2022-12-15 19:02:16,898 INFO org.apache.hadoop.yarn.event.AsyncDispatcher: Waiting for AsyncDispatcher to drain. Thread state is :RUNNABLE
2022-12-15 19:02:16,999 INFO org.apache.hadoop.yarn.event.AsyncDispatcher: Waiting for AsyncDispatcher to drain. Thread state is :RUNNABLE
2022-12-15 19:02:17,099 INFO org.apache.hadoop.yarn.event.AsyncDispatcher: Waiting for AsyncDispatcher to drain. Thread state is :RUNNABLE
2022-12-15 19:02:17,199 INFO org.apache.hadoop.yarn.event.AsyncDispatcher: Waiting for AsyncDispatcher to drain. Thread state is :RUNNABLE
2022-12-15 19:02:17,299 INFO org.apache.hadoop.yarn.event.AsyncDispatcher: Waiting for AsyncDispatcher to drain. Thread state is :RUNNABLE
2022-12-15 19:02:17,400 INFO org.apache.hadoop.yarn.event.AsyncDispatcher: Waiting for AsyncDispatcher to drain. Thread state is :RUNNABLE
2022-12-15 19:02:17,500 INFO org.apache.hadoop.yarn.event.AsyncDispatcher: Waiting for AsyncDispatcher to drain. Thread state is :RUNNABLE
2022-12-15 19:02:17,600 INFO org.apache.hadoop.yarn.event.AsyncDispatcher: Waiting for AsyncDispatcher to drain. Thread state is :RUNNABLE
2022-12-15 19:02:17,700 INFO org.apache.hadoop.yarn.event.AsyncDispatcher: Waiting for AsyncDispatcher to drain. Thread state is :RUNNABLE
2022-12-15 19:02:17,801 INFO org.apache.hadoop.yarn.event.AsyncDispatcher: Waiting for AsyncDispatcher to drain. Thread state is :RUNNABLE
2022-12-15 19:02:17,901 INFO org.apache.hadoop.yarn.event.AsyncDispatcher: Waiting for AsyncDispatcher to drain. Thread state is :RUNNABLE
2022-12-15 19:02:18,001 INFO org.apache.hadoop.yarn.event.AsyncDispatcher: Waiting for AsyncDispatcher to drain. Thread state is :RUNNABLE
2022-12-15 19:02:18,101 INFO org.apache.hadoop.yarn.event.AsyncDispatcher: Waiting for AsyncDispatcher to drain. Thread state is :RUNNABLE
2022-12-15 19:02:18,202 INFO org.apache.hadoop.yarn.event.AsyncDispatcher: Waiting for AsyncDispatcher to drain. Thread state is :RUNNABLE
2022-12-15 19:02:18,302 INFO org.apache.hadoop.yarn.event.AsyncDispatcher: Waiting for AsyncDispatcher to drain. Thread state is :RUNNABLE
2022-12-15 19:02:18,402 INFO org.apache.hadoop.yarn.event.AsyncDispatcher: Waiting for AsyncDispatcher to drain. Thread state is :RUNNABLE
2022-12-15 19:02:18,502 INFO org.apache.hadoop.yarn.event.AsyncDispatcher: Waiting for AsyncDispatcher to drain. Thread state is :RUNNABLE
2022-12-15 19:02:18,602 INFO org.apache.hadoop.yarn.event.AsyncDispatcher: Waiting for AsyncDispatcher to drain. Thread state is :RUNNABLE
2022-12-15 19:02:18,703 INFO org.apache.hadoop.yarn.event.AsyncDispatcher: Waiting for AsyncDispatcher to drain. Thread state is :RUNNABLE
2022-12-15 19:02:18,803 INFO org.apache.hadoop.yarn.event.AsyncDispatcher: Waiting for AsyncDispatcher to drain. Thread state is :RUNNABLE
2022-12-15 19:02:18,903 INFO org.apache.hadoop.yarn.event.AsyncDispatcher: Waiting for AsyncDispatcher to drain. Thread state is :RUNNABLE
2022-12-15 19:02:19,003 INFO org.apache.hadoop.yarn.event.AsyncDispatcher: Waiting for AsyncDispatcher to drain. Thread state is :RUNNABLE
2022-12-15 19:02:19,103 INFO org.apache.hadoop.yarn.event.AsyncDispatcher: Waiting for AsyncDispatcher to drain. Thread state is :RUNNABLE
2022-12-15 19:02:19,204 INFO org.apache.hadoop.yarn.event.AsyncDispatcher: Waiting for AsyncDispatcher to drain. Thread state is :RUNNABLE
2022-12-15 19:02:19,304 INFO org.apache.hadoop.yarn.event.AsyncDispatcher: Waiting for AsyncDispatcher to drain. Thread state is :RUNNABLE
2022-12-15 19:02:19,404 INFO org.apache.hadoop.yarn.event.AsyncDispatcher: Waiting for AsyncDispatcher to drain. Thread state is :RUNNABLE
2022-12-15 19:02:19,504 INFO org.apache.hadoop.yarn.event.AsyncDispatcher: Waiting for AsyncDispatcher to drain. Thread state is :RUNNABLE
2022-12-15 19:02:19,605 INFO org.apache.hadoop.yarn.event.AsyncDispatcher: Waiting for AsyncDispatcher to drain. Thread state is :RUNNABLE
2022-12-15 19:02:19,705 INFO org.apache.hadoop.yarn.event.AsyncDispatcher: Waiting for AsyncDispatcher to drain. Thread state is :RUNNABLE
2022-12-15 19:02:19,805 INFO org.apache.hadoop.yarn.event.AsyncDispatcher: Waiting for AsyncDispatcher to drain. Thread state is :RUNNABLE
2022-12-15 19:02:19,905 INFO org.apache.hadoop.yarn.event.AsyncDispatcher: Waiting for AsyncDispatcher to drain. Thread state is :RUNNABLE
2022-12-15 19:02:20,006 INFO org.apache.hadoop.yarn.event.AsyncDispatcher: Waiting for AsyncDispatcher to drain. Thread state is :RUNNABLE
2022-12-15 19:02:20,106 INFO org.apache.hadoop.yarn.event.AsyncDispatcher: Waiting for AsyncDispatcher to drain. Thread state is :RUNNABLE
2022-12-15 19:02:20,206 INFO org.apache.hadoop.yarn.event.AsyncDispatcher: Waiting for AsyncDispatcher to drain. Thread state is :RUNNABLE
2022-12-15 19:02:20,306 INFO org.apache.hadoop.yarn.event.AsyncDispatcher: Waiting for AsyncDispatcher to drain. Thread state is :RUNNABLE
2022-12-15 19:02:20,407 INFO org.apache.hadoop.yarn.event.AsyncDispatcher: Waiting for AsyncDispatcher to drain. Thread state is :RUNNABLE
2022-12-15 19:02:20,507 INFO org.apache.hadoop.yarn.event.AsyncDispatcher: Waiting for AsyncDispatcher to drain. Thread state is :RUNNABLE
2022-12-15 19:02:20,607 INFO org.apache.hadoop.yarn.event.AsyncDispatcher: Waiting for AsyncDispatcher to drain. Thread state is :RUNNABLE
2022-12-15 19:02:20,707 INFO org.apache.hadoop.yarn.event.AsyncDispatcher: Waiting for AsyncDispatcher to drain. Thread state is :RUNNABLE
2022-12-15 19:02:20,807 INFO org.apache.hadoop.yarn.event.AsyncDispatcher: Waiting for AsyncDispatcher to drain. Thread state is :RUNNABLE
2022-12-15 19:02:20,908 INFO org.apache.hadoop.yarn.event.AsyncDispatcher: Waiting for AsyncDispatcher to drain. Thread state is :RUNNABLE
2022-12-15 19:02:21,008 INFO org.apache.hadoop.yarn.event.AsyncDispatcher: Waiting for AsyncDispatcher to drain. Thread state is :RUNNABLE
2022-12-15 19:02:21,108 INFO org.apache.hadoop.yarn.event.AsyncDispatcher: Waiting for AsyncDispatcher to drain. Thread state is :RUNNABLE
2022-12-15 19:02:21,208 INFO org.apache.hadoop.yarn.event.AsyncDispatcher: Waiting for AsyncDispatcher to drain. Thread state is :RUNNABLE
2022-12-15 19:02:21,309 INFO org.apache.hadoop.yarn.event.AsyncDispatcher: Waiting for AsyncDispatcher to drain. Thread state is :RUNNABLE
2022-12-15 19:02:21,409 INFO org.apache.hadoop.yarn.event.AsyncDispatcher: Waiting for AsyncDispatcher to drain. Thread state is :RUNNABLE
2022-12-15 19:02:21,509 INFO org.apache.hadoop.yarn.event.AsyncDispatcher: Waiting for AsyncDispatcher to drain. Thread state is :RUNNABLE
2022-12-15 19:02:21,609 INFO org.apache.hadoop.yarn.event.AsyncDispatcher: Waiting for AsyncDispatcher to drain. Thread state is :RUNNABLE
2022-12-15 19:02:21,710 INFO org.apache.hadoop.yarn.event.AsyncDispatcher: Waiting for AsyncDispatcher to drain. Thread state is :RUNNABLE
2022-12-15 19:02:21,810 INFO org.apache.hadoop.yarn.event.AsyncDispatcher: Waiting for AsyncDispatcher to drain. Thread state is :RUNNABLE
2022-12-15 19:02:21,910 INFO org.apache.hadoop.yarn.event.AsyncDispatcher: Waiting for AsyncDispatcher to drain. Thread state is :RUNNABLE
2022-12-15 19:02:22,010 INFO org.apache.hadoop.yarn.event.AsyncDispatcher: Waiting for AsyncDispatcher to drain. Thread state is :RUNNABLE
2022-12-15 19:02:22,111 INFO org.apache.hadoop.yarn.event.AsyncDispatcher: Waiting for AsyncDispatcher to drain. Thread state is :RUNNABLE
2022-12-15 19:02:22,211 INFO org.apache.hadoop.yarn.event.AsyncDispatcher: Waiting for AsyncDispatcher to drain. Thread state is :RUNNABLE
2022-12-15 19:02:22,311 INFO org.apache.hadoop.yarn.event.AsyncDispatcher: Waiting for AsyncDispatcher to drain. Thread state is :RUNNABLE
2022-12-15 19:02:22,411 INFO org.apache.hadoop.yarn.event.AsyncDispatcher: Waiting for AsyncDispatcher to drain. Thread state is :RUNNABLE
2022-12-15 19:02:22,512 INFO org.apache.hadoop.yarn.event.AsyncDispatcher: Waiting for AsyncDispatcher to drain. Thread state is :RUNNABLE
2022-12-15 19:02:22,612 INFO org.apache.hadoop.yarn.event.AsyncDispatcher: Waiting for AsyncDispatcher to drain. Thread state is :RUNNABLE
2022-12-15 19:02:22,712 INFO org.apache.hadoop.yarn.event.AsyncDispatcher: Waiting for AsyncDispatcher to drain. Thread state is :RUNNABLE
2022-12-15 19:02:22,812 INFO org.apache.hadoop.yarn.event.AsyncDispatcher: Waiting for AsyncDispatcher to drain. Thread state is :RUNNABLE
2022-12-15 19:02:22,913 INFO org.apache.hadoop.yarn.event.AsyncDispatcher: Waiting for AsyncDispatcher to drain. Thread state is :RUNNABLE
2022-12-15 19:02:23,013 INFO org.apache.hadoop.yarn.event.AsyncDispatcher: Waiting for AsyncDispatcher to drain. Thread state is :RUNNABLE
2022-12-15 19:02:23,113 INFO org.apache.hadoop.yarn.event.AsyncDispatcher: Waiting for AsyncDispatcher to drain. Thread state is :RUNNABLE
2022-12-15 19:02:23,213 INFO org.apache.hadoop.yarn.event.AsyncDispatcher: Waiting for AsyncDispatcher to drain. Thread state is :RUNNABLE
2022-12-15 19:02:23,314 INFO org.apache.hadoop.yarn.event.AsyncDispatcher: Waiting for AsyncDispatcher to drain. Thread state is :RUNNABLE
2022-12-15 19:02:23,414 INFO org.apache.hadoop.yarn.event.AsyncDispatcher: Waiting for AsyncDispatcher to drain. Thread state is :RUNNABLE
2022-12-15 19:02:23,514 INFO org.apache.hadoop.yarn.event.AsyncDispatcher: Waiting for AsyncDispatcher to drain. Thread state is :RUNNABLE
2022-12-15 19:02:23,614 INFO org.apache.hadoop.yarn.event.AsyncDispatcher: Waiting for AsyncDispatcher to drain. Thread state is :RUNNABLE
2022-12-15 19:02:23,715 INFO org.apache.hadoop.yarn.event.AsyncDispatcher: Waiting for AsyncDispatcher to drain. Thread state is :RUNNABLE
2022-12-15 19:02:23,815 INFO org.apache.hadoop.yarn.event.AsyncDispatcher: Waiting for AsyncDispatcher to drain. Thread state is :RUNNABLE
2022-12-15 19:02:23,915 INFO org.apache.hadoop.yarn.event.AsyncDispatcher: Waiting for AsyncDispatcher to drain. Thread state is :RUNNABLE
2022-12-15 19:02:24,015 INFO org.apache.hadoop.yarn.event.AsyncDispatcher: Waiting for AsyncDispatcher to drain. Thread state is :RUNNABLE
2022-12-15 19:02:24,116 INFO org.apache.hadoop.yarn.event.AsyncDispatcher: Waiting for AsyncDispatcher to drain. Thread state is :RUNNABLE
2022-12-15 19:02:24,216 INFO org.apache.hadoop.yarn.event.AsyncDispatcher: Waiting for AsyncDispatcher to drain. Thread state is :RUNNABLE
2022-12-15 19:02:24,316 INFO org.apache.hadoop.yarn.event.AsyncDispatcher: Waiting for AsyncDispatcher to drain. Thread state is :RUNNABLE
2022-12-15 19:02:24,416 INFO org.apache.hadoop.yarn.event.AsyncDispatcher: Waiting for AsyncDispatcher to drain. Thread state is :RUNNABLE
2022-12-15 19:02:24,516 INFO org.apache.hadoop.yarn.event.AsyncDispatcher: Waiting for AsyncDispatcher to drain. Thread state is :RUNNABLE
2022-12-15 19:02:24,617 INFO org.apache.hadoop.yarn.event.AsyncDispatcher: Waiting for AsyncDispatcher to drain. Thread state is :RUNNABLE
2022-12-15 19:02:24,717 INFO org.apache.hadoop.yarn.event.AsyncDispatcher: Waiting for AsyncDispatcher to drain. Thread state is :RUNNABLE
2022-12-15 19:02:24,817 INFO org.apache.hadoop.yarn.event.AsyncDispatcher: Waiting for AsyncDispatcher to drain. Thread state is :RUNNABLE
2022-12-15 19:02:24,917 INFO org.apache.hadoop.yarn.event.AsyncDispatcher: Waiting for AsyncDispatcher to drain. Thread state is :RUNNABLE
2022-12-15 19:02:25,018 INFO org.apache.hadoop.yarn.event.AsyncDispatcher: Waiting for AsyncDispatcher to drain. Thread state is :RUNNABLE
2022-12-15 19:02:25,118 INFO org.apache.hadoop.yarn.event.AsyncDispatcher: Waiting for AsyncDispatcher to drain. Thread state is :RUNNABLE
2022-12-15 19:02:25,218 INFO org.apache.hadoop.yarn.event.AsyncDispatcher: Waiting for AsyncDispatcher to drain. Thread state is :RUNNABLE
2022-12-15 19:02:25,319 INFO org.apache.hadoop.yarn.event.AsyncDispatcher: Waiting for AsyncDispatcher to drain. Thread state is :RUNNABLE
2022-12-15 19:02:25,419 INFO org.apache.hadoop.yarn.event.AsyncDispatcher: Waiting for AsyncDispatcher to drain. Thread state is :RUNNABLE
2022-12-15 19:02:25,519 INFO org.apache.hadoop.yarn.event.AsyncDispatcher: Waiting for AsyncDispatcher to drain. Thread state is :RUNNABLE
2022-12-15 19:02:25,619 INFO org.apache.hadoop.yarn.event.AsyncDispatcher: Waiting for AsyncDispatcher to drain. Thread state is :RUNNABLE
2022-12-15 19:02:25,719 INFO org.apache.hadoop.yarn.event.AsyncDispatcher: Waiting for AsyncDispatcher to drain. Thread state is :RUNNABLE
2022-12-15 19:02:25,820 INFO org.apache.hadoop.yarn.event.AsyncDispatcher: Waiting for AsyncDispatcher to drain. Thread state is :RUNNABLE
2022-12-15 19:02:25,920 INFO org.apache.hadoop.yarn.event.AsyncDispatcher: Waiting for AsyncDispatcher to drain. Thread state is :RUNNABLE
2022-12-15 19:02:26,020 INFO org.apache.hadoop.yarn.event.AsyncDispatcher: Waiting for AsyncDispatcher to drain. Thread state is :RUNNABLE
2022-12-15 19:02:26,120 INFO org.apache.hadoop.yarn.event.AsyncDispatcher: Waiting for AsyncDispatcher to drain. Thread state is :RUNNABLE
2022-12-15 19:02:26,221 INFO org.apache.hadoop.yarn.event.AsyncDispatcher: Waiting for AsyncDispatcher to drain. Thread state is :RUNNABLE
2022-12-15 19:02:26,321 INFO org.apache.hadoop.yarn.event.AsyncDispatcher: Waiting for AsyncDispatcher to drain. Thread state is :RUNNABLE
2022-12-15 19:02:26,421 INFO org.apache.hadoop.yarn.event.AsyncDispatcher: Waiting for AsyncDispatcher to drain. Thread state is :RUNNABLE
2022-12-15 19:02:26,521 INFO org.apache.hadoop.yarn.event.AsyncDispatcher: Waiting for AsyncDispatcher to drain. Thread state is :RUNNABLE
2022-12-15 19:02:26,621 INFO org.apache.hadoop.yarn.event.AsyncDispatcher: Waiting for AsyncDispatcher to drain. Thread state is :RUNNABLE
2022-12-15 19:02:26,722 INFO org.apache.hadoop.yarn.event.AsyncDispatcher: Waiting for AsyncDispatcher to drain. Thread state is :RUNNABLE
2022-12-15 19:02:26,822 INFO org.apache.hadoop.yarn.event.AsyncDispatcher: Waiting for AsyncDispatcher to drain. Thread state is :RUNNABLE
2022-12-15 19:02:26,922 INFO org.apache.hadoop.yarn.event.AsyncDispatcher: Waiting for AsyncDispatcher to drain. Thread state is :RUNNABLE
2022-12-15 19:02:27,022 INFO org.apache.hadoop.yarn.event.AsyncDispatcher: Waiting for AsyncDispatcher to drain. Thread state is :RUNNABLE
2022-12-15 19:02:27,123 INFO org.apache.hadoop.yarn.event.AsyncDispatcher: Waiting for AsyncDispatcher to drain. Thread state is :RUNNABLE
2022-12-15 19:02:27,223 INFO org.apache.hadoop.yarn.event.AsyncDispatcher: Waiting for AsyncDispatcher to drain. Thread state is :RUNNABLE
2022-12-15 19:02:27,323 INFO org.apache.hadoop.yarn.event.AsyncDispatcher: Waiting for AsyncDispatcher to drain. Thread state is :RUNNABLE
2022-12-15 19:02:27,423 INFO org.apache.hadoop.yarn.event.AsyncDispatcher: Waiting for AsyncDispatcher to drain. Thread state is :RUNNABLE
2022-12-15 19:02:27,524 INFO org.apache.hadoop.yarn.event.AsyncDispatcher: Waiting for AsyncDispatcher to drain. Thread state is :RUNNABLE
2022-12-15 19:02:27,624 INFO org.apache.hadoop.yarn.event.AsyncDispatcher: Waiting for AsyncDispatcher to drain. Thread state is :RUNNABLE
2022-12-15 19:02:27,724 INFO org.apache.hadoop.yarn.event.AsyncDispatcher: Waiting for AsyncDispatcher to drain. Thread state is :RUNNABLE
2022-12-15 19:02:27,824 INFO org.apache.hadoop.yarn.event.AsyncDispatcher: Waiting for AsyncDispatcher to drain. Thread state is :RUNNABLE
2022-12-15 19:02:27,924 INFO org.apache.hadoop.yarn.event.AsyncDispatcher: Waiting for AsyncDispatcher to drain. Thread state is :RUNNABLE
2022-12-15 19:02:28,025 INFO org.apache.hadoop.yarn.event.AsyncDispatcher: Waiting for AsyncDispatcher to drain. Thread state is :RUNNABLE
2022-12-15 19:02:28,125 INFO org.apache.hadoop.yarn.event.AsyncDispatcher: Waiting for AsyncDispatcher to drain. Thread state is :RUNNABLE
2022-12-15 19:02:28,225 INFO org.apache.hadoop.yarn.event.AsyncDispatcher: Waiting for AsyncDispatcher to drain. Thread state is :RUNNABLE
2022-12-15 19:02:28,326 INFO org.apache.hadoop.yarn.event.AsyncDispatcher: Waiting for AsyncDispatcher to drain. Thread state is :RUNNABLE
2022-12-15 19:02:28,426 INFO org.apache.hadoop.yarn.event.AsyncDispatcher: Waiting for AsyncDispatcher to drain. Thread state is :RUNNABLE
2022-12-15 19:02:28,526 INFO org.apache.hadoop.yarn.event.AsyncDispatcher: Waiting for AsyncDispatcher to drain. Thread state is :RUNNABLE
2022-12-15 19:02:28,626 INFO org.apache.hadoop.yarn.event.AsyncDispatcher: Waiting for AsyncDispatcher to drain. Thread state is :RUNNABLE
2022-12-15 19:02:28,726 INFO org.apache.hadoop.yarn.event.AsyncDispatcher: Waiting for AsyncDispatcher to drain. Thread state is :RUNNABLE
2022-12-15 19:02:28,827 INFO org.apache.hadoop.yarn.event.AsyncDispatcher: Waiting for AsyncDispatcher to drain. Thread state is :RUNNABLE
2022-12-15 19:02:28,927 INFO org.apache.hadoop.yarn.event.AsyncDispatcher: Waiting for AsyncDispatcher to drain. Thread state is :RUNNABLE
2022-12-15 19:02:29,027 INFO org.apache.hadoop.yarn.event.AsyncDispatcher: Waiting for AsyncDispatcher to drain. Thread state is :RUNNABLE
2022-12-15 19:02:29,127 INFO org.apache.hadoop.yarn.event.AsyncDispatcher: Waiting for AsyncDispatcher to drain. Thread state is :RUNNABLE
2022-12-15 19:02:29,228 INFO org.apache.hadoop.yarn.event.AsyncDispatcher: Waiting for AsyncDispatcher to drain. Thread state is :RUNNABLE
2022-12-15 19:02:29,328 INFO org.apache.hadoop.yarn.event.AsyncDispatcher: Waiting for AsyncDispatcher to drain. Thread state is :RUNNABLE
2022-12-15 19:02:29,428 INFO org.apache.hadoop.yarn.event.AsyncDispatcher: Waiting for AsyncDispatcher to drain. Thread state is :RUNNABLE
2022-12-15 19:02:29,528 INFO org.apache.hadoop.yarn.event.AsyncDispatcher: Waiting for AsyncDispatcher to drain. Thread state is :RUNNABLE
2022-12-15 19:02:29,629 INFO org.apache.hadoop.yarn.event.AsyncDispatcher: Waiting for AsyncDispatcher to drain. Thread state is :RUNNABLE
2022-12-15 19:02:29,729 INFO org.apache.hadoop.yarn.event.AsyncDispatcher: Waiting for AsyncDispatcher to drain. Thread state is :RUNNABLE
2022-12-15 19:02:29,829 INFO org.apache.hadoop.yarn.event.AsyncDispatcher: Waiting for AsyncDispatcher to drain. Thread state is :RUNNABLE
2022-12-15 19:02:29,929 INFO org.apache.hadoop.yarn.event.AsyncDispatcher: Waiting for AsyncDispatcher to drain. Thread state is :RUNNABLE
2022-12-15 19:02:30,029 INFO org.apache.hadoop.yarn.event.AsyncDispatcher: Waiting for AsyncDispatcher to drain. Thread state is :RUNNABLE
2022-12-15 19:02:30,130 INFO org.apache.hadoop.yarn.event.AsyncDispatcher: Waiting for AsyncDispatcher to drain. Thread state is :RUNNABLE
2022-12-15 19:02:30,230 INFO org.apache.hadoop.yarn.event.AsyncDispatcher: Waiting for AsyncDispatcher to drain. Thread state is :RUNNABLE
2022-12-15 19:02:30,330 INFO org.apache.hadoop.yarn.event.AsyncDispatcher: Waiting for AsyncDispatcher to drain. Thread state is :RUNNABLE
2022-12-15 19:02:30,430 INFO org.apache.hadoop.yarn.event.AsyncDispatcher: Waiting for AsyncDispatcher to drain. Thread state is :RUNNABLE
2022-12-15 19:02:30,531 INFO org.apache.hadoop.yarn.event.AsyncDispatcher: Waiting for AsyncDispatcher to drain. Thread state is :RUNNABLE
2022-12-15 19:02:30,631 INFO org.apache.hadoop.yarn.event.AsyncDispatcher: Waiting for AsyncDispatcher to drain. Thread state is :RUNNABLE
2022-12-15 19:02:30,731 INFO org.apache.hadoop.yarn.event.AsyncDispatcher: Waiting for AsyncDispatcher to drain. Thread state is :RUNNABLE
2022-12-15 19:02:30,831 INFO org.apache.hadoop.yarn.event.AsyncDispatcher: Waiting for AsyncDispatcher to drain. Thread state is :RUNNABLE
2022-12-15 19:02:30,931 INFO org.apache.hadoop.yarn.event.AsyncDispatcher: Waiting for AsyncDispatcher to drain. Thread state is :RUNNABLE
2022-12-15 19:02:31,032 INFO org.apache.hadoop.yarn.event.AsyncDispatcher: Waiting for AsyncDispatcher to drain. Thread state is :RUNNABLE
2022-12-15 19:02:31,132 INFO org.apache.hadoop.yarn.event.AsyncDispatcher: Waiting for AsyncDispatcher to drain. Thread state is :RUNNABLE
2022-12-15 19:02:31,232 INFO org.apache.hadoop.yarn.event.AsyncDispatcher: Waiting for AsyncDispatcher to drain. Thread state is :RUNNABLE
2022-12-15 19:02:31,332 INFO org.apache.hadoop.yarn.event.AsyncDispatcher: Waiting for AsyncDispatcher to drain. Thread state is :RUNNABLE
2022-12-15 19:02:31,432 INFO org.apache.hadoop.yarn.event.AsyncDispatcher: Waiting for AsyncDispatcher to drain. Thread state is :RUNNABLE
2022-12-15 19:02:31,532 INFO org.apache.hadoop.yarn.event.AsyncDispatcher: Waiting for AsyncDispatcher to drain. Thread state is :RUNNABLE
2022-12-15 19:02:31,633 INFO org.apache.hadoop.yarn.event.AsyncDispatcher: Waiting for AsyncDispatcher to drain. Thread state is :RUNNABLE
2022-12-15 19:02:31,733 INFO org.apache.hadoop.yarn.event.AsyncDispatcher: Waiting for AsyncDispatcher to drain. Thread state is :RUNNABLE
2022-12-15 19:02:31,833 INFO org.apache.hadoop.yarn.event.AsyncDispatcher: Waiting for AsyncDispatcher to drain. Thread state is :RUNNABLE
2022-12-15 19:02:31,933 INFO org.apache.hadoop.yarn.event.AsyncDispatcher: Waiting for AsyncDispatcher to drain. Thread state is :RUNNABLE
2022-12-15 19:02:32,033 INFO org.apache.hadoop.yarn.event.AsyncDispatcher: Waiting for AsyncDispatcher to drain. Thread state is :RUNNABLE
2022-12-15 19:02:32,133 INFO org.apache.hadoop.yarn.event.AsyncDispatcher: Waiting for AsyncDispatcher to drain. Thread state is :RUNNABLE
2022-12-15 19:02:32,234 INFO org.apache.hadoop.yarn.event.AsyncDispatcher: Waiting for AsyncDispatcher to drain. Thread state is :RUNNABLE
2022-12-15 19:02:32,334 INFO org.apache.hadoop.yarn.event.AsyncDispatcher: Waiting for AsyncDispatcher to drain. Thread state is :RUNNABLE
2022-12-15 19:02:32,434 INFO org.apache.hadoop.yarn.event.AsyncDispatcher: Waiting for AsyncDispatcher to drain. Thread state is :RUNNABLE
2022-12-15 19:02:32,534 INFO org.apache.hadoop.yarn.event.AsyncDispatcher: Waiting for AsyncDispatcher to drain. Thread state is :RUNNABLE
2022-12-15 19:02:32,634 INFO org.apache.hadoop.yarn.event.AsyncDispatcher: Waiting for AsyncDispatcher to drain. Thread state is :RUNNABLE
2022-12-15 19:02:32,735 INFO org.apache.hadoop.yarn.event.AsyncDispatcher: Waiting for AsyncDispatcher to drain. Thread state is :RUNNABLE
2022-12-15 19:02:32,835 INFO org.apache.hadoop.yarn.event.AsyncDispatcher: Waiting for AsyncDispatcher to drain. Thread state is :RUNNABLE
2022-12-15 19:02:32,935 INFO org.apache.hadoop.yarn.event.AsyncDispatcher: Waiting for AsyncDispatcher to drain. Thread state is :RUNNABLE
2022-12-15 19:02:33,035 INFO org.apache.hadoop.yarn.event.AsyncDispatcher: Waiting for AsyncDispatcher to drain. Thread state is :RUNNABLE
2022-12-15 19:02:33,136 INFO org.apache.hadoop.yarn.event.AsyncDispatcher: Waiting for AsyncDispatcher to drain. Thread state is :RUNNABLE
2022-12-15 19:02:33,236 INFO org.apache.hadoop.yarn.event.AsyncDispatcher: Waiting for AsyncDispatcher to drain. Thread state is :RUNNABLE
2022-12-15 19:02:33,336 INFO org.apache.hadoop.yarn.event.AsyncDispatcher: Waiting for AsyncDispatcher to drain. Thread state is :RUNNABLE
2022-12-15 19:02:33,436 INFO org.apache.hadoop.yarn.event.AsyncDispatcher: Waiting for AsyncDispatcher to drain. Thread state is :RUNNABLE
2022-12-15 19:02:33,537 INFO org.apache.hadoop.yarn.event.AsyncDispatcher: Waiting for AsyncDispatcher to drain. Thread state is :RUNNABLE
2022-12-15 19:02:33,637 INFO org.apache.hadoop.yarn.event.AsyncDispatcher: Waiting for AsyncDispatcher to drain. Thread state is :RUNNABLE
2022-12-15 19:02:33,737 INFO org.apache.hadoop.yarn.event.AsyncDispatcher: Waiting for AsyncDispatcher to drain. Thread state is :RUNNABLE
2022-12-15 19:02:33,837 INFO org.apache.hadoop.yarn.event.AsyncDispatcher: Waiting for AsyncDispatcher to drain. Thread state is :RUNNABLE
2022-12-15 19:02:33,937 INFO org.apache.hadoop.yarn.event.AsyncDispatcher: Waiting for AsyncDispatcher to drain. Thread state is :RUNNABLE
2022-12-15 19:02:34,038 INFO org.apache.hadoop.yarn.event.AsyncDispatcher: Waiting for AsyncDispatcher to drain. Thread state is :RUNNABLE
2022-12-15 19:02:34,138 INFO org.apache.hadoop.yarn.event.AsyncDispatcher: Waiting for AsyncDispatcher to drain. Thread state is :RUNNABLE
2022-12-15 19:02:34,238 INFO org.apache.hadoop.yarn.event.AsyncDispatcher: Waiting for AsyncDispatcher to drain. Thread state is :RUNNABLE
2022-12-15 19:02:34,338 INFO org.apache.hadoop.yarn.event.AsyncDispatcher: Waiting for AsyncDispatcher to drain. Thread state is :RUNNABLE
2022-12-15 19:02:34,439 INFO org.apache.hadoop.yarn.event.AsyncDispatcher: Waiting for AsyncDispatcher to drain. Thread state is :RUNNABLE
2022-12-15 19:02:34,539 INFO org.apache.hadoop.yarn.event.AsyncDispatcher: Waiting for AsyncDispatcher to drain. Thread state is :RUNNABLE
2022-12-15 19:02:34,639 INFO org.apache.hadoop.yarn.event.AsyncDispatcher: Waiting for AsyncDispatcher to drain. Thread state is :RUNNABLE
2022-12-15 19:02:34,739 INFO org.apache.hadoop.yarn.event.AsyncDispatcher: Waiting for AsyncDispatcher to drain. Thread state is :RUNNABLE
2022-12-15 19:02:34,840 INFO org.apache.hadoop.yarn.event.AsyncDispatcher: Waiting for AsyncDispatcher to drain. Thread state is :RUNNABLE
2022-12-15 19:02:34,940 INFO org.apache.hadoop.yarn.event.AsyncDispatcher: Waiting for AsyncDispatcher to drain. Thread state is :RUNNABLE
2022-12-15 19:02:35,040 INFO org.apache.hadoop.yarn.event.AsyncDispatcher: Waiting for AsyncDispatcher to drain. Thread state is :RUNNABLE
2022-12-15 19:02:35,140 INFO org.apache.hadoop.yarn.event.AsyncDispatcher: Waiting for AsyncDispatcher to drain. Thread state is :RUNNABLE
2022-12-15 19:02:35,240 INFO org.apache.hadoop.yarn.event.AsyncDispatcher: Waiting for AsyncDispatcher to drain. Thread state is :RUNNABLE
2022-12-15 19:02:35,341 INFO org.apache.hadoop.yarn.event.AsyncDispatcher: Waiting for AsyncDispatcher to drain. Thread state is :RUNNABLE
2022-12-15 19:02:35,441 INFO org.apache.hadoop.yarn.event.AsyncDispatcher: Waiting for AsyncDispatcher to drain. Thread state is :RUNNABLE
2022-12-15 19:02:35,541 INFO org.apache.hadoop.yarn.event.AsyncDispatcher: Waiting for AsyncDispatcher to drain. Thread state is :RUNNABLE
2022-12-15 19:02:35,641 INFO org.apache.hadoop.yarn.event.AsyncDispatcher: Waiting for AsyncDispatcher to drain. Thread state is :RUNNABLE
2022-12-15 19:02:35,742 INFO org.apache.hadoop.yarn.event.AsyncDispatcher: Waiting for AsyncDispatcher to drain. Thread state is :RUNNABLE
2022-12-15 19:02:35,842 INFO org.apache.hadoop.yarn.event.AsyncDispatcher: Waiting for AsyncDispatcher to drain. Thread state is :RUNNABLE
2022-12-15 19:02:35,942 INFO org.apache.hadoop.yarn.event.AsyncDispatcher: Waiting for AsyncDispatcher to drain. Thread state is :RUNNABLE
2022-12-15 19:02:36,042 INFO org.apache.hadoop.yarn.event.AsyncDispatcher: Waiting for AsyncDispatcher to drain. Thread state is :RUNNABLE
2022-12-15 19:02:36,142 INFO org.apache.hadoop.yarn.event.AsyncDispatcher: Waiting for AsyncDispatcher to drain. Thread state is :RUNNABLE
2022-12-15 19:02:36,243 INFO org.apache.hadoop.yarn.event.AsyncDispatcher: Waiting for AsyncDispatcher to drain. Thread state is :RUNNABLE
2022-12-15 19:02:36,343 INFO org.apache.hadoop.yarn.event.AsyncDispatcher: Waiting for AsyncDispatcher to drain. Thread state is :RUNNABLE
2022-12-15 19:02:36,443 INFO org.apache.hadoop.yarn.event.AsyncDispatcher: Waiting for AsyncDispatcher to drain. Thread state is :RUNNABLE
2022-12-15 19:02:36,543 INFO org.apache.hadoop.yarn.event.AsyncDispatcher: Waiting for AsyncDispatcher to drain. Thread state is :RUNNABLE
2022-12-15 19:02:36,644 INFO org.apache.hadoop.yarn.event.AsyncDispatcher: Waiting for AsyncDispatcher to drain. Thread state is :RUNNABLE
2022-12-15 19:02:36,744 INFO org.apache.hadoop.yarn.event.AsyncDispatcher: Waiting for AsyncDispatcher to drain. Thread state is :RUNNABLE
2022-12-15 19:02:36,844 INFO org.apache.hadoop.yarn.event.AsyncDispatcher: Waiting for AsyncDispatcher to drain. Thread state is :RUNNABLE
2022-12-15 19:02:36,944 INFO org.apache.hadoop.yarn.event.AsyncDispatcher: Waiting for AsyncDispatcher to drain. Thread state is :RUNNABLE
2022-12-15 19:02:37,044 INFO org.apache.hadoop.yarn.event.AsyncDispatcher: Waiting for AsyncDispatcher to drain. Thread state is :RUNNABLE
2022-12-15 19:02:37,144 INFO org.apache.hadoop.yarn.event.AsyncDispatcher: Waiting for AsyncDispatcher to drain. Thread state is :RUNNABLE
2022-12-15 19:02:37,245 INFO org.apache.hadoop.yarn.event.AsyncDispatcher: Waiting for AsyncDispatcher to drain. Thread state is :RUNNABLE
2022-12-15 19:02:37,345 INFO org.apache.hadoop.yarn.event.AsyncDispatcher: Waiting for AsyncDispatcher to drain. Thread state is :RUNNABLE
2022-12-15 19:02:37,445 INFO org.apache.hadoop.yarn.event.AsyncDispatcher: Waiting for AsyncDispatcher to drain. Thread state is :RUNNABLE
2022-12-15 19:02:37,545 INFO org.apache.hadoop.yarn.event.AsyncDispatcher: Waiting for AsyncDispatcher to drain. Thread state is :RUNNABLE
2022-12-15 19:02:37,645 INFO org.apache.hadoop.yarn.event.AsyncDispatcher: Waiting for AsyncDispatcher to drain. Thread state is :RUNNABLE
2022-12-15 19:02:37,746 INFO org.apache.hadoop.yarn.event.AsyncDispatcher: Waiting for AsyncDispatcher to drain. Thread state is :RUNNABLE
2022-12-15 19:02:37,846 INFO org.apache.hadoop.yarn.event.AsyncDispatcher: Waiting for AsyncDispatcher to drain. Thread state is :RUNNABLE
2022-12-15 19:02:37,946 INFO org.apache.hadoop.yarn.event.AsyncDispatcher: Waiting for AsyncDispatcher to drain. Thread state is :RUNNABLE
2022-12-15 19:02:38,046 INFO org.apache.hadoop.yarn.event.AsyncDispatcher: Waiting for AsyncDispatcher to drain. Thread state is :RUNNABLE
2022-12-15 19:02:38,147 INFO org.apache.hadoop.yarn.event.AsyncDispatcher: Waiting for AsyncDispatcher to drain. Thread state is :RUNNABLE
2022-12-15 19:02:38,247 INFO org.apache.hadoop.yarn.event.AsyncDispatcher: Waiting for AsyncDispatcher to drain. Thread state is :RUNNABLE
2022-12-15 19:02:38,347 INFO org.apache.hadoop.yarn.event.AsyncDispatcher: Waiting for AsyncDispatcher to drain. Thread state is :RUNNABLE
2022-12-15 19:02:38,448 INFO org.apache.hadoop.yarn.event.AsyncDispatcher: Waiting for AsyncDispatcher to drain. Thread state is :RUNNABLE
2022-12-15 19:02:38,548 INFO org.apache.hadoop.yarn.event.AsyncDispatcher: Waiting for AsyncDispatcher to drain. Thread state is :RUNNABLE
2022-12-15 19:02:38,648 INFO org.apache.hadoop.yarn.event.AsyncDispatcher: Waiting for AsyncDispatcher to drain. Thread state is :RUNNABLE
2022-12-15 19:02:38,749 INFO org.apache.hadoop.yarn.event.AsyncDispatcher: Waiting for AsyncDispatcher to drain. Thread state is :RUNNABLE
2022-12-15 19:02:38,849 INFO org.apache.hadoop.yarn.event.AsyncDispatcher: Waiting for AsyncDispatcher to drain. Thread state is :RUNNABLE
2022-12-15 19:02:38,949 INFO org.apache.hadoop.yarn.event.AsyncDispatcher: Waiting for AsyncDispatcher to drain. Thread state is :RUNNABLE
2022-12-15 19:02:39,049 INFO org.apache.hadoop.yarn.event.AsyncDispatcher: Waiting for AsyncDispatcher to drain. Thread state is :RUNNABLE
2022-12-15 19:02:39,150 INFO org.apache.hadoop.yarn.event.AsyncDispatcher: Waiting for AsyncDispatcher to drain. Thread state is :RUNNABLE
2022-12-15 19:02:39,250 INFO org.apache.hadoop.yarn.event.AsyncDispatcher: Waiting for AsyncDispatcher to drain. Thread state is :RUNNABLE
2022-12-15 19:02:39,350 INFO org.apache.hadoop.yarn.event.AsyncDispatcher: Waiting for AsyncDispatcher to drain. Thread state is :RUNNABLE
2022-12-15 19:02:39,450 INFO org.apache.hadoop.yarn.event.AsyncDispatcher: Waiting for AsyncDispatcher to drain. Thread state is :RUNNABLE
2022-12-15 19:02:39,551 INFO org.apache.hadoop.yarn.event.AsyncDispatcher: Waiting for AsyncDispatcher to drain. Thread state is :RUNNABLE
2022-12-15 19:02:39,651 INFO org.apache.hadoop.yarn.event.AsyncDispatcher: Waiting for AsyncDispatcher to drain. Thread state is :RUNNABLE
2022-12-15 19:02:39,751 INFO org.apache.hadoop.yarn.event.AsyncDispatcher: Waiting for AsyncDispatcher to drain. Thread state is :RUNNABLE
2022-12-15 19:02:39,851 INFO org.apache.hadoop.yarn.event.AsyncDispatcher: Waiting for AsyncDispatcher to drain. Thread state is :RUNNABLE
2022-12-15 19:02:39,951 INFO org.apache.hadoop.yarn.event.AsyncDispatcher: Waiting for AsyncDispatcher to drain. Thread state is :RUNNABLE
2022-12-15 19:02:40,051 INFO org.apache.hadoop.yarn.event.AsyncDispatcher: Waiting for AsyncDispatcher to drain. Thread state is :RUNNABLE
2022-12-15 19:02:40,152 INFO org.apache.hadoop.yarn.event.AsyncDispatcher: Waiting for AsyncDispatcher to drain. Thread state is :RUNNABLE
2022-12-15 19:02:40,252 INFO org.apache.hadoop.yarn.event.AsyncDispatcher: Waiting for AsyncDispatcher to drain. Thread state is :RUNNABLE
2022-12-15 19:02:40,352 INFO org.apache.hadoop.yarn.event.AsyncDispatcher: Waiting for AsyncDispatcher to drain. Thread state is :RUNNABLE
2022-12-15 19:02:40,452 INFO org.apache.hadoop.yarn.event.AsyncDispatcher: Waiting for AsyncDispatcher to drain. Thread state is :RUNNABLE
2022-12-15 19:02:40,552 INFO org.apache.hadoop.yarn.event.AsyncDispatcher: Waiting for AsyncDispatcher to drain. Thread state is :RUNNABLE
2022-12-15 19:02:40,653 INFO org.apache.hadoop.yarn.event.AsyncDispatcher: Waiting for AsyncDispatcher to drain. Thread state is :RUNNABLE
2022-12-15 19:02:40,753 INFO org.apache.hadoop.yarn.event.AsyncDispatcher: Waiting for AsyncDispatcher to drain. Thread state is :RUNNABLE
2022-12-15 19:02:40,853 INFO org.apache.hadoop.yarn.event.AsyncDispatcher: Waiting for AsyncDispatcher to drain. Thread state is :RUNNABLE
2022-12-15 19:02:40,953 INFO org.apache.hadoop.yarn.event.AsyncDispatcher: Waiting for AsyncDispatcher to drain. Thread state is :RUNNABLE
2022-12-15 19:02:41,053 INFO org.apache.hadoop.yarn.event.AsyncDispatcher: Waiting for AsyncDispatcher to drain. Thread state is :RUNNABLE
2022-12-15 19:02:41,154 INFO org.apache.hadoop.yarn.event.AsyncDispatcher: Waiting for AsyncDispatcher to drain. Thread state is :RUNNABLE
2022-12-15 19:02:41,254 INFO org.apache.hadoop.yarn.event.AsyncDispatcher: Waiting for AsyncDispatcher to drain. Thread state is :RUNNABLE
2022-12-15 19:02:41,354 INFO org.apache.hadoop.yarn.event.AsyncDispatcher: Waiting for AsyncDispatcher to drain. Thread state is :RUNNABLE
2022-12-15 19:02:41,454 INFO org.apache.hadoop.yarn.event.AsyncDispatcher: Waiting for AsyncDispatcher to drain. Thread state is :RUNNABLE
2022-12-15 19:02:41,555 INFO org.apache.hadoop.yarn.event.AsyncDispatcher: Waiting for AsyncDispatcher to drain. Thread state is :RUNNABLE
2022-12-15 19:02:41,655 INFO org.apache.hadoop.yarn.event.AsyncDispatcher: Waiting for AsyncDispatcher to drain. Thread state is :RUNNABLE
2022-12-15 19:02:41,755 INFO org.apache.hadoop.yarn.event.AsyncDispatcher: Waiting for AsyncDispatcher to drain. Thread state is :RUNNABLE
2022-12-15 19:02:41,855 INFO org.apache.hadoop.yarn.event.AsyncDispatcher: Waiting for AsyncDispatcher to drain. Thread state is :RUNNABLE
2022-12-15 19:02:41,956 INFO org.apache.hadoop.yarn.event.AsyncDispatcher: Waiting for AsyncDispatcher to drain. Thread state is :RUNNABLE
2022-12-15 19:02:42,056 INFO org.apache.hadoop.yarn.event.AsyncDispatcher: Waiting for AsyncDispatcher to drain. Thread state is :RUNNABLE
2022-12-15 19:02:42,156 INFO org.apache.hadoop.yarn.event.AsyncDispatcher: Waiting for AsyncDispatcher to drain. Thread state is :RUNNABLE
2022-12-15 19:02:42,256 INFO org.apache.hadoop.yarn.event.AsyncDispatcher: Waiting for AsyncDispatcher to drain. Thread state is :RUNNABLE
2022-12-15 19:02:42,356 INFO org.apache.hadoop.yarn.event.AsyncDispatcher: Waiting for AsyncDispatcher to drain. Thread state is :RUNNABLE
2022-12-15 19:02:42,457 INFO org.apache.hadoop.yarn.event.AsyncDispatcher: Waiting for AsyncDispatcher to drain. Thread state is :RUNNABLE
2022-12-15 19:02:42,557 INFO org.apache.hadoop.yarn.event.AsyncDispatcher: Waiting for AsyncDispatcher to drain. Thread state is :RUNNABLE
2022-12-15 19:02:42,657 INFO org.apache.hadoop.yarn.event.AsyncDispatcher: Waiting for AsyncDispatcher to drain. Thread state is :RUNNABLE
2022-12-15 19:02:42,757 INFO org.apache.hadoop.yarn.event.AsyncDispatcher: Waiting for AsyncDispatcher to drain. Thread state is :RUNNABLE
2022-12-15 19:02:42,858 INFO org.apache.hadoop.yarn.event.AsyncDispatcher: Waiting for AsyncDispatcher to drain. Thread state is :RUNNABLE
2022-12-15 19:02:42,958 INFO org.apache.hadoop.yarn.event.AsyncDispatcher: Waiting for AsyncDispatcher to drain. Thread state is :RUNNABLE
2022-12-15 19:02:43,058 INFO org.apache.hadoop.yarn.event.AsyncDispatcher: Waiting for AsyncDispatcher to drain. Thread state is :RUNNABLE
2022-12-15 19:02:43,158 INFO org.apache.hadoop.yarn.event.AsyncDispatcher: Waiting for AsyncDispatcher to drain. Thread state is :RUNNABLE
2022-12-15 19:02:43,259 INFO org.apache.hadoop.yarn.event.AsyncDispatcher: Waiting for AsyncDispatcher to drain. Thread state is :RUNNABLE
2022-12-15 19:02:43,359 INFO org.apache.hadoop.yarn.event.AsyncDispatcher: Waiting for AsyncDispatcher to drain. Thread state is :RUNNABLE
2022-12-15 19:02:43,459 INFO org.apache.hadoop.yarn.event.AsyncDispatcher: Waiting for AsyncDispatcher to drain. Thread state is :RUNNABLE
2022-12-15 19:02:43,559 INFO org.apache.hadoop.yarn.event.AsyncDispatcher: Waiting for AsyncDispatcher to drain. Thread state is :RUNNABLE
2022-12-15 19:02:43,660 INFO org.apache.hadoop.yarn.event.AsyncDispatcher: Waiting for AsyncDispatcher to drain. Thread state is :RUNNABLE
2022-12-15 19:02:43,760 INFO org.apache.hadoop.yarn.event.AsyncDispatcher: Waiting for AsyncDispatcher to drain. Thread state is :RUNNABLE
2022-12-15 19:02:43,860 INFO org.apache.hadoop.yarn.event.AsyncDispatcher: Waiting for AsyncDispatcher to drain. Thread state is :RUNNABLE
2022-12-15 19:02:43,960 INFO org.apache.hadoop.yarn.event.AsyncDispatcher: Waiting for AsyncDispatcher to drain. Thread state is :RUNNABLE
2022-12-15 19:02:44,060 INFO org.apache.hadoop.yarn.event.AsyncDispatcher: Waiting for AsyncDispatcher to drain. Thread state is :RUNNABLE
2022-12-15 19:02:44,161 INFO org.apache.hadoop.yarn.event.AsyncDispatcher: Waiting for AsyncDispatcher to drain. Thread state is :RUNNABLE
2022-12-15 19:02:44,261 INFO org.apache.hadoop.yarn.event.AsyncDispatcher: Waiting for AsyncDispatcher to drain. Thread state is :RUNNABLE
2022-12-15 19:02:44,361 INFO org.apache.hadoop.yarn.event.AsyncDispatcher: Waiting for AsyncDispatcher to drain. Thread state is :RUNNABLE
2022-12-15 19:02:44,461 INFO org.apache.hadoop.yarn.event.AsyncDispatcher: Waiting for AsyncDispatcher to drain. Thread state is :RUNNABLE
2022-12-15 19:02:44,562 INFO org.apache.hadoop.yarn.event.AsyncDispatcher: Waiting for AsyncDispatcher to drain. Thread state is :RUNNABLE
2022-12-15 19:02:44,662 INFO org.apache.hadoop.yarn.event.AsyncDispatcher: Waiting for AsyncDispatcher to drain. Thread state is :RUNNABLE
2022-12-15 19:02:44,762 INFO org.apache.hadoop.yarn.event.AsyncDispatcher: Waiting for AsyncDispatcher to drain. Thread state is :RUNNABLE
2022-12-15 19:02:44,862 INFO org.apache.hadoop.yarn.event.AsyncDispatcher: Waiting for AsyncDispatcher to drain. Thread state is :RUNNABLE
2022-12-15 19:02:44,962 INFO org.apache.hadoop.yarn.event.AsyncDispatcher: Waiting for AsyncDispatcher to drain. Thread state is :RUNNABLE
2022-12-15 19:02:45,063 INFO org.apache.hadoop.yarn.event.AsyncDispatcher: Waiting for AsyncDispatcher to drain. Thread state is :RUNNABLE
2022-12-15 19:02:45,163 INFO org.apache.hadoop.yarn.event.AsyncDispatcher: Waiting for AsyncDispatcher to drain. Thread state is :RUNNABLE
2022-12-15 19:02:45,263 INFO org.apache.hadoop.yarn.event.AsyncDispatcher: Waiting for AsyncDispatcher to drain. Thread state is :RUNNABLE
2022-12-15 19:02:45,363 INFO org.apache.hadoop.yarn.event.AsyncDispatcher: Waiting for AsyncDispatcher to drain. Thread state is :RUNNABLE
2022-12-15 19:02:45,464 INFO org.apache.hadoop.yarn.event.AsyncDispatcher: Waiting for AsyncDispatcher to drain. Thread state is :RUNNABLE
2022-12-15 19:02:45,564 INFO org.apache.hadoop.yarn.event.AsyncDispatcher: Waiting for AsyncDispatcher to drain. Thread state is :RUNNABLE
2022-12-15 19:02:45,664 INFO org.apache.hadoop.yarn.event.AsyncDispatcher: Waiting for AsyncDispatcher to drain. Thread state is :RUNNABLE
2022-12-15 19:02:45,764 INFO org.apache.hadoop.yarn.event.AsyncDispatcher: Waiting for AsyncDispatcher to drain. Thread state is :RUNNABLE
2022-12-15 19:02:45,865 INFO org.apache.hadoop.yarn.event.AsyncDispatcher: Waiting for AsyncDispatcher to drain. Thread state is :RUNNABLE
2022-12-15 19:02:45,965 INFO org.apache.hadoop.yarn.event.AsyncDispatcher: Waiting for AsyncDispatcher to drain. Thread state is :RUNNABLE
2022-12-15 19:02:46,065 INFO org.apache.hadoop.yarn.event.AsyncDispatcher: Waiting for AsyncDispatcher to drain. Thread state is :RUNNABLE
2022-12-15 19:02:46,165 INFO org.apache.hadoop.yarn.event.AsyncDispatcher: Waiting for AsyncDispatcher to drain. Thread state is :RUNNABLE
2022-12-15 19:02:46,265 INFO org.apache.hadoop.yarn.event.AsyncDispatcher: Waiting for AsyncDispatcher to drain. Thread state is :RUNNABLE
2022-12-15 19:02:46,366 INFO org.apache.hadoop.yarn.event.AsyncDispatcher: Waiting for AsyncDispatcher to drain. Thread state is :RUNNABLE
2022-12-15 19:02:46,466 INFO org.apache.hadoop.yarn.event.AsyncDispatcher: Waiting for AsyncDispatcher to drain. Thread state is :RUNNABLE
2022-12-15 19:02:46,566 INFO org.apache.hadoop.yarn.event.AsyncDispatcher: Waiting for AsyncDispatcher to drain. Thread state is :RUNNABLE
2022-12-15 19:02:46,666 INFO org.apache.hadoop.yarn.event.AsyncDispatcher: Waiting for AsyncDispatcher to drain. Thread state is :RUNNABLE
2022-12-15 19:02:46,766 INFO org.apache.hadoop.yarn.event.AsyncDispatcher: Waiting for AsyncDispatcher to drain. Thread state is :RUNNABLE
2022-12-15 19:02:46,866 INFO org.apache.hadoop.yarn.event.AsyncDispatcher: Waiting for AsyncDispatcher to drain. Thread state is :RUNNABLE
2022-12-15 19:02:46,967 INFO org.apache.hadoop.yarn.event.AsyncDispatcher: Waiting for AsyncDispatcher to drain. Thread state is :RUNNABLE
2022-12-15 19:02:47,067 INFO org.apache.hadoop.yarn.event.AsyncDispatcher: Waiting for AsyncDispatcher to drain. Thread state is :RUNNABLE
2022-12-15 19:02:47,167 INFO org.apache.hadoop.yarn.event.AsyncDispatcher: Waiting for AsyncDispatcher to drain. Thread state is :RUNNABLE
2022-12-15 19:02:47,267 INFO org.apache.hadoop.yarn.event.AsyncDispatcher: Waiting for AsyncDispatcher to drain. Thread state is :RUNNABLE
2022-12-15 19:02:47,367 INFO org.apache.hadoop.yarn.event.AsyncDispatcher: Waiting for AsyncDispatcher to drain. Thread state is :RUNNABLE
2022-12-15 19:02:47,468 INFO org.apache.hadoop.yarn.event.AsyncDispatcher: Waiting for AsyncDispatcher to drain. Thread state is :RUNNABLE
2022-12-15 19:02:47,568 INFO org.apache.hadoop.yarn.event.AsyncDispatcher: Waiting for AsyncDispatcher to drain. Thread state is :RUNNABLE
2022-12-15 19:02:47,668 INFO org.apache.hadoop.yarn.event.AsyncDispatcher: Waiting for AsyncDispatcher to drain. Thread state is :RUNNABLE
2022-12-15 19:02:47,768 INFO org.apache.hadoop.yarn.event.AsyncDispatcher: Waiting for AsyncDispatcher to drain. Thread state is :RUNNABLE
2022-12-15 19:02:47,869 INFO org.apache.hadoop.yarn.event.AsyncDispatcher: Waiting for AsyncDispatcher to drain. Thread state is :RUNNABLE
2022-12-15 19:02:47,969 INFO org.apache.hadoop.yarn.event.AsyncDispatcher: Waiting for AsyncDispatcher to drain. Thread state is :RUNNABLE
2022-12-15 19:02:48,069 INFO org.apache.hadoop.yarn.event.AsyncDispatcher: Waiting for AsyncDispatcher to drain. Thread state is :RUNNABLE
2022-12-15 19:02:48,169 INFO org.apache.hadoop.yarn.event.AsyncDispatcher: Waiting for AsyncDispatcher to drain. Thread state is :RUNNABLE
2022-12-15 19:02:48,270 INFO org.apache.hadoop.yarn.event.AsyncDispatcher: Waiting for AsyncDispatcher to drain. Thread state is :RUNNABLE
2022-12-15 19:02:48,370 INFO org.apache.hadoop.yarn.event.AsyncDispatcher: Waiting for AsyncDispatcher to drain. Thread state is :RUNNABLE
2022-12-15 19:02:48,470 INFO org.apache.hadoop.yarn.event.AsyncDispatcher: Waiting for AsyncDispatcher to drain. Thread state is :RUNNABLE
2022-12-15 19:02:48,570 INFO org.apache.hadoop.yarn.event.AsyncDispatcher: Waiting for AsyncDispatcher to drain. Thread state is :RUNNABLE
2022-12-15 19:02:48,671 INFO org.apache.hadoop.yarn.event.AsyncDispatcher: Waiting for AsyncDispatcher to drain. Thread state is :RUNNABLE
2022-12-15 19:02:48,771 INFO org.apache.hadoop.yarn.event.AsyncDispatcher: Waiting for AsyncDispatcher to drain. Thread state is :RUNNABLE
2022-12-15 19:02:48,871 INFO org.apache.hadoop.yarn.event.AsyncDispatcher: Waiting for AsyncDispatcher to drain. Thread state is :RUNNABLE
2022-12-15 19:02:48,971 INFO org.apache.hadoop.yarn.event.AsyncDispatcher: Waiting for AsyncDispatcher to drain. Thread state is :RUNNABLE
2022-12-15 19:02:49,072 INFO org.apache.hadoop.yarn.event.AsyncDispatcher: Waiting for AsyncDispatcher to drain. Thread state is :RUNNABLE
2022-12-15 19:02:49,172 INFO org.apache.hadoop.yarn.event.AsyncDispatcher: Waiting for AsyncDispatcher to drain. Thread state is :RUNNABLE
2022-12-15 19:02:49,272 INFO org.apache.hadoop.yarn.event.AsyncDispatcher: Waiting for AsyncDispatcher to drain. Thread state is :RUNNABLE
2022-12-15 19:02:49,372 INFO org.apache.hadoop.yarn.event.AsyncDispatcher: Waiting for AsyncDispatcher to drain. Thread state is :RUNNABLE
2022-12-15 19:02:49,472 INFO org.apache.hadoop.yarn.event.AsyncDispatcher: Waiting for AsyncDispatcher to drain. Thread state is :RUNNABLE
2022-12-15 19:02:49,573 INFO org.apache.hadoop.yarn.event.AsyncDispatcher: Waiting for AsyncDispatcher to drain. Thread state is :RUNNABLE
2022-12-15 19:02:49,673 INFO org.apache.hadoop.yarn.event.AsyncDispatcher: Waiting for AsyncDispatcher to drain. Thread state is :RUNNABLE
2022-12-15 19:02:49,773 INFO org.apache.hadoop.yarn.event.AsyncDispatcher: Waiting for AsyncDispatcher to drain. Thread state is :RUNNABLE
2022-12-15 19:02:49,873 INFO org.apache.hadoop.yarn.event.AsyncDispatcher: Waiting for AsyncDispatcher to drain. Thread state is :RUNNABLE
2022-12-15 19:02:49,974 INFO org.apache.hadoop.yarn.event.AsyncDispatcher: Waiting for AsyncDispatcher to drain. Thread state is :RUNNABLE
2022-12-15 19:02:50,074 INFO org.apache.hadoop.yarn.event.AsyncDispatcher: Waiting for AsyncDispatcher to drain. Thread state is :RUNNABLE
2022-12-15 19:02:50,174 INFO org.apache.hadoop.yarn.event.AsyncDispatcher: Waiting for AsyncDispatcher to drain. Thread state is :RUNNABLE
2022-12-15 19:02:50,274 INFO org.apache.hadoop.yarn.event.AsyncDispatcher: Waiting for AsyncDispatcher to drain. Thread state is :RUNNABLE
2022-12-15 19:02:50,375 INFO org.apache.hadoop.yarn.event.AsyncDispatcher: Waiting for AsyncDispatcher to drain. Thread state is :RUNNABLE
2022-12-15 19:02:50,475 INFO org.apache.hadoop.yarn.event.AsyncDispatcher: Waiting for AsyncDispatcher to drain. Thread state is :RUNNABLE
2022-12-15 19:02:50,575 INFO org.apache.hadoop.yarn.event.AsyncDispatcher: Waiting for AsyncDispatcher to drain. Thread state is :RUNNABLE
2022-12-15 19:02:50,675 INFO org.apache.hadoop.yarn.event.AsyncDispatcher: Waiting for AsyncDispatcher to drain. Thread state is :RUNNABLE
2022-12-15 19:02:50,775 INFO org.apache.hadoop.yarn.event.AsyncDispatcher: Waiting for AsyncDispatcher to drain. Thread state is :RUNNABLE
2022-12-15 19:02:50,876 INFO org.apache.hadoop.yarn.event.AsyncDispatcher: Waiting for AsyncDispatcher to drain. Thread state is :RUNNABLE
2022-12-15 19:02:50,976 INFO org.apache.hadoop.yarn.event.AsyncDispatcher: Waiting for AsyncDispatcher to drain. Thread state is :RUNNABLE
2022-12-15 19:02:51,076 INFO org.apache.hadoop.yarn.event.AsyncDispatcher: Waiting for AsyncDispatcher to drain. Thread state is :RUNNABLE
2022-12-15 19:02:51,176 INFO org.apache.hadoop.yarn.event.AsyncDispatcher: Waiting for AsyncDispatcher to drain. Thread state is :RUNNABLE
2022-12-15 19:02:51,277 INFO org.apache.hadoop.yarn.event.AsyncDispatcher: Waiting for AsyncDispatcher to drain. Thread state is :RUNNABLE
2022-12-15 19:02:51,377 INFO org.apache.hadoop.yarn.event.AsyncDispatcher: Waiting for AsyncDispatcher to drain. Thread state is :RUNNABLE
2022-12-15 19:02:51,477 INFO org.apache.hadoop.yarn.event.AsyncDispatcher: Waiting for AsyncDispatcher to drain. Thread state is :RUNNABLE
2022-12-15 19:02:51,577 INFO org.apache.hadoop.yarn.event.AsyncDispatcher: Waiting for AsyncDispatcher to drain. Thread state is :RUNNABLE
2022-12-15 19:02:51,678 INFO org.apache.hadoop.yarn.event.AsyncDispatcher: Waiting for AsyncDispatcher to drain. Thread state is :RUNNABLE
2022-12-15 19:02:51,778 INFO org.apache.hadoop.yarn.event.AsyncDispatcher: Waiting for AsyncDispatcher to drain. Thread state is :RUNNABLE
2022-12-15 19:02:51,878 INFO org.apache.hadoop.yarn.event.AsyncDispatcher: Waiting for AsyncDispatcher to drain. Thread state is :RUNNABLE
2022-12-15 19:02:51,978 INFO org.apache.hadoop.yarn.event.AsyncDispatcher: Waiting for AsyncDispatcher to drain. Thread state is :RUNNABLE
2022-12-15 19:02:52,079 INFO org.apache.hadoop.yarn.event.AsyncDispatcher: Waiting for AsyncDispatcher to drain. Thread state is :RUNNABLE
2022-12-15 19:02:52,179 INFO org.apache.hadoop.yarn.event.AsyncDispatcher: Waiting for AsyncDispatcher to drain. Thread state is :RUNNABLE
2022-12-15 19:02:52,279 INFO org.apache.hadoop.yarn.event.AsyncDispatcher: Waiting for AsyncDispatcher to drain. Thread state is :RUNNABLE
2022-12-15 19:02:52,379 INFO org.apache.hadoop.yarn.event.AsyncDispatcher: Waiting for AsyncDispatcher to drain. Thread state is :RUNNABLE
2022-12-15 19:02:52,480 INFO org.apache.hadoop.yarn.event.AsyncDispatcher: Waiting for AsyncDispatcher to drain. Thread state is :RUNNABLE
2022-12-15 19:02:52,580 INFO org.apache.hadoop.yarn.event.AsyncDispatcher: Waiting for AsyncDispatcher to drain. Thread state is :RUNNABLE
2022-12-15 19:02:52,680 INFO org.apache.hadoop.yarn.event.AsyncDispatcher: Waiting for AsyncDispatcher to drain. Thread state is :RUNNABLE
2022-12-15 19:02:52,780 INFO org.apache.hadoop.yarn.event.AsyncDispatcher: Waiting for AsyncDispatcher to drain. Thread state is :RUNNABLE
2022-12-15 19:02:52,880 INFO org.apache.hadoop.yarn.event.AsyncDispatcher: Waiting for AsyncDispatcher to drain. Thread state is :RUNNABLE
2022-12-15 19:02:52,981 INFO org.apache.hadoop.yarn.event.AsyncDispatcher: Waiting for AsyncDispatcher to drain. Thread state is :RUNNABLE
2022-12-15 19:02:53,081 INFO org.apache.hadoop.yarn.event.AsyncDispatcher: Waiting for AsyncDispatcher to drain. Thread state is :RUNNABLE
2022-12-15 19:02:53,181 INFO org.apache.hadoop.yarn.event.AsyncDispatcher: Waiting for AsyncDispatcher to drain. Thread state is :RUNNABLE
2022-12-15 19:02:53,281 INFO org.apache.hadoop.yarn.event.AsyncDispatcher: Waiting for AsyncDispatcher to drain. Thread state is :RUNNABLE
2022-12-15 19:02:53,382 INFO org.apache.hadoop.yarn.event.AsyncDispatcher: Waiting for AsyncDispatcher to drain. Thread state is :RUNNABLE
2022-12-15 19:02:53,482 INFO org.apache.hadoop.yarn.event.AsyncDispatcher: Waiting for AsyncDispatcher to drain. Thread state is :RUNNABLE
2022-12-15 19:02:53,582 INFO org.apache.hadoop.yarn.event.AsyncDispatcher: Waiting for AsyncDispatcher to drain. Thread state is :RUNNABLE
2022-12-15 19:02:53,682 INFO org.apache.hadoop.yarn.event.AsyncDispatcher: Waiting for AsyncDispatcher to drain. Thread state is :RUNNABLE
2022-12-15 19:02:53,782 INFO org.apache.hadoop.yarn.event.AsyncDispatcher: Waiting for AsyncDispatcher to drain. Thread state is :RUNNABLE
2022-12-15 19:02:53,883 INFO org.apache.hadoop.yarn.event.AsyncDispatcher: Waiting for AsyncDispatcher to drain. Thread state is :RUNNABLE
2022-12-15 19:02:53,983 INFO org.apache.hadoop.yarn.event.AsyncDispatcher: Waiting for AsyncDispatcher to drain. Thread state is :RUNNABLE
2022-12-15 19:02:54,083 INFO org.apache.hadoop.yarn.event.AsyncDispatcher: Waiting for AsyncDispatcher to drain. Thread state is :RUNNABLE
2022-12-15 19:02:54,184 INFO org.apache.hadoop.yarn.event.AsyncDispatcher: Waiting for AsyncDispatcher to drain. Thread state is :RUNNABLE
2022-12-15 19:02:54,284 INFO org.apache.hadoop.yarn.event.AsyncDispatcher: Waiting for AsyncDispatcher to drain. Thread state is :RUNNABLE
2022-12-15 19:02:54,384 INFO org.apache.hadoop.yarn.event.AsyncDispatcher: Waiting for AsyncDispatcher to drain. Thread state is :RUNNABLE
2022-12-15 19:02:54,484 INFO org.apache.hadoop.yarn.event.AsyncDispatcher: Waiting for AsyncDispatcher to drain. Thread state is :RUNNABLE
2022-12-15 19:02:54,584 INFO org.apache.hadoop.yarn.event.AsyncDispatcher: Waiting for AsyncDispatcher to drain. Thread state is :RUNNABLE
2022-12-15 19:02:54,685 INFO org.apache.hadoop.yarn.event.AsyncDispatcher: Waiting for AsyncDispatcher to drain. Thread state is :RUNNABLE
2022-12-15 19:02:54,785 INFO org.apache.hadoop.yarn.event.AsyncDispatcher: Waiting for AsyncDispatcher to drain. Thread state is :RUNNABLE
2022-12-15 19:02:54,885 INFO org.apache.hadoop.yarn.event.AsyncDispatcher: Waiting for AsyncDispatcher to drain. Thread state is :RUNNABLE
2022-12-15 19:02:54,985 INFO org.apache.hadoop.yarn.event.AsyncDispatcher: Waiting for AsyncDispatcher to drain. Thread state is :RUNNABLE
2022-12-15 19:02:55,086 INFO org.apache.hadoop.yarn.event.AsyncDispatcher: Waiting for AsyncDispatcher to drain. Thread state is :RUNNABLE
2022-12-15 19:02:55,186 INFO org.apache.hadoop.yarn.event.AsyncDispatcher: Waiting for AsyncDispatcher to drain. Thread state is :RUNNABLE
2022-12-15 19:02:55,286 INFO org.apache.hadoop.yarn.event.AsyncDispatcher: Waiting for AsyncDispatcher to drain. Thread state is :RUNNABLE
2022-12-15 19:02:55,386 INFO org.apache.hadoop.yarn.event.AsyncDispatcher: Waiting for AsyncDispatcher to drain. Thread state is :RUNNABLE
2022-12-15 19:02:55,486 INFO org.apache.hadoop.yarn.event.AsyncDispatcher: Waiting for AsyncDispatcher to drain. Thread state is :RUNNABLE
2022-12-15 19:02:55,587 INFO org.apache.hadoop.yarn.event.AsyncDispatcher: Waiting for AsyncDispatcher to drain. Thread state is :RUNNABLE
2022-12-15 19:02:55,687 INFO org.apache.hadoop.yarn.event.AsyncDispatcher: Waiting for AsyncDispatcher to drain. Thread state is :RUNNABLE
2022-12-15 19:02:55,787 INFO org.apache.hadoop.yarn.event.AsyncDispatcher: Waiting for AsyncDispatcher to drain. Thread state is :RUNNABLE
2022-12-15 19:02:55,887 INFO org.apache.hadoop.yarn.event.AsyncDispatcher: Waiting for AsyncDispatcher to drain. Thread state is :RUNNABLE
2022-12-15 19:02:55,987 INFO org.apache.hadoop.yarn.event.AsyncDispatcher: Waiting for AsyncDispatcher to drain. Thread state is :RUNNABLE
2022-12-15 19:02:56,087 INFO org.apache.hadoop.yarn.event.AsyncDispatcher: Waiting for AsyncDispatcher to drain. Thread state is :RUNNABLE
2022-12-15 19:02:56,188 INFO org.apache.hadoop.yarn.event.AsyncDispatcher: Waiting for AsyncDispatcher to drain. Thread state is :RUNNABLE
2022-12-15 19:02:56,288 INFO org.apache.hadoop.yarn.event.AsyncDispatcher: Waiting for AsyncDispatcher to drain. Thread state is :RUNNABLE
2022-12-15 19:02:56,388 INFO org.apache.hadoop.yarn.event.AsyncDispatcher: Waiting for AsyncDispatcher to drain. Thread state is :RUNNABLE
2022-12-15 19:02:56,488 INFO org.apache.hadoop.yarn.event.AsyncDispatcher: Waiting for AsyncDispatcher to drain. Thread state is :RUNNABLE
2022-12-15 19:02:56,589 INFO org.apache.hadoop.yarn.event.AsyncDispatcher: Waiting for AsyncDispatcher to drain. Thread state is :RUNNABLE
2022-12-15 19:02:56,689 INFO org.apache.hadoop.yarn.event.AsyncDispatcher: Waiting for AsyncDispatcher to drain. Thread state is :RUNNABLE
2022-12-15 19:02:56,789 INFO org.apache.hadoop.yarn.event.AsyncDispatcher: Waiting for AsyncDispatcher to drain. Thread state is :RUNNABLE
2022-12-15 19:02:56,889 INFO org.apache.hadoop.yarn.event.AsyncDispatcher: Waiting for AsyncDispatcher to drain. Thread state is :RUNNABLE
2022-12-15 19:02:56,990 INFO org.apache.hadoop.yarn.event.AsyncDispatcher: Waiting for AsyncDispatcher to drain. Thread state is :RUNNABLE
2022-12-15 19:02:57,090 INFO org.apache.hadoop.yarn.event.AsyncDispatcher: Waiting for AsyncDispatcher to drain. Thread state is :RUNNABLE
2022-12-15 19:02:57,190 INFO org.apache.hadoop.yarn.event.AsyncDispatcher: Waiting for AsyncDispatcher to drain. Thread state is :RUNNABLE
2022-12-15 19:02:57,290 INFO org.apache.hadoop.yarn.event.AsyncDispatcher: Waiting for AsyncDispatcher to drain. Thread state is :RUNNABLE
2022-12-15 19:02:57,390 INFO org.apache.hadoop.yarn.event.AsyncDispatcher: Waiting for AsyncDispatcher to drain. Thread state is :RUNNABLE
2022-12-15 19:02:57,491 INFO org.apache.hadoop.yarn.event.AsyncDispatcher: Waiting for AsyncDispatcher to drain. Thread state is :RUNNABLE
2022-12-15 19:02:57,591 INFO org.apache.hadoop.yarn.event.AsyncDispatcher: Waiting for AsyncDispatcher to drain. Thread state is :RUNNABLE
2022-12-15 19:02:57,691 INFO org.apache.hadoop.yarn.event.AsyncDispatcher: Waiting for AsyncDispatcher to drain. Thread state is :RUNNABLE
2022-12-15 19:02:57,792 INFO org.apache.hadoop.yarn.event.AsyncDispatcher: Waiting for AsyncDispatcher to drain. Thread state is :RUNNABLE
2022-12-15 19:02:57,892 INFO org.apache.hadoop.yarn.event.AsyncDispatcher: Waiting for AsyncDispatcher to drain. Thread state is :RUNNABLE
2022-12-15 19:02:57,992 INFO org.apache.hadoop.yarn.event.AsyncDispatcher: Waiting for AsyncDispatcher to drain. Thread state is :RUNNABLE
2022-12-15 19:02:58,092 INFO org.apache.hadoop.yarn.event.AsyncDispatcher: Waiting for AsyncDispatcher to drain. Thread state is :RUNNABLE
2022-12-15 19:02:58,193 INFO org.apache.hadoop.yarn.event.AsyncDispatcher: Waiting for AsyncDispatcher to drain. Thread state is :RUNNABLE
2022-12-15 19:02:58,293 INFO org.apache.hadoop.yarn.event.AsyncDispatcher: Waiting for AsyncDispatcher to drain. Thread state is :RUNNABLE
2022-12-15 19:02:58,393 INFO org.apache.hadoop.yarn.event.AsyncDispatcher: Waiting for AsyncDispatcher to drain. Thread state is :RUNNABLE
2022-12-15 19:02:58,493 INFO org.apache.hadoop.yarn.event.AsyncDispatcher: Waiting for AsyncDispatcher to drain. Thread state is :RUNNABLE
2022-12-15 19:02:58,594 INFO org.apache.hadoop.yarn.event.AsyncDispatcher: Waiting for AsyncDispatcher to drain. Thread state is :RUNNABLE
2022-12-15 19:02:58,694 INFO org.apache.hadoop.yarn.event.AsyncDispatcher: Waiting for AsyncDispatcher to drain. Thread state is :RUNNABLE
2022-12-15 19:02:58,794 INFO org.apache.hadoop.yarn.event.AsyncDispatcher: Waiting for AsyncDispatcher to drain. Thread state is :RUNNABLE
2022-12-15 19:02:58,895 INFO org.apache.hadoop.yarn.event.AsyncDispatcher: Waiting for AsyncDispatcher to drain. Thread state is :RUNNABLE
2022-12-15 19:02:58,995 INFO org.apache.hadoop.yarn.event.AsyncDispatcher: Waiting for AsyncDispatcher to drain. Thread state is :RUNNABLE
2022-12-15 19:02:59,095 INFO org.apache.hadoop.yarn.event.AsyncDispatcher: Waiting for AsyncDispatcher to drain. Thread state is :RUNNABLE
2022-12-15 19:02:59,195 INFO org.apache.hadoop.yarn.event.AsyncDispatcher: Waiting for AsyncDispatcher to drain. Thread state is :RUNNABLE
2022-12-15 19:02:59,296 INFO org.apache.hadoop.yarn.event.AsyncDispatcher: Waiting for AsyncDispatcher to drain. Thread state is :RUNNABLE
2022-12-15 19:02:59,396 INFO org.apache.hadoop.yarn.event.AsyncDispatcher: Waiting for AsyncDispatcher to drain. Thread state is :RUNNABLE
2022-12-15 19:02:59,496 INFO org.apache.hadoop.yarn.event.AsyncDispatcher: Waiting for AsyncDispatcher to drain. Thread state is :RUNNABLE
2022-12-15 19:02:59,596 INFO org.apache.hadoop.yarn.event.AsyncDispatcher: Waiting for AsyncDispatcher to drain. Thread state is :RUNNABLE
2022-12-15 19:02:59,697 INFO org.apache.hadoop.yarn.event.AsyncDispatcher: Waiting for AsyncDispatcher to drain. Thread state is :RUNNABLE
2022-12-15 19:02:59,797 INFO org.apache.hadoop.yarn.event.AsyncDispatcher: Waiting for AsyncDispatcher to drain. Thread state is :RUNNABLE
2022-12-15 19:02:59,897 INFO org.apache.hadoop.yarn.event.AsyncDispatcher: Waiting for AsyncDispatcher to drain. Thread state is :RUNNABLE
2022-12-15 19:02:59,997 INFO org.apache.hadoop.yarn.event.AsyncDispatcher: Waiting for AsyncDispatcher to drain. Thread state is :RUNNABLE
2022-12-15 19:03:00,098 INFO org.apache.hadoop.yarn.event.AsyncDispatcher: Waiting for AsyncDispatcher to drain. Thread state is :RUNNABLE
2022-12-15 19:03:00,198 INFO org.apache.hadoop.yarn.event.AsyncDispatcher: Waiting for AsyncDispatcher to drain. Thread state is :RUNNABLE
2022-12-15 19:03:00,298 INFO org.apache.hadoop.yarn.event.AsyncDispatcher: Waiting for AsyncDispatcher to drain. Thread state is :RUNNABLE
2022-12-15 19:03:00,398 INFO org.apache.hadoop.yarn.event.AsyncDispatcher: Waiting for AsyncDispatcher to drain. Thread state is :RUNNABLE
2022-12-15 19:03:00,499 INFO org.apache.hadoop.yarn.event.AsyncDispatcher: Waiting for AsyncDispatcher to drain. Thread state is :RUNNABLE
2022-12-15 19:03:00,599 INFO org.apache.hadoop.yarn.event.AsyncDispatcher: Waiting for AsyncDispatcher to drain. Thread state is :RUNNABLE
2022-12-15 19:03:00,699 INFO org.apache.hadoop.yarn.event.AsyncDispatcher: Waiting for AsyncDispatcher to drain. Thread state is :RUNNABLE
2022-12-15 19:03:00,799 INFO org.apache.hadoop.yarn.event.AsyncDispatcher: Waiting for AsyncDispatcher to drain. Thread state is :RUNNABLE
2022-12-15 19:03:00,900 INFO org.apache.hadoop.yarn.event.AsyncDispatcher: Waiting for AsyncDispatcher to drain. Thread state is :RUNNABLE
2022-12-15 19:03:01,000 INFO org.apache.hadoop.yarn.event.AsyncDispatcher: Waiting for AsyncDispatcher to drain. Thread state is :RUNNABLE
2022-12-15 19:03:01,100 INFO org.apache.hadoop.yarn.event.AsyncDispatcher: Waiting for AsyncDispatcher to drain. Thread state is :RUNNABLE
2022-12-15 19:03:01,200 INFO org.apache.hadoop.yarn.event.AsyncDispatcher: Waiting for AsyncDispatcher to drain. Thread state is :RUNNABLE
2022-12-15 19:03:01,301 INFO org.apache.hadoop.yarn.event.AsyncDispatcher: Waiting for AsyncDispatcher to drain. Thread state is :RUNNABLE
2022-12-15 19:03:01,401 INFO org.apache.hadoop.yarn.event.AsyncDispatcher: Waiting for AsyncDispatcher to drain. Thread state is :RUNNABLE
2022-12-15 19:03:01,501 INFO org.apache.hadoop.yarn.event.AsyncDispatcher: Waiting for AsyncDispatcher to drain. Thread state is :RUNNABLE
2022-12-15 19:03:01,602 INFO org.apache.hadoop.yarn.event.AsyncDispatcher: Waiting for AsyncDispatcher to drain. Thread state is :RUNNABLE
2022-12-15 19:03:01,702 INFO org.apache.hadoop.yarn.event.AsyncDispatcher: Waiting for AsyncDispatcher to drain. Thread state is :RUNNABLE
2022-12-15 19:03:01,802 INFO org.apache.hadoop.yarn.event.AsyncDispatcher: Waiting for AsyncDispatcher to drain. Thread state is :RUNNABLE
2022-12-15 19:03:01,902 INFO org.apache.hadoop.yarn.event.AsyncDispatcher: Waiting for AsyncDispatcher to drain. Thread state is :RUNNABLE
2022-12-15 19:03:02,003 INFO org.apache.hadoop.yarn.event.AsyncDispatcher: Waiting for AsyncDispatcher to drain. Thread state is :RUNNABLE
2022-12-15 19:03:02,103 INFO org.apache.hadoop.yarn.event.AsyncDispatcher: Waiting for AsyncDispatcher to drain. Thread state is :RUNNABLE
2022-12-15 19:03:02,203 INFO org.apache.hadoop.yarn.event.AsyncDispatcher: Waiting for AsyncDispatcher to drain. Thread state is :RUNNABLE
2022-12-15 19:03:02,304 INFO org.apache.hadoop.yarn.event.AsyncDispatcher: Waiting for AsyncDispatcher to drain. Thread state is :RUNNABLE
2022-12-15 19:03:02,404 INFO org.apache.hadoop.yarn.event.AsyncDispatcher: Waiting for AsyncDispatcher to drain. Thread state is :RUNNABLE
2022-12-15 19:03:02,504 INFO org.apache.hadoop.yarn.event.AsyncDispatcher: Waiting for AsyncDispatcher to drain. Thread state is :RUNNABLE
2022-12-15 19:03:02,604 INFO org.apache.hadoop.yarn.event.AsyncDispatcher: Waiting for AsyncDispatcher to drain. Thread state is :RUNNABLE
2022-12-15 19:03:02,705 INFO org.apache.hadoop.yarn.event.AsyncDispatcher: Waiting for AsyncDispatcher to drain. Thread state is :RUNNABLE
2022-12-15 19:03:02,806 INFO org.apache.hadoop.yarn.event.AsyncDispatcher: Waiting for AsyncDispatcher to drain. Thread state is :RUNNABLE
2022-12-15 19:03:02,907 INFO org.apache.hadoop.yarn.event.AsyncDispatcher: Waiting for AsyncDispatcher to drain. Thread state is :RUNNABLE
2022-12-15 19:03:03,007 INFO org.apache.hadoop.yarn.event.AsyncDispatcher: Waiting for AsyncDispatcher to drain. Thread state is :RUNNABLE
2022-12-15 19:03:03,107 INFO org.apache.hadoop.yarn.event.AsyncDispatcher: Waiting for AsyncDispatcher to drain. Thread state is :RUNNABLE
2022-12-15 19:03:03,207 INFO org.apache.hadoop.yarn.event.AsyncDispatcher: Waiting for AsyncDispatcher to drain. Thread state is :RUNNABLE
2022-12-15 19:03:03,308 INFO org.apache.hadoop.yarn.event.AsyncDispatcher: Waiting for AsyncDispatcher to drain. Thread state is :RUNNABLE
2022-12-15 19:03:03,408 INFO org.apache.hadoop.yarn.event.AsyncDispatcher: Waiting for AsyncDispatcher to drain. Thread state is :RUNNABLE
2022-12-15 19:03:03,508 INFO org.apache.hadoop.yarn.event.AsyncDispatcher: Waiting for AsyncDispatcher to drain. Thread state is :RUNNABLE
2022-12-15 19:03:03,608 INFO org.apache.hadoop.yarn.event.AsyncDispatcher: Waiting for AsyncDispatcher to drain. Thread state is :RUNNABLE
2022-12-15 19:03:03,709 INFO org.apache.hadoop.yarn.event.AsyncDispatcher: Waiting for AsyncDispatcher to drain. Thread state is :RUNNABLE
2022-12-15 19:03:03,809 INFO org.apache.hadoop.yarn.event.AsyncDispatcher: Waiting for AsyncDispatcher to drain. Thread state is :RUNNABLE
2022-12-15 19:03:03,909 INFO org.apache.hadoop.yarn.event.AsyncDispatcher: Waiting for AsyncDispatcher to drain. Thread state is :RUNNABLE
2022-12-15 19:03:04,009 INFO org.apache.hadoop.yarn.event.AsyncDispatcher: Waiting for AsyncDispatcher to drain. Thread state is :RUNNABLE
2022-12-15 19:03:04,110 INFO org.apache.hadoop.yarn.event.AsyncDispatcher: Waiting for AsyncDispatcher to drain. Thread state is :RUNNABLE
2022-12-15 19:03:04,210 INFO org.apache.hadoop.yarn.event.AsyncDispatcher: Waiting for AsyncDispatcher to drain. Thread state is :RUNNABLE
2022-12-15 19:03:04,310 INFO org.apache.hadoop.yarn.event.AsyncDispatcher: Waiting for AsyncDispatcher to drain. Thread state is :RUNNABLE
2022-12-15 19:03:04,410 INFO org.apache.hadoop.yarn.event.AsyncDispatcher: Waiting for AsyncDispatcher to drain. Thread state is :RUNNABLE
2022-12-15 19:03:04,510 INFO org.apache.hadoop.yarn.event.AsyncDispatcher: Waiting for AsyncDispatcher to drain. Thread state is :RUNNABLE
2022-12-15 19:03:04,611 INFO org.apache.hadoop.yarn.event.AsyncDispatcher: Waiting for AsyncDispatcher to drain. Thread state is :RUNNABLE
2022-12-15 19:03:04,711 INFO org.apache.hadoop.yarn.event.AsyncDispatcher: Waiting for AsyncDispatcher to drain. Thread state is :RUNNABLE
2022-12-15 19:03:04,811 INFO org.apache.hadoop.yarn.event.AsyncDispatcher: Waiting for AsyncDispatcher to drain. Thread state is :RUNNABLE
2022-12-15 19:03:04,911 INFO org.apache.hadoop.yarn.event.AsyncDispatcher: Waiting for AsyncDispatcher to drain. Thread state is :RUNNABLE
2022-12-15 19:03:05,012 INFO org.apache.hadoop.yarn.event.AsyncDispatcher: Waiting for AsyncDispatcher to drain. Thread state is :RUNNABLE
2022-12-15 19:03:05,112 INFO org.apache.hadoop.yarn.event.AsyncDispatcher: Waiting for AsyncDispatcher to drain. Thread state is :RUNNABLE
2022-12-15 19:03:05,212 INFO org.apache.hadoop.yarn.event.AsyncDispatcher: Waiting for AsyncDispatcher to drain. Thread state is :RUNNABLE
2022-12-15 19:03:05,312 INFO org.apache.hadoop.yarn.event.AsyncDispatcher: Waiting for AsyncDispatcher to drain. Thread state is :RUNNABLE
2022-12-15 19:03:05,413 INFO org.apache.hadoop.yarn.event.AsyncDispatcher: Waiting for AsyncDispatcher to drain. Thread state is :RUNNABLE
2022-12-15 19:03:05,513 INFO org.apache.hadoop.yarn.event.AsyncDispatcher: Waiting for AsyncDispatcher to drain. Thread state is :RUNNABLE
2022-12-15 19:03:05,613 INFO org.apache.hadoop.yarn.event.AsyncDispatcher: Waiting for AsyncDispatcher to drain. Thread state is :RUNNABLE
2022-12-15 19:03:05,713 INFO org.apache.hadoop.yarn.event.AsyncDispatcher: Waiting for AsyncDispatcher to drain. Thread state is :RUNNABLE
2022-12-15 19:03:05,813 INFO org.apache.hadoop.yarn.event.AsyncDispatcher: Waiting for AsyncDispatcher to drain. Thread state is :RUNNABLE
2022-12-15 19:03:05,913 INFO org.apache.hadoop.yarn.event.AsyncDispatcher: Waiting for AsyncDispatcher to drain. Thread state is :RUNNABLE
2022-12-15 19:03:06,014 INFO org.apache.hadoop.yarn.event.AsyncDispatcher: Waiting for AsyncDispatcher to drain. Thread state is :RUNNABLE
2022-12-15 19:03:06,114 INFO org.apache.hadoop.yarn.event.AsyncDispatcher: Waiting for AsyncDispatcher to drain. Thread state is :RUNNABLE
2022-12-15 19:03:06,214 INFO org.apache.hadoop.yarn.event.AsyncDispatcher: Waiting for AsyncDispatcher to drain. Thread state is :RUNNABLE
2022-12-15 19:03:06,314 INFO org.apache.hadoop.yarn.event.AsyncDispatcher: Waiting for AsyncDispatcher to drain. Thread state is :RUNNABLE
2022-12-15 19:03:06,415 INFO org.apache.hadoop.yarn.event.AsyncDispatcher: Waiting for AsyncDispatcher to drain. Thread state is :RUNNABLE
2022-12-15 19:03:06,515 INFO org.apache.hadoop.yarn.event.AsyncDispatcher: Waiting for AsyncDispatcher to drain. Thread state is :RUNNABLE
2022-12-15 19:03:06,615 INFO org.apache.hadoop.yarn.event.AsyncDispatcher: Waiting for AsyncDispatcher to drain. Thread state is :RUNNABLE
2022-12-15 19:03:06,715 INFO org.apache.hadoop.yarn.event.AsyncDispatcher: Waiting for AsyncDispatcher to drain. Thread state is :RUNNABLE
2022-12-15 19:03:06,815 INFO org.apache.hadoop.yarn.event.AsyncDispatcher: Waiting for AsyncDispatcher to drain. Thread state is :RUNNABLE
2022-12-15 19:03:06,915 INFO org.apache.hadoop.yarn.event.AsyncDispatcher: Waiting for AsyncDispatcher to drain. Thread state is :RUNNABLE
2022-12-15 19:03:07,016 INFO org.apache.hadoop.yarn.event.AsyncDispatcher: Waiting for AsyncDispatcher to drain. Thread state is :RUNNABLE
2022-12-15 19:03:07,116 INFO org.apache.hadoop.yarn.event.AsyncDispatcher: Waiting for AsyncDispatcher to drain. Thread state is :RUNNABLE
2022-12-15 19:03:07,216 INFO org.apache.hadoop.yarn.event.AsyncDispatcher: Waiting for AsyncDispatcher to drain. Thread state is :RUNNABLE
2022-12-15 19:03:07,317 INFO org.apache.hadoop.yarn.event.AsyncDispatcher: Waiting for AsyncDispatcher to drain. Thread state is :RUNNABLE
2022-12-15 19:03:07,417 INFO org.apache.hadoop.yarn.event.AsyncDispatcher: Waiting for AsyncDispatcher to drain. Thread state is :RUNNABLE
2022-12-15 19:03:07,517 INFO org.apache.hadoop.yarn.event.AsyncDispatcher: Waiting for AsyncDispatcher to drain. Thread state is :RUNNABLE
2022-12-15 19:03:07,617 INFO org.apache.hadoop.yarn.event.AsyncDispatcher: Waiting for AsyncDispatcher to drain. Thread state is :RUNNABLE
2022-12-15 19:03:07,718 INFO org.apache.hadoop.yarn.event.AsyncDispatcher: Waiting for AsyncDispatcher to drain. Thread state is :RUNNABLE
2022-12-15 19:03:07,818 INFO org.apache.hadoop.yarn.event.AsyncDispatcher: Waiting for AsyncDispatcher to drain. Thread state is :RUNNABLE
2022-12-15 19:03:07,918 INFO org.apache.hadoop.yarn.event.AsyncDispatcher: Waiting for AsyncDispatcher to drain. Thread state is :RUNNABLE
2022-12-15 19:03:08,018 INFO org.apache.hadoop.yarn.event.AsyncDispatcher: Waiting for AsyncDispatcher to drain. Thread state is :RUNNABLE
2022-12-15 19:03:08,119 INFO org.apache.hadoop.yarn.event.AsyncDispatcher: Waiting for AsyncDispatcher to drain. Thread state is :RUNNABLE
2022-12-15 19:03:08,219 INFO org.apache.hadoop.yarn.event.AsyncDispatcher: Waiting for AsyncDispatcher to drain. Thread state is :RUNNABLE
2022-12-15 19:03:08,319 INFO org.apache.hadoop.yarn.event.AsyncDispatcher: Waiting for AsyncDispatcher to drain. Thread state is :RUNNABLE
2022-12-15 19:03:08,419 INFO org.apache.hadoop.yarn.event.AsyncDispatcher: Waiting for AsyncDispatcher to drain. Thread state is :RUNNABLE
2022-12-15 19:03:08,520 INFO org.apache.hadoop.yarn.event.AsyncDispatcher: Waiting for AsyncDispatcher to drain. Thread state is :RUNNABLE
2022-12-15 19:03:08,620 INFO org.apache.hadoop.yarn.event.AsyncDispatcher: Waiting for AsyncDispatcher to drain. Thread state is :RUNNABLE
2022-12-15 19:03:08,720 INFO org.apache.hadoop.yarn.event.AsyncDispatcher: Waiting for AsyncDispatcher to drain. Thread state is :RUNNABLE
2022-12-15 19:03:08,820 INFO org.apache.hadoop.yarn.event.AsyncDispatcher: Waiting for AsyncDispatcher to drain. Thread state is :RUNNABLE
2022-12-15 19:03:08,921 INFO org.apache.hadoop.yarn.event.AsyncDispatcher: Waiting for AsyncDispatcher to drain. Thread state is :RUNNABLE
2022-12-15 19:03:09,021 INFO org.apache.hadoop.yarn.event.AsyncDispatcher: Waiting for AsyncDispatcher to drain. Thread state is :RUNNABLE
2022-12-15 19:03:09,121 INFO org.apache.hadoop.yarn.event.AsyncDispatcher: Waiting for AsyncDispatcher to drain. Thread state is :RUNNABLE
2022-12-15 19:03:09,221 INFO org.apache.hadoop.yarn.event.AsyncDispatcher: Waiting for AsyncDispatcher to drain. Thread state is :RUNNABLE
2022-12-15 19:03:09,321 INFO org.apache.hadoop.yarn.event.AsyncDispatcher: Waiting for AsyncDispatcher to drain. Thread state is :RUNNABLE
2022-12-15 19:03:09,422 INFO org.apache.hadoop.yarn.event.AsyncDispatcher: Waiting for AsyncDispatcher to drain. Thread state is :RUNNABLE
2022-12-15 19:03:09,522 INFO org.apache.hadoop.yarn.event.AsyncDispatcher: Waiting for AsyncDispatcher to drain. Thread state is :RUNNABLE
2022-12-15 19:03:09,622 INFO org.apache.hadoop.yarn.event.AsyncDispatcher: Waiting for AsyncDispatcher to drain. Thread state is :RUNNABLE
2022-12-15 19:03:09,723 INFO org.apache.hadoop.yarn.event.AsyncDispatcher: Waiting for AsyncDispatcher to drain. Thread state is :RUNNABLE
2022-12-15 19:03:09,823 INFO org.apache.hadoop.yarn.event.AsyncDispatcher: Waiting for AsyncDispatcher to drain. Thread state is :RUNNABLE
2022-12-15 19:03:09,923 INFO org.apache.hadoop.yarn.event.AsyncDispatcher: Waiting for AsyncDispatcher to drain. Thread state is :RUNNABLE
2022-12-15 19:03:10,023 INFO org.apache.hadoop.yarn.event.AsyncDispatcher: Waiting for AsyncDispatcher to drain. Thread state is :RUNNABLE
2022-12-15 19:03:10,124 INFO org.apache.hadoop.yarn.event.AsyncDispatcher: Waiting for AsyncDispatcher to drain. Thread state is :RUNNABLE
2022-12-15 19:03:10,224 INFO org.apache.hadoop.yarn.event.AsyncDispatcher: Waiting for AsyncDispatcher to drain. Thread state is :RUNNABLE
2022-12-15 19:03:10,324 INFO org.apache.hadoop.yarn.event.AsyncDispatcher: Waiting for AsyncDispatcher to drain. Thread state is :RUNNABLE
2022-12-15 19:03:10,424 INFO org.apache.hadoop.yarn.event.AsyncDispatcher: Waiting for AsyncDispatcher to drain. Thread state is :RUNNABLE
2022-12-15 19:03:10,524 INFO org.apache.hadoop.yarn.event.AsyncDispatcher: Waiting for AsyncDispatcher to drain. Thread state is :RUNNABLE
2022-12-15 19:03:10,625 INFO org.apache.hadoop.yarn.event.AsyncDispatcher: Waiting for AsyncDispatcher to drain. Thread state is :RUNNABLE
2022-12-15 19:03:10,725 INFO org.apache.hadoop.yarn.event.AsyncDispatcher: Waiting for AsyncDispatcher to drain. Thread state is :RUNNABLE
2022-12-15 19:03:10,825 INFO org.apache.hadoop.yarn.event.AsyncDispatcher: Waiting for AsyncDispatcher to drain. Thread state is :RUNNABLE
2022-12-15 19:03:10,925 INFO org.apache.hadoop.yarn.event.AsyncDispatcher: Waiting for AsyncDispatcher to drain. Thread state is :RUNNABLE
2022-12-15 19:03:11,026 INFO org.apache.hadoop.yarn.event.AsyncDispatcher: Waiting for AsyncDispatcher to drain. Thread state is :RUNNABLE
2022-12-15 19:03:11,126 INFO org.apache.hadoop.yarn.event.AsyncDispatcher: Waiting for AsyncDispatcher to drain. Thread state is :RUNNABLE
2022-12-15 19:03:11,226 INFO org.apache.hadoop.yarn.event.AsyncDispatcher: Waiting for AsyncDispatcher to drain. Thread state is :RUNNABLE
2022-12-15 19:03:11,326 INFO org.apache.hadoop.yarn.event.AsyncDispatcher: Waiting for AsyncDispatcher to drain. Thread state is :RUNNABLE
2022-12-15 19:03:11,426 INFO org.apache.hadoop.yarn.event.AsyncDispatcher: Waiting for AsyncDispatcher to drain. Thread state is :RUNNABLE
2022-12-15 19:03:11,527 INFO org.apache.hadoop.yarn.event.AsyncDispatcher: Waiting for AsyncDispatcher to drain. Thread state is :RUNNABLE
2022-12-15 19:03:11,627 INFO org.apache.hadoop.yarn.event.AsyncDispatcher: Waiting for AsyncDispatcher to drain. Thread state is :RUNNABLE
2022-12-15 19:03:11,727 INFO org.apache.hadoop.yarn.event.AsyncDispatcher: Waiting for AsyncDispatcher to drain. Thread state is :RUNNABLE
2022-12-15 19:03:11,827 INFO org.apache.hadoop.yarn.event.AsyncDispatcher: Waiting for AsyncDispatcher to drain. Thread state is :RUNNABLE
2022-12-15 19:03:11,928 INFO org.apache.hadoop.yarn.event.AsyncDispatcher: Waiting for AsyncDispatcher to drain. Thread state is :RUNNABLE
2022-12-15 19:03:12,028 INFO org.apache.hadoop.yarn.event.AsyncDispatcher: Waiting for AsyncDispatcher to drain. Thread state is :RUNNABLE
2022-12-15 19:03:12,128 INFO org.apache.hadoop.yarn.event.AsyncDispatcher: Waiting for AsyncDispatcher to drain. Thread state is :RUNNABLE
2022-12-15 19:03:12,228 INFO org.apache.hadoop.yarn.event.AsyncDispatcher: Waiting for AsyncDispatcher to drain. Thread state is :RUNNABLE
2022-12-15 19:03:12,329 INFO org.apache.hadoop.yarn.event.AsyncDispatcher: Waiting for AsyncDispatcher to drain. Thread state is :RUNNABLE
2022-12-15 19:03:12,429 INFO org.apache.hadoop.yarn.event.AsyncDispatcher: Waiting for AsyncDispatcher to drain. Thread state is :RUNNABLE
2022-12-15 19:03:12,529 INFO org.apache.hadoop.yarn.event.AsyncDispatcher: Waiting for AsyncDispatcher to drain. Thread state is :RUNNABLE
2022-12-15 19:03:12,629 INFO org.apache.hadoop.yarn.event.AsyncDispatcher: Waiting for AsyncDispatcher to drain. Thread state is :RUNNABLE
2022-12-15 19:03:12,730 INFO org.apache.hadoop.yarn.event.AsyncDispatcher: Waiting for AsyncDispatcher to drain. Thread state is :RUNNABLE
2022-12-15 19:03:12,830 INFO org.apache.hadoop.yarn.event.AsyncDispatcher: Waiting for AsyncDispatcher to drain. Thread state is :RUNNABLE
2022-12-15 19:03:12,930 INFO org.apache.hadoop.yarn.event.AsyncDispatcher: Waiting for AsyncDispatcher to drain. Thread state is :RUNNABLE
2022-12-15 19:03:13,030 INFO org.apache.hadoop.yarn.event.AsyncDispatcher: Waiting for AsyncDispatcher to drain. Thread state is :RUNNABLE
2022-12-15 19:03:13,131 INFO org.apache.hadoop.yarn.event.AsyncDispatcher: Waiting for AsyncDispatcher to drain. Thread state is :RUNNABLE
2022-12-15 19:03:13,166 INFO org.apache.hadoop.yarn.client.api.impl.TimelineConnector: Exception caught by TimelineClientConnectionRetry, will try 29 more time(s).
Message: java.net.SocketTimeoutException: Call From null to adh-test-00-mnode2.ru-central1.internal:8188 failed on socket timeout exception: java.net.SocketTimeoutException: connect timed out; For more details see:  http://wiki.apache.org/hadoop/SocketTimeout
2022-12-15 19:03:13,197 INFO org.apache.hadoop.yarn.client.api.impl.TimelineConnector: Exception caught by TimelineClientConnectionRetry, will try 29 more time(s).
Message: java.net.SocketTimeoutException: Call From null to adh-test-00-mnode2.ru-central1.internal:8188 failed on socket timeout exception: java.net.SocketTimeoutException: connect timed out; For more details see:  http://wiki.apache.org/hadoop/SocketTimeout
2022-12-15 19:03:13,231 INFO org.apache.hadoop.yarn.event.AsyncDispatcher: Waiting for AsyncDispatcher to drain. Thread state is :TIMED_WAITING
2022-12-15 19:03:13,331 INFO org.apache.hadoop.yarn.event.AsyncDispatcher: Waiting for AsyncDispatcher to drain. Thread state is :TIMED_WAITING
2022-12-15 19:03:13,432 INFO org.apache.hadoop.yarn.event.AsyncDispatcher: Waiting for AsyncDispatcher to drain. Thread state is :TIMED_WAITING
2022-12-15 19:03:13,532 INFO org.apache.hadoop.yarn.event.AsyncDispatcher: Waiting for AsyncDispatcher to drain. Thread state is :TIMED_WAITING
2022-12-15 19:03:13,632 INFO org.apache.hadoop.yarn.event.AsyncDispatcher: Waiting for AsyncDispatcher to drain. Thread state is :TIMED_WAITING
2022-12-15 19:03:13,732 INFO org.apache.hadoop.yarn.event.AsyncDispatcher: Waiting for AsyncDispatcher to drain. Thread state is :TIMED_WAITING
2022-12-15 19:03:13,833 INFO org.apache.hadoop.yarn.event.AsyncDispatcher: Waiting for AsyncDispatcher to drain. Thread state is :TIMED_WAITING
2022-12-15 19:03:13,933 INFO org.apache.hadoop.yarn.event.AsyncDispatcher: Waiting for AsyncDispatcher to drain. Thread state is :TIMED_WAITING
2022-12-15 19:03:14,033 INFO org.apache.hadoop.yarn.event.AsyncDispatcher: Waiting for AsyncDispatcher to drain. Thread state is :TIMED_WAITING
2022-12-15 19:03:14,133 INFO org.apache.hadoop.yarn.event.AsyncDispatcher: Waiting for AsyncDispatcher to drain. Thread state is :TIMED_WAITING
2022-12-15 19:03:14,234 INFO org.apache.hadoop.yarn.event.AsyncDispatcher: Waiting for AsyncDispatcher to drain. Thread state is :RUNNABLE
2022-12-15 19:03:14,334 INFO org.apache.hadoop.yarn.event.AsyncDispatcher: Waiting for AsyncDispatcher to drain. Thread state is :RUNNABLE
2022-12-15 19:03:14,434 INFO org.apache.hadoop.yarn.event.AsyncDispatcher: Waiting for AsyncDispatcher to drain. Thread state is :RUNNABLE
2022-12-15 19:03:14,534 INFO org.apache.hadoop.yarn.event.AsyncDispatcher: Waiting for AsyncDispatcher to drain. Thread state is :RUNNABLE
2022-12-15 19:03:14,634 INFO org.apache.hadoop.yarn.event.AsyncDispatcher: Waiting for AsyncDispatcher to drain. Thread state is :BLOCKED
2022-12-15 19:03:14,735 INFO org.apache.hadoop.yarn.event.AsyncDispatcher: Waiting for AsyncDispatcher to drain. Thread state is :RUNNABLE
2022-12-15 19:03:14,761 INFO org.apache.hadoop.yarn.event.AsyncDispatcher: Waiting for AsyncDispatcher to drain. Thread state is :WAITING
2022-12-15 19:03:14,761 INFO org.apache.hadoop.yarn.event.AsyncDispatcher: AsyncDispatcher is draining to stop, ignoring any new events.
2022-12-15 19:03:14,762 INFO org.apache.hadoop.yarn.event.AsyncDispatcher: Waiting for AsyncDispatcher to drain. Thread state is :RUNNABLE
2022-12-15 19:03:14,762 INFO org.apache.hadoop.yarn.event.AsyncDispatcher: AsyncDispatcher is draining to stop, ignoring any new events.
2022-12-15 19:03:14,762 INFO org.apache.hadoop.yarn.event.AsyncDispatcher: AsyncDispatcher is draining to stop, ignoring any new events.
2022-12-15 19:03:14,763 INFO org.apache.hadoop.yarn.event.AsyncDispatcher: AsyncDispatcher is draining to stop, ignoring any new events.
2022-12-15 19:03:14,763 INFO org.apache.hadoop.yarn.event.AsyncDispatcher: AsyncDispatcher is draining to stop, ignoring any new events.
2022-12-15 19:03:14,763 INFO org.apache.hadoop.yarn.event.AsyncDispatcher: AsyncDispatcher is draining to stop, ignoring any new events.
2022-12-15 19:03:14,763 INFO org.apache.hadoop.yarn.event.AsyncDispatcher: AsyncDispatcher is draining to stop, ignoring any new events.
2022-12-15 19:03:14,763 INFO org.apache.hadoop.yarn.event.AsyncDispatcher: AsyncDispatcher is draining to stop, ignoring any new events.
2022-12-15 19:03:14,763 INFO org.apache.hadoop.ipc.Server: Stopping server on 8033
2022-12-15 19:03:14,764 INFO org.apache.hadoop.yarn.server.resourcemanager.ResourceManager: Transitioning to standby state
2022-12-15 19:03:14,764 INFO org.apache.hadoop.ipc.Server: Stopping IPC Server listener on 8033
2022-12-15 19:03:14,764 INFO org.apache.hadoop.yarn.server.resourcemanager.ResourceManager: Transitioned to standby state
2022-12-15 19:03:14,764 INFO org.apache.hadoop.ipc.Server: Stopping IPC Server Responder
2022-12-15 19:03:14,764 FATAL org.apache.hadoop.yarn.server.resourcemanager.ResourceManager: Error starting ResourceManager
org.apache.hadoop.service.ServiceStateException: org.apache.hadoop.hdfs.server.namenode.SafeModeException: Cannot create directory /system/yarn/node-labels. Name node is in safe mode.
The reported blocks 0 needs additional 11 blocks to reach the threshold 0.9990 of total blocks 12.
The number of live datanodes 0 has reached the minimum number 0. Safe mode will be turned off automatically once the thresholds have been reached. NamenodeHostName:adh-test-00-mnode1.ru-central1.internal
	at org.apache.hadoop.hdfs.server.namenode.FSNamesystem.newSafemodeException(FSNamesystem.java:1461)
	at org.apache.hadoop.hdfs.server.namenode.FSNamesystem.checkNameNodeSafeMode(FSNamesystem.java:1448)
	at org.apache.hadoop.hdfs.server.namenode.FSNamesystem.mkdirs(FSNamesystem.java:3145)
	at org.apache.hadoop.hdfs.server.namenode.NameNodeRpcServer.mkdirs(NameNodeRpcServer.java:1126)
	at org.apache.hadoop.hdfs.protocolPB.ClientNamenodeProtocolServerSideTranslatorPB.mkdirs(ClientNamenodeProtocolServerSideTranslatorPB.java:707)
	at org.apache.hadoop.hdfs.protocol.proto.ClientNamenodeProtocolProtos$ClientNamenodeProtocol$2.callBlockingMethod(ClientNamenodeProtocolProtos.java)
	at org.apache.hadoop.ipc.ProtobufRpcEngine$Server$ProtoBufRpcInvoker.call(ProtobufRpcEngine.java:523)
	at org.apache.hadoop.ipc.RPC$Server.call(RPC.java:991)
	at org.apache.hadoop.ipc.Server$RpcCall.run(Server.java:872)
	at org.apache.hadoop.ipc.Server$RpcCall.run(Server.java:818)
	at java.security.AccessController.doPrivileged(Native Method)
	at javax.security.auth.Subject.doAs(Subject.java:422)
	at org.apache.hadoop.security.UserGroupInformation.doAs(UserGroupInformation.java:1729)
	at org.apache.hadoop.ipc.Server$Handler.run(Server.java:2678)

	at org.apache.hadoop.service.ServiceStateException.convert(ServiceStateException.java:105)
	at org.apache.hadoop.service.AbstractService.start(AbstractService.java:203)
